Workbook
Name SegmentaciónDeDatos_Data: #N/A
Name SegmentaciónDeDatos_Linia_Negoci: #N/A

Sheet Agenda_05
A1: COMPTE DE RESULTATS 2026 | B1: Gener | C1: Febrer | D1: Març | E1: Abril | F1: Maig | G1: Juny | H1: Juliol | I1: Agost | J1: Setembre | K1: Octubre | L1: Novembre | M1: Desembre | N1: TOTAL
A2: . VENDES | B2: 11598.18 | C2: 13093.09 | D2: 22719.31 | E2: 19204.84 | F2: 34909.12 | N2: =SUM(B2:M2) -> 101524.54
A3: . PRESTACIO DE SEVEIS | B3: 0 | C3: 0 | D3: 0 | E3: 0 | F3: 0 | N3: =SUM(B3:M3) -> 0
A4: . ALTRES INGRESSOS | B4: 3004.21 | C4: 3004.21 | D4: 3004.21 | E4: 3004.21 | F4: 3004.21 | N4: =SUM(B4:M4) -> 15021.05
A5: . VARIACIO EXISTENCIES | B5: 0 | C5: 0 | D5: 0 | E5: 0 | F5: 0 | N5: =SUM(B5:M5) -> 0
A6: TOTAL INGRESSOS EXPLOTACIO | B6: =SUM(B2:B5) -> 14602.39 | C6: =SUM(C2:C5) -> 16097.3 | D6: =SUM(D2:D5) -> 25723.52 | E6: =SUM(E2:E5) -> 22209.05 | F6: =SUM(F2:F5) -> 37913.33 | G6: =SUM(G2:G5) -> 0 | H6: =SUM(H2:H5) -> 0 | I6: =SUM(I2:I5) -> 0 | ... M6: =SUM(M2:M5) -> 0 | N6: =SUM(B6:M6) -> 116545.59
A7: 0.25 | B7: =-$A$7*B6 -> -3650.5975 | C7: =-$A$7*C6 -> -4024.325 | D7: =-$A$7*D6 -> -6430.88 | E7: =-$A$7*E6 -> -5552.2625 | F7: =-$A$7*F6 -> -9478.3325
A8: . ALTRES APROVISIONAMENTS | B8: 84 | C8: 0 | D8: 0 | E8: 0 | F8: 0 | N8: =SUM(B8:M8) -> 84
A9: . VARIACIO EXISTENICIES COMPRES | B9: 0 | C9: 0 | D9: 0 | E9: 0 | F9: 0 | N9: =SUM(B9:M9) -> 0
A10: TOTAL COMPRES | B10: =B7+B8 -> -3566.5975 | C10: =C7+C8 -> -4024.325 | D10: =D7+D8 -> -6430.88 | E10: =E7+E8 -> -5552.2625 | F10: =F7+F8 -> -9478.3325 | G10: =G7+G8 -> 0 | H10: =H7+H8 -> 0 | I10: =I7+I8 -> 0 | ... M10: =M7+M8 -> 0 | N10: =SUM(B10:M10) -> -29052.397 | O10: =N10/$N$6 -> -0.24927925
A11: . SOUS I SALARIS | B11: -414614.43 | C11: -414827.96 | D11: -441884.46 | E11: -443403.37 | F11: -495789.03 | N11: =SUM(B11:M11) -> -2210519.2
A12: 0.15 | B12: =B6*-$A$12 -> -2190.3585 | C12: =C6*-$A$12 -> -2414.595 | D12: =D6*-$A$12 -> -3858.528 | E12: =E6*-$A$12 -> -3331.3575 | F12: =F6*-$A$12 -> -5686.9995 | G12: =G6*-$A$12 -> 0 | H12: =H6*-$A$12 -> 0 | I12: =I6*-$A$12 -> 0 | ... M12: =M6*-$A$12 -> 0 | N12: =SUM(B12:M12) -> -17481.838
A13: . ESTRUCTURA FIX | B13: -5000 | C13: -5000 | D13: -5000 | E13: -5000 | F13: -5000
A14: . INDEMNITZACIONS | B14: 0 | C14: 0 | D14: 0 | N14: =SUM(B14:M14) -> 0
A15: . SEGURETAT SOCIAL | N15: =SUM(B15:M15) -> 0
A16: . ALTRES DESPESES SOCIALS | N16: =SUM(B16:M16) -> 0
A17: TOTAL COST SALARIAL | B17: =SUM(B12:B16) -> -7190.3585 | C17: =SUM(C12:C16) -> -7414.595 | D17: =SUM(D12:D16) -> -8858.528 | E17: =SUM(E12:E16) -> -8331.3575 | F17: =SUM(F12:F16) -> -10686.999 | G17: =SUM(G11:G16) -> 0 | H17: =SUM(H11:H16) -> 0 | I17: =SUM(I11:I16) -> 0 | J17: =SUM(J11:J16) -> 0 | K17: =SUM(K11:K16) -> 0 | L17: =SUM(L11:L16) -> 0 | M17: =SUM(M11:M16) -> 0 | N17: =SUM(B17:M17) -> -42481.838 | O17: =N17/$N$6 -> -0.36450833
A18: TOTAL DESPESES GESTIO CENTRAL | B18: -79477.48 | C18: -65034.81 | D18: -100634.18 | E18: -133357.73 | F18: -131629.55 | N18: =SUM(B18:M18) -> -510133.75
A19: 0.1 | B19: =$A$19*B18 -> -7947.748 | C19: =$A$19*C18 -> -6503.481 | D19: =$A$19*D18 -> -10063.418 | E19: =$A$19*E18 -> -13335.773 | F19: =$A$19*F18 -> -13162.955 | G19: =$A$19*G18 -> 0 | H19: =$A$19*H18 -> 0 | I19: =$A$19*I18 -> 0 | ... M19: =$A$19*M18 -> 0
A20: TOTAL DESPESES GESTIO | B20: =SUM(B19) -> -7947.748 | C20: =SUM(C19) -> -6503.481 | D20: =SUM(D19) -> -10063.418 | E20: =SUM(E19) -> -13335.773 | F20: =SUM(F19) -> -13162.955 | G20: =SUM(G19) -> 0 | H20: =SUM(H19) -> 0 | I20: =SUM(I19) -> 0 | ... M20: =SUM(M19) -> 0 | N20: =SUM(B20:M20) -> -51013.375
A21: TOTAL GESTIO + SALARIS | B21: =B20+B17 -> -15138.106 | C21: =C20+C17 -> -13918.076 | D21: =D20+D17 -> -18921.946 | E21: =E20+E17 -> -21667.13 | F21: =F20+F17 -> -23849.954 | G21: =G20+G17 -> 0 | H21: =H20+H17 -> 0 | I21: =I20+I17 -> 0 | ... M21: =M20+M17 -> 0
A22: EBITDA | B22: =B6+(B10+B17+B20) -> -4102.314 | C22: =C6+(C10+C17+C20) -> -1845.101 | D22: =D6+(D10+D17+D20) -> 370.694 | E22: =E6+(E10+E17+E20) -> -5010.343 | F22: =F6+(F10+F17+F20) -> 4585.043 | G22: =G6+(G10+G17+G20) -> 0 | H22: =H6+(H10+H17+H20) -> 0 | I22: =I6+(I10+I17+I20) -> 0 | ... M22: =M6+(M10+M17+M20) -> 0 | N22: =SUM(B22:M22) -> -6002.021
A23: % | B23: =B22/B6 -> -0.28093442 | C23: =C22/C6 -> -0.11462177 | D23: =D22/D6 -> 0.014410703 | E23: =E22/E6 -> -0.22559916 | F23: =F22/F6 -> 0.12093485

Sheet Dades
A3: LN00000 | B3: PRECUINATS
A4: TOTAL INGRESSOS EXPLOTACIO | B4: Les sumen en el total, en el desglos de cada LN no ho tenim en compte
A5: TOTAL COMPRES | B5: Porcentatge repartim endtre les diferents LN
B6: En el total em de treure la compra interna de LN00001 sino estariem doblant valor
B7: Hem de restar del total el 45% sobre vendes de LN00004 i cal.lcular porcentatges en fucnio a de le svendes deñl 2025
A8: TOTAL COST SALARIAL | B8: Restem els 20.000 mensuals imputat ja en la LN00001
B9: Hem de veure quins departaments impliquen a totes les LN i en aquest fer la part % segons vendes del 2025
B10: El % que no implica a totes LN assignar a cada LN segon % vendes
A11: TOTAL DESPESES GESTIO
A13: LN00000 | B13: AGENDA
A14: TOTAL INGRESSOS EXPLOTACIO | B14: Vendes
A15: TOTAL COMPRES | B15: Imputem un fixe 25% sobre vendes
A16: TOTAL COST SALARIAL | B16: Imputem un fixe de 5000, d'estructura
B17: 10% de perosnal sobre vendes
A18: TOTAL DESPESES GESTIO | B18: Un fixe sobre els cosotso fixes de la central del 10%
A20: LN00001 | B20: RESTAURACIO
A21: TOTAL INGRESSOS EXPLOTACIO | B21: Ja te la seva propia C.Explotació.
A22: TOTAL COMPRES | B22: Restar de del total de compres el consum intern a les comprs de LN00000
A23: TOTAL COST SALARIAL | B23: S'hauria de fer els traspassos intenrs de les hores treallades fora de centre en una altre LN
A24: TOTAL DESPESES GESTIO | B24: Ja te imputades les seves pròpies
A26: LN00002 | B26: EMPRESA
A27: TOTAL INGRESSOS EXPLOTACIO
A28: TOTAL COMPRES | B28: % vendes del 2025 treient les vendes, LN0000, LN00001 , LN00006, LN00005 i LN00004 i aquest % sera el que aplicaem sobre la compra restant
A29: TOTAL COST SALARIAL | B29: % de vendes del 2025 excepte LN00001 sobre tots els departements
B30: Restar el 20.0000 de Restauracio i el % GreenVita
A31: TOTAL DESPESES GESTIO | B31: Restem el % LN00006
B32: % apliquem de les vendes del 2025
A34: LN00003 | B34: CASAMENTS
A35: TOTAL INGRESSOS EXPLOTACIO
A36: TOTAL COMPRES | B36: % vendes del 2025 treient les vendes, LN0000, LN00001 , LN00006, LN00005 i LN00004 i aquest % sera el que aplicaem sobre la compra restant
A37: TOTAL COST SALARIAL | B37: % de vendes del 2025 excepte LN00001 sobre tots els departements
B38: Restar el 20.0000 de Restauracio i els 10.000 GreenVita
A39: TOTAL DESPESES GESTIO | B39: Restem el % LN00006
B40: % apliquem de les vendes del 2025
A42: LN00004 | B42: PRECUINATS
A43: TOTAL INGRESSOS EXPLOTACIO | B43: S'ha d'aplicar el rappel del 2%
B44: Total sortira aquest 2% menys
A45: TOTAL COMPRES | B45: 45% sobre la facturacio
A46: TOTAL COST SALARIAL | B46: Imputem el cost empresa mensual de 1 treballador logistica 3500
B47: % de le vendes 2025 sobre departaments de RRHH. Comptabilitat, Compres, Cuina Central, Manteniment
...

Sheet Restaurants_05
A1: COMPTE DE RESULTATS 2026 | B1: Gener | C1: Febrer | D1: Març | E1: Abril | F1: Maig | G1: Juny | H1: Juliol | I1: Agost | J1: Setembre | K1: Octubre | L1: Novembre | M1: Desembre | N1: TOTAL
A2: . VENDES | B2: 387044.54 | C2: 451350.88 | D2: 581201.05 | E2: 570984.57 | F2: 640094.54 | N2: =SUM(B2:M2) -> 2630675.6
A3: . ALTRES | B3: 1069 | C3: 18189 | D3: 1100 | E3: 17092 | F3: 2185.44 | N3: =SUM(B3:M3) -> 39635.44
A4: . PRESTACIO DE SEVEIS | B4: 0 | C4: 0 | D4: 0 | E4: 0 | F4: 0 | N4: =SUM(B4:M4) -> 0
A5: . ALTRES INGRESSOS | B5: 4617.95 | C5: 4617.95 | D5: 4617.95 | E5: 4617.95 | F5: 4617.95 | N5: =SUM(B5:M5) -> 23089.75
A6: . VARIACIO EXISTENCIES | B6: 0 | C6: 0 | D6: 0 | E6: 0 | F6: 0 | N6: =SUM(B6:M6) -> 0
A7: TOTAL INGRESSOS EXPLOTACIO | B7: =SUM(B2:B6) -> 392731.49 | C7: =SUM(C2:C6) -> 474157.83 | D7: =SUM(D2:D6) -> 586919 | E7: =SUM(E2:E6) -> 592694.52 | F7: =SUM(F2:F6) -> 646897.93 | G7: =SUM(G2:G6) -> 0 | H7: =SUM(H2:H6) -> 0 | I7: =SUM(I2:I6) -> 0 | ... M7: =SUM(M2:M6) -> 0 | N7: =SUM(B7:M7) -> 2693400.8
A8: . COMPRES | B8: -83569.37 | C8: -102354.42 | D8: -119547.25 | E8: -125816.95 | F8: -129731.94 | N8: =SUM(B8:M8) -> -561019.93
A9: . ALTRES APROVISIONAMENTS | B9: -8313.31 | C9: -9250.55 | D9: -9342.87 | E9: -5630.13 | F9: -8068.66 | N9: =SUM(B9:M9) -> -40605.52
B10: =SUM(B8:B9) -> -91882.68 | C10: =SUM(C8:C9) -> -111604.97 | D10: =SUM(D8:D9) -> -128890.12 | E10: =SUM(E8:E9) -> -131447.08 | F10: =SUM(F8:F9) -> -137800.6 | N10: =SUM(B10:M10) -> -601625.45
A11: . CONSUMS INTERNS | B11: -38863.39 | C11: -37571.38 | D11: -53459.6 | E11: -68084.45 | F11: -74144.71 | N11: =SUM(B11:M11) -> -272123.53 | O11: =N11/N7 -> -0.10103343
A12: . VARIACIO EXISTENICIES COMPRES | B12: 0 | C12: 0 | D12: 0 | E12: 0 | F12: 0 | N12: =SUM(B12:M12) -> 0
A13: TOTAL COMPRES | B13: =SUM(B10:B12) -> -130746.07 | C13: =SUM(C10:C12) -> -149176.35 | D13: =SUM(D10:D12) -> -182349.72 | E13: =SUM(E10:E12) -> -199531.53 | F13: =SUM(F10:F12) -> -211945.31 | G13: =SUM(G8:G12) -> 0 | H13: =SUM(H8:H12) -> 0 | I13: =SUM(I8:I12) -> 0 | J13: =SUM(J8:J12) -> 0 | K13: =SUM(K8:K12) -> 0 | L13: =SUM(L8:L12) -> 0 | M13: =SUM(M8:M12) -> 0 | N13: =SUM(B13:M13) -> -873748.98 | O13: =N13/$N$7 -> -0.32440363
A14: . ESTRUCTURA FIX | B14: -20000 | C14: -20000 | D14: -20000 | E14: -20000 | F14: -20000 | N14: =SUM(B14:M14) -> -100000
A15: . SOUS I SALARIS | B15: =-240865.21 -> -240865.21 | C15: =-229230.19 -> -229230.19 | D15: =-253674.15 -> -253674.15 | E15: =-256915.37 -> -256915.37 | F15: =-253123.37 -> -253123.37 | N15: =SUM(B15:M15) -> -1233808.3
A16: . SALARIS | B16: -6442.71 | C16: 8493.25 | D16: -8727.71 | E16: -5870.32 | F16: -4972.41 | N16: =SUM(B16:M16) -> -17519.9
A17: . INDEMNITZACIONS | B17: -2000 | C17: -21000 | D17: 0 | E17: 0 | F17: -2200 | N17: =SUM(B17:M17) -> -25200
A18: . SEGURETAT SOCIAL | B18: -62895.34 | C18: -64940.94 | D18: -67531.7 | E18: -75595.64 | F18: -75385.48 | N18: =SUM(B18:M18) -> -346349.1
A19: . ALTRES DESPESES SOCIALS | B19: -2425.78 | C19: -1494.4 | D19: -1480.31 | E19: -2502.05 | F19: -1778.57 | N19: =SUM(B19:M19) -> -9681.11
A20: TOTAL COST SALARIAL | B20: =SUM(B14:B19) -> -334629.04 | C20: =SUM(C14:C19) -> -328172.28 | D20: =SUM(D14:D19) -> -351413.87 | E20: =SUM(E14:E19) -> -360883.38 | F20: =SUM(F14:F19) -> -357459.83 | G20: =SUM(G14:G19) -> 0 | H20: =SUM(H14:H19) -> 0 | I20: =SUM(I14:I19) -> 0 | ... M20: =SUM(M14:M19) -> 0 | N20: =SUM(B20:M20) -> -1732558.4 | O20: =N20/$N$7 -> -0.64326053
A21: . ARRENDAMENTS I CANONS | B21: -24126.84 | C21: -31160.25 | D21: -34984.2 | E21: -45678.55 | F21: -44091.64 | N21: =SUM(B21:M21) -> -180041.48
A22: . REPARACIONS I CONSERVACIO | B22: -15891.89 | C22: -11100.92 | D22: -18424.79 | E22: -18690.59 | F22: -16432.73 | N22: =SUM(B22:M22) -> -80540.92
A23: . SERVEIS PROFESSIONALS | B23: -1882.99 | C23: -1712.87 | D23: -2627.16 | E23: -2317.08 | F23: -6583.63 | N23: =SUM(B23:M23) -> -15123.73
A24: . SERVEIS PROFESSIONALS | C24: -415 | D24: -710 | E24: -280 | F24: -200
A25: . TRANSPORTS | B25: -350 | C25: 0 | D25: -25.2 | E25: 0 | F25: 0 | N25: =SUM(B25:M25) -> -375.2
A26: . PRIMES D'ASSEGURANCES | B26: -1513.17 | C26: -1417.17 | D26: -1417.17 | E26: -1417.17 | F26: -1417.17 | N26: =SUM(B26:M26) -> -7181.85
A27: . SERVEIS BANCARIS | B27: -1572.02 | C27: -2033.07 | D27: -2931.03 | E27: -3147.63 | F27: -2927.84 | N27: =SUM(B27:M27) -> -12611.59
A28: . PUBLICITAT I PROPAGANDA | B28: -933.97 | C28: -323.96 | D28: -1628.25 | E28: -1839.79 | F28: -810.74 | N28: =SUM(B28:M28) -> -5536.71
A29: . SUBMINISTRAMENTS | B29: -22044.31 | C29: -17620.1 | D29: -18511.09 | E29: -21222.18 | F29: -18492.4 | N29: =SUM(B29:M29) -> -97890.08
A30: . ALTRES DESPESES | B30: -8766.98 | C30: -16450.01 | D30: -18198.81 | E30: -12204.85 | F30: -8652.39 | N30: =SUM(B30:M30) -> -64273.04
A31: . ALTRES TRIBUTS | B31: -3010.38 | C31: -2533.33 | D31: -2533.33 | E31: -2879.9 | F31: -2891.37 | N31: =SUM(B31:M31) -> -13848.31
A32: . DOTACIO PER INSOLVENCIA | B32: 0 | C32: 0 | D32: 0 | E32: 0 | F32: 0 | N32: =SUM(B32:M32) -> 0
A33: MOVIMENTS INTERNS | B33: 0 | C33: 0 | D33: 0 | E33: 0 | F33: 0 | N33: =SUM(B33:M33) -> 0
A34: TOTAL DESPESES GESTIO | B34: =SUM(B21:B33) -> -80092.55 | C34: =SUM(C21:C33) -> -84766.68 | D34: =SUM(D21:D33) -> -101991.03 | E34: =SUM(E21:E33) -> -109677.74 | F34: =SUM(F21:F33) -> -102499.91 | G34: =SUM(G21:G33) -> 0 | H34: =SUM(H21:H33) -> 0 | I34: =SUM(I21:I33) -> 0 | ... M34: =SUM(M21:M33) -> 0 | N34: =SUM(B34:M34) -> -479027.91 | O34: =N34/$N$7 -> -0.17785244
A35: TOTAL GESTIO + SALARIS | B35: =B34+B20 -> -414721.59 | C35: =C34+C20 -> -412938.96 | D35: =D34+D20 -> -453404.9 | E35: =E34+E20 -> -470561.12 | F35: =F34+F20 -> -459959.74 | G35: =G34+G20 -> 0 | H35: =H34+H20 -> 0 | I35: =I34+I20 -> 0 | ... M35: =M34+M20 -> 0 | N35: =SUM(B35:M35) -> -2211586.3
A36: EBITDA | B36: =B7+(B13+B20+B34) -> -152736.17 | C36: =C7+(C13+C20+C34) -> -87957.48 | D36: =D7+(D13+D20+D34) -> -48835.62 | E36: =E7+(E13+E20+E34) -> -77398.13 | F36: =F7+(F13+F20+F34) -> -25007.12 | G36: =G7+(G13+G20+G34) -> 0 | H36: =H7+(H13+H20+H34) -> 0 | I36: =I7+(I13+I20+I34) -> 0 | ... M36: =M7+(M13+M20+M34) -> 0 | N36: =SUM(B36:M36) -> -391934.52
A37: % | B37: =B36/B7 -> -0.38890737 | C37: =C36/C7 -> -0.18550254 | D37: =D36/D7 -> -0.083206746 | E37: =E36/E7 -> -0.13058688 | F37: =F36/F7 -> -0.038656979 | N37: =N36/N7 -> -0.1455166

Sheet Empresa_05
A1: COMPTE DE RESULTATS 2026 | B1: Gener | C1: Febrer | D1: Març | E1: Abril | F1: Maig | G1: Juny | H1: Juliol | I1: Agost | J1: Setembre | K1: Octubre | L1: Novembre | M1: Desembre | N1: TOTAL
A2: . VENDES | B2: 289300.57 | C2: 522944.53 | D2: 693442.52 | E2: 532165.29 | F2: 1272615.1 | N2: =SUM(B2:M2) -> 3310468
A3: . PRESTACIO DE SEVEIS | B3: 0 | C3: 0 | D3: 0 | E3: 0 | F3: 0 | N3: =SUM(B3:M3) -> 0
A4: . ALTRES INGRESSOS | B4: 0 | C4: 0 | D4: 0 | E4: 0 | F4: 0 | N4: =SUM(B4:M4) -> 0
A5: . VARIACIO EXISTENCIES | B5: 0 | C5: 0 | D5: 0 | E5: 0 | F5: 0 | N5: =SUM(B5:M5) -> 0
A6: TOTAL INGRESSOS EXPLOTACIO | B6: =SUM(B2:B5) -> 289300.57 | C6: =SUM(C2:C5) -> 522944.53 | D6: =SUM(D2:D5) -> 693442.52 | E6: =SUM(E2:E5) -> 532165.29 | F6: =SUM(F2:F5) -> 1272615.1 | G6: =SUM(G2:G5) -> 0 | H6: =SUM(H2:H5) -> 0 | I6: =SUM(I2:I5) -> 0 | ... M6: =SUM(M2:M5) -> 0 | N6: =SUM(B6:M6) -> 3310468
A7: . COMPRES | B7: -64 | C7: 0 | D7: 0 | E7: -253.4 | F7: -497.64 | N7: =SUM(B7:M7) -> -815.04
A8: . ALTRES APROVISIONAMENTS | B8: -1275.3 | C8: -802.97 | D8: -558.52 | E8: -2165.52 | F8: -478.97 | N8: =SUM(B8:M8) -> -5281.28
A9: . COMPRA LN00000 | B9: -408725.23 | C9: -510110.91 | D9: -622510.5 | E9: -536165.77 | F9: -727844.97 | N9: =SUM(B9:M9) -> -2805357.4
A10: Precuinats | B10: =Precuinats_05!B11 -> -248909.16 | C10: =Precuinats_05!C11 -> -226949.34 | D10: =Precuinats_05!D11 -> -246027.31 | E10: =Precuinats_05!E11 -> -258992.74 | F10: =Precuinats_05!F11 -> -247173 | G10: =Precuinats_05!G11 -> 0 | H10: =Precuinats_05!H11 -> 0 | I10: =Precuinats_05!I11 -> 0 | ... M10: =Precuinats_05!M11 -> 0 | N10: =SUM(B10:M10) -> -1228051.6
A11: Green Vita | B11: ='Green Vita_05'!B8 -> -10867.987 | C11: ='Green Vita_05'!C8 -> -24849.577 | D11: ='Green Vita_05'!D8 -> -27767.548 | E11: ='Green Vita_05'!E8 -> -17762.685 | F11: ='Green Vita_05'!F8 -> -22083.3 | G11: ='Green Vita_05'!G8 -> 0 | H11: ='Green Vita_05'!H8 -> 0 | I11: ='Green Vita_05'!I8 -> 0 | ... M11: ='Green Vita_05'!M8 -> 0 | N11: =SUM(B11:M11) -> -103331.1
A12: Agenda | B12: =Agenda_05!B10 -> -3566.5975 | C12: =Agenda_05!C10 -> -4024.325 | D12: =Agenda_05!D10 -> -6430.88 | E12: =Agenda_05!E10 -> -5552.2625 | F12: =Agenda_05!F10 -> -9478.3325 | G12: =Agenda_05!G10 -> 0 | H12: =Agenda_05!H10 -> 0 | I12: =Agenda_05!I10 -> 0 | ... M12: =Agenda_05!M10 -> 0 | N12: =SUM(B12:M12) -> -29052.397
A13: Foodlovers | B13: =Foodlovers_05!B7 -> -267.12 | C13: =Foodlovers_05!C7 -> -11688.172 | D13: =Foodlovers_05!D7 -> -16802.674 | E13: =Foodlovers_05!E7 -> -34620.922 | F13: =Foodlovers_05!F7 -> -47688.346 | G13: =Foodlovers_05!G7 -> 0 | H13: =Foodlovers_05!H7 -> 0 | I13: =Foodlovers_05!I7 -> 0 | ... M13: =Foodlovers_05!M7 -> 0 | N13: =SUM(B13:M13) -> -111067.23
B14: =B9-(B10+B11+B12+B13) -> -145114.37 | C14: =C9-(C10+C11+C12+C13) -> -242599.5 | D14: =D9-(D10+D11+D12+D13) -> -325482.09 | E14: =E9-(E10+E11+E12+E13) -> -219237.16 | F14: =F9-(F10+F11+F12+F13) -> -401421.99 | G14: =G9-(G10+G11+G12+G13) -> 0 | H14: =H9-(H10+H11+H12+H13) -> 0 | I14: =I9-(I10+I11+I12+I13) -> 0 | ... M14: =M9-(M10+M11+M12+M13) -> 0 | N14: =SUM(B14:M14) -> -1333855.1
A15: Pestanya dades % aplicar | B15: =B14*Dades!C120 -> -133008.25 | C15: =C14*Dades!E120 -> -223258.99 | D15: =D14*Dades!G120 -> -289591.7 | E15: =E14*Dades!I120 -> -156550.6 | F15: =F14*Dades!K120 -> -258342.72 | G15: =G14*Dades!L120 -> 0 | I15: =I14*Dades!N120 -> 0 | J15: =J14*Dades!O120 -> 0 | K15: =K14*Dades!P120 -> 0 | L15: =L14*Dades!Q120 -> 0 | M15: =M14*Dades!R120 -> 0 | N15: =N14*Dades!S120 -> 0
A16: TOTAL COMPRES | B16: =B7+B8+B15 -> -134347.55 | C16: =C7+C8+C15 -> -224061.96 | D16: =D7+D8+D15 -> -290150.22 | E16: =E7+E8+E15 -> -158969.52 | F16: =F7+F8+F15 -> -259319.33 | G16: =SUM(G7:G15) -> 0 | H16: =SUM(H7:H15) -> 0 | I16: =SUM(I7:I15) -> 0 | J16: =SUM(J7:J15) -> 0 | K16: =SUM(K7:K15) -> 0 | L16: =SUM(L7:L15) -> 0 | M16: =SUM(M7:M15) -> 0 | N16: =SUM(B16:M16) -> -1066848.6 | O16: =N16/$N$6 -> -0.32226519
A17: . ESTRUCTURA LN00000 | B17: -532718.66 | C17: -537228.61 | D17: -580718.51 | E17: -607883.8 | F17: -646229.83 | N17: =SUM(B17:M17) -> -2904779.4
A18: Restem LN0001 | B18: -20000 | C18: -20000 | D18: -20000 | E18: -20000 | F18: -20000 | N18: =SUM(B18:M18) -> -100000
A19: Restem Green Vita | B19: ='Green Vita_05'!B14 -> -11520.792 | C19: ='Green Vita_05'!C14 -> -19909.747 | D19: ='Green Vita_05'!D14 -> -21660.529 | E19: ='Green Vita_05'!E14 -> -15657.611 | F19: ='Green Vita_05'!F14 -> -18249.98 | G19: ='Green Vita_05'!G14 -> 0 | H19: ='Green Vita_05'!H14 -> 0 | I19: ='Green Vita_05'!I14 -> 0 | ... M19: ='Green Vita_05'!M14 -> 0 | N19: =SUM(B19:M19) -> -86998.659
A20: Foodlovers | B20: =Foodlovers_05!B13 -> -5162.18 | C20: =Foodlovers_05!C13 -> -12096.39 | D20: =Foodlovers_05!D13 -> -15201.624 | E20: =Foodlovers_05!E13 -> -26019.845 | F20: =Foodlovers_05!F13 -> -33953.638 | G20: =Foodlovers_05!G13 -> 0 | H20: =Foodlovers_05!H13 -> 0 | I20: =Foodlovers_05!I13 -> 0 | ... M20: =Foodlovers_05!M13 -> 0 | N20: =SUM(B20:M20) -> -92433.677
A21: Agenda | B21: =Agenda_05!B17 -> -7190.3585 | C21: =Agenda_05!C17 -> -7414.595 | D21: =Agenda_05!D17 -> -8858.528 | E21: =Agenda_05!E17 -> -8331.3575 | F21: =Agenda_05!F17 -> -10686.999 | G21: =Agenda_05!G17 -> 0 | H21: =Agenda_05!H17 -> 0 | I21: =Agenda_05!I17 -> 0 | ... M21: =Agenda_05!M17 -> 0 | N21: =SUM(B21:M21) -> -42481.838
B22: =B18+B19+B20+B21 -> -43873.331 | C22: =C18+C19+C20+C21 -> -59420.731 | D22: =D18+D19+D20+D21 -> -65720.68 | E22: =E18+E19+E20+E21 -> -70008.814 | F22: =F18+F19+F20+F21 -> -82890.618 | G22: =G18+G19+G20+G21 -> 0 | H22: =H18+H19+H20+H21 -> 0 | I22: =I18+I19+I20+I21 -> 0 | ... M22: =M18+M19+M20+M21 -> 0 | N22: =SUM(B22:M22) -> -321914.17
A23: Pestanya dades % aplicar | B23: =(B17-B22)*Dades!C125 -> -162786.8 | C23: =(C17-C22)*Dades!E125 -> -232959.27 | D23: =(D17-D22)*Dades!G125 -> -269299.72 | E23: =(E17-E22)*Dades!I125 -> -216716.54 | F23: =(F17-F22)*Dades!K125 -> -283734.48 | G23: =(G17-G22)*Dades!H125 -> 0 | H23: =(H17-H22)*Dades!I125 -> 0 | I23: =(I17-I22)*Dades!J125 -> 0 | J23: =(J17-J22)*Dades!K125 -> 0 | K23: =(K17-K22)*Dades!L125 -> 0 | M23: =(M17-M22)*Dades!N125 -> 0 | N23: =SUM(B23:M23) -> -1165496.8
A24: . SOUS I SALARIS dept. | B24: -22116.05 | C24: -18130.26 | D24: -22980.88 | E24: -23486.13 | F24: -24690.8 | N24: =SUM(B24:M24) -> -111404.12
B25: -2589.05 | C25: -4174.93 | D25: -8686.08 | E25: -10808.41 | F25: -25630.83 | N25: =SUM(B25:M25) -> -51889.3
A26: Pestanya dades % aplicar | B26: =B25*Dades!$C$120 -> -2373.0594 | C26: =C25*Dades!$E$120 -> -3842.0964 | D26: =D25*Dades!$G$120 -> -7728.28 | E26: =E25*Dades!$I$120 -> -7717.9576 | F26: =F25*Dades!$K$120 -> -16495.206 | G26: =G25*Dades!$C$120 -> 0 | H26: =H25*Dades!$C$120 -> 0 | I26: =I25*Dades!$C$120 -> 0 | J26: =J25*Dades!$C$120 -> 0 | K26: =K25*Dades!$C$120 -> 0 | L26: =L25*Dades!$C$120 -> 0 | M26: =M25*Dades!$C$120 -> 0 | N26: =SUM(B26:M26) -> -38156.599
A27: . TRASPASSOS INTERNS | N27: =SUM(B27:M27) -> 0
A28: . INDEMNITZACIONS | B28: 0 | C28: 0 | D28: 0 | E28: 0 | F28: 0 | N28: =SUM(B28:M28) -> 0
A29: . SEGURETAT SOCIAL | B29: -7063.2 | C29: -5963.44 | D29: -7214.03 | E29: -7630.44 | F29: -7736.57 | N29: =SUM(B29:M29) -> -35607.68
A30: . ALTRES DESPESES SOCIALS | B30: -329.83 | C30: -375.09 | D30: -52.52 | E30: -218.24 | F30: -238.9 | N30: =SUM(B30:M30) -> -1214.58
A31: TOTAL COST SALARIAL | B31: =B23+B24+B26+B29+B30 -> -194668.94 | C31: =C23+C24+C26+C29+C30 -> -261270.16 | D31: =D23+D24+D26+D29+D30 -> -307275.43 | E31: =E23+E24+E26+E29+E30 -> -255769.31 | F31: =F23+F24+F26+F29+F30 -> -332895.95 | G31: =G23+G24+G26+G29+G30 -> 0 | H31: =H23+H24+H26+H29+H30 -> 0 | I31: =I23+I24+I26+I29+I30 -> 0 | ... M31: =M23+M24+M26+M29+M30 -> 0 | N31: =SUM(B31:M31) -> -1351879.8 | O31: =N31/$N$6 -> -0.40836516
A32: . GESTIO DE LN00000 | B32: -79477.48 | C32: -65034.81 | D32: -100634.18 | E32: -133354.73 | F32: -131629.55
A33: 0.44 | B33: =$A$33*B32 -> -34970.091 | C33: =$A$33*C32 -> -28615.316 | D33: =$A$33*D32 -> -44279.039 | E33: =$A$33*E32 -> -58676.081 | F33: =$A$33*F32 -> -57917.002
A34: . ARRENDAMENTS I CANONS | B34: -1857.14 | C34: -12920.01 | D34: -22596.34 | E34: -24236.09 | F34: -28175.89 | N34: =SUM(B34:M34) -> -89785.47
A35: . REPARACIONS I CONSERVACIO | B35: -520.83 | C35: -4988.08 | D35: -2969.32 | E35: -3469.82 | F35: -412.78 | N35: =SUM(B35:M35) -> -12360.83
A36: . SERVEIS PROFESSIONALS | B36: -11590.09 | C36: -34114.73 | D36: -52997.76 | E36: -21287.48 | F36: -77626.68 | N36: =SUM(B36:M36) -> -197616.74
A37: . TRANSPORTS | B37: -186.85 | C37: -376.97 | D37: -81.79 | E37: -86.5 | F37: -134.26 | N37: =SUM(B37:M37) -> -866.37
A38: . PRIMES D'ASSEGURANCES | B38: -96 | C38: 0 | D38: 0 | E38: 0 | F38: 0 | N38: =SUM(B38:M38) -> -96
A39: . SERVEIS BANCARIS | B39: -59.26 | C39: -108.3 | D39: -413.62 | E39: -747.22 | F39: -202.08 | N39: =SUM(B39:M39) -> -1530.48
A40: . PUBLICITAT I PROPAGANDA | B40: -5629.55 | C40: -1265.91 | D40: -3506.86 | E40: -5083.88 | F40: -186.99 | N40: =SUM(B40:M40) -> -15673.19
...

Sheet Casaments_05
A1: COMPTE DE RESULTATS 2026 | B1: Gener | C1: Febrer | D1: Març | E1: Abril | F1: Maig | G1: Juny | H1: Juliol | I1: Agost | J1: Setembre | K1: Octubre | L1: Novembre | M1: Desembre | N1: TOTAL
A2: . VENDES | B2: 19110.49 | C2: 33824.11 | D2: 85941.41 | E2: 197120.54 | F2: 628068.27 | N2: =SUM(B2:M2) -> 964064.82
A3: . ALTRES | B3: 7221 | C3: 11477.6 | E3: 14471 | F3: 68830.62 | N3: =SUM(B3:M3) -> 102000.22
A4: . PRESTACIO DE SEVEIS | B4: 0 | C4: 0 | D4: 0 | E4: 0 | F4: 0 | N4: =SUM(B4:M4) -> 0
A5: . ALTRES INGRESSOS | B5: 0 | C5: 0 | D5: 0 | E5: 1500 | F5: 3870 | N5: =SUM(B5:M5) -> 5370
A6: . INGRESSOS | F6: 4050 | N6: =SUM(B6:M6) -> 4050
A7: . VARIACIO EXISTENCIES | B7: 0 | C7: 0 | D7: 0 | E7: 0 | F7: 0 | N7: =SUM(B7:M7) -> 0
A8: TOTAL INGRESSOS EXPLOTACIO | B8: =SUM(B2:B7) -> 26331.49 | C8: =SUM(C2:C7) -> 45301.71 | D8: =SUM(D2:D7) -> 85941.41 | E8: =SUM(E2:E7) -> 213091.54 | F8: =SUM(F2:F7) -> 704818.89 | G8: =SUM(G2:G7) -> 0 | H8: =SUM(H2:H7) -> 0 | I8: =SUM(I2:I7) -> 0 | ... M8: =SUM(M2:M7) -> 0 | N8: =SUM(B8:M8) -> 1075485
A9: . COMPRA LN00000 s/precuintas | B9: -408725.23 | C9: -510110.91 | D9: -622510.5 | E9: -536165.77 | F9: -727844.97 | N9: =SUM(B9:M9) -> -2805357.4
A10: Precuinats | B10: =Precuinats_05!B11 -> -248909.16 | C10: =Precuinats_05!C11 -> -226949.34 | D10: =Precuinats_05!D11 -> -246027.31 | E10: =Precuinats_05!E11 -> -258992.74 | F10: =Precuinats_05!F11 -> -247173 | G10: =Precuinats_05!G11 -> 0 | H10: =Precuinats_05!H11 -> 0 | I10: =Precuinats_05!I11 -> 0 | ... M10: =Precuinats_05!M11 -> 0 | N10: =SUM(B10:M10) -> -1228051.6
A11: Green Vita | B11: ='Green Vita_05'!B8 -> -10867.987 | C11: ='Green Vita_05'!C8 -> -24849.577 | D11: ='Green Vita_05'!D8 -> -27767.548 | E11: ='Green Vita_05'!E8 -> -17762.685 | F11: ='Green Vita_05'!F8 -> -22083.3 | G11: ='Green Vita_05'!G8 -> 0 | H11: ='Green Vita_05'!H8 -> 0 | I11: ='Green Vita_05'!I8 -> 0 | ... M11: ='Green Vita_05'!M8 -> 0 | N11: =SUM(B11:M11) -> -103331.1
A12: Agenda | B12: =Agenda_05!B10 -> -3566.5975 | C12: =Agenda_05!C10 -> -4024.325 | D12: =Agenda_05!D10 -> -6430.88 | E12: =Agenda_05!E10 -> -5552.2625 | F12: =Agenda_05!F10 -> -9478.3325 | G12: =Agenda_05!G10 -> 0 | H12: =Agenda_05!H10 -> 0 | I12: =Agenda_05!I10 -> 0 | ... M12: =Agenda_05!M10 -> 0 | N12: =SUM(B12:M12) -> -29052.397
A13: Foodlovers | B13: =Foodlovers_05!B7 -> -267.12 | C13: =Foodlovers_05!C7 -> -11688.172 | D13: =Foodlovers_05!D7 -> -16802.674 | E13: =Foodlovers_05!E7 -> -34620.922 | F13: =Foodlovers_05!F7 -> -47688.346 | G13: =Foodlovers_05!G7 -> 0 | H13: =Foodlovers_05!H7 -> 0 | I13: =Foodlovers_05!I7 -> 0 | ... M13: =Foodlovers_05!M7 -> 0 | N13: =SUM(B13:M13) -> -111067.23
B14: =B9-(B10+B11+B12+B13) -> -145114.37 | C14: =C9-(C10+C11+C12+C13) -> -242599.5 | D14: =D9-(D10+D11+D12+D13) -> -325482.09 | E14: =E9-(E10+E11+E12+E13) -> -219237.16 | F14: =F9-(F10+F11+F12+F13) -> -401421.99 | G14: =G9-(G10+G11+G12+G13) -> 0 | H14: =H9-(H10+H11+H12+H13) -> 0 | I14: =I9-(I10+I11+I12+I13) -> 0 | ... M14: =M9-(M10+M11+M12+M13) -> 0 | N14: =SUM(B14:M14) -> -1333855.1
A15: Pestanya dades % aplicar | B15: =Dades!C121*B14 -> -12106.113 | C15: =Dades!E121*C14 -> -19340.51 | D15: =Dades!G121*D14 -> -35890.385 | E15: =Dades!I121*E14 -> -62686.555 | F15: =Dades!K121*F14 -> -143079.27 | G15: =Dades!L121*G14 -> 0 | I15: =Dades!N121*I14 -> 0 | J15: =Dades!O121*J14 -> 0 | K15: =Dades!P121*K14 -> 0 | L15: =Dades!Q121*L14 -> 0 | M15: =Dades!R121*M14 -> 0 | N15: =SUM(B15:M15) -> -273102.83
A16: . COMPRES | B16: -35 | C16: 0 | D16: 0 | E16: 0 | F16: -1472.78 | N16: =SUM(B16:M16) -> -1507.78
A17: . ALTRES APROVISIONAMENTS | B17: -494.07 | C17: -70.69 | D17: -700.47 | E17: -1110.1 | F17: -352.88 | N17: =SUM(B17:M17) -> -2728.21
A18: . APROVISIONAMENTS | E18: -53.52
A19: TOTAL COMPRES | B19: =SUM(B15:B17) -> -12635.183 | C19: =SUM(C15:C17) -> -19411.2 | D19: =SUM(D15:D17) -> -36590.855 | E19: =SUM(E15:E18) -> -63850.175 | F19: =SUM(F15:F17) -> -144904.93 | G19: =SUM(G16:G17) -> 0 | H19: =SUM(H16:H17) -> 0 | I19: =SUM(I16:I17) -> 0 | J19: =SUM(J16:J17) -> 0 | K19: =SUM(K16:K17) -> 0 | L19: =SUM(L16:L17) -> 0 | M19: =SUM(M16:M17) -> 0 | N19: =SUM(B19:M19) -> -277392.34 | O19: =N19/$N$8 -> -0.25792301
A20: . ESTRUCTURA LN00000 | B20: -532718.66 | C20: -537228.61 | D20: -580718.51 | E20: -607883.8 | F20: -646229.83 | N20: =SUM(B20:M20) -> -2904779.4
A21: Restem LN0001 | B21: -20000 | C21: -20000 | D21: -20000 | E21: -20000 | F21: -20000 | N21: =SUM(B21:M21) -> -100000
A22: Restem Green Vita | B22: ='Green Vita_05'!B20 -> -24563.585 | C22: ='Green Vita_05'!C20 -> -43419.493 | D22: ='Green Vita_05'!D20 -> -46702.057 | E22: ='Green Vita_05'!E20 -> -32602.222 | F22: ='Green Vita_05'!F20 -> -48606.81 | G22: ='Green Vita_05'!G20 -> 0 | H22: ='Green Vita_05'!H20 -> 0 | I22: ='Green Vita_05'!I20 -> 0 | ... M22: ='Green Vita_05'!M20 -> 0 | N22: =SUM(B22:M22) -> -195894.17
A23: Foodlovers | B23: =Foodlovers_05!B20 -> -14082.14 | C23: =Foodlovers_05!C20 -> -24870.01 | D23: =Foodlovers_05!D20 -> -28128.894 | E23: =Foodlovers_05!E20 -> -43343.766 | F23: =Foodlovers_05!F20 -> -48756.348 | G23: =Foodlovers_05!G20 -> 0 | H23: =Foodlovers_05!H20 -> 0 | I23: =Foodlovers_05!I20 -> 0 | ... M23: =Foodlovers_05!M20 -> 0 | N23: =SUM(B23:M23) -> -159181.16
A24: Agenda | B24: =Agenda_05!B17 -> -7190.3585 | C24: =Agenda_05!C17 -> -7414.595 | D24: =Agenda_05!D17 -> -8858.528 | E24: =Agenda_05!E17 -> -8331.3575 | F24: =Agenda_05!F17 -> -10686.999 | G24: =Agenda_05!G17 -> 0 | H24: =Agenda_05!H17 -> 0 | I24: =Agenda_05!I17 -> 0 | ... M24: =Agenda_05!M17 -> 0 | N24: =SUM(B24:M24) -> -42481.838
B25: =B21+B22+B23+B24 -> -65836.083 | C25: =C21+C22+C23+C24 -> -95704.098 | D25: =D21+D22+D23+D24 -> -103689.48 | E25: =E21+E22+E23+E24 -> -104277.35 | F25: =F21+F22+F23+F24 -> -128050.16 | G25: =G21+G22+G23+G24 -> 0 | H25: =H21+H22+H23+H24 -> 0 | I25: =I21+I22+I23+I24 -> 0 | ... M25: =M21+M22+M23+M24 -> 0 | N25: =SUM(B25:M25) -> -497557.16
A26: Pestanya dades % aplicar | B26: =(B20-B25)*Dades!C126 -> -14150.817 | C26: =(C20-C25)*Dades!E126 -> -18648.353 | D26: =(D20-D25)*Dades!G126 -> -30914.862 | E26: =(E20-E25)*Dades!I126 -> -81249.681 | F26: =(F20-F25)*Dades!K126 -> -144544.97 | G26: =(G20-G25)*Dades!H126 -> 0 | H26: =(H20-H25)*Dades!I126 -> 0 | I26: =(I20-I25)*Dades!J126 -> 0 | J26: =(J20-J25)*Dades!K126 -> 0 | K26: =(K20-K25)*Dades!L126 -> 0 | M26: =(M20-M25)*Dades!N126 -> 0 | N26: =SUM(B26:M26) -> -289508.68
A27: . SOUS I SALARIS dept. | B27: -14593.57 | C27: -14965.37 | D27: -15581.39 | E27: -16901.53 | F27: -18629.55 | N27: =SUM(B27:M27) -> -80671.41
B28: -2589.05 | C28: -4174.93 | D28: -8686.08 | E28: -10808.41 | F28: -25630.83 | N28: =SUM(B28:M28) -> -51889.3
A29: Pestanya dades % aplicar | B29: =B28*Dades!C121 -> -215.99056 | C29: =C28*Dades!$E$121 -> -332.83365 | D29: =D28*Dades!$G$121 -> -957.80004 | E29: =E28*Dades!$I$121 -> -3090.4524 | F29: =F28*Dades!$K$121 -> -9135.624 | G29: =G28*Dades!$C$121 -> 0 | H29: =H28*Dades!$C$121 -> 0 | I29: =I28*Dades!$C$121 -> 0 | J29: =J28*Dades!$C$121 -> 0 | K29: =K28*Dades!$C$121 -> 0 | L29: =L28*Dades!$C$121 -> 0 | M29: =M28*Dades!$C$121 -> 0 | N29: =SUM(B29:M29) -> -13732.701
A30: . INDEMNITZACIONS | B30: 0 | C30: 0 | D30: 0 | E30: 0 | F30: 0 | N30: =SUM(B30:M30) -> 0
A31: . SEGURETAT SOCIAL | B31: -4626.15 | C31: -4451.84 | D31: -4671.13 | E31: -5328.14 | F31: -5253.39 | N31: =SUM(B31:M31) -> -24330.65
A32: . ALTRES DESPESES SOCIALS | B32: 0 | C32: -126 | D32: -517.12 | E32: -199.96 | F32: -202.5 | N32: =SUM(B32:M32) -> -1045.58
A33: TOTAL COST SALARIAL | B33: =B26+B27+B29+B31+B32+B30 -> -33586.528 | C33: =C26+C27+C29+C31+C32+C30 -> -38524.397 | D33: =D26+D27+D29+D31+D32+D30 -> -52642.302 | E33: =E26+E27+E29+E31+E32+E30 -> -106769.76 | F33: =F26+F27+F29+F31+F32+F30 -> -177766.03 | G33: =G26+G27+G29+G31+G32+G30 -> 0 | H33: =H26+H27+H29+H31+H32+H30 -> 0 | I33: =I26+I27+I29+I31+I32+I30 -> 0 | ... M33: =M26+M27+M29+M31+M32+M30 -> 0 | N33: =SUM(B33:M33) -> -409289.02 | O33: =N33/$N$8 -> -0.38056226
A34: . GESTIO DE LN00000 | B34: -79477.48 | C34: -65034.81 | D34: -100634.18 | E34: -133354.73 | F34: -131629.55
A35: =Dades!R77 -> 0.14 | B35: =$A$35*B34 -> -11126.847 | C35: =$A$35*C34 -> -9104.8734 | D35: =$A$35*D34 -> -14088.785 | E35: =$A$35*E34 -> -18669.662 | F35: =$A$35*F34 -> -18428.137
A36: . ARRENDAMENTS I CANONS | B36: -24238.12 | C36: -25118.02 | D36: -26499.01 | E36: -26682.33 | F36: -25826.93 | N36: =SUM(B36:M36) -> -128364.41
A37: . REPARACIONS I CONSERVACIO | B37: -299.81 | C37: 0 | D37: -485.07 | E37: -670.45 | F37: -669.71 | N37: =SUM(B37:M37) -> -2125.04
A38: . SERVEIS PROFESSIONALS | B38: 0 | C38: -2286.08 | D38: -2322.8 | E38: -8013.02 | F38: -18171.29 | N38: =SUM(B38:M38) -> -30793.19
A39: . SERVEIS PROFESSIONALS | D39: -175 | E39: -630 | F39: -1830
A40: . TRANSPORTS | B40: 0 | C40: -1.2 | D40: 0 | E40: 0 | F40: 0 | N40: =SUM(B40:M40) -> -1.2
...

Sheet Precuinats_05
A1: COMPTE DE RESULTATS 2026 | B1: Gener | C1: Febrer | D1: Març | E1: Abril | F1: Maig | G1: Juny | H1: Juliol | I1: Agost | J1: Setembre | K1: Octubre | L1: Novembre | M1: Desembre | N1: TOTAL
A2: . VENDES | B2: 553131.46 | C2: 504331.86 | D2: 546727.36 | E2: 575539.43 | F2: 549273.34 | N2: =SUM(B2:M2) -> 2729003.4
A3: . RAPPEL 2% | B3: =-B2*0.02 -> -11062.629 | C3: =-C2*0.02 -> -10086.637 | D3: =-D2*0.02 -> -10934.547 | E3: =-E2*0.02 -> -11510.789 | F3: =-F2*0.02 -> -10985.467 | N3: =SUM(B3:M3) -> -54580.069
A4: . ALTRES INGRESSOS | B4: 0 | C4: 0 | D4: 0 | E4: 0 | F4: 0 | N4: =SUM(B4:M4) -> 0
A5: . VARIACIO EXISTENCIES | B5: 0 | C5: 0 | D5: 0 | E5: 0 | F5: 0 | N5: =SUM(B5:M5) -> 0
A6: TOTAL INGRESSOS EXPLOTACIO | B6: =SUM(B2:B5) -> 542068.83 | C6: =SUM(C2:C5) -> 494245.22 | D6: =SUM(D2:D5) -> 535792.81 | E6: =SUM(E2:E5) -> 564028.64 | F6: =SUM(F2:F5) -> 538287.87 | G6: =SUM(G2:G5) -> 0 | H6: =SUM(H2:H5) -> 0 | I6: =SUM(I2:I5) -> 0 | ... M6: =SUM(M2:M5) -> 0 | N6: =SUM(B6:M6) -> 2674423.4
A7: . COMPRES | F7: =SUM(G7:I7) -> 0 | N7: =SUM(B7:M7) -> 0
A8: . ALTRES APROVISIONAMENTS | F8: 0 | N8: =SUM(B8:M8) -> 0
A9: 0.45 | B9: =-B2*$A$9 -> -248909.16 | C9: =-C2*$A$9 -> -226949.34 | D9: =-D2*$A$9 -> -246027.31 | E9: =-E2*$A$9 -> -258992.74 | F9: =-F2*$A$9 -> -247173 | G9: =-G2*$A$9 -> 0 | H9: =-H2*$A$9 -> 0 | I9: =-I2*$A$9 -> 0 | ... M9: =-M2*$A$9 -> 0 | N9: =SUM(B9:M9) -> -1228051.6
A10: . VARIACIO EXISTENICIES COMPRES | F10: 0 | N10: =SUM(B10:M10) -> 0
A11: TOTAL COMPRES | B11: =SUM(B7:B10) -> -248909.16 | C11: =SUM(C7:C10) -> -226949.34 | D11: =SUM(D7:D10) -> -246027.31 | E11: =SUM(E7:E10) -> -258992.74 | F11: =SUM(F7:F10) -> -247173 | G11: =SUM(G7:G10) -> 0 | H11: =SUM(H7:H10) -> 0 | I11: =SUM(I7:I10) -> 0 | ... M11: =SUM(M7:M10) -> 0 | N11: =SUM(B11:M11) -> -1228051.6 | O11: =N11/$N$6 -> -0.45918367
A12: . ESTRUCTURA LN00000 | B12: -532718.66 | C12: -537228.61 | D12: -580718.51 | E12: -607883.8 | F12: -646229.83 | N12: =SUM(B12:M12) -> -2904779.4
A13: Restem LN0001 | B13: -20000 | C13: -20000 | D13: -20000 | E13: -20000 | F13: -20000 | N13: =SUM(B13:M13) -> -100000
A14: Restem Green Vita | B14: ='Green Vita_05'!B20 -> -24563.585 | C14: ='Green Vita_05'!C20 -> -43419.493 | D14: ='Green Vita_05'!D20 -> -46702.057 | E14: ='Green Vita_05'!E20 -> -32602.222 | F14: ='Green Vita_05'!F20 -> -48606.81 | G14: ='Green Vita_05'!G20 -> 0 | H14: ='Green Vita_05'!H20 -> 0 | I14: ='Green Vita_05'!I20 -> 0 | ... M14: ='Green Vita_05'!M20 -> 0 | N14: =SUM(B14:M14) -> -195894.17
A15: Foodlovers | B15: =Foodlovers_05!B20 -> -14082.14 | C15: =Foodlovers_05!C20 -> -24870.01 | D15: =Foodlovers_05!D20 -> -28128.894 | E15: =Foodlovers_05!E20 -> -43343.766 | F15: =Foodlovers_05!F20 -> -48756.348 | G15: =Foodlovers_05!G20 -> 0 | H15: =Foodlovers_05!H20 -> 0 | I15: =Foodlovers_05!I20 -> 0 | ... M15: =Foodlovers_05!M20 -> 0 | N15: =SUM(B15:M15) -> -159181.16
A16: Agenda | B16: =Agenda_05!B17 -> -7190.3585 | C16: =Agenda_05!C17 -> -7414.595 | D16: =Agenda_05!D17 -> -8858.528 | E16: =Agenda_05!E17 -> -8331.3575 | F16: =Agenda_05!F17 -> -10686.999 | G16: =Agenda_05!G17 -> 0 | H16: =Agenda_05!H17 -> 0 | I16: =Agenda_05!I17 -> 0 | ... M16: =Agenda_05!M17 -> 0 | N16: =SUM(B16:M16) -> -42481.838
B17: =SUM(B13:B16) -> -65836.083 | C17: =SUM(C13:C16) -> -95704.098 | D17: =SUM(D13:D16) -> -103689.48 | E17: =SUM(E13:E16) -> -104277.35 | F17: =SUM(F13:F16) -> -128050.16 | G17: =SUM(G13:G16) -> 0 | H17: =SUM(H13:H16) -> 0 | I17: =SUM(I13:I16) -> 0 | ... M17: =SUM(M13:M16) -> 0 | N17: =SUM(B17:M17) -> -497557.16
A18: Pestanya dades % aplicar | B18: =(B12-B17)*Dades!C127 -> -297258.62 | C18: =(C12-C17)*Dades!E127 -> -207607.15 | D18: =(D12-D17)*Dades!G127 -> -196668.88 | E18: =(E12-E17)*Dades!I127 -> -219447.45 | F18: =(F12-F17)*Dades!K127 -> -112645.53 | G18: =(G12-G17)*Dades!H127 -> 0 | H18: =(H12-H17)*Dades!I127 -> 0 | I18: =(I12-I17)*Dades!J127 -> 0 | J18: =(J12-J17)*Dades!K127 -> 0 | K18: =(K12-K17)*Dades!L127 -> 0 | L18: =(L12-L17)*Dades!M127 -> 0 | M18: =(M12-M17)*Dades!N127 -> 0 | N18: =SUM(B18:M18) -> -1033627.6
A19: . SOUS I SALARIS dept. | B19: -50301.51 | C19: -51584.76 | D19: -58122.77 | E19: -58505.6 | F19: -61890.8 | N19: =SUM(B19:M19) -> -280405.44
A20: . INDEMNITZACIONS | B20: 0 | C20: 0 | D20: -28100 | E20: 0 | F20: 0 | N20: =SUM(B20:M20) -> -28100
A21: . SEGURETAT SOCIAL | B21: -10903.14 | C21: -13495.5 | D21: -16003.53 | E21: -16541.71 | F21: -17869.29 | N21: =SUM(B21:M21) -> -74813.17
A22: . ALTRES DESPESES SOCIALS | B22: -437.49 | C22: -397.2 | D22: -852.13 | E22: -589.11 | F22: -289.8 | N22: =SUM(B22:M22) -> -2565.73
A23: TOTAL COST SALARIAL | B23: =SUM(B18:B22) -> -358900.76 | C23: =SUM(C18:C22) -> -273084.61 | D23: =SUM(D18:D22) -> -299747.31 | E23: =SUM(E18:E22) -> -295083.87 | F23: =SUM(F18:F22) -> -192695.42 | G23: =SUM(G18:G22) -> 0 | H23: =SUM(H18:H22) -> 0 | I23: =SUM(I18:I22) -> 0 | ... M23: =SUM(M18:M22) -> 0 | N23: =SUM(B23:M23) -> -1419512 | O23: =N23/$N$6 -> -0.53077309
A24: . GESTIO DE LN00000 | B24: -79477.48 | C24: -65034.81 | D24: -100634.18 | E24: -133354.73 | F24: -131629.55
A25: 0.3 | B25: =$A$25*B24 -> -23843.244 | C25: =$A$25*C24 -> -19510.443 | D25: =$A$25*D24 -> -30190.254 | E25: =$A$25*E24 -> -40006.419 | F25: =$A$25*F24 -> -39488.865 | G25: =$A$25*G24 -> 0 | H25: =$A$25*H24 -> 0 | I25: =$A$25*I24 -> 0 | ... L25: =$A$25*L24 -> 0
A26: . ARRENDAMENTS I CANONS | B26: -651 | C26: -588 | D26: -651 | E26: -630 | F26: 0 | N26: =SUM(B26:M26) -> -2520
A27: . REPARACIONS I CONSERVACIO | B27: -4139.51 | C27: -6150.86 | D27: -3917.62 | E27: -3576.16 | F27: -3301.79 | N27: =SUM(B27:M27) -> -21085.94
A28: . SERVEIS PROFESSIONALS | B28: 0 | C28: 0 | D28: 0 | E28: 0 | F28: 0 | N28: =SUM(B28:M28) -> 0
A29: . TRANSPORTS | B29: -739.5 | C29: -876.61 | D29: -901 | E29: -831.5 | F29: 0 | N29: =SUM(B29:M29) -> -3348.61
A30: . PRIMES D'ASSEGURANCES | B30: 0 | C30: 0 | D30: 0 | E30: 0 | F30: 0 | N30: =SUM(B30:M30) -> 0
A31: . SERVEIS BANCARIS | B31: 0 | C31: 0 | D31: 0 | E31: 0 | F31: 0 | N31: =SUM(B31:M31) -> 0
A32: . PUBLICITAT I PROPAGANDA | B32: 0 | C32: -1000 | D32: 0 | E32: 0 | F32: 0 | N32: =SUM(B32:M32) -> -1000
A33: . SUBMINISTRAMENTS | B33: -6018.27 | C33: -5218.85 | D33: -5349.47 | E33: -4620.58 | F33: -6679.36 | N33: =SUM(B33:M33) -> -27886.53
A34: . ALTRES DESPESES | B34: -281.94 | C34: 0 | D34: -157.16 | E34: -604.93 | F34: -1690 | N34: =SUM(B34:M34) -> -2734.03
A35: . DOTACIO PER INSOLVENCIA | B35: 0 | C35: 0 | D35: 0 | E35: 0 | F35: 0 | N35: =SUM(B35:M35) -> 0
A36: MOVIMENTS INTERNS | B36: 0 | C36: 0 | D36: 0 | E36: 0 | F36: 0 | N36: =SUM(B36:M36) -> 0
A37: TOTAL DESPESES GESTIO | B37: =SUM(B25:B36) -> -35673.464 | C37: =SUM(C25:C36) -> -33344.763 | D37: =SUM(D25:D36) -> -41166.504 | E37: =SUM(E25:E36) -> -50269.589 | F37: =SUM(F25:F36) -> -51160.015 | G37: =SUM(G25:G36) -> 0 | H37: =SUM(H25:H36) -> 0 | I37: =SUM(I25:I36) -> 0 | ... M37: =SUM(M25:M36) -> 0 | N37: =SUM(B37:M37) -> -211614.34 | O37: =N37/$N$6 -> -0.079125219
A38: TOTAL GESTIO + SALARIS | B38: =B37+B23 -> -394574.22 | C38: =C37+C23 -> -306429.37 | D38: =D37+D23 -> -340913.81 | E38: =E37+E23 -> -345353.46 | F38: =F37+F23 -> -243855.43 | G38: =G37+G23 -> 0 | H38: =H37+H23 -> 0 | I38: =I37+I23 -> 0 | ... M38: =M37+M23 -> 0 | N38: =SUM(B38:M38) -> -1631126.3
A39: EBITDA | B39: =B6+(B11+B23+B37) -> -101414.55 | C39: =C6+(C11+C23+C37) -> -39133.483 | D39: =D6+(D11+D23+D37) -> -51148.314 | E39: =E6+(E11+E23+E37) -> -40317.562 | F39: =F6+(F11+F23+F37) -> 47259.437 | G39: =G6+(G11+G23+G37) -> 0 | H39: =H6+(H11+H23+H37) -> 0 | I39: =I6+(I11+I23+I37) -> 0 | ... M39: =M6+(M11+M23+M37) -> 0 | N39: =SUM(B39:M39) -> -184754.47
A40: % | B40: =B39/B6 -> -0.18708795 | C40: =C39/C6 -> -0.079178273 | D40: =D39/D6 -> -0.095462859 | E40: =E39/E6 -> -0.071481409 | F40: =F39/F6 -> 0.087795841 | N40: =N39/N6 -> -0.069081982

Sheet Foodlovers_05
A1: COMPTE DE RESULTATS 2026 | B1: Gener | C1: Febrer | D1: Març | E1: Abril | F1: Maig | G1: Juny | H1: Juliol | I1: Agost | J1: Setembre | K1: Octubre | L1: Novembre | M1: Desembre | N1: TOTAL
A2: . VENDES | B2: 954 | C2: 41743.47 | D2: 60009.55 | E2: 123646.15 | F2: 170315.52 | N2: =SUM(B2:M2) -> 396668.69
A3: . PRESTACIO DE SEVEIS | B3: 0 | C3: 0 | D3: 0 | E3: 0 | F3: 0 | N3: =SUM(B3:M3) -> 0
A4: . ALTRES INGRESSOS | B4: 0 | C4: 0 | D4: 0 | E4: 0 | F4: 0 | N4: =SUM(B4:M4) -> 0
A5: . VARIACIO EXISTENCIES | B5: 0 | C5: 0 | D5: 0 | E5: 0 | F5: 0 | N5: =SUM(B5:M5) -> 0
A6: TOTAL INGRESSOS EXPLOTACIO | B6: =SUM(B2:B5) -> 954 | C6: =SUM(C2:C5) -> 41743.47 | D6: =SUM(D2:D5) -> 60009.55 | E6: =SUM(E2:E5) -> 123646.15 | F6: =SUM(F2:F5) -> 170315.52 | G6: =SUM(G2:G5) -> 0 | H6: =SUM(H2:H5) -> 0 | I6: =SUM(I2:I5) -> 0 | ... M6: =SUM(M2:M5) -> 0 | N6: =SUM(B6:M6) -> 396668.69
A7: 0.28 | B7: =-$A$7*B6 -> -267.12 | C7: =-$A$7*C6 -> -11688.172 | D7: =-$A$7*D6 -> -16802.674 | E7: =-$A$7*E6 -> -34620.922 | F7: =-$A$7*F6 -> -47688.346 | G7: =-$A$7*G6 -> 0 | H7: =-$A$7*H6 -> 0 | I7: =-$A$7*I6 -> 0 | ... M7: =-$A$7*M6 -> 0
B8: -8528.89 | C8: -5084.08 | D8: -1316.73 | E8: -15787.2 | F8: -532.89
A9: . ALTRES APROVISIONAMENTS | B9: -384.3 | C9: -1422.11 | D9: -1176.8 | E9: -278.62 | F9: 0 | N9: =SUM(B9:M9) -> -3261.83
A10: TOTAL COMPRES | B10: =SUM(B7:B9) -> -9180.31 | C10: =SUM(C7:C9) -> -18194.362 | D10: =SUM(D7:D9) -> -19296.204 | E10: =SUM(E7:E9) -> -50686.742 | F10: =SUM(F7:F9) -> -48221.236 | G10: =SUM(G7:G9) -> 0 | H10: =SUM(H7:H9) -> 0 | I10: =SUM(I7:I9) -> 0 | ... M10: =SUM(M7:M9) -> 0 | N10: =SUM(B10:M10) -> -145578.85 | O10: =N10/$N$6 -> -0.36700364
A11: . ESTRUCTURA Fixe | B11: -5000 | C11: -5000 | D11: -5000 | E11: -5000 | F11: -5000 | N11: =SUM(B11:M11) -> -25000
A12: 0.17 | B12: =-$A$12*B6 -> -162.18 | C12: =-$A$12*C6 -> -7096.3899 | D12: =-$A$12*D6 -> -10201.624 | E12: =-$A$12*E6 -> -21019.845 | F12: =-$A$12*F6 -> -28953.638 | N12: =SUM(B12:M12) -> -67433.677
B13: =SUM(B11:B12) -> -5162.18 | C13: =SUM(C11:C12) -> -12096.39 | D13: =SUM(D11:D12) -> -15201.624 | E13: =SUM(E11:E12) -> -26019.845 | F13: =SUM(F11:F12) -> -33953.638 | G13: =SUM(G11:G12) -> 0 | H13: =SUM(H11:H12) -> 0 | I13: =SUM(I11:I12) -> 0 | ... M13: =SUM(M11:M12) -> 0 | N13: =SUM(B13:M13) -> -92433.677
A14: . SOUS I SALARIS dept. | B14: -6809.58 | C14: -8658.47 | D14: -9486.11 | E14: -12134.68 | F14: -10741.55 | N14: =SUM(B14:M14) -> -47830.39
A15: . SALARIS | B15: 70 | C15: -1324.57 | D15: -317.75 | E15: -1038.5 | F15: -505 | N15: =SUM(B15:M15) -> -3115.82
A16: . INDEMNITZACIONS | B16: 0 | C16: 0 | D16: 0 | E16: 0 | F16: 0 | N16: =SUM(B16:M16) -> 0
A17: . SEGURETAT SOCIAL | B17: -2180.38 | C17: -2790.58 | D17: -3070.89 | E17: -4150.74 | F17: -3556.16 | N17: =SUM(B17:M17) -> -15748.75
A18: . ALTRES DESPESES SOCIALS | B18: 0 | C18: 0 | D18: -52.52 | E18: 0 | F18: 0 | N18: =SUM(B18:M18) -> -52.52
A19: . TRASPAS INTERN
A20: TOTAL COST SALARIAL | B20: =SUM(B13:B18) -> -14082.14 | C20: =SUM(C13:C18) -> -24870.01 | D20: =SUM(D13:D18) -> -28128.894 | E20: =SUM(E13:E18) -> -43343.766 | F20: =SUM(F13:F18) -> -48756.348 | G20: =SUM(G13:G18) -> 0 | H20: =SUM(H13:H18) -> 0 | I20: =SUM(I13:I18) -> 0 | ... M20: =SUM(M13:M18) -> 0 | N20: =SUM(B20:M20) -> -159181.16 | O20: =N20/$N$6 -> -0.40129499
A21: . GESTIO DE LN00000 | B21: -79477.48 | C21: -65034.81 | D21: -100634.18 | E21: -133354.73 | F21: -131629.55
A22: 0.08 | B22: =$A$22*B21 -> -6358.1984 | C22: =$A$22*C21 -> -5202.7848 | D22: =$A$22*D21 -> -8050.7344 | E22: =$A$22*E21 -> -10668.378 | F22: =$A$22*F21 -> -10530.364
A23: . ARRENDAMENTS I CANONS | B23: -9514.67 | C23: -13247.72 | D23: -16195.92 | E23: -34991.26 | F23: -17280.98 | N23: =SUM(B23:M23) -> -91230.55
A24: . REPARACIONS I CONSERVACIO | B24: -697.57 | C24: -594.98 | D24: -593.01 | E24: -1005.81 | F24: -567.37 | N24: =SUM(B24:M24) -> -3458.74
A25: . SERVEIS PROFESSIONALS | B25: -42 | C25: -1106.54 | D25: 0 | E25: -4526.66 | F25: -1619.27 | N25: =SUM(B25:M25) -> -7294.47
A26: . TRANSPORTS | B26: 0 | C26: 0 | D26: 0 | E26: -31.8 | F26: 0 | N26: =SUM(B26:M26) -> -31.8
A27: . PRIMES D'ASSEGURANCES | B27: 0 | C27: 0 | D27: 0 | E27: 0 | F27: 0 | N27: =SUM(B27:M27) -> 0
A28: . SERVEIS BANCARIS | B28: 1.1 | C28: -243.43 | D28: -77.85 | E28: -1036.19 | F28: -9.24 | N28: =SUM(B28:M28) -> -1365.61
A29: . PUBLICITAT I PROPAGANDA | B29: 0 | C29: -160 | D29: -87 | E29: -682 | F29: -112.93 | N29: =SUM(B29:M29) -> -1041.93
A30: . SUBMINISTRAMENTS | B30: 0 | C30: -257.85 | D30: 0 | E30: 0 | F30: -380 | N30: =SUM(B30:M30) -> -637.85
A31: . ALTRES DESPESES | B31: -1999.65 | C31: -738.04 | D31: -49 | E31: -3416.85 | F31: -208 | N31: =SUM(B31:M31) -> -6411.54
A32: . DOTACIO PER INSOLVENCIA | B32: 0 | C32: 0 | D32: 0 | E32: 0 | F32: 0 | N32: =SUM(B32:M32) -> 0
A33: MOVIMENTS INTERNS | B33: 0 | C33: 0 | D33: 0 | E33: 0 | F33: 0 | N33: =SUM(B33:M33) -> 0
A34: TOTAL DESPESES GESTIO | B34: =SUM(B22:B33) -> -18610.988 | C34: =SUM(C22:C33) -> -21551.345 | D34: =SUM(D22:D33) -> -25053.514 | E34: =SUM(E22:E33) -> -56358.948 | F34: =SUM(F22:F33) -> -30708.154 | G34: =SUM(G23:G33) -> 0 | H34: =SUM(H23:H33) -> 0 | I34: =SUM(I23:I33) -> 0 | J34: =SUM(J23:J33) -> 0 | K34: =SUM(K23:K33) -> 0 | L34: =SUM(L23:L33) -> 0 | M34: =SUM(M23:M33) -> 0 | N34: =SUM(B34:M34) -> -152282.95 | O34: =N34/$N$6 -> -0.38390464
A35: TOTAL GESTIO + SALARIS | B35: =B34+B20 -> -32693.128 | C35: =C34+C20 -> -46421.355 | D35: =D34+D20 -> -53182.408 | E35: =E34+E20 -> -99702.714 | F35: =F34+F20 -> -79464.502 | G35: =G34+G20 -> 0 | H35: =H34+H20 -> 0 | I35: =I34+I20 -> 0 | ... M35: =M34+M20 -> 0 | N35: =SUM(B35:M35) -> -311464.11
A36: EBITDA | B36: =B6+(B10+B20+B34) -> -40919.438 | C36: =C6+(C10+C20+C34) -> -22872.246 | D36: =D6+(D10+D20+D34) -> -12469.062 | E36: =E6+(E10+E20+E34) -> -26743.306 | F36: =F6+(F10+F20+F34) -> 42629.782 | G36: =G6+(G10+G20+G34) -> 0 | H36: =H6+(H10+H20+H34) -> 0 | I36: =I6+(I10+I20+I34) -> 0 | ... M36: =M6+(M10+M20+M34) -> 0 | N36: =SUM(B36:M36) -> -60374.271
A37: % | B37: =B36/B6 -> -42.892493 | C37: =C36/C6 -> -0.54792393 | D37: =D36/D6 -> -0.20778463 | E37: =E36/E6 -> -0.21628903 | F37: =F36/F6 -> 0.25029887 | N37: =N36/N6 -> -0.15220327

Sheet Green Vita_05
A1: COMPTE DE RESULTATS 2026 | B1: Gener | C1: Febrer | D1: Març | E1: Abril | F1: Maig | G1: Juny | H1: Juliol | I1: Agost | J1: Setembre | K1: Octubre | L1: Novembre | M1: Desembre | N1: TOTAL
A2: . VENDES | B2: 43471.95 | C2: 99398.31 | D2: 111070.19 | E2: 71050.74 | F2: 88333.2 | N2: =SUM(B2:M2) -> 413324.39
A3: . PRESTACIO DE SEVEIS | B3: 0 | C3: 0 | D3: 0 | E3: 0 | F3: 0 | N3: =SUM(B3:M3) -> 0
A4: . ALTRES INGRESSOS | B4: 0 | C4: 0 | D4: 0 | E4: 0 | F4: 0 | N4: =SUM(B4:M4) -> 0
A5: . VARIACIO EXISTENCIES | B5: 0 | C5: 0 | D5: 0 | E5: 0 | F5: 0 | N5: =SUM(B5:M5) -> 0
A6: TOTAL INGRESSOS EXPLOTACIO | B6: =SUM(B2:B5) -> 43471.95 | C6: =SUM(C2:C5) -> 99398.31 | D6: =SUM(D2:D5) -> 111070.19 | E6: =SUM(E2:E5) -> 71050.74 | F6: =SUM(F2:F5) -> 88333.2 | G6: =SUM(G2:G5) -> 0 | H6: =SUM(H2:H5) -> 0 | I6: =SUM(I2:I5) -> 0 | ... M6: =SUM(M2:M5) -> 0 | N6: =SUM(B6:M6) -> 413324.39
N7: =SUM(B7:M7) -> 0
A8: 0.25 | B8: =-B6*$A$8 -> -10867.987 | C8: =-C6*$A$8 -> -24849.577 | D8: =-D6*$A$8 -> -27767.548 | E8: =-E6*$A$8 -> -17762.685 | F8: =-F6*$A$8 -> -22083.3
A9: . COMPRES | B9: 0 | C9: 0 | D9: 0 | E9: -1790.1 | F9: -1643.31 | N9: =SUM(B9:M9) -> -3433.41
A10: . ALTRES APROVISIONAMENTS | B10: 0 | C10: 0 | D10: 0 | E10: -533.85 | F10: -581.74 | N10: =SUM(B10:M10) -> -1115.59
A11: TOTAL COMPRES | B11: =B9+B10+B8 -> -10867.987 | C11: =C9+C10+C8 -> -24849.577 | D11: =D9+D10+D8 -> -27767.548 | E11: =E9+E10+E8 -> -20086.635 | F11: =F9+F10+F8 -> -24308.35 | G11: =SUM(G9:G10) -> 0 | H11: =SUM(H9:H10) -> 0 | I11: =SUM(I9:I10) -> 0 | J11: =SUM(J9:J10) -> 0 | K11: =SUM(K9:K10) -> 0 | L11: =SUM(L9:L10) -> 0 | M11: =SUM(M9:M10) -> 0 | N11: =SUM(B11:M11) -> -107880.1 | O11: =N11/$N$6 -> -0.26100588
A12: ESTRUCTURA FIXE | B12: -5000 | C12: -5000 | D12: -5000 | E12: -5000 | F12: -5000 | N12: =SUM(B12:M12) -> -25000
A13: 0.15 | B13: =$A$13*-B6 -> -6520.7925 | C13: =$A$13*-C6 -> -14909.746 | D13: =$A$13*-D6 -> -16660.529 | E13: =$A$13*-E6 -> -10657.611 | F13: =$A$13*-F6 -> -13249.98 | N13: =SUM(B13:M13) -> -61998.658
B14: =SUM(B12:B13) -> -11520.792 | C14: =SUM(C12:C13) -> -19909.747 | D14: =SUM(D12:D13) -> -21660.529 | E14: =SUM(E12:E13) -> -15657.611 | F14: =SUM(F12:F13) -> -18249.98 | G14: =SUM(G12:G13) -> 0 | H14: =SUM(H12:H13) -> 0 | I14: =SUM(I12:I13) -> 0 | ... M14: =SUM(M12:M13) -> 0 | N14: =SUM(B14:M14) -> -86998.659
A15: . SOUS I SALARIS dept. | B15: 0 | C15: 0 | D15: 0 | E15: 0 | F15: -9291.48 | N15: =SUM(B15:M15) -> -9291.48
A16: . INDEMNITZACIONS | B16: 0 | C16: 0 | D16: 0 | E16: 0 | F16: 0 | N16: =SUM(B16:M16) -> 0
A17: . SEGURETAT SOCIAL | B17: 0 | C17: 0 | D17: 0 | E17: 0 | F17: -2815.37 | N17: =SUM(B17:M17) -> -2815.37
A18: . ALTRES DESPESES SOCIALS | B18: 0 | C18: 0 | D18: 0 | E18: 0 | F18: 0 | N18: =SUM(B18:M18) -> 0
A19: . TRASPAS INTERN | B19: -1522 | C19: -3600 | D19: -3381 | E19: -1287 | N19: =SUM(B19:M19) -> -9790
A20: TOTAL COST SALARIAL | B20: =SUM(B12:B19) -> -24563.585 | C20: =SUM(C12:C19) -> -43419.493 | D20: =SUM(D12:D19) -> -46702.057 | E20: =SUM(E12:E19) -> -32602.222 | F20: =SUM(F12:F19) -> -48606.81 | G20: =SUM(G12:G18) -> 0 | H20: =SUM(H12:H18) -> 0 | I20: =SUM(I12:I18) -> 0 | J20: =SUM(J12:J18) -> 0 | K20: =SUM(K12:K18) -> 0 | L20: =SUM(L12:L18) -> 0 | M20: =SUM(M12:M18) -> 0 | N20: =SUM(B20:M20) -> -195894.17 | O20: =N20/$N$6 -> -0.47394776
A21: . GESTIO DE LN00000 | B21: -79477.48 | C21: -65034.81 | D21: -100634.18 | E21: -133354.73 | F21: -131629.55
A22: 0.04 | B22: =$A$22*B21 -> -3179.0992 | C22: =$A$22*C21 -> -2601.3924 | D22: =$A$22*D21 -> -4025.3672 | E22: =$A$22*E21 -> -5334.1892 | F22: =$A$22*F21 -> -5265.182
A23: . ARRENDAMENTS I CANONS | B23: -6967.35 | C23: -19408.74 | D23: -14214.11 | E23: -6327.02 | F23: 0 | N23: =SUM(B23:M23) -> -46917.22
A24: . REPARACIONS I CONSERVACIO | B24: 0 | C24: 0 | D24: 0 | E24: 0 | F24: -40 | N24: =SUM(B24:M24) -> -40
A25: . SERVEIS PROFESSIONALS | B25: 0 | C25: 0 | D25: 0 | E25: 0 | F25: 0 | N25: =SUM(B25:M25) -> 0
A26: . TRANSPORTS | B26: 0 | C26: 0 | D26: 0 | E26: 0 | F26: 0 | N26: =SUM(B26:M26) -> 0
A27: . PRIMES D'ASSEGURANCES | B27: 0 | C27: 0 | D27: 0 | E27: 0 | F27: 0 | N27: =SUM(B27:M27) -> 0
A28: . SERVEIS BANCARIS | B28: 0 | C28: 0 | D28: 0 | E28: 0 | F28: 0 | N28: =SUM(B28:M28) -> 0
A29: . PUBLICITAT I PROPAGANDA | B29: 0 | C29: -1991.16 | D29: 0 | E29: 0 | F29: 0 | N29: =SUM(B29:M29) -> -1991.16
A30: . SUBMINISTRAMENTS | B30: 0 | C30: 0 | D30: 0 | E30: 0 | F30: 0 | N30: =SUM(B30:M30) -> 0
A31: . ALTRES DESPESES | B31: 0 | C31: 0 | D31: -2588.09 | E31: -1974.45 | F31: -21911.7 | N31: =SUM(B31:M31) -> -26474.24
A32: . DOTACIO PER INSOLVENCIA | B32: 0 | C32: 0 | D32: -733.14 | E32: 0 | F32: 0 | N32: =SUM(B32:M32) -> -733.14
A33: MOVIMENTS INTERNS | B33: 0 | C33: 0 | D33: 0 | E33: 0 | F33: 0 | N33: =SUM(B33:M33) -> 0
A34: TOTAL DESPESES GESTIO | B34: =SUM(B22:B33) -> -10146.449 | C34: =SUM(C22:C33) -> -24001.292 | D34: =SUM(D22:D33) -> -21560.707 | E34: =SUM(E22:E33) -> -13635.659 | F34: =SUM(F22:F33) -> -27216.882 | G34: =SUM(G23:G33) -> 0 | H34: =SUM(H23:H33) -> 0 | I34: =SUM(I23:I33) -> 0 | J34: =SUM(J23:J33) -> 0 | K34: =SUM(K23:K33) -> 0 | L34: =SUM(L23:L33) -> 0 | M34: =SUM(M23:M33) -> 0 | N34: =SUM(B34:M34) -> -96560.99 | O34: =N34/$N$6 -> -0.23362035
A35: TOTAL GESTIO + SALARIS | B35: =B34+B20 -> -34710.034 | C35: =C34+C20 -> -67420.785 | D35: =D34+D20 -> -68262.764 | E35: =E34+E20 -> -46237.881 | F35: =F34+F20 -> -75823.692 | G35: =G34+G20 -> 0 | H35: =H34+H20 -> 0 | I35: =I34+I20 -> 0 | ... M35: =M34+M20 -> 0 | N35: =SUM(B35:M35) -> -292455.16
A36: EBITDA | B36: =B6+(B11+B20+B34) -> -2106.0717 | C36: =C6+(C11+C20+C34) -> 7127.9471 | D36: =D6+(D11+D20+D34) -> 15039.878 | E36: =E6+(E11+E20+E34) -> 4726.2238 | F36: =F6+(F11+F20+F34) -> -11798.842 | G36: =G6+(G11+G20+G34) -> 0 | H36: =H6+(H11+H20+H34) -> 0 | I36: =I6+(I11+I20+I34) -> 0 | ... M36: =M6+(M11+M20+M34) -> 0 | N36: =SUM(B36:M36) -> 12989.135
A37: % | B37: =B36/B6 -> -0.048446681 | C37: =C36/C6 -> 0.071710949 | D37: =D36/D6 -> 0.13540877 | E37: =E36/E6 -> 0.066518995 | F37: =F36/F6 -> -0.133572 | N37: =N36/N6 -> 0.031426008

Sheet TOTAL
A1: COMPTE DE RESULTATS 2026 | B1: Gener | C1: Febrer | D1: Març | E1: Abril | F1: Maig | G1: Juny | H1: Juliol | I1: Agost | J1: Setembre | K1: Octubre | L1: Novembre | M1: Desembre | N1: TOTAL
A2: . VENDES | N2: =SUM(B2:M2) -> 0
A3: . PRESTACIO DE SEVEIS | N3: =SUM(B3:M3) -> 0
A4: . ALTRES INGRESSOS | N4: =SUM(B4:M4) -> 0
A5: . VARIACIO EXISTENCIES | N5: =SUM(B5:M5) -> 0
A6: TOTAL INGRESSOS EXPLOTACIO | B6: =Precuinats_05!B6+Empresa_05!B6+Casaments_05!B8+Foodlovers_05!B6+'Green Vita_05'!B6+Restaurants_05!B7+Agenda_05!B6 -> 1309460.7 | C6: =Precuinats_05!C6+Empresa_05!C6+Casaments_05!C8+Foodlovers_05!C6+'Green Vita_05'!C6+Restaurants_05!C7+Agenda_05!C6 -> 1693888.4 | D6: =Precuinats_05!D6+Empresa_05!D6+Casaments_05!D8+Foodlovers_05!D6+'Green Vita_05'!D6+Restaurants_05!D7+Agenda_05!D6 -> 2098899 | E6: =Precuinats_05!E6+Empresa_05!E6+Casaments_05!E8+Foodlovers_05!E6+'Green Vita_05'!E6+Restaurants_05!E7+Agenda_05!E6 -> 2118885.9 | F6: =Precuinats_05!F6+Empresa_05!F6+Casaments_05!F8+Foodlovers_05!F6+'Green Vita_05'!F6+Restaurants_05!F7+Agenda_05!F6 -> 3459181.8 | G6: =Precuinats_05!G6+Empresa_05!G6+Casaments_05!G8+Foodlovers_05!G6+'Green Vita_05'!G6+Restaurants_05!G7+Agenda_05!G6 -> 0 | H6: =Precuinats_05!H6+Empresa_05!H6+Casaments_05!H8+Foodlovers_05!H6+'Green Vita_05'!H6+Restaurants_05!H7+Agenda_05!H6 -> 0 | I6: =Precuinats_05!I6+Empresa_05!I6+Casaments_05!I8+Foodlovers_05!I6+'Green Vita_05'!I6+Restaurants_05!I7+Agenda_05!I6 -> 0 | ... M6: =Precuinats_05!M6+Empresa_05!M6+Casaments_05!M8+Foodlovers_05!M6+'Green Vita_05'!M6+Restaurants_05!M7+Agenda_05!M6 -> 0 | N6: =SUM(B6:M6)+REAL_05!D5 -> 10683320 | O6: =N6+(Precuinats_05!N3*-1) -> 10737900
A7: . COMPRES | G7: =Precuinats_05!G11+Empresa_05!G16+Casaments_05!G19+Foodlovers_05!G10+'Green Vita_05'!G11+Restaurants_05!G13+Agenda_05!G10 -> 0 | H7: =Precuinats_05!H11+Empresa_05!H16+Casaments_05!H19+Foodlovers_05!H10+'Green Vita_05'!H11+Restaurants_05!H13+Agenda_05!H10 -> 0 | I7: =Precuinats_05!I11+Empresa_05!I16+Casaments_05!I19+Foodlovers_05!I10+'Green Vita_05'!I11+Restaurants_05!I13+Agenda_05!I10 -> 0 | J7: =Precuinats_05!J11+Empresa_05!J16+Casaments_05!J19+Foodlovers_05!J10+'Green Vita_05'!J11+Restaurants_05!J13+Agenda_05!J10 -> 0 | K7: =Precuinats_05!K11+Empresa_05!K16+Casaments_05!K19+Foodlovers_05!K10+'Green Vita_05'!K11+Restaurants_05!K13+Agenda_05!K10 -> 0 | L7: =Precuinats_05!L11+Empresa_05!L16+Casaments_05!L19+Foodlovers_05!L10+'Green Vita_05'!L11+Restaurants_05!L13+Agenda_05!L10 -> 0 | M7: =Precuinats_05!M11+Empresa_05!M16+Casaments_05!M19+Foodlovers_05!M10+'Green Vita_05'!M11+Restaurants_05!M13+Agenda_05!M10 -> 0 | N7: =SUM(B7:M7) -> 0
A8: . ALTRES APROVISIONAMENTS | N8: =SUM(B8:M8) -> 0
A9: . CONSUMS INTERNS | N9: =SUM(B9:M9) -> 0
A10: . VARIACIO EXISTENICIES COMPRES | N10: =SUM(B10:M10) -> 0
A11: TOTAL COMPRES | B11: =Agenda_05!B10+Restaurants_05!B10+Empresa_05!B16+Casaments_05!B19+Precuinats_05!B11+Foodlovers_05!B10+'Green Vita_05'!B11 -> -511389.47 | C11: =Agenda_05!C10+Restaurants_05!C10+Empresa_05!C16+Casaments_05!C19+Precuinats_05!C11+Foodlovers_05!C10+'Green Vita_05'!C11 -> -629095.73 | D11: =Agenda_05!D10+Restaurants_05!D10+Empresa_05!D16+Casaments_05!D19+Precuinats_05!D11+Foodlovers_05!D10+'Green Vita_05'!D11 -> -755153.14 | E11: =Agenda_05!E10+Restaurants_05!E10+Empresa_05!E16+Casaments_05!E19+Precuinats_05!E11+Foodlovers_05!E10+'Green Vita_05'!E11 -> -689585.16 | F11: =Agenda_05!F10+Restaurants_05!F10+Empresa_05!F16+Casaments_05!F19+Precuinats_05!F11+Foodlovers_05!F10+'Green Vita_05'!F11 -> -871205.78 | G11: =Agenda_05!G10+Restaurants_05!G10+Empresa_05!G16+Casaments_05!G19+Precuinats_05!G11+Foodlovers_05!G10+'Green Vita_05'!G11 -> 0 | H11: =Agenda_05!H10+Restaurants_05!H10+Empresa_05!H16+Casaments_05!H19+Precuinats_05!H11+Foodlovers_05!H10+'Green Vita_05'!H11 -> 0 | I11: =Agenda_05!I10+Restaurants_05!I10+Empresa_05!I16+Casaments_05!I19+Precuinats_05!I11+Foodlovers_05!I10+'Green Vita_05'!I11 -> 0 | ... M11: =Agenda_05!M10+Restaurants_05!M10+Empresa_05!M16+Casaments_05!M19+Precuinats_05!M11+Foodlovers_05!M10+'Green Vita_05'!M11 -> 0 | N11: =SUM(B11:M11) -> -3456429.3 | O11: =N11/$O$6 -> -0.32189062
A12: . ESTRUCTURA FIX | N12: =SUM(B12:M12) -> 0
A13: . SOUS I SALARIS | N13: =SUM(B13:M13) -> 0
A14: . INDEMNITZACIONS | N14: =SUM(B14:M14) -> 0
A15: . SEGURETAT SOCIAL | N15: =SUM(B15:M15) -> 0
A16: . ALTRES DESPESES SOCIALS | N16: =SUM(B16:M16) -> 0
A17: TOTAL COST SALARIAL | B17: =Precuinats_05!B23+Empresa_05!B31+Casaments_05!B33+Foodlovers_05!B20+'Green Vita_05'!B20+Restaurants_05!B20+Agenda_05!B17 -> -967621.35 | C17: =Precuinats_05!C23+Empresa_05!C31+Casaments_05!C33+Foodlovers_05!C20+'Green Vita_05'!C20+Restaurants_05!C20+Agenda_05!C17 -> -976755.54 | D17: =Precuinats_05!D23+Empresa_05!D31+Casaments_05!D33+Foodlovers_05!D20+'Green Vita_05'!D20+Restaurants_05!D20+Agenda_05!D17 -> -1094768.4 | E17: =Precuinats_05!E23+Empresa_05!E31+Casaments_05!E33+Foodlovers_05!E20+'Green Vita_05'!E20+Restaurants_05!E20+Agenda_05!E17 -> -1102783.7 | F17: =Precuinats_05!F23+Empresa_05!F31+Casaments_05!F33+Foodlovers_05!F20+'Green Vita_05'!F20+Restaurants_05!F20+Agenda_05!F17 -> -1168867.4 | G17: =Precuinats_05!G23+Empresa_05!G31+Casaments_05!G33+Foodlovers_05!G20+'Green Vita_05'!G20+Restaurants_05!G20+Agenda_05!G17 -> 0 | H17: =Precuinats_05!H23+Empresa_05!H31+Casaments_05!H33+Foodlovers_05!H20+'Green Vita_05'!H20+Restaurants_05!H20+Agenda_05!H17 -> 0 | I17: =Precuinats_05!I23+Empresa_05!I31+Casaments_05!I33+Foodlovers_05!I20+'Green Vita_05'!I20+Restaurants_05!I20+Agenda_05!I17 -> 0 | ... M17: =Precuinats_05!M23+Empresa_05!M31+Casaments_05!M33+Foodlovers_05!M20+'Green Vita_05'!M20+Restaurants_05!M20+Agenda_05!M17 -> 0 | N17: =SUM(B17:M17) -> -5310796.3 | O17: =N17/$O$6 -> -0.49458426
A18: . ARRENDAMENTS I CANONS
A19: . REPARACIONS I CONSERVACIO
A20: . SERVEIS PROFESSIONALS
A21: . TRANSPORTS
A22: . PRIMES D'ASSEGURANCES
A23: . SERVEIS BANCARIS
A24: . PUBLICITAT I PROPAGANDA
A25: . SUBMINISTRAMENTS
A26: . ALTRES DESPESES
A27: . ALTRES TRIBUTS
A28: . DOTACIO PER INSOLVENCIA
A29: MOVIMENTS INTERNS
A30: TOTAL DESPESES GESTIO | B30: =Restaurants_05!B34+Empresa_05!B46+Casaments_05!B48+Precuinats_05!B37+Foodlovers_05!B34+'Green Vita_05'!B34 -> -250449.99 | C30: =Restaurants_05!C34+Empresa_05!C46+Casaments_05!C48+Precuinats_05!C37+Foodlovers_05!C34+'Green Vita_05'!C34 -> -300262.07 | D30: =Restaurants_05!D34+Empresa_05!D46+Casaments_05!D48+Precuinats_05!D37+Foodlovers_05!D34+'Green Vita_05'!D34 -> -384814.58 | E30: =Restaurants_05!E34+Empresa_05!E46+Casaments_05!E48+Precuinats_05!E37+Foodlovers_05!E34+'Green Vita_05'!E34 -> -449639.69 | F30: =Restaurants_05!F34+Empresa_05!F46+Casaments_05!F48+Precuinats_05!F37+Foodlovers_05!F34+'Green Vita_05'!F34 -> -524962.61 | G30: =Restaurants_05!G34+Empresa_05!G46+Casaments_05!G48+Precuinats_05!G37+Foodlovers_05!G34+'Green Vita_05'!G34 -> 0 | H30: =Restaurants_05!H34+Empresa_05!H46+Casaments_05!H48+Precuinats_05!H37+Foodlovers_05!H34+'Green Vita_05'!H34 -> 0 | I30: =Restaurants_05!I34+Empresa_05!I46+Casaments_05!I48+Precuinats_05!I37+Foodlovers_05!I34+'Green Vita_05'!I34 -> 0 | ... M30: =Restaurants_05!M34+Empresa_05!M46+Casaments_05!M48+Precuinats_05!M37+Foodlovers_05!M34+'Green Vita_05'!M34 -> 0 | N30: =SUM(B30:M30) -> -1910128.9 | O30: =N30/$O$6 -> -0.17788664
A31: TOTAL GESTIO + SALARIS | B31: =B30+B17 -> -1218071.3 | C31: =C30+C17 -> -1277017.6 | D31: =D30+D17 -> -1479583 | E31: =E30+E17 -> -1552423.4 | F31: =F30+F17 -> -1693830 | G31: =G30+G17 -> 0 | H31: =H30+H17 -> 0 | I31: =I30+I17 -> 0 | ... M31: =M30+M17 -> 0 | N31: =SUM(B31:M31) -> -7220925.3
A32: EBITDA | B32: =B6+(B11+B17+B30) -> -420000.08 | C32: =C6+(C11+C17+C30) -> -212224.97 | D32: =D6+(D11+D17+D30) -> -135837.1 | E32: =E6+(E11+E17+E30) -> -123122.59 | F32: =F6+(F11+F17+F30) -> 894146.03 | G32: =G6+(G11+G17+G30) -> 0 | H32: =H6+(H11+H17+H30) -> 0 | I32: =I6+(I11+I17+I30) -> 0 | ... M32: =M6+(M11+M17+M30) -> 0 | N32: =O6+(N11+N17+N30) -> 60545.569
A33: % | B33: =B32/B6 -> -0.32074279 | C33: =C32/C6 -> -0.12528864 | D33: =D32/D6 -> -0.064718266 | E33: =E32/E6 -> -0.058107228 | F33: =F32/F6 -> 0.25848483 | N33: =N32/N6 -> 0.005667299

Sheet REAL_05
A1: Node | B1: Description | C1: TOTAL | D1: LN00000 | E1: LN00001 | F1: LN00002 | G1: LN00003 | H1: LN00004 | I1: LN00005 | J1: LN00006 | K1: Sin LN
A2: 1 | B2: COMPTE DE RESULTATS | C2: 0 | D2: 0 | E2: 0 | F2: 0 | G2: 0 | H2: 0 | I2: 0 | J2: 0 | K2: 0
