Workbook

Sheet Traspas hores centres
A1: Data | B1: Empleado | C1: Organizaciones | D1: Origen Codi | E1: Origen Nom | F1: Proyecto | G1: Desti codi | H1: Desti Nom | I1: Minutos | J1: hores | K1: Preu hora | L1: TOTAL
A2: 46143 | B2: ARAYA SAEZ LIDON | C2: Plural sala, Cambrer/a Plural | D2: =_xlfn.XLOOKUP(C2,Conversio!$B:$B,Conversio!$C:$C,"No trobat",0) -> CCR00009 | E2: =_xlfn.XLOOKUP(D2,Conversio!$C:$C,Conversio!$D:$D,"No trobat",0) -> RESTAURANT VALKIRIA | F2: Camp Nou | G2: =_xlfn.XLOOKUP(F2,Conversio!$B:$B,Conversio!$C:$C,"No trobat",0) -> CCR00004 | H2: =_xlfn.XLOOKUP(G2,Conversio!$C:$C,Conversio!$D:$D,"No trobat",0) -> RESTAURANT CAMP NOU | I2: 360 | J2: =I2/60 -> 6 | K2: 18 | L2: =J2*K2 -> 108
A3: 46143 | B3: GISLENE GOMES RIBEIRO POTRATZ | C3: Juno sala, Cambrer/a Juno, Juno House | D3: =_xlfn.XLOOKUP(C3,Conversio!$B:$B,Conversio!$C:$C,"No trobat",0) -> CCR00007 | E3: =_xlfn.XLOOKUP(D3,Conversio!$C:$C,Conversio!$D:$D,"No trobat",0) -> RESTAURANT JUNO HOUSE | F3: Camp Nou | G3: =_xlfn.XLOOKUP(F3,Conversio!$B:$B,Conversio!$C:$C,"No trobat",0) -> CCR00004 | H3: =_xlfn.XLOOKUP(G3,Conversio!$C:$C,Conversio!$D:$D,"No trobat",0) -> RESTAURANT CAMP NOU | I3: 811 | J3: =I3/60 -> 13.516667 | K3: 18 | L3: =J3*K3 -> 243.3
A4: 46143 | B4: JAIME SALOM I MERCE | C4: La Masia sala, La Masia, Cambrer/a Masia | D4: =_xlfn.XLOOKUP(C4,Conversio!$B:$B,Conversio!$C:$C,"No trobat",0) -> CCR00003 | E4: =_xlfn.XLOOKUP(D4,Conversio!$C:$C,Conversio!$D:$D,"No trobat",0) -> RESTAURANT LA MASIA D'ESPLUGUES | F4: Camp Nou | G4: =_xlfn.XLOOKUP(F4,Conversio!$B:$B,Conversio!$C:$C,"No trobat",0) -> CCR00004 | H4: =_xlfn.XLOOKUP(G4,Conversio!$C:$C,Conversio!$D:$D,"No trobat",0) -> RESTAURANT CAMP NOU | I4: 380 | J4: =I4/60 -> 6.3333333 | K4: 18 | L4: =J4*K4 -> 114
A5: 46143 | B5: LIDA LILIAN SIGAS NIETO | C5: Juno sala, Responsable sala Juno, Juno House | D5: =_xlfn.XLOOKUP(C5,Conversio!$B:$B,Conversio!$C:$C,"No trobat",0) -> CCR00007 | E5: =_xlfn.XLOOKUP(D5,Conversio!$C:$C,Conversio!$D:$D,"No trobat",0) -> RESTAURANT JUNO HOUSE | F5: Camp Nou | G5: =_xlfn.XLOOKUP(F5,Conversio!$B:$B,Conversio!$C:$C,"No trobat",0) -> CCR00004 | H5: =_xlfn.XLOOKUP(G5,Conversio!$C:$C,Conversio!$D:$D,"No trobat",0) -> RESTAURANT CAMP NOU | I5: 442 | J5: =I5/60 -> 7.3666667 | K5: 18 | L5: =J5*K5 -> 132.6
A6: 46143 | B6: ANA ISABEL CABELLO RODRIGUEZ | C6: Soliver sala, Cambrer/a Soliver | D6: =_xlfn.XLOOKUP(C6,Conversio!$B:$B,Conversio!$C:$C,"No trobat",0) -> CCR00010 | E6: =_xlfn.XLOOKUP(D6,Conversio!$C:$C,Conversio!$D:$D,"No trobat",0) -> RESTAURANT SOLIVER | F6: Càtering | G6: =_xlfn.XLOOKUP(F6,Conversio!$B:$B,Conversio!$C:$C,"No trobat",0) -> CCE00000 | H6: =_xlfn.XLOOKUP(G6,Conversio!$C:$C,Conversio!$D:$D,"No trobat",0) -> ADMINISTRACIO EMPRESA | I6: 3081 | J6: =I6/60 -> 51.35 | K6: 18 | L6: =J6*K6 -> 924.3
A7: 46143 | B7: ARAYA SAEZ LIDON | C7: Plural sala, Cambrer/a Plural | D7: =_xlfn.XLOOKUP(C7,Conversio!$B:$B,Conversio!$C:$C,"No trobat",0) -> CCR00009 | E7: =_xlfn.XLOOKUP(D7,Conversio!$C:$C,Conversio!$D:$D,"No trobat",0) -> RESTAURANT VALKIRIA | F7: Càtering | G7: =_xlfn.XLOOKUP(F7,Conversio!$B:$B,Conversio!$C:$C,"No trobat",0) -> CCE00000 | H7: =_xlfn.XLOOKUP(G7,Conversio!$C:$C,Conversio!$D:$D,"No trobat",0) -> ADMINISTRACIO EMPRESA | I7: 970 | J7: =I7/60 -> 16.166667 | K7: 18 | L7: =J7*K7 -> 291
A8: 46143 | B8: CHAYMAE BIBIH KAMROUCHI | C8: Orígens cuina, Cuiner/a Orígens | D8: =_xlfn.XLOOKUP(C8,Conversio!$B:$B,Conversio!$C:$C,"No trobat",0) -> CCR00001 | E8: =_xlfn.XLOOKUP(D8,Conversio!$C:$C,Conversio!$D:$D,"No trobat",0) -> RESTAURANT ORIGENS | F8: Càtering | G8: =_xlfn.XLOOKUP(F8,Conversio!$B:$B,Conversio!$C:$C,"No trobat",0) -> CCE00000 | H8: =_xlfn.XLOOKUP(G8,Conversio!$C:$C,Conversio!$D:$D,"No trobat",0) -> ADMINISTRACIO EMPRESA | I8: 541 | J8: =I8/60 -> 9.0166667 | K8: 18 | L8: =J8*K8 -> 162.3
A9: 46143 | B9: CHRISTIAN OMAR ROJAS DE LA CRUZ | C9: Plural cuina, Greenvita cuina, Responsable cuina Plural | D9: =_xlfn.XLOOKUP(C9,Conversio!$B:$B,Conversio!$C:$C,"No trobat",0) -> CCR00009 | E9: =_xlfn.XLOOKUP(D9,Conversio!$C:$C,Conversio!$D:$D,"No trobat",0) -> RESTAURANT VALKIRIA | F9: Càtering | G9: =_xlfn.XLOOKUP(F9,Conversio!$B:$B,Conversio!$C:$C,"No trobat",0) -> CCE00000 | H9: =_xlfn.XLOOKUP(G9,Conversio!$C:$C,Conversio!$D:$D,"No trobat",0) -> ADMINISTRACIO EMPRESA | I9: 1290 | J9: =I9/60 -> 21.5 | K9: 18 | L9: =J9*K9 -> 387
A10: 46143 | B10: CYNTHIA OSARU | C10: Camp Nou cuina, Cuiner/a Camp Nou | D10: =_xlfn.XLOOKUP(C10,Conversio!$B:$B,Conversio!$C:$C,"No trobat",0) -> CCR00004 | E10: =_xlfn.XLOOKUP(D10,Conversio!$C:$C,Conversio!$D:$D,"No trobat",0) -> RESTAURANT CAMP NOU | F10: Càtering | G10: =_xlfn.XLOOKUP(F10,Conversio!$B:$B,Conversio!$C:$C,"No trobat",0) -> CCE00000 | H10: =_xlfn.XLOOKUP(G10,Conversio!$C:$C,Conversio!$D:$D,"No trobat",0) -> ADMINISTRACIO EMPRESA | I10: 540 | J10: =I10/60 -> 9 | K10: 18 | L10: =J10*K10 -> 162
A11: 46143 | B11: DANIELA MARIN MUÑOZ | C11: Juno sala, Cambrer/a Juno, Juno House, Serveis externs | D11: =_xlfn.XLOOKUP(C11,Conversio!$B:$B,Conversio!$C:$C,"No trobat",0) -> CCR00009 | E11: =_xlfn.XLOOKUP(D11,Conversio!$C:$C,Conversio!$D:$D,"No trobat",0) -> RESTAURANT VALKIRIA | F11: Càtering | G11: =_xlfn.XLOOKUP(F11,Conversio!$B:$B,Conversio!$C:$C,"No trobat",0) -> CCE00000 | H11: =_xlfn.XLOOKUP(G11,Conversio!$C:$C,Conversio!$D:$D,"No trobat",0) -> ADMINISTRACIO EMPRESA | I11: 1844 | J11: =I11/60 -> 30.733333 | K11: 18 | L11: =J11*K11 -> 553.2
A12: 46143 | B12: GABRIEL ALEXIS IBACACHE ARAYA | C12: Soliver sala, Cambrer/a Soliver | D12: =_xlfn.XLOOKUP(C12,Conversio!$B:$B,Conversio!$C:$C,"No trobat",0) -> CCR00010 | E12: =_xlfn.XLOOKUP(D12,Conversio!$C:$C,Conversio!$D:$D,"No trobat",0) -> RESTAURANT SOLIVER | F12: Càtering | G12: =_xlfn.XLOOKUP(F12,Conversio!$B:$B,Conversio!$C:$C,"No trobat",0) -> CCE00000 | H12: =_xlfn.XLOOKUP(G12,Conversio!$C:$C,Conversio!$D:$D,"No trobat",0) -> ADMINISTRACIO EMPRESA | I12: 3822 | J12: =I12/60 -> 63.7 | K12: 18 | L12: =J12*K12 -> 1146.6
A13: 46143 | B13: GERARDO ANTONIO PEREZ LOPEZ | C13: La Masia cuina, La Masia, Cuiner/a Masia | D13: =_xlfn.XLOOKUP(C13,Conversio!$B:$B,Conversio!$C:$C,"No trobat",0) -> CCR00003 | E13: =_xlfn.XLOOKUP(D13,Conversio!$C:$C,Conversio!$D:$D,"No trobat",0) -> RESTAURANT LA MASIA D'ESPLUGUES | F13: Càtering | G13: =_xlfn.XLOOKUP(F13,Conversio!$B:$B,Conversio!$C:$C,"No trobat",0) -> CCE00000 | H13: =_xlfn.XLOOKUP(G13,Conversio!$C:$C,Conversio!$D:$D,"No trobat",0) -> ADMINISTRACIO EMPRESA | I13: 300 | J13: =I13/60 -> 5 | K13: 18 | L13: =J13*K13 -> 90
... A54: 46143 | B54: JOSE ANTONIO OCHOA SANCHEZ | C54: Bases cuina central, Bases cuina central | D54: =_xlfn.XLOOKUP(C54,Conversio!$B:$B,Conversio!$C:$C,"No trobat",0) -> CCC00007 | E54: =_xlfn.XLOOKUP(D54,Conversio!$C:$C,Conversio!$D:$D,"No trobat",0) -> CUINA CENTRAL | F54: Cuina Càtering | G54: =_xlfn.XLOOKUP(F54,Conversio!$B:$B,Conversio!$C:$C,"No trobat",0) -> CCE00000 | H54: =_xlfn.XLOOKUP(G54,Conversio!$C:$C,Conversio!$D:$D,"No trobat",0) -> ADMINISTRACIO EMPRESA | I54: 14311 | J54: =I54/60 -> 238.51667 | K54: 18 | L54: =J54*K54 -> 4293.3
A55: 46143 | B55: JOSE DELIO REYES GUZMAN | D55: =_xlfn.XLOOKUP(C55,Conversio!$B:$B,Conversio!$C:$C,"No trobat",0) -> No trobat | E55: =_xlfn.XLOOKUP(D55,Conversio!$C:$C,Conversio!$D:$D,"No trobat",0) -> No trobat | F55: Cuina Càtering | G55: =_xlfn.XLOOKUP(F55,Conversio!$B:$B,Conversio!$C:$C,"No trobat",0) -> CCE00000 | H55: =_xlfn.XLOOKUP(G55,Conversio!$C:$C,Conversio!$D:$D,"No trobat",0) -> ADMINISTRACIO EMPRESA | I55: 1125 | J55: =I55/60 -> 18.75 | K55: 18 | L55: =J55*K55 -> 337.5
A56: 46143 | B56: LESYA MANKO | C56: Soliver cuina, Responsable cuina Soliver | D56: =_xlfn.XLOOKUP(C56,Conversio!$B:$B,Conversio!$C:$C,"No trobat",0) -> CCR00010 | E56: =_xlfn.XLOOKUP(D56,Conversio!$C:$C,Conversio!$D:$D,"No trobat",0) -> RESTAURANT SOLIVER | F56: Cuina Càtering | G56: =_xlfn.XLOOKUP(F56,Conversio!$B:$B,Conversio!$C:$C,"No trobat",0) -> CCE00000 | H56: =_xlfn.XLOOKUP(G56,Conversio!$C:$C,Conversio!$D:$D,"No trobat",0) -> ADMINISTRACIO EMPRESA | I56: 2950 | J56: =I56/60 -> 49.166667 | K56: 18 | L56: =J56*K56 -> 885
A57: 46143 | B57: MARIA BEGOÑA GUILLEN BORBOLLA | C57: Events cuina central, Events cuina central | D57: =_xlfn.XLOOKUP(C57,Conversio!$B:$B,Conversio!$C:$C,"No trobat",0) -> CCC00007 | E57: =_xlfn.XLOOKUP(D57,Conversio!$C:$C,Conversio!$D:$D,"No trobat",0) -> CUINA CENTRAL | F57: Cuina Càtering | G57: =_xlfn.XLOOKUP(F57,Conversio!$B:$B,Conversio!$C:$C,"No trobat",0) -> CCE00000 | H57: =_xlfn.XLOOKUP(G57,Conversio!$C:$C,Conversio!$D:$D,"No trobat",0) -> ADMINISTRACIO EMPRESA | I57: 3707 | J57: =I57/60 -> 61.783333 | K57: 18 | L57: =J57*K57 -> 1112.1
A58: 46143 | B58: MAURICIO DIAS GRILLO | C58: Precuinats cuina central, Precuinats cuina central | D58: =_xlfn.XLOOKUP(C58,Conversio!$B:$B,Conversio!$C:$C,"No trobat",0) -> CCP00014 | E58: =_xlfn.XLOOKUP(D58,Conversio!$C:$C,Conversio!$D:$D,"No trobat",0) -> CENTRE PRODUCCIO | F58: Cuina Càtering | G58: =_xlfn.XLOOKUP(F58,Conversio!$B:$B,Conversio!$C:$C,"No trobat",0) -> CCE00000 | H58: =_xlfn.XLOOKUP(G58,Conversio!$C:$C,Conversio!$D:$D,"No trobat",0) -> ADMINISTRACIO EMPRESA | I58: 1081 | J58: =I58/60 -> 18.016667 | K58: 18 | L58: =J58*K58 -> 324.3
A59: 46143 | B59: MOHAMMED CHAATOUF BOUFTILA | C59: Font de la Canya cuina, Responsable cuina FDLC | D59: =_xlfn.XLOOKUP(C59,Conversio!$B:$B,Conversio!$C:$C,"No trobat",0) -> CCR00008 | E59: =_xlfn.XLOOKUP(D59,Conversio!$C:$C,Conversio!$D:$D,"No trobat",0) -> RESTAURANT FONT DE LA CANYA | F59: Cuina Càtering | G59: =_xlfn.XLOOKUP(F59,Conversio!$B:$B,Conversio!$C:$C,"No trobat",0) -> CCE00000 | H59: =_xlfn.XLOOKUP(G59,Conversio!$C:$C,Conversio!$D:$D,"No trobat",0) -> ADMINISTRACIO EMPRESA | I59: 608 | J59: =I59/60 -> 10.133333 | K59: 18 | L59: =J59*K59 -> 182.4
A60: 46143 | B60: NADIA MANKO | C60: Soliver cuina, Cuiner/a Soliver | D60: =_xlfn.XLOOKUP(C60,Conversio!$B:$B,Conversio!$C:$C,"No trobat",0) -> CCR00010 | E60: =_xlfn.XLOOKUP(D60,Conversio!$C:$C,Conversio!$D:$D,"No trobat",0) -> RESTAURANT SOLIVER | F60: Cuina Càtering | G60: =_xlfn.XLOOKUP(F60,Conversio!$B:$B,Conversio!$C:$C,"No trobat",0) -> CCE00000 | H60: =_xlfn.XLOOKUP(G60,Conversio!$C:$C,Conversio!$D:$D,"No trobat",0) -> ADMINISTRACIO EMPRESA | I60: 2689 | J60: =I60/60 -> 44.816667 | K60: 18 | L60: =J60*K60 -> 806.7
A61: 46143 | B61: NANCY ESMERALDA AGUILAR PALMA | C61: Bases cuina central, Bases cuina central | D61: =_xlfn.XLOOKUP(C61,Conversio!$B:$B,Conversio!$C:$C,"No trobat",0) -> CCC00007 | E61: =_xlfn.XLOOKUP(D61,Conversio!$C:$C,Conversio!$D:$D,"No trobat",0) -> CUINA CENTRAL | F61: Cuina Càtering | G61: =_xlfn.XLOOKUP(F61,Conversio!$B:$B,Conversio!$C:$C,"No trobat",0) -> CCE00000 | H61: =_xlfn.XLOOKUP(G61,Conversio!$C:$C,Conversio!$D:$D,"No trobat",0) -> ADMINISTRACIO EMPRESA | I61: 691 | J61: =I61/60 -> 11.516667 | K61: 18 | L61: =J61*K61 -> 207.3
A62: 46143 | B62: NEUS JUVÉ MARTINEZ | C62: Events cuina central, Events cuina central | D62: =_xlfn.XLOOKUP(C62,Conversio!$B:$B,Conversio!$C:$C,"No trobat",0) -> CCC00007 | E62: =_xlfn.XLOOKUP(D62,Conversio!$C:$C,Conversio!$D:$D,"No trobat",0) -> CUINA CENTRAL | F62: Cuina Càtering | G62: =_xlfn.XLOOKUP(F62,Conversio!$B:$B,Conversio!$C:$C,"No trobat",0) -> CCE00000 | H62: =_xlfn.XLOOKUP(G62,Conversio!$C:$C,Conversio!$D:$D,"No trobat",0) -> ADMINISTRACIO EMPRESA | I62: 3556 | J62: =I62/60 -> 59.266667 | K62: 18 | L62: =J62*K62 -> 1066.8
A63: 46143 | B63: RACHID BAKALI ALLOUCHI | C63: Events cuina central, Events cuina central | D63: =_xlfn.XLOOKUP(C63,Conversio!$B:$B,Conversio!$C:$C,"No trobat",0) -> CCC00007 | E63: =_xlfn.XLOOKUP(D63,Conversio!$C:$C,Conversio!$D:$D,"No trobat",0) -> CUINA CENTRAL | F63: Cuina Càtering | G63: =_xlfn.XLOOKUP(F63,Conversio!$B:$B,Conversio!$C:$C,"No trobat",0) -> CCE00000 | H63: =_xlfn.XLOOKUP(G63,Conversio!$C:$C,Conversio!$D:$D,"No trobat",0) -> ADMINISTRACIO EMPRESA | I63: 3054 | J63: =I63/60 -> 50.9 | K63: 18 | L63: =J63*K63 -> 916.2
A64: 46143 | B64: SABAH NOUNOUH | C64: Events cuina central, Events cuina central | D64: =_xlfn.XLOOKUP(C64,Conversio!$B:$B,Conversio!$C:$C,"No trobat",0) -> CCC00007 | E64: =_xlfn.XLOOKUP(D64,Conversio!$C:$C,Conversio!$D:$D,"No trobat",0) -> CUINA CENTRAL | F64: Cuina Càtering | G64: =_xlfn.XLOOKUP(F64,Conversio!$B:$B,Conversio!$C:$C,"No trobat",0) -> CCE00000 | H64: =_xlfn.XLOOKUP(G64,Conversio!$C:$C,Conversio!$D:$D,"No trobat",0) -> ADMINISTRACIO EMPRESA | I64: 1876 | J64: =I64/60 -> 31.266667 | K64: 18 | L64: =J64*K64 -> 562.8
A65: 46143 | B65: SARA GUTIERREZ GARCIA | C65: Events cuina central, Events cuina central | D65: =_xlfn.XLOOKUP(C65,Conversio!$B:$B,Conversio!$C:$C,"No trobat",0) -> CCC00007 | E65: =_xlfn.XLOOKUP(D65,Conversio!$C:$C,Conversio!$D:$D,"No trobat",0) -> CUINA CENTRAL | F65: Cuina Càtering | G65: =_xlfn.XLOOKUP(F65,Conversio!$B:$B,Conversio!$C:$C,"No trobat",0) -> CCE00000 | H65: =_xlfn.XLOOKUP(G65,Conversio!$C:$C,Conversio!$D:$D,"No trobat",0) -> ADMINISTRACIO EMPRESA | I65: 1327 | J65: =I65/60 -> 22.116667 | K65: 18 | L65: =J65*K65 -> 398.1
A66: 46143 | B66: SERGIO DELGADO ACOSTA | C66: Camp Nou cuina, Cuiner/a Camp Nou | D66: =_xlfn.XLOOKUP(C66,Conversio!$B:$B,Conversio!$C:$C,"No trobat",0) -> CCR00004 | E66: =_xlfn.XLOOKUP(D66,Conversio!$C:$C,Conversio!$D:$D,"No trobat",0) -> RESTAURANT CAMP NOU | F66: Cuina Càtering | G66: =_xlfn.XLOOKUP(F66,Conversio!$B:$B,Conversio!$C:$C,"No trobat",0) -> CCE00000 | H66: =_xlfn.XLOOKUP(G66,Conversio!$C:$C,Conversio!$D:$D,"No trobat",0) -> ADMINISTRACIO EMPRESA | I66: 360 | J66: =I66/60 -> 6 | K66: 18 | L66: =J66*K66 -> 108
A67: 46143 | B67: SERGIO MARTINEZ MOLEDO | C67: Orígens cuina, Cuiner/a Orígens | D67: =_xlfn.XLOOKUP(C67,Conversio!$B:$B,Conversio!$C:$C,"No trobat",0) -> CCR00001 | E67: =_xlfn.XLOOKUP(D67,Conversio!$C:$C,Conversio!$D:$D,"No trobat",0) -> RESTAURANT ORIGENS | F67: Cuina Càtering | G67: =_xlfn.XLOOKUP(F67,Conversio!$B:$B,Conversio!$C:$C,"No trobat",0) -> CCE00000 | H67: =_xlfn.XLOOKUP(G67,Conversio!$C:$C,Conversio!$D:$D,"No trobat",0) -> ADMINISTRACIO EMPRESA | I67: 720 | J67: =I67/60 -> 12 | K67: 18 | L67: =J67*K67 -> 216
A68: 46143 | B68: SOULAIMANE EL BOUZIDI JABBARI | C68: Events cuina central, Responsable events cuina central | D68: =_xlfn.XLOOKUP(C68,Conversio!$B:$B,Conversio!$C:$C,"No trobat",0) -> CCC00008 | E68: =_xlfn.XLOOKUP(D68,Conversio!$C:$C,Conversio!$D:$D,"No trobat",0) -> SERVEIS EXTERNS | F68: Cuina Càtering | G68: =_xlfn.XLOOKUP(F68,Conversio!$B:$B,Conversio!$C:$C,"No trobat",0) -> CCE00000 | H68: =_xlfn.XLOOKUP(G68,Conversio!$C:$C,Conversio!$D:$D,"No trobat",0) -> ADMINISTRACIO EMPRESA | I68: 1168 | J68: =I68/60 -> 19.466667 | K68: 18 | L68: =J68*K68 -> 350.4
A69: 46143 | B69: CHAYMAE BIBIH KAMROUCHI | C69: Orígens cuina, Cuiner/a Orígens | D69: =_xlfn.XLOOKUP(C69,Conversio!$B:$B,Conversio!$C:$C,"No trobat",0) -> CCR00001 | E69: =_xlfn.XLOOKUP(D69,Conversio!$C:$C,Conversio!$D:$D,"No trobat",0) -> RESTAURANT ORIGENS | F69: Cuina Central | G69: =_xlfn.XLOOKUP(F69,Conversio!$B:$B,Conversio!$C:$C,"No trobat",0) -> CCC00007 | H69: =_xlfn.XLOOKUP(G69,Conversio!$C:$C,Conversio!$D:$D,"No trobat",0) -> CUINA CENTRAL | I69: 7206 | J69: =I69/60 -> 120.1 | K69: 18 | L69: =J69*K69 -> 2161.8 | M69: =K69*L69 -> 38912.4
A70: 46143 | B70: CHRISTIAN OMAR ROJAS DE LA CRUZ | C70: Plural cuina, Greenvita cuina, Responsable cuina Plural | D70: =_xlfn.XLOOKUP(C70,Conversio!$B:$B,Conversio!$C:$C,"No trobat",0) -> CCR00009 | E70: =_xlfn.XLOOKUP(D70,Conversio!$C:$C,Conversio!$D:$D,"No trobat",0) -> RESTAURANT VALKIRIA | F70: Fira BCN | G70: =_xlfn.XLOOKUP(F70,Conversio!$B:$B,Conversio!$C:$C,"No trobat",0) -> CCR00011 | H70: =_xlfn.XLOOKUP(G70,Conversio!$C:$C,Conversio!$D:$D,"No trobat",0) -> GREEN VITA | I70: 5700 | J70: =I70/60 -> 95 | K70: 18 | L70: =J70*K70 -> 1710
A71: 46143 | B71: GERARDO ANTONIO PEREZ LOPEZ | C71: La Masia cuina, La Masia, Cuiner/a Masia | D71: =_xlfn.XLOOKUP(C71,Conversio!$B:$B,Conversio!$C:$C,"No trobat",0) -> CCR00003 | E71: =_xlfn.XLOOKUP(D71,Conversio!$C:$C,Conversio!$D:$D,"No trobat",0) -> RESTAURANT LA MASIA D'ESPLUGUES | F71: Fira BCN | G71: =_xlfn.XLOOKUP(F71,Conversio!$B:$B,Conversio!$C:$C,"No trobat",0) -> CCR00011 | H71: =_xlfn.XLOOKUP(G71,Conversio!$C:$C,Conversio!$D:$D,"No trobat",0) -> GREEN VITA | I71: 1440 | J71: =I71/60 -> 24 | K71: 18 | L71: =J71*K71 -> 432
A72: 46143 | B72: VICENTE ALBORNOZ | C72: Camp Nou cuina, Cuiner/a Camp Nou | D72: =_xlfn.XLOOKUP(C72,Conversio!$B:$B,Conversio!$C:$C,"No trobat",0) -> CCR00004 | E72: =_xlfn.XLOOKUP(D72,Conversio!$C:$C,Conversio!$D:$D,"No trobat",0) -> RESTAURANT CAMP NOU | F72: Fira BCN | G72: =_xlfn.XLOOKUP(F72,Conversio!$B:$B,Conversio!$C:$C,"No trobat",0) -> CCR00011 | H72: =_xlfn.XLOOKUP(G72,Conversio!$C:$C,Conversio!$D:$D,"No trobat",0) -> GREEN VITA | I72: 1500 | J72: =I72/60 -> 25 | K72: 18 | L72: =J72*K72 -> 450 | M72: =K72*L72 -> 8100
A73: 46143 | B73: HASSANA ABDALESS | C73: Mirador cuina, Cuiner/a Mirador | D73: =_xlfn.XLOOKUP(C73,Conversio!$B:$B,Conversio!$C:$C,"No trobat",0) -> CCR00006 | E73: =_xlfn.XLOOKUP(D73,Conversio!$C:$C,Conversio!$D:$D,"No trobat",0) -> RESTAURANT MIRADOR DE LES CAVES | F73: Font de la Canya | G73: =_xlfn.XLOOKUP(F73,Conversio!$B:$B,Conversio!$C:$C,"No trobat",0) -> CCR00008 | H73: =_xlfn.XLOOKUP(G73,Conversio!$C:$C,Conversio!$D:$D,"No trobat",0) -> RESTAURANT FONT DE LA CANYA | I73: 789 | J73: =I73/60 -> 13.15 | K73: 18 | L73: =J73*K73 -> 236.7
A74: 46143 | B74: MOHAMMED CHAATOUF BOUFTILA | C74: Font de la Canya cuina, Responsable cuina FDLC | D74: =_xlfn.XLOOKUP(C74,Conversio!$B:$B,Conversio!$C:$C,"No trobat",0) -> CCR00008 | E74: =_xlfn.XLOOKUP(D74,Conversio!$C:$C,Conversio!$D:$D,"No trobat",0) -> RESTAURANT FONT DE LA CANYA | F74: Font de la Canya | G74: =_xlfn.XLOOKUP(F74,Conversio!$B:$B,Conversio!$C:$C,"No trobat",0) -> CCR00008 | H74: =_xlfn.XLOOKUP(G74,Conversio!$C:$C,Conversio!$D:$D,"No trobat",0) -> RESTAURANT FONT DE LA CANYA | I74: 388 | J74: =I74/60 -> 6.4666667 | K74: 18 | L74: =J74*K74 -> 116.4 | M74: =K74*L74 -> 2095.2
A75: 46143 | B75: CYNTHIA OSARU | C75: Camp Nou cuina, Cuiner/a Camp Nou | D75: =_xlfn.XLOOKUP(C75,Conversio!$B:$B,Conversio!$C:$C,"No trobat",0) -> CCR00004 | E75: =_xlfn.XLOOKUP(D75,Conversio!$C:$C,Conversio!$D:$D,"No trobat",0) -> RESTAURANT CAMP NOU | F75: Juno | G75: =_xlfn.XLOOKUP(F75,Conversio!$B:$B,Conversio!$C:$C,"No trobat",0) -> CCR00007 | H75: =_xlfn.XLOOKUP(G75,Conversio!$C:$C,Conversio!$D:$D,"No trobat",0) -> RESTAURANT JUNO HOUSE | I75: 300 | J75: =I75/60 -> 5 | K75: 18 | L75: =J75*K75 -> 90
A76: 46143 | B76: PATRICIA PORTILLO TERENCIO | C76: Camp Nou sala, Cambrer/a Camp Nou | D76: =_xlfn.XLOOKUP(C76,Conversio!$B:$B,Conversio!$C:$C,"No trobat",0) -> CCR00004 | E76: =_xlfn.XLOOKUP(D76,Conversio!$C:$C,Conversio!$D:$D,"No trobat",0) -> RESTAURANT CAMP NOU | F76: Juno | G76: =_xlfn.XLOOKUP(F76,Conversio!$B:$B,Conversio!$C:$C,"No trobat",0) -> CCR00007 | H76: =_xlfn.XLOOKUP(G76,Conversio!$C:$C,Conversio!$D:$D,"No trobat",0) -> RESTAURANT JUNO HOUSE | I76: 565 | J76: =I76/60 -> 9.4166667 | K76: 18 | L76: =J76*K76 -> 169.5
A77: 46143 | B77: VICENTE ALBORNOZ | C77: Camp Nou cuina, Cuiner/a Camp Nou | D77: =_xlfn.XLOOKUP(C77,Conversio!$B:$B,Conversio!$C:$C,"No trobat",0) -> CCR00004 | E77: =_xlfn.XLOOKUP(D77,Conversio!$C:$C,Conversio!$D:$D,"No trobat",0) -> RESTAURANT CAMP NOU | F77: Juno | G77: =_xlfn.XLOOKUP(F77,Conversio!$B:$B,Conversio!$C:$C,"No trobat",0) -> CCR00007 | H77: =_xlfn.XLOOKUP(G77,Conversio!$C:$C,Conversio!$D:$D,"No trobat",0) -> RESTAURANT JUNO HOUSE | I77: 300 | J77: =I77/60 -> 5 | K77: 18 | L77: =J77*K77 -> 90 | M77: =K77*L77 -> 1620
A78: 46143 | B78: MELVIN ALBERTO SANCHEZ RODRIGUEZ | C78: Producció, Tècnic/a producció | D78: =_xlfn.XLOOKUP(C78,Conversio!$B:$B,Conversio!$C:$C,"No trobat",0) -> CCC00005 | E78: =_xlfn.XLOOKUP(D78,Conversio!$C:$C,Conversio!$D:$D,"No trobat",0) -> OFICINES CAL BLAY | F78: Logística | G78: =_xlfn.XLOOKUP(F78,Conversio!$B:$B,Conversio!$C:$C,"No trobat",0) -> CCC00004 | H78: =_xlfn.XLOOKUP(G78,Conversio!$C:$C,Conversio!$D:$D,"No trobat",0) -> LOGISTICA | I78: 851 | J78: =I78/60 -> 14.183333 | K78: 18 | L78: =J78*K78 -> 255.3 | M78: =K78*L78 -> 4595.4
A79: 46143 | B79: ARAYA SAEZ LIDON | C79: Plural sala, Cambrer/a Plural | D79: =_xlfn.XLOOKUP(C79,Conversio!$B:$B,Conversio!$C:$C,"No trobat",0) -> CCR00009 | E79: =_xlfn.XLOOKUP(D79,Conversio!$C:$C,Conversio!$D:$D,"No trobat",0) -> RESTAURANT VALKIRIA | F79: Masia | G79: =_xlfn.XLOOKUP(F79,Conversio!$B:$B,Conversio!$C:$C,"No trobat",0) -> CCR00003 | H79: =_xlfn.XLOOKUP(G79,Conversio!$C:$C,Conversio!$D:$D,"No trobat",0) -> RESTAURANT LA MASIA D'ESPLUGUES | I79: 1650 | J79: =I79/60 -> 27.5 | K79: 18 | L79: =J79*K79 -> 495
A80: 46143 | B80: CHRISTIAN OMAR ROJAS DE LA CRUZ | C80: Plural cuina, Greenvita cuina, Responsable cuina Plural | D80: =_xlfn.XLOOKUP(C80,Conversio!$B:$B,Conversio!$C:$C,"No trobat",0) -> CCR00009 | E80: =_xlfn.XLOOKUP(D80,Conversio!$C:$C,Conversio!$D:$D,"No trobat",0) -> RESTAURANT VALKIRIA | F80: Masia | G80: =_xlfn.XLOOKUP(F80,Conversio!$B:$B,Conversio!$C:$C,"No trobat",0) -> CCR00003 | H80: =_xlfn.XLOOKUP(G80,Conversio!$C:$C,Conversio!$D:$D,"No trobat",0) -> RESTAURANT LA MASIA D'ESPLUGUES | I80: 960 | J80: =I80/60 -> 16 | K80: 18 | L80: =J80*K80 -> 288
...

Sheet employee_by_project_costs-2026-
A1: Empleado | B1: ID externo de empleado | C1: Organizaciones | D1: ID de proyecto | E1: ID del proyecto padre | F1: Proyecto | G1: Minutos | H1: Coste total | I1: Coste medio hora | J1: Gastos - Total | K1: Gastos - Despeses gestió empresa | L1: Gastos - Kilometraje
A2: AIDA JACKELINE PUCHA LAIÑO | B2: 941 | C2: Cuina adminsitració, Cuina adminsitració | D2: 15734340 | F2: Cuina Càtering | G2: 3435
A3: AISSA RABBOUH | B3: 156 | C3: Mirador cuina, Cuiner/a Mirador | D3: 15734340 | F3: Cuina Càtering | G3: 600
A4: AISSA RABBOUH | B4: 156 | C4: Mirador cuina, Cuiner/a Mirador | D4: 15734332 | F4: Mirador | G4: 472
A5: AISSA RABBOUH | B5: 156 | C5: Mirador cuina, Cuiner/a Mirador | D5: 15734330 | F5: Nàutic | G5: 1578
A6: ALAN GARCIA SANCHEZ | B6: 1085 | C6: Recepció cuina central, Recepció cuina central | D6: 15734340 | F6: Cuina Càtering | G6: 2888
A7: ANA ISABEL CABELLO RODRIGUEZ | B7: 1090 | C7: Soliver sala, Cambrer/a Soliver | D7: 15769388 | F7: Càtering | G7: 3081
A8: ANDREA MARGARITA AMPOSTA MERO | B8: 687 | C8: Events cuina central, Events cuina central | D8: 15734340 | F8: Cuina Càtering | G8: 1841
A9: ANGELA ESTELA FLORES MEDRANO | B9: 979 | C9: Precuinats cuina central, Precuinats cuina central | D9: 15734340 | F9: Cuina Càtering | G9: 583
A10: ANTONIO JOSE PEREZ MARIN | B10: 1009 | C10: Sortides càtering, Sortides càtering | D10: 15734340 | F10: Cuina Càtering | G10: 14703
A11: ARAYA SAEZ LIDON | B11: 111022 | C11: Plural sala, Cambrer/a Plural | D11: 15734336 | F11: Camp Nou | G11: 360
A12: ARAYA SAEZ LIDON | B12: 111022 | C12: Plural sala, Cambrer/a Plural | D12: 15769388 | F12: Càtering | G12: 970
A13: ARAYA SAEZ LIDON | B13: 111022 | C13: Plural sala, Cambrer/a Plural | D13: 15734333 | F13: Masia | G13: 1650
... A62: JOSE ANTONIO OCHOA SANCHEZ | B62: 663 | C62: Bases cuina central, Bases cuina central | D62: 15734340 | F62: Cuina Càtering | G62: 14311
A63: JOSE DELIO REYES GUZMAN | B63: 1058 | D63: 15734340 | F63: Cuina Càtering | G63: 1125
A64: JUAN MARTIN GOMEZ VASQUEZ | B64: 138 | C64: Tarraco cuina, Responsable cuina Tarraco | D64: 15734335 | F64: Tarraco | G64: 6173
A65: LESYA MANKO | B65: 1093 | C65: Soliver cuina, Responsable cuina Soliver | D65: 15734340 | F65: Cuina Càtering | G65: 2950
A66: LIDA LILIAN SIGAS NIETO | B66: 450022 | C66: Juno sala, Responsable sala Juno, Juno House | D66: 15734336 | F66: Camp Nou | G66: 442
A67: LUIS FERNANDO GOMEZ FLOREZ | B67: 515 | C67: La Masia sala, La Masia, Cambrer/a Masia | D67: 15769388 | F67: Càtering | G67: 2173
A68: MARC DOMENECH VILA | B68: 290015 | C68: La Masia cuina, La Masia, Cuiner/a Masia | D68: 15769388 | F68: Càtering | G68: 270
A69: MARIA BEGOÑA GUILLEN BORBOLLA | B69: 898 | C69: Events cuina central, Events cuina central | D69: 15734340 | F69: Cuina Càtering | G69: 3707
A70: MARIA BEGOÑA PINILLOS ARAGAY | B70: 985 | C70: Juno sala, Cambrer/a Juno, Juno House | D70: 15734333 | F70: Masia | G70: 808
A71: MARIA ISABEL GONZALEZ FERNANDEZ | B71: 313 | C71: Mirador sala, Cambrer/a Mirador | D71: 15734330 | F71: Nàutic | G71: 632
A72: MAURICIO DIAS GRILLO | B72: 521 | C72: Precuinats cuina central, Precuinats cuina central | D72: 15769388 | F72: Càtering | G72: 3863
A73: MAURICIO DIAS GRILLO | B73: 521 | C73: Precuinats cuina central, Precuinats cuina central | D73: 15734340 | F73: Cuina Càtering | G73: 1081
A74: MELVIN ALBERTO SANCHEZ RODRIGUEZ | B74: 1022 | C74: Producció, Tècnic/a producció | D74: 15776283 | F74: Logística | G74: 851
A75: MIRIAM CASTRO ORTIZ | B75: 251 | C75: Decoració | D75: 15769388 | F75: Càtering | G75: 1399
... A108: YASSINE CHARA | B108: 134 | C108: Tarraco sala, Responsable sala Tarraco | D108: 15739585 | F108: Tarraco Festivals | G108: 252

Sheet Conversio
B2: Plural sala, Cambrer/a Plural | C2: CCR00009 | D2: RESTAURANT VALKIRIA
B3: Juno sala, Cambrer/a Juno, Juno House | C3: CCR00007 | D3: RESTAURANT JUNO HOUSE
B4: La Masia sala, La Masia, Cambrer/a Masia | C4: CCR00003 | D4: RESTAURANT LA MASIA D'ESPLUGUES
B5: Juno sala, Responsable sala Juno, Juno House | C5: CCR00007 | D5: RESTAURANT JUNO HOUSE
B6: Soliver sala, Cambrer/a Soliver | C6: CCR00010 | D6: RESTAURANT SOLIVER
B7: Orígens cuina, Cuiner/a Orígens | C7: CCR00001 | D7: RESTAURANT ORIGENS
B8: Plural cuina, Greenvita cuina, Responsable cuina Plural | C8: CCR00009 | D8: RESTAURANT VALKIRIA
B9: Camp Nou cuina, Cuiner/a Camp Nou | C9: CCR00004 | D9: RESTAURANT CAMP NOU
B10: Juno sala, Cambrer/a Juno, Juno House, Serveis externs | C10: CCR00009 | D10: RESTAURANT VALKIRIA
B11: La Masia cuina, La Masia, Cuiner/a Masia | C11: CCR00003 | D11: RESTAURANT LA MASIA D'ESPLUGUES
B12: Cuina Central, Sortides càtering | C12: CCC00007 | D12: CUINA CENTRAL
B13: Precuinats cuina central, Precuinats cuina central | C13: CCP00014 | D13: CENTRE PRODUCCIO
... B61: Juno sala, Cambrer/a Juno | C61: CCR00007 | D61: RESTAURANT JUNO HOUSE
