Workbook

Sheet Origens
B1: ORIGENS | C1: Gener | D1: Febrer | E1: Març | F1: Abril | G1: Maig | H1: Juny | I1: Juliol | J1: Agost | K1: Setembre | L1: Octubre | M1: Novembre | N1: Desembre | O1: TOTAL | P1: %
B3: . VENDES | C3: 18693.99 | D3: 19741.34 | E3: 35815.3 | F3: 28671.8 | G3: 33967.08 | O3: =SUM(C3:N3) -> 136889.51
B4: . PRESTACIO DE SEVEIS | C4: 0 | D4: 0 | E4: 0 | F4: 0 | G4: 0 | O4: =SUM(C4:N4) -> 0
B5: . ALTRES INGRESSOS | C5: 0 | D5: 0 | E5: 0 | F5: 0 | G5: 0 | O5: =SUM(C5:N5) -> 0
B6: . VARIACIO EXISTENCIES | C6: 0 | D6: 0 | E6: 0 | F6: 0 | G6: 0 | O6: =SUM(C6:N6) -> 0
B7: TOTAL INGRESSOS EXPLOTACIO | C7: 18693.99 | D7: 19741.34 | E7: 35815.3 | F7: 28671.8 | G7: 33967.08 | O7: =SUM(C7:N7) -> 136889.51
B8: . COMPRES | C8: -5048.9 | D8: -4678.78 | E8: -7125.8 | F8: -8289.26 | G8: -8643.92 | O8: =SUM(C8:N8) -> -33786.66
B9: . ALTRES APROVISIONAMENTS | C9: -467.42 | D9: -430.14 | E9: -183.65 | F9: -735.07 | G9: -436.94 | O9: =SUM(C9:N9) -> -2253.22
B10: . CONSUMS INTERNS | C10: -2572.47 | D10: -2903.9 | E10: -4619.8 | F10: -4143.95 | G10: -7297.03 | O10: =SUM(C10:N10) -> -21537.15
B11: . VARIACIO EXISTENICIES COMPRES | C11: 0 | D11: 0 | E11: 0 | F11: 0 | G11: 0 | O11: =SUM(C11:N11) -> 0
B12: TOTAL COMPRES | C12: =SUM(C8:C11) -> -8088.79 | D12: =SUM(D8:D11) -> -8012.82 | E12: =SUM(E8:E11) -> -11929.25 | F12: =SUM(F8:F11) -> -13168.28 | G12: =SUM(G8:G11) -> -16377.89 | H12: =SUM(H8:H11) -> 0 | I12: =SUM(I8:I11) -> 0 | J12: =SUM(J8:J11) -> 0 | ... N12: =SUM(N8:N11) -> 0 | O12: =SUM(C12:N12) -> -57577.03 | P12: =O12/$O$7 -> -0.42060951
B13: MARGE BRUT TOTAL | C13: 13177.67 | D13: 14632.42 | E13: 27405.85 | F13: 19647.47 | G13: 25646.34 | O13: =SUM(C13:N13) -> 100509.75
B14: . SOUS I SALARIS | C14: -11714.42 | D14: -12669.86 | E14: -13398.3 | F14: -14208.23 | G14: -13870.79 | O14: =SUM(C14:N14) -> -65861.6
B15: . INDEMNITZACIONS | C15: 0 | D15: 0 | E15: 0 | F15: 0 | G15: 0 | O15: =SUM(C15:N15) -> 0
B16: . SEGURETAT SOCIAL | C16: -3935.15 | D16: -4606.24 | E16: -4790.16 | F16: -4731.84 | G16: -4438.09 | O16: =SUM(C16:N16) -> -22501.48
B17: . ALTRES DESPESES SOCIALS | C17: -56.98 | D17: 0 | E17: 0 | F17: -35.95 | G17: 0 | O17: =SUM(C17:N17) -> -92.93
B18: TOTAL COST SALARIAL | C18: =SUM(C14:C17) -> -15706.55 | D18: =SUM(D14:D17) -> -17276.1 | E18: =SUM(E14:E17) -> -18188.46 | F18: =SUM(F14:F17) -> -18976.02 | G18: =SUM(G14:G17) -> -18308.88 | H18: =SUM(H14:H17) -> 0 | I18: =SUM(I14:I17) -> 0 | J18: =SUM(J14:J17) -> 0 | ... N18: =SUM(N14:N17) -> 0 | O18: =SUM(C18:N18) -> -88456.01 | P18: =O18/$O$7 -> -0.64618545
B19: . ARRENDAMENTS I CANONS | C19: -203.12 | D19: 0 | E19: 0 | F19: 0 | G19: 0 | O19: =SUM(C19:N19) -> -203.12
B20: . REPARACIONS I CONSERVACIO | C20: -3254.51 | D20: 2145.21 | E20: -538.53 | F20: -1372.21 | G20: -797.99 | O20: =SUM(C20:N20) -> -3818.03
B21: . SERVEIS PROFESSIONALS | C21: -233.12 | D21: -270.41 | E21: -242.36 | F21: -303.56 | G21: -260.21 | O21: =SUM(C21:N21) -> -1309.66
B22: . TRANSPORTS | C22: 0 | D22: 0 | E22: 0 | F22: 0 | G22: 0 | O22: =SUM(C22:N22) -> 0
B23: . PRIMES D'ASSEGURANCES | C23: 0 | D23: -439.61 | E23: -439.61 | F23: -439.61 | G23: -439.61 | O23: =SUM(C23:N23) -> -1758.44
B24: . SERVEIS BANCARIS | C24: -78.93 | D24: -76.51 | E24: 1813.05 | F24: -98.49 | G24: -148.58 | O24: =SUM(C24:N24) -> 1410.54
B25: . PUBLICITAT I PROPAGANDA | C25: 0 | D25: 0 | E25: -138 | F25: -216.95 | G25: -10.74 | O25: =SUM(C25:N25) -> -365.69
B26: . SUBMINISTRAMENTS | C26: -4.5 | D26: -1904.5 | E26: -1900 | F26: -1903 | G26: -1591.65 | O26: =SUM(C26:N26) -> -7303.65
B27: . ALTRES DESPESES | C27: -297.85 | D27: -423.16 | E27: -225.1 | F27: -1165.83 | G27: -672.77 | O27: =SUM(C27:N27) -> -2784.71
B28: . ALTRES TRIBUTS | C28: 0 | D28: -1159.76 | E28: -1159.76 | F28: -1159.76 | G28: -1159.76 | O28: =SUM(C28:N28) -> -4639.04
B29: . DOTACIO PER INSOLVENCIA | C29: 0 | D29: 0 | E29: 0 | F29: 0 | G29: 0 | O29: =SUM(C29:N29) -> 0
B30: MOVIMENTS INTERNS | C30: 0 | D30: 0 | E30: 0 | F30: 0 | G30: 0 | O30: =SUM(C30:N30) -> 0
B31: TOTAL DESPESES GESTIO | C31: =SUM(C19:C30) -> -4072.03 | D31: =SUM(D19:D30) -> -2128.74 | E31: =SUM(E19:E30) -> -2830.31 | F31: =SUM(F19:F30) -> -6659.41 | G31: =SUM(G19:G30) -> -5081.31 | H31: =SUM(H19:H30) -> 0 | I31: =SUM(I19:I30) -> 0 | J31: =SUM(J19:J30) -> 0 | ... N31: =SUM(N19:N30) -> 0 | O31: =SUM(C31:N31) -> -20771.8 | P31: =O31/$O$7 -> -0.15174136
B32: TOTAL GESTIO + SALARIS | C32: =C31+C18 -> -19778.58 | D32: =D31+D18 -> -19404.84 | E32: =E31+E18 -> -21018.77 | F32: =F31+F18 -> -25635.43 | G32: =G31+G18 -> -23390.19 | H32: =H31+H18 -> 0 | I32: =I31+I18 -> 0 | J32: =J31+J18 -> 0 | ... N32: =N31+N18 -> 0 | O32: =SUM(C32:N32) -> -109227.81
B33: EBITDA | C33: =C7+(C12+C18+C31) -> -9173.38 | D33: =D7+(D12+D18+D31) -> -7676.32 | E33: =E7+(E12+E18+E31) -> 2867.28 | F33: =F7+(F12+F18+F31) -> -10131.91 | G33: =G7+(G12+G18+G31) -> -5801 | H33: =H7+(H12+H18+H31) -> 0 | I33: =I7+(I12+I18+I31) -> 0 | J33: =J7+(J12+J18+J31) -> 0 | ... N33: =N7+(N12+N18+N31) -> 0 | O33: =SUM(C33:N33) -> -29915.33 | P33: =O33/$O$7 -> -0.21853632
B34: EBITDA ACUMULAT | C34: =C33 -> -9173.38 | D34: =C34+D33 -> -16849.7 | E34: =D34+E33 -> -13982.42 | F34: =E34+F33 -> -24114.33 | G34: =F34+G33 -> -29915.33

Sheet Nautic
B1: NAUTIC DE VILANOVA | C1: Gener | D1: Febrer | E1: Març | F1: Abril | G1: Maig | H1: Juny | I1: Juliol | J1: Agost | K1: Setembre | L1: Octubre | M1: Novembre | N1: Desembre | O1: TOTAL | P1: %
C2: 0 | D2: 0 | E2: 0 | F2: 0 | G2: 0
B3: . VENDES | C3: 51803.66 | D3: 96733.27 | E3: 100069.21 | F3: 126925.13 | G3: 136858.38 | O3: =SUM(C3:N3) -> 512389.65
B4: . PRESTACIO DE SEVEIS | C4: 0 | D4: 0 | E4: 0 | F4: 0 | G4: 0 | O4: =SUM(C4:N4) -> 0
B5: . ALTRES INGRESSOS | C5: 0 | D5: 0 | E5: 0 | F5: 0 | G5: 0 | O5: =SUM(C5:N5) -> 0
B6: . VARIACIO EXISTENCIES | C6: 0 | D6: 0 | E6: 0 | F6: 0 | G6: 0 | O6: =SUM(C6:N6) -> 0
B7: TOTAL INGRESSOS EXPLOTACIO | C7: 51803.66 | D7: 96733.27 | E7: 100069.21 | F7: 126925.13 | G7: 136858.38 | O7: =SUM(C7:N7) -> 512389.65
B8: . COMPRES | C8: -6473.87 | D8: -22952.12 | E8: -26112.02 | F8: -32690.27 | G8: -27957.1 | O8: =SUM(C8:N8) -> -116185.38
B9: . ALTRES APROVISIONAMENTS | C9: -208.15 | D9: -1241.6 | E9: -1175.34 | F9: -782.91 | G9: -1180.38 | O9: =SUM(C9:N9) -> -4588.38
B10: . CONSUMS INTERNS | C10: 0 | D10: -7189.71 | E10: -9766.87 | F10: -12426.49 | G10: -13640.98 | O10: =SUM(C10:N10) -> -43024.05
B11: . VARIACIO EXISTENICIES COMPRES | C11: 0 | D11: 0 | E11: 0 | F11: 0 | G11: 0 | O11: =SUM(C11:N11) -> 0
B12: TOTAL COMPRES | C12: =SUM(C8:C11) -> -6682.02 | D12: =SUM(D8:D11) -> -31383.43 | E12: =SUM(E8:E11) -> -37054.23 | F12: =SUM(F8:F11) -> -45899.67 | G12: =SUM(G8:G11) -> -42778.46 | H12: =SUM(H8:H11) -> 0 | I12: =SUM(I8:I11) -> 0 | J12: =SUM(J8:J11) -> 0 | ... N12: =SUM(N8:N11) -> 0 | O12: =SUM(C12:N12) -> -163797.81 | P12: =O12/$O$7 -> -0.31967431
B13: MARGE BRUT TOTAL | C13: 45121.64 | D13: 58074.55 | E13: 72781.85 | F13: 93451.95 | G13: 112653.34 | O13: =SUM(C13:N13) -> 382083.33
B14: . SOUS I SALARIS | C14: -40891.36 | D14: -36125.61 | E14: -46166.57 | F14: -41215.89 | G14: -49560.69 | O14: =SUM(C14:N14) -> -213960.12
B15: . INDEMNITZACIONS | C15: 0 | D15: 0 | E15: 0 | F15: 0 | G15: 0 | O15: =SUM(C15:N15) -> 0
B16: . SEGURETAT SOCIAL | C16: -10685.37 | D16: -10993.69 | E16: -10982.44 | F16: -11045.05 | G16: -12436.82 | O16: =SUM(C16:N16) -> -56143.37
B17: . ALTRES DESPESES SOCIALS | C17: -99.41 | D17: -13.55 | E17: 0 | F17: -163.73 | G17: -22.2 | O17: =SUM(C17:N17) -> -298.89
B18: TOTAL COST SALARIAL | C18: =SUM(C14:C17) -> -51676.14 | D18: =SUM(D14:D17) -> -47132.85 | E18: =SUM(E14:E17) -> -57149.01 | F18: =SUM(F14:F17) -> -52424.67 | G18: =SUM(G14:G17) -> -62019.71 | H18: =SUM(H14:H17) -> 0 | I18: =SUM(I14:I17) -> 0 | J18: =SUM(J14:J17) -> 0 | ... N18: =SUM(N14:N17) -> 0 | O18: =SUM(C18:N18) -> -270402.38 | P18: =O18/$O$7 -> -0.52772803
B19: . ARRENDAMENTS I CANONS | C19: -8527.52 | D19: -4931.99 | E19: -4832.99 | F19: -5089.09 | G19: -5131.99 | O19: =SUM(C19:N19) -> -28513.58
B20: . REPARACIONS I CONSERVACIO | C20: -1050.96 | D20: -543.62 | E20: -542.24 | F20: -3097.58 | G20: -763.74 | O20: =SUM(C20:N20) -> -5998.14
B21: . SERVEIS PROFESSIONALS | C21: -649.45 | D21: -512.66 | E21: -749.81 | F21: -915.56 | G21: -1076.21 | O21: =SUM(C21:N21) -> -3903.69
B22: . TRANSPORTS | C22: 0 | D22: 0 | E22: 0 | F22: 0 | G22: 0 | O22: =SUM(C22:N22) -> 0
B23: . PRIMES D'ASSEGURANCES | C23: -146.9 | D23: -150.36 | E23: -150.36 | F23: -150.36 | G23: -150.36 | O23: =SUM(C23:N23) -> -748.34
B24: . SERVEIS BANCARIS | C24: -209.63 | D24: -305.5 | E24: -376.96 | F24: -502.53 | G24: -445.24 | O24: =SUM(C24:N24) -> -1839.86
B25: . PUBLICITAT I PROPAGANDA | C25: 0 | D25: 0 | E25: -48 | F25: -736 | G25: 0 | O25: =SUM(C25:N25) -> -784
B26: . SUBMINISTRAMENTS | C26: -1502.44 | D26: -1700 | E26: -721.17 | F26: -1700 | G26: -1700 | O26: =SUM(C26:N26) -> -7323.61
B27: . ALTRES DESPESES | C27: -1263.91 | D27: -2692.5 | E27: -1316.38 | F27: -2941.29 | G27: -965.93 | O27: =SUM(C27:N27) -> -9180.01
B28: . ALTRES TRIBUTS | C28: -332.5 | D28: -656.64 | E28: -656.64 | F28: -656.64 | G28: -656.64 | O28: =SUM(C28:N28) -> -2959.06
B29: . DOTACIO PER INSOLVENCIA | C29: 0 | D29: 0 | E29: 0 | F29: 0 | G29: 0 | O29: =SUM(C29:N29) -> 0
B30: MOVIMENTS INTERNS | C30: 0 | D30: 0 | E30: 0 | F30: 0 | G30: 0 | O30: =SUM(C30:N30) -> 0
B31: TOTAL DESPESES GESTIO | C31: =SUM(C19:C30) -> -13683.31 | D31: =SUM(D19:D30) -> -11493.27 | E31: =SUM(E19:E30) -> -9394.55 | F31: =SUM(F19:F30) -> -15789.05 | G31: =SUM(G19:G30) -> -10890.11 | H31: =SUM(H19:H30) -> 0 | I31: =SUM(I19:I30) -> 0 | J31: =SUM(J19:J30) -> 0 | ... N31: =SUM(N19:N30) -> 0 | O31: =SUM(C31:N31) -> -61250.29 | P31: =O31/$O$7 -> -0.1195385
B32: TOTAL GESTIO + SALARIS | C32: =C31+C18 -> -65359.45 | D32: =D31+D18 -> -58626.12 | E32: =E31+E18 -> -66543.56 | F32: =F31+F18 -> -68213.72 | G32: =G31+G18 -> -72909.82 | H32: =H31+H18 -> 0 | I32: =I31+I18 -> 0 | J32: =J31+J18 -> 0 | ... N32: =N31+N18 -> 0 | O32: =SUM(C32:N32) -> -331652.67
B33: EBITDA | C33: =C7+(C12+C18+C31) -> -20237.81 | D33: =D7+(D12+D18+D31) -> 6723.72 | E33: =E7+(E12+E18+E31) -> -3528.58 | F33: =F7+(F12+F18+F31) -> 12811.74 | G33: =G7+(G12+G18+G31) -> 21170.1 | H33: =H7+(H12+H18+H31) -> 0 | I33: =I7+(I12+I18+I31) -> 0 | J33: =J7+(J12+J18+J31) -> 0 | ... N33: =N7+(N12+N18+N31) -> 0 | O33: =SUM(C33:N33) -> 16939.17 | P33: =O33/$O$7 -> 0.033059157
B34: EBITDA ACUMULAT | C34: =C33 -> -20237.81 | D34: =C34+D33 -> -13514.09 | E34: =D34+E33 -> -17042.67 | F34: =E34+F33 -> -4230.93 | G34: =F34+G33 -> 16939.17

Sheet Masia
B1: LA MASIA D'ESPLUGUES | C1: Gener | D1: Febrer | E1: Març | F1: Abril | G1: Maig | H1: Juny | I1: Juliol | J1: Agost | K1: Setembre | L1: Octubre | M1: Novembre | N1: Desembre | O1: TOTAL | P1: %
C2: 0 | D2: 0 | E2: 0 | F2: 0 | G2: 0
B3: . VENDES | C3: 151918.26 | D3: 146360.25 | E3: 186639.53 | F3: 150292.65 | G3: 190133.71 | O3: =SUM(C3:N3) -> 825344.4
B4: . PRESTACIO DE SEVEIS | C4: 0 | D4: 0 | E4: 0 | F4: 0 | G4: 0 | O4: =SUM(C4:N4) -> 0
B5: . ALTRES INGRESSOS | C5: 317.95 | D5: 317.95 | E5: 317.95 | F5: 317.95 | G5: 317.95 | O5: =SUM(C5:N5) -> 1589.75
B6: . VARIACIO EXISTENCIES | C6: 0 | D6: 0 | E6: 0 | F6: 0 | G6: 0 | O6: =SUM(C6:N6) -> 0
B7: TOTAL INGRESSOS EXPLOTACIO | C7: 152236.21 | D7: 146678.2 | E7: 186957.48 | F7: 150610.6 | G7: 190451.66 | O7: =SUM(C7:N7) -> 826934.15
B8: . COMPRES | C8: -33596.34 | D8: -30849.57 | E8: -33967.97 | F8: -27535.46 | G8: -38115.44 | O8: =SUM(C8:N8) -> -164064.78
B9: . ALTRES APROVISIONAMENTS | C9: -3506.15 | D9: -5252.69 | E9: -4507.62 | F9: -2217.81 | G9: -2481.5 | O9: =SUM(C9:N9) -> -17965.77
B10: . CONSUMS INTERNS | C10: -15776.51 | D10: -10134.9 | E10: -14430.12 | F10: -18464.35 | G10: -20280.87 | O10: =SUM(C10:N10) -> -79086.75
B11: . VARIACIO EXISTENICIES COMPRES | C11: 0 | D11: 0 | E11: 0 | F11: 0 | G11: 0 | O11: =SUM(C11:N11) -> 0
B12: TOTAL COMPRES | C12: =SUM(C8:C11) -> -52879 | D12: =SUM(D8:D11) -> -46237.16 | E12: =SUM(E8:E11) -> -52905.71 | F12: =SUM(F8:F11) -> -48217.62 | G12: =SUM(G8:G11) -> -60877.81 | H12: =SUM(H8:H11) -> 0 | I12: =SUM(I8:I11) -> 0 | J12: =SUM(J8:J11) -> 0 | ... N12: =SUM(N8:N11) -> 0 | O12: =SUM(C12:N12) -> -261117.3 | P12: =O12/$O$7 -> -0.31576553
B13: MARGE BRUT TOTAL | C13: 114064.72 | D13: 110575.94 | E13: 148481.89 | F13: 103789.33 | G13: 152451.29 | O13: =SUM(C13:N13) -> 629363.17
B14: . SOUS I SALARIS | C14: -46433.39 | D14: -42435.38 | E14: -46675.39 | F14: -47996.51 | G14: -55318.37 | O14: =SUM(C14:N14) -> -238859.04
B15: . INDEMNITZACIONS | C15: -2000 | D15: -20000 | E15: 0 | F15: 0 | G15: 0 | O15: =SUM(C15:N15) -> -22000
B16: . SEGURETAT SOCIAL | C16: -11074.13 | D16: -11238.02 | E16: -14225.03 | F16: -15657.56 | G16: -16841.82 | O16: =SUM(C16:N16) -> -69036.56
B17: . ALTRES DESPESES SOCIALS | C17: -256.11 | D17: -274.45 | E17: -23.55 | F17: -205.46 | G17: -31.8 | O17: =SUM(C17:N17) -> -791.37
B18: TOTAL COST SALARIAL | C18: =SUM(C14:C17) -> -59763.63 | D18: =SUM(D14:D17) -> -73947.85 | E18: =SUM(E14:E17) -> -60923.97 | F18: =SUM(F14:F17) -> -63859.53 | G18: =SUM(G14:G17) -> -72191.99 | H18: =SUM(H14:H17) -> 0 | I18: =SUM(I14:I17) -> 0 | J18: =SUM(J14:J17) -> 0 | ... N18: =SUM(N14:N17) -> 0 | O18: =SUM(C18:N18) -> -330686.97 | P18: =O18/$O$7 -> -0.39989517
B19: . ARRENDAMENTS I CANONS | C19: -267.58 | D19: -267.58 | E19: -267.58 | F19: -267.58 | G19: -267.58 | O19: =SUM(C19:N19) -> -1337.9
B20: . REPARACIONS I CONSERVACIO | C20: -2711.7 | D20: -6241.38 | E20: -5604.76 | F20: -5656.65 | G20: -3403.34 | O20: =SUM(C20:N20) -> -23617.83
B21: . SERVEIS PROFESSIONALS | C21: -385.6 | D21: -471.26 | E21: -980.3 | F21: -329.06 | G21: -1382.96 | O21: =SUM(C21:N21) -> -3549.18
B22: . TRANSPORTS | C22: 0 | D22: 0 | E22: -25.2 | F22: 0 | G22: 0 | O22: =SUM(C22:N22) -> -25.2
B23: . PRIMES D'ASSEGURANCES | C23: 0 | D23: -374.13 | E23: -374.13 | F23: -374.13 | G23: -374.13 | O23: =SUM(C23:N23) -> -1496.52
B24: . SERVEIS BANCARIS | C24: -441.85 | D24: -554.9 | E24: -684.75 | F24: -486.82 | G24: -473.9 | O24: =SUM(C24:N24) -> -2642.22
B25: . PUBLICITAT I PROPAGANDA | C25: -236.36 | D25: -15 | E25: -48 | F25: -75 | G25: 0 | O25: =SUM(C25:N25) -> -374.36
B26: . SUBMINISTRAMENTS | C26: -286.12 | D26: -4650 | E26: -5635.62 | F26: -4650 | G26: -4936.12 | O26: =SUM(C26:N26) -> -20157.86
B27: . ALTRES DESPESES | C27: -2777.96 | D27: -3545.24 | E27: -4179.9 | F27: -4303.86 | G27: -3689.8 | O27: =SUM(C27:N27) -> -18496.76
B28: . ALTRES TRIBUTS | C28: 0 | D28: -276.39 | E28: -276.39 | F28: -276.39 | G28: -276.39 | O28: =SUM(C28:N28) -> -1105.56
B29: . DOTACIO PER INSOLVENCIA | C29: 0 | D29: 0 | E29: 0 | F29: 0 | G29: 0 | O29: =SUM(C29:N29) -> 0
B30: MOVIMENTS INTERNS | C30: 0 | D30: 0 | E30: 0 | F30: 0 | G30: 0 | O30: =SUM(C30:N30) -> 0
B31: TOTAL DESPESES GESTIO | C31: =SUM(C19:C30) -> -7107.17 | D31: =SUM(D19:D30) -> -16395.88 | E31: =SUM(E19:E30) -> -18076.63 | F31: =SUM(F19:F30) -> -16419.49 | G31: =SUM(G19:G30) -> -14804.22 | H31: =SUM(H19:H30) -> 0 | I31: =SUM(I19:I30) -> 0 | J31: =SUM(J19:J30) -> 0 | ... N31: =SUM(N19:N30) -> 0 | O31: =SUM(C31:N31) -> -72803.39 | P31: =O31/$O$7 -> -0.08804013
B32: TOTAL GESTIO + SALARIS | C32: =C31+C18 -> -66870.8 | D32: =D31+D18 -> -90343.73 | E32: =E31+E18 -> -79000.6 | F32: =F31+F18 -> -80279.02 | G32: =G31+G18 -> -86996.21 | H32: =H31+H18 -> 0 | I32: =I31+I18 -> 0 | J32: =J31+J18 -> 0 | ... N32: =N31+N18 -> 0 | O32: =SUM(C32:N32) -> -403490.36
B33: EBITDA | C33: =C7+(C12+C18+C31) -> 32486.41 | D33: =D7+(D12+D18+D31) -> 10097.31 | E33: =E7+(E12+E18+E31) -> 55051.17 | F33: =F7+(F12+F18+F31) -> 22113.96 | G33: =G7+(G12+G18+G31) -> 42577.64 | H33: =H7+(H12+H18+H31) -> 0 | I33: =I7+(I12+I18+I31) -> 0 | J33: =J7+(J12+J18+J31) -> 0 | ... N33: =N7+(N12+N18+N31) -> 0 | O33: =SUM(C33:N33) -> 162326.49 | P33: =O33/$O$7 -> 0.19629917
B34: EBITDA ACUMULAT | C34: =C33 -> 32486.41 | D34: =C34+D33 -> 42583.72 | E34: =D34+E33 -> 97634.89 | F34: =E34+F33 -> 119748.85 | G34: =F34+G33 -> 162326.49

Sheet Camp Nou
B1: CAMP NOU SPOTIFY | C1: Gener | D1: Febrer | E1: Març | F1: Abril | G1: Maig | H1: Juny | I1: Juliol | J1: Agost | K1: Setembre | L1: Octubre | M1: Novembre | N1: Desembre | O1: TOTAL | P1: %
C2: 0 | D2: 0 | E2: 0 | F2: 0 | G2: 0
B3: . VENDES | C3: 43870.36 | D3: 74656.85 | E3: 99746.34 | F3: 136713.88 | G3: 121798.71 | O3: =SUM(C3:N3) -> 476786.14
B4: . PRESTACIO DE SEVEIS | C4: 0 | D4: 0 | E4: 0 | F4: 0 | G4: 0 | O4: =SUM(C4:N4) -> 0
B5: . ALTRES INGRESSOS | C5: 0 | D5: 0 | E5: 0 | F5: 0 | G5: 0 | O5: =SUM(C5:N5) -> 0
B6: . VARIACIO EXISTENCIES | C6: 0 | D6: 0 | E6: 0 | F6: 0 | G6: 0 | O6: =SUM(C6:N6) -> 0
B7: TOTAL INGRESSOS EXPLOTACIO | C7: 43870.36 | D7: 74656.85 | E7: 99746.34 | F7: 136713.88 | G7: 121798.71 | O7: =SUM(C7:N7) -> 476786.14
B8: . COMPRES | C8: -7205.9 | D8: -13329.34 | E8: -20937.83 | F8: -25255.55 | G8: -22034.97 | O8: =SUM(C8:N8) -> -88763.59
B9: . ALTRES APROVISIONAMENTS | C9: -367.41 | D9: -68.96 | E9: -415.22 | F9: -641.89 | G9: -416.43 | O9: =SUM(C9:N9) -> -1909.91
B10: . CONSUMS INTERNS | C10: -3167.41 | D10: -5411.22 | E10: -5023.94 | F10: -8824.97 | G10: -7562.89 | O10: =SUM(C10:N10) -> -29990.43
B11: . VARIACIO EXISTENICIES COMPRES | C11: 0 | D11: 0 | E11: 0 | F11: 0 | G11: 0 | O11: =SUM(C11:N11) -> 0
B12: TOTAL COMPRES | C12: =SUM(C8:C11) -> -10740.72 | D12: =SUM(D8:D11) -> -18809.52 | E12: =SUM(E8:E11) -> -26376.99 | F12: =SUM(F8:F11) -> -34722.41 | G12: =SUM(G8:G11) -> -30014.29 | H12: =SUM(H8:H11) -> 0 | I12: =SUM(I8:I11) -> 0 | J12: =SUM(J8:J11) -> 0 | ... N12: =SUM(N8:N11) -> 0 | O12: =SUM(C12:N12) -> -120663.93 | P12: =O12/$O$7 -> -0.25307768
B13: MARGE BRUT TOTAL | C13: 36297.05 | D13: 61258.55 | E13: 78393.29 | F13: 110816.44 | G13: 99986.25 | O13: =SUM(C13:N13) -> 386751.58
B14: . SOUS I SALARIS | C14: -23470.88 | D14: -24044.33 | E14: -26696.66 | F14: -31475.15 | G14: -30051.94 | O14: =SUM(C14:N14) -> -135738.96
B15: . INDEMNITZACIONS | C15: 0 | D15: -1000 | E15: 0 | F15: 0 | G15: -2200 | O15: =SUM(C15:N15) -> -3200
B16: . SEGURETAT SOCIAL | C16: -6168.37 | D16: -6825.56 | E16: -7826.67 | F16: -9685.94 | G16: -8926.75 | O16: =SUM(C16:N16) -> -39433.29
B17: . ALTRES DESPESES SOCIALS | C17: -949.95 | D17: -310.04 | E17: -294.53 | F17: -586.24 | G17: -476.58 | O17: =SUM(C17:N17) -> -2617.34
B18: TOTAL COST SALARIAL | C18: =SUM(C14:C17) -> -30589.2 | D18: =SUM(D14:D17) -> -32179.93 | E18: =SUM(E14:E17) -> -34817.86 | F18: =SUM(F14:F17) -> -41747.33 | G18: =SUM(G14:G17) -> -41655.27 | H18: =SUM(H14:H17) -> 0 | I18: =SUM(I14:I17) -> 0 | J18: =SUM(J14:J17) -> 0 | ... N18: =SUM(N14:N17) -> 0 | O18: =SUM(C18:N18) -> -180989.59 | P18: =O18/$O$7 -> -0.3796033
B19: . ARRENDAMENTS I CANONS | C19: 0 | D19: -14930.94 | E19: -19382.47 | F19: -27342.18 | G19: -24359.07 | O19: =SUM(C19:N19) -> -86014.66
B20: . REPARACIONS I CONSERVACIO | C20: -851.3 | D20: -513.24 | E20: -421.07 | F20: -452.07 | G20: -328.34 | O20: =SUM(C20:N20) -> -2566.02
B21: . SERVEIS PROFESSIONALS | C21: -62 | D21: -63.86 | E21: -63.86 | F21: -63.86 | G21: -63.86 | O21: =SUM(C21:N21) -> -317.44
B22: . TRANSPORTS | C22: 0 | D22: 0 | E22: 0 | F22: 0 | G22: 0 | O22: =SUM(C22:N22) -> 0
B23: . PRIMES D'ASSEGURANCES | C23: 0 | D23: -40.81 | E23: -40.81 | F23: -40.81 | G23: -40.81 | O23: =SUM(C23:N23) -> -163.24
B24: . SERVEIS BANCARIS | C24: -453.45 | D24: -605.18 | E24: -1034.05 | F24: -1225.05 | G24: -1249.49 | O24: =SUM(C24:N24) -> -4567.22
B25: . PUBLICITAT I PROPAGANDA | C25: 0 | D25: -15 | E25: 0 | F25: 0 | G25: 0 | O25: =SUM(C25:N25) -> -15
B26: . SUBMINISTRAMENTS | C26: 0 | D26: -1034 | E26: -1034 | F26: -1034 | G26: -1034 | O26: =SUM(C26:N26) -> -4136
B27: . ALTRES DESPESES | C27: -615.34 | D27: -585.16 | E27: -1089.32 | F27: -1059.3 | G27: -967.62 | O27: =SUM(C27:N27) -> -4316.74
B28: . ALTRES TRIBUTS | C28: 0 | D28: -207.23 | E28: -207.23 | F28: -207.23 | G28: -207.23 | O28: =SUM(C28:N28) -> -828.92
B29: . DOTACIO PER INSOLVENCIA | C29: 0 | D29: 0 | E29: 0 | F29: 0 | G29: 0 | O29: =SUM(C29:N29) -> 0
B30: MOVIMENTS INTERNS | C30: 0 | D30: 0 | E30: 0 | F30: 0 | G30: 0 | O30: =SUM(C30:N30) -> 0
B31: TOTAL DESPESES GESTIO | C31: =SUM(C19:C30) -> -1982.09 | D31: =SUM(D19:D30) -> -17995.42 | E31: =SUM(E19:E30) -> -23272.81 | F31: =SUM(F19:F30) -> -31424.5 | G31: =SUM(G19:G30) -> -28250.42 | H31: =SUM(H19:H30) -> 0 | I31: =SUM(I19:I30) -> 0 | J31: =SUM(J19:J30) -> 0 | ... N31: =SUM(N19:N30) -> 0 | O31: =SUM(C31:N31) -> -102925.24 | P31: =O31/$O$7 -> -0.21587297
B32: TOTAL GESTIO + SALARIS | C32: =C31+C18 -> -32571.29 | D32: =D31+D18 -> -50175.35 | E32: =E31+E18 -> -58090.67 | F32: =F31+F18 -> -73171.83 | G32: =G31+G18 -> -69905.69 | H32: =H31+H18 -> 0 | I32: =I31+I18 -> 0 | J32: =J31+J18 -> 0 | ... N32: =N31+N18 -> 0 | O32: =SUM(C32:N32) -> -283914.83
B33: EBITDA | C33: =C7+(C12+C18+C31) -> 558.35 | D33: =D7+(D12+D18+D31) -> 5671.98 | E33: =E7+(E12+E18+E31) -> 15278.68 | F33: =F7+(F12+F18+F31) -> 28819.64 | G33: =G7+(G12+G18+G31) -> 21878.73 | H33: =H7+(H12+H18+H31) -> 0 | I33: =I7+(I12+I18+I31) -> 0 | J33: =J7+(J12+J18+J31) -> 0 | ... N33: =N7+(N12+N18+N31) -> 0 | O33: =SUM(C33:N33) -> 72207.38 | P33: =O33/$O$7 -> 0.15144606
B34: EBITDA ACUMULAT | C34: =C33 -> 558.35 | D34: =C34+D33 -> 6230.33 | E34: =D34+E33 -> 21509.01 | F34: =E34+F33 -> 50328.65 | G34: =F34+G33 -> 72207.38

Sheet Tarraco
B1: TARRACO | C1: Gener | D1: Febrer | E1: Març | F1: Abril | G1: Maig | H1: Juny | I1: Juliol | J1: Agost | K1: Setembre | L1: Octubre | M1: Novembre | N1: Desembre | O1: TOTAL | P1: %
C2: 0 | D2: 0 | E2: 0 | F2: 0 | G2: 0
B3: . VENDES | C3: 2719.86 | D3: 9232.34 | E3: 6572.48 | F3: 13678.02 | G3: 17474.96 | O3: =SUM(C3:N3) -> 49677.66
B4: . PRESTACIO DE SEVEIS | C4: 0 | D4: 0 | E4: 0 | F4: 0 | G4: 0 | O4: =SUM(C4:N4) -> 0
B5: . ALTRES INGRESSOS | C5: 0 | D5: 0 | E5: 0 | F5: 0 | G5: 0 | O5: =SUM(C5:N5) -> 0
B6: . VARIACIO EXISTENCIES | C6: 0 | D6: 0 | E6: 0 | F6: 0 | G6: 0 | O6: =SUM(C6:N6) -> 0
B7: TOTAL INGRESSOS EXPLOTACIO | C7: 2719.86 | D7: 9232.34 | E7: 6572.48 | F7: 13678.02 | G7: 17474.96 | O7: =SUM(C7:N7) -> 49677.66
B8: . COMPRES | C8: -325.27 | D8: -2131.74 | E8: -2047.52 | F8: -3775.03 | G8: -4520 | O8: =SUM(C8:N8) -> -12799.56
B9: . ALTRES APROVISIONAMENTS | C9: -86.77 | D9: -231.21 | E9: -254.46 | F9: -226.84 | G9: -382.18 | O9: =SUM(C9:N9) -> -1181.46
B10: . CONSUMS INTERNS | C10: -549.12 | D10: -1503.55 | E10: -1522.77 | F10: -3636.52 | G10: -3814.06 | O10: =SUM(C10:N10) -> -11026.02
B11: . VARIACIO EXISTENICIES COMPRES | C11: 0 | D11: 0 | E11: 0 | F11: 0 | G11: 0 | O11: =SUM(C11:N11) -> 0
B12: TOTAL COMPRES | C12: =SUM(C8:C11) -> -961.16 | D12: =SUM(D8:D11) -> -3866.5 | E12: =SUM(E8:E11) -> -3824.75 | F12: =SUM(F8:F11) -> -7638.39 | G12: =SUM(G8:G11) -> -8716.24 | H12: =SUM(H8:H11) -> 0 | I12: =SUM(I8:I11) -> 0 | J12: =SUM(J8:J11) -> 0 | ... N12: =SUM(N8:N11) -> 0 | O12: =SUM(C12:N12) -> -25007.04 | P12: =O12/$O$7 -> -0.50338603
B13: MARGE BRUT TOTAL | C13: 2307.82 | D13: 6869.39 | E13: 4270.5 | F13: 9676.15 | G13: 13267.26 | O13: =SUM(C13:N13) -> 36391.12
B14: . SOUS I SALARIS | C14: -7356.03 | D14: -8620.18 | E14: -8018.64 | F14: -9543.47 | G14: -10005.28 | O14: =SUM(C14:N14) -> -43543.6
B15: . INDEMNITZACIONS | C15: 0 | D15: 0 | E15: 0 | F15: 0 | G15: 0 | O15: =SUM(C15:N15) -> 0
B16: . SEGURETAT SOCIAL | C16: -2623.61 | D16: -2609.91 | E16: -2719.78 | F16: -3044.27 | G16: -2954.4 | O16: =SUM(C16:N16) -> -13951.97
B17: . ALTRES DESPESES SOCIALS | C17: -290.9 | D17: -207.8 | E17: -401.38 | F17: -392.75 | G17: -486.57 | O17: =SUM(C17:N17) -> -1779.4
B18: TOTAL COST SALARIAL | C18: =SUM(C14:C17) -> -10270.54 | D18: =SUM(D14:D17) -> -11437.89 | E18: =SUM(E14:E17) -> -11139.8 | F18: =SUM(F14:F17) -> -12980.49 | G18: =SUM(G14:G17) -> -13446.25 | H18: =SUM(H14:H17) -> 0 | I18: =SUM(I14:I17) -> 0 | J18: =SUM(J14:J17) -> 0 | ... N18: =SUM(N14:N17) -> 0 | O18: =SUM(C18:N18) -> -59274.97 | P18: =O18/$O$7 -> -1.1931917
B19: . ARRENDAMENTS I CANONS | C19: -1030 | D19: -1500 | E19: -1500 | F19: -1500 | G19: -1500 | O19: =SUM(C19:N19) -> -7030
B20: . REPARACIONS I CONSERVACIO | C20: -278.15 | D20: -240.14 | E20: -271.81 | F20: -549.79 | G20: -509.48 | O20: =SUM(C20:N20) -> -1849.37
B21: . SERVEIS PROFESSIONALS | C21: -181.04 | D21: -135.26 | E21: -170.96 | F21: -145.46 | G21: -288.26 | O21: =SUM(C21:N21) -> -920.98
B22: . TRANSPORTS | C22: 0 | D22: 0 | E22: 0 | F22: 0 | G22: 0 | O22: =SUM(C22:N22) -> 0
B23: . PRIMES D'ASSEGURANCES | C23: 0 | D23: -96.37 | E23: -96.37 | F23: -96.37 | G23: -96.37 | O23: =SUM(C23:N23) -> -385.48
B24: . SERVEIS BANCARIS | C24: -24.08 | D24: -42.6 | E24: -52.37 | F24: -68.05 | G24: -96.01 | O24: =SUM(C24:N24) -> -283.11
B25: . PUBLICITAT I PROPAGANDA | C25: 0 | D25: 0 | E25: -50 | F25: -225 | G25: -800 | O25: =SUM(C25:N25) -> -1075
B26: . SUBMINISTRAMENTS | C26: -640.91 | D26: -50.45 | E26: -77.26 | F26: 0 | G26: 0 | O26: =SUM(C26:N26) -> -768.62
B27: . ALTRES DESPESES | C27: 0 | D27: -118.72 | E27: -118.78 | F27: -118.78 | G27: -118.78 | O27: =SUM(C27:N27) -> -475.06
B28: . ALTRES TRIBUTS | C28: -152.05 | D28: -114 | E28: -114 | F28: -114 | G28: -114 | O28: =SUM(C28:N28) -> -608.05
B29: . DOTACIO PER INSOLVENCIA | C29: 0 | D29: 0 | E29: 0 | F29: 0 | G29: 0 | O29: =SUM(C29:N29) -> 0
B30: MOVIMENTS INTERNS | C30: 0 | D30: 0 | E30: 0 | F30: 0 | G30: 0 | O30: =SUM(C30:N30) -> 0
B31: TOTAL DESPESES GESTIO | C31: =SUM(C19:C30) -> -2306.23 | D31: =SUM(D19:D30) -> -2297.54 | E31: =SUM(E19:E30) -> -2451.55 | F31: =SUM(F19:F30) -> -2817.45 | G31: =SUM(G19:G30) -> -3522.9 | H31: =SUM(H19:H30) -> 0 | I31: =SUM(I19:I30) -> 0 | J31: =SUM(J19:J30) -> 0 | ... N31: =SUM(N19:N30) -> 0 | O31: =SUM(C31:N31) -> -13395.67 | P31: =O31/$O$7 -> -0.26965179
B32: TOTAL GESTIO + SALARIS | C32: =C31+C18 -> -12576.77 | D32: =D31+D18 -> -13735.43 | E32: =E31+E18 -> -13591.35 | F32: =F31+F18 -> -15797.94 | G32: =G31+G18 -> -16969.15 | H32: =H31+H18 -> 0 | I32: =I31+I18 -> 0 | J32: =J31+J18 -> 0 | ... N32: =N31+N18 -> 0 | O32: =SUM(C32:N32) -> -72670.64
B33: EBITDA | C33: =C7+(C12+C18+C31) -> -10818.07 | D33: =D7+(D12+D18+D31) -> -8369.59 | E33: =E7+(E12+E18+E31) -> -10843.62 | F33: =F7+(F12+F18+F31) -> -9758.31 | G33: =G7+(G12+G18+G31) -> -8210.43 | H33: =H7+(H12+H18+H31) -> 0 | I33: =I7+(I12+I18+I31) -> 0 | J33: =J7+(J12+J18+J31) -> 0 | ... N33: =N7+(N12+N18+N31) -> 0 | O33: =SUM(C33:N33) -> -48000.02 | P33: =O33/$O$7 -> -0.96622949
B34: EBITDA ACUMULAT | C34: =C33 -> -10818.07 | D34: =C34+D33 -> -19187.66 | E34: =D34+E33 -> -30031.28 | F34: =E34+F33 -> -39789.59 | G34: =F34+G33 -> -48000.02

Sheet Mirador
B1: MIRADOR DE LES CAVES | C1: Gener | D1: Febrer | E1: Març | F1: Abril | G1: Maig | H1: Juny | I1: Juliol | J1: Agost | K1: Setembre | L1: Octubre | M1: Novembre | N1: Desembre | O1: TOTAL | P1: %
C2: 0 | D2: 0 | E2: 0 | F2: 0 | G2: 0
B3: . VENDES | C3: 76714.09 | D3: 71218.51 | E3: 87466.44 | F3: 77330.75 | G3: 96794.86 | O3: =SUM(C3:N3) -> 409524.65
B4: . PRESTACIO DE SEVEIS | C4: 0 | D4: 0 | E4: 0 | F4: 0 | G4: 0 | O4: =SUM(C4:N4) -> 0
B5: . ALTRES INGRESSOS | C5: 0 | D5: 0 | E5: 0 | F5: 0 | G5: 0 | O5: =SUM(C5:N5) -> 0
B6: . VARIACIO EXISTENCIES | C6: 0 | D6: 0 | E6: 0 | F6: 0 | G6: 0 | O6: =SUM(C6:N6) -> 0
B7: TOTAL INGRESSOS EXPLOTACIO | C7: 76714.09 | D7: 71218.51 | E7: 87466.44 | F7: 77330.75 | G7: 96794.86 | O7: =SUM(C7:N7) -> 409524.65
B8: . COMPRES | C8: -14758.52 | D8: -19315.2 | E8: -18747.32 | F8: -18140.65 | G8: -20498.49 | O8: =SUM(C8:N8) -> -91460.18
B9: . ALTRES APROVISIONAMENTS | C9: -1659.16 | D9: -737.81 | E9: -1344.17 | F9: -445.44 | G9: -2577.15 | O9: =SUM(C9:N9) -> -6763.73
B10: . CONSUMS INTERNS | C10: -8308.26 | D10: -3113.2 | E10: -11244.79 | F10: -13194.01 | G10: -11218.3 | O10: =SUM(C10:N10) -> -47078.56
B11: . VARIACIO EXISTENICIES COMPRES | C11: 0 | D11: 0 | E11: 0 | F11: 0 | G11: 0 | O11: =SUM(C11:N11) -> 0
B12: TOTAL COMPRES | C12: =SUM(C8:C11) -> -24725.94 | D12: =SUM(D8:D11) -> -23166.21 | E12: =SUM(E8:E11) -> -31336.28 | F12: =SUM(F8:F11) -> -31780.1 | G12: =SUM(G8:G11) -> -34293.94 | H12: =SUM(H8:H11) -> 0 | I12: =SUM(I8:I11) -> 0 | J12: =SUM(J8:J11) -> 0 | ... N12: =SUM(N8:N11) -> 0 | O12: =SUM(C12:N12) -> -145302.47 | P12: =O12/$O$7 -> -0.35480763
B13: MARGE BRUT TOTAL | C13: 60296.41 | D13: 51165.5 | E13: 67374.95 | F13: 58744.66 | G13: 76576.53 | O13: =SUM(C13:N13) -> 314158.05
B14: . SOUS I SALARIS | C14: -29262.63 | D14: -28850.87 | E14: -32788.36 | F14: -33943.32 | G14: -31447.15 | O14: =SUM(C14:N14) -> -156292.33
B15: . INDEMNITZACIONS | C15: 0 | D15: 0 | E15: 0 | F15: 0 | G15: 0 | O15: =SUM(C15:N15) -> 0
B16: . SEGURETAT SOCIAL | C16: -8016.9 | D16: -7748.67 | E16: -7445.6 | F16: -9572.64 | G16: -10112 | O16: =SUM(C16:N16) -> -42895.81
B17: . ALTRES DESPESES SOCIALS | C17: -113.98 | D17: 0 | E17: -45.5 | F17: -217.49 | G17: 0 | O17: =SUM(C17:N17) -> -376.97
B18: TOTAL COST SALARIAL | C18: =SUM(C14:C17) -> -37393.51 | D18: =SUM(D14:D17) -> -36599.54 | E18: =SUM(E14:E17) -> -40279.46 | F18: =SUM(F14:F17) -> -43733.45 | G18: =SUM(G14:G17) -> -41559.15 | H18: =SUM(H14:H17) -> 0 | I18: =SUM(I14:I17) -> 0 | J18: =SUM(J14:J17) -> 0 | ... N18: =SUM(N14:N17) -> 0 | O18: =SUM(C18:N18) -> -199565.11 | P18: =O18/$O$7 -> -0.48730915
B19: . ARRENDAMENTS I CANONS | C19: -4220.36 | D19: -4329.36 | E19: -4220.36 | F19: -4220.36 | G19: -4220.36 | O19: =SUM(C19:N19) -> -21210.8
B20: . REPARACIONS I CONSERVACIO | C20: -4241.75 | D20: -3820.33 | E20: -6295.59 | F20: -3713.46 | G20: -8521.21 | O20: =SUM(C20:N20) -> -26592.34
B21: . SERVEIS PROFESSIONALS | C21: -248 | D21: -201.56 | E21: -170.96 | F21: -285.71 | G21: -250.01 | O21: =SUM(C21:N21) -> -1156.24
B22: . TRANSPORTS | C22: 0 | D22: 0 | E22: 0 | F22: 0 | G22: 0 | O22: =SUM(C22:N22) -> 0
B23: . PRIMES D'ASSEGURANCES | C23: -96 | D23: -287.54 | E23: -287.54 | F23: -287.54 | G23: -287.54 | O23: =SUM(C23:N23) -> -1246.16
B24: . SERVEIS BANCARIS | C24: -200.34 | D24: -244.54 | E24: -283.39 | F24: -355.06 | G24: -339.2 | O24: =SUM(C24:N24) -> -1422.53
B25: . PUBLICITAT I PROPAGANDA | C25: -148.74 | D25: -138.96 | E25: -418.25 | F25: -94.84 | G25: 0 | O25: =SUM(C25:N25) -> -800.79
B26: . SUBMINISTRAMENTS | C26: 0 | D26: -2738.27 | E26: -3654.54 | F26: -8788.33 | G26: -3099.2 | O26: =SUM(C26:N26) -> -18280.34
B27: . ALTRES DESPESES | C27: -529.66 | D27: -1572.69 | E27: -1596.49 | F27: -1566.36 | G27: -1386.57 | O27: =SUM(C27:N27) -> -6651.77
B28: . ALTRES TRIBUTS | C28: -325 | D28: -68.65 | E28: -68.65 | F28: -245.67 | G28: -161.45 | O28: =SUM(C28:N28) -> -869.42
B29: . DOTACIO PER INSOLVENCIA | C29: 0 | D29: 0 | E29: 0 | F29: 0 | G29: 0 | O29: =SUM(C29:N29) -> 0
B30: MOVIMENTS INTERNS | C30: 0 | D30: 0 | E30: 0 | F30: 0 | G30: 0 | O30: =SUM(C30:N30) -> 0
B31: TOTAL DESPESES GESTIO | C31: =SUM(C19:C30) -> -10009.85 | D31: =SUM(D19:D30) -> -13401.9 | E31: =SUM(E19:E30) -> -16995.77 | F31: =SUM(F19:F30) -> -19557.33 | G31: =SUM(G19:G30) -> -18265.54 | H31: =SUM(H19:H30) -> 0 | I31: =SUM(I19:I30) -> 0 | J31: =SUM(J19:J30) -> 0 | ... N31: =SUM(N19:N30) -> 0 | O31: =SUM(C31:N31) -> -78230.39 | P31: =O31/$O$7 -> -0.1910273
B32: TOTAL GESTIO + SALARIS | C32: =C31+C18 -> -47403.36 | D32: =D31+D18 -> -50001.44 | E32: =E31+E18 -> -57275.23 | F32: =F31+F18 -> -63290.78 | G32: =G31+G18 -> -59824.69 | H32: =H31+H18 -> 0 | I32: =I31+I18 -> 0 | J32: =J31+J18 -> 0 | ... N32: =N31+N18 -> 0 | O32: =SUM(C32:N32) -> -277795.5
B33: EBITDA | C33: =C7+(C12+C18+C31) -> 4584.79 | D33: =D7+(D12+D18+D31) -> -1949.14 | E33: =E7+(E12+E18+E31) -> -1145.07 | F33: =F7+(F12+F18+F31) -> -17740.13 | G33: =G7+(G12+G18+G31) -> 2676.23 | H33: =H7+(H12+H18+H31) -> 0 | I33: =I7+(I12+I18+I31) -> 0 | J33: =J7+(J12+J18+J31) -> 0 | ... N33: =N7+(N12+N18+N31) -> 0 | O33: =SUM(C33:N33) -> -13573.32 | P33: =O33/$O$7 -> -0.033144085
B34: EBITDA ACUMULAT | C34: =C33 -> 4584.79 | D34: =C34+D33 -> 2635.65 | E34: =D34+E33 -> 1490.58 | F34: =E34+F33 -> -16249.55 | G34: =F34+G33 -> -13573.32

Sheet Juno
B1: JUNO HOUSE | C1: Gener | D1: Febrer | E1: Març | F1: Abril | G1: Maig | H1: Juny | I1: Juliol | J1: Agost | K1: Setembre | L1: Octubre | M1: Novembre | N1: Desembre | O1: TOTAL | P1: %
C2: 0 | D2: 0 | E2: 0 | F2: 0 | G2: 0
B3: . VENDES | C3: 11838.87 | D3: 21668.3 | E3: 30063.06 | F3: 18202.54 | G3: 19731.36 | O3: =SUM(C3:N3) -> 101504.13
B4: . PRESTACIO DE SEVEIS | C4: 0 | D4: 0 | E4: 0 | F4: 0 | G4: 0 | O4: =SUM(C4:N4) -> 0
B5: . ALTRES INGRESSOS | C5: 4300 | D5: 4300 | E5: 4300 | F5: 4300 | G5: 4300 | O5: =SUM(C5:N5) -> 21500
B6: . VARIACIO EXISTENCIES | C6: 0 | D6: 0 | E6: 0 | F6: 0 | G6: 0 | O6: =SUM(C6:N6) -> 0
B7: TOTAL INGRESSOS EXPLOTACIO | C7: 16138.87 | D7: 25968.3 | E7: 34363.06 | F7: 22502.54 | G7: 24031.36 | O7: =SUM(C7:N7) -> 123004.13
B8: . COMPRES | C8: -2323.58 | D8: -2828.19 | E8: -2782.84 | F8: -2253.84 | G8: -2164.37 | O8: =SUM(C8:N8) -> -12352.82
B9: . ALTRES APROVISIONAMENTS | C9: -15.3 | D9: -31.41 | E9: -36.7 | F9: -240.15 | G9: -21.85 | O9: =SUM(C9:N9) -> -345.41
B10: . CONSUMS INTERNS | C10: -963.4 | D10: -2609.91 | E10: -2653.21 | F10: -1061.99 | G10: -2188.87 | O10: =SUM(C10:N10) -> -9477.38
B11: . VARIACIO EXISTENICIES COMPRES | C11: 0 | D11: 0 | E11: 0 | F11: 0 | G11: 0 | O11: =SUM(C11:N11) -> 0
B12: TOTAL COMPRES | C12: =SUM(C8:C11) -> -3302.28 | D12: =SUM(D8:D11) -> -5469.51 | E12: =SUM(E8:E11) -> -5472.75 | F12: =SUM(F8:F11) -> -3555.98 | G12: =SUM(G8:G11) -> -4375.09 | H12: =SUM(H8:H11) -> 0 | I12: =SUM(I8:I11) -> 0 | J12: =SUM(J8:J11) -> 0 | ... N12: =SUM(N8:N11) -> 0 | O12: =SUM(C12:N12) -> -22175.61 | P12: =O12/$O$7 -> -0.18028346
B13: MARGE BRUT TOTAL | C13: 13799.99 | D13: 23108.7 | E13: 31543.52 | F13: 20008.55 | G13: 21954.31 | O13: =SUM(C13:N13) -> 110415.07
B14: . SOUS I SALARIS | C14: -11197.31 | D14: -13708.45 | E14: -11637.99 | F14: -12249.41 | G14: -13259.25 | O14: =SUM(C14:N14) -> -62052.41
B15: . INDEMNITZACIONS | C15: 0 | D15: 0 | E15: 0 | F15: 0 | G15: 0 | O15: =SUM(C15:N15) -> 0
B16: . SEGURETAT SOCIAL | C16: -2481.63 | D16: -3914.99 | E16: -3997.76 | F16: -4167.63 | G16: -3987 | O16: =SUM(C16:N16) -> -18549.01
B17: . ALTRES DESPESES SOCIALS | C17: -278.28 | D17: -284.05 | E17: -287.25 | F17: -275.08 | G17: -228.4 | O17: =SUM(C17:N17) -> -1353.06
B18: TOTAL COST SALARIAL | C18: =SUM(C14:C17) -> -13957.22 | D18: =SUM(D14:D17) -> -17907.49 | E18: =SUM(E14:E17) -> -15923 | F18: =SUM(F14:F17) -> -16692.12 | G18: =SUM(G14:G17) -> -17474.65 | H18: =SUM(H14:H17) -> 0 | I18: =SUM(I14:I17) -> 0 | J18: =SUM(J14:J17) -> 0 | ... N18: =SUM(N14:N17) -> 0 | O18: =SUM(C18:N18) -> -81954.48 | P18: =O18/$O$7 -> -0.66627421
B19: . ARRENDAMENTS I CANONS | C19: 0 | D19: -200 | E19: -50 | F19: 0 | G19: 0 | O19: =SUM(C19:N19) -> -250
B20: . REPARACIONS I CONSERVACIO | C20: -933.29 | D20: -44 | E20: -74 | F20: -398.53 | G20: -422.49 | O20: =SUM(C20:N20) -> -1872.31
B21: . SERVEIS PROFESSIONALS | C21: -71.92 | D21: -68.96 | E21: -66.41 | F21: -91.91 | G21: -86.81 | O21: =SUM(C21:N21) -> -386.01
B22: . TRANSPORTS | C22: -350 | D22: 0 | E22: 0 | F22: 0 | G22: 0 | O22: =SUM(C22:N22) -> -350
B23: . PRIMES D'ASSEGURANCES | C23: 0 | D23: 0 | E23: 0 | F23: 0 | G23: 0 | O23: =SUM(C23:N23) -> 0
B24: . SERVEIS BANCARIS | C24: -71.57 | D24: -78.46 | E24: -88.85 | F24: -73.37 | G24: -67.01 | O24: =SUM(C24:N24) -> -379.26
B25: . PUBLICITAT I PROPAGANDA | C25: 0 | D25: 0 | E25: 0 | F25: 0 | G25: 0 | O25: =SUM(C25:N25) -> 0
B26: . SUBMINISTRAMENTS | C26: 0 | D26: 0 | E26: 0 | F26: 0 | G26: 0 | O26: =SUM(C26:N26) -> 0
B27: . ALTRES DESPESES | C27: -796.71 | D27: -124 | E27: -1074.5 | F27: -124 | G27: -124 | O27: =SUM(C27:N27) -> -2243.21
B28: . ALTRES TRIBUTS | C28: 0 | D28: 0 | E28: 0 | F28: 0 | G28: 0 | O28: =SUM(C28:N28) -> 0
B29: . DOTACIO PER INSOLVENCIA | C29: 0 | D29: 0 | E29: 0 | F29: 0 | G29: 0 | O29: =SUM(C29:N29) -> 0
B30: MOVIMENTS INTERNS | C30: 0 | D30: 0 | E30: 0 | F30: 0 | G30: 0 | O30: =SUM(C30:N30) -> 0
B31: TOTAL DESPESES GESTIO | C31: =SUM(C19:C30) -> -2223.49 | D31: =SUM(D19:D30) -> -515.42 | E31: =SUM(E19:E30) -> -1353.76 | F31: =SUM(F19:F30) -> -687.81 | G31: =SUM(G19:G30) -> -700.31 | H31: =SUM(H19:H30) -> 0 | I31: =SUM(I19:I30) -> 0 | J31: =SUM(J19:J30) -> 0 | ... N31: =SUM(N19:N30) -> 0 | O31: =SUM(C31:N31) -> -5480.79 | P31: =O31/$O$7 -> -0.044557772
B32: TOTAL GESTIO + SALARIS | C32: =C31+C18 -> -16180.71 | D32: =D31+D18 -> -18422.91 | E32: =E31+E18 -> -17276.76 | F32: =F31+F18 -> -17379.93 | G32: =G31+G18 -> -18174.96 | H32: =H31+H18 -> 0 | I32: =I31+I18 -> 0 | J32: =J31+J18 -> 0 | ... N32: =N31+N18 -> 0 | O32: =SUM(C32:N32) -> -87435.27
B33: EBITDA | C33: =C7+(C12+C18+C31) -> -3344.12 | D33: =D7+(D12+D18+D31) -> 2075.88 | E33: =E7+(E12+E18+E31) -> 11613.55 | F33: =F7+(F12+F18+F31) -> 1566.63 | G33: =G7+(G12+G18+G31) -> 1481.31 | H33: =H7+(H12+H18+H31) -> 0 | I33: =I7+(I12+I18+I31) -> 0 | J33: =J7+(J12+J18+J31) -> 0 | ... N33: =N7+(N12+N18+N31) -> 0 | O33: =SUM(C33:N33) -> 13393.25 | P33: =O33/$O$7 -> 0.10888456
B34: EBITDA ACUMULAT | C34: =C33 -> -3344.12 | D34: =C34+D33 -> -1268.24 | E34: =D34+E33 -> 10345.31 | F34: =E34+F33 -> 11911.94 | G34: =F34+G33 -> 13393.25

Sheet FDLC
B1: COMPTE DE RESULTATS | C1: Gener | D1: Febrer | E1: Març | F1: Abril | G1: Maig | H1: Juny | I1: Juliol | J1: Agost | K1: Setembre | L1: Octubre | M1: Novembre | N1: Desembre | O1: TOTAL
C2: 0 | D2: 0 | E2: 0 | F2: 0 | G2: 0
B3: . VENDES
B4: . PRESTACIO DE SEVEIS
B5: . ALTRES INGRESSOS
B6: . VARIACIO EXISTENCIES
B7: TOTAL INGRESSOS EXPLOTACIO
B8: . COMPRES
B9: . ALTRES APROVISIONAMENTS
B10: . CONSUMS INTERNS
B11: . VARIACIO EXISTENICIES COMPRES
B12: TOTAL COMPRES
B13: MARGE BRUT TOTAL
B14: . SOUS I SALARIS
... B34: EBITDA ACUMULAT

Sheet Plural
B1: PLURAL | C1: Gener | D1: Febrer | E1: Març | F1: Abril | G1: Maig | H1: Juny | I1: Juliol | J1: Agost | K1: Setembre | L1: Octubre | M1: Novembre | N1: Desembre | O1: TOTAL | P1: %
C2: 0 | D2: 0 | E2: 0 | F2: 0 | G2: 0
B3: . VENDES | C3: 5396.3 | D3: 5326.24 | E3: 6486 | F3: 4970.7 | G3: 4375 | O3: =SUM(C3:N3) -> 26554.24
B4: . PRESTACIO DE SEVEIS | C4: 0 | D4: 0 | E4: 0 | F4: 0 | G4: 0 | O4: =SUM(C4:N4) -> 0
B5: . ALTRES INGRESSOS | C5: 0 | D5: 0 | E5: 0 | F5: 0 | G5: 0 | O5: =SUM(C5:N5) -> 0
B6: . VARIACIO EXISTENCIES | C6: 0 | D6: 0 | E6: 0 | F6: 0 | G6: 0 | O6: =SUM(C6:N6) -> 0
B7: TOTAL INGRESSOS EXPLOTACIO | C7: 5396.3 | D7: 5326.24 | E7: 6486 | F7: 4970.7 | G7: 4375 | O7: =SUM(C7:N7) -> 26554.24
B8: . COMPRES | C8: -2203.2 | D8: -1366.75 | E8: -1332.28 | F8: -1198.16 | G8: -1272.26 | O8: =SUM(C8:N8) -> -7372.65
B9: . ALTRES APROVISIONAMENTS | C9: -219.22 | D9: -34.22 | E9: -286.56 | F9: -198.7 | G9: -7.72 | O9: =SUM(C9:N9) -> -746.42
B10: . CONSUMS INTERNS | C10: -1249.7 | D10: -2137.47 | E10: -1229.44 | F10: -1754.65 | G10: -1085.24 | O10: =SUM(C10:N10) -> -7456.5
B11: . VARIACIO EXISTENICIES COMPRES | C11: 0 | D11: 0 | E11: 0 | F11: 0 | G11: 0 | O11: =SUM(C11:N11) -> 0
B12: TOTAL COMPRES | C12: =SUM(C8:C11) -> -3672.12 | D12: =SUM(D8:D11) -> -3538.44 | E12: =SUM(E8:E11) -> -2848.28 | F12: =SUM(F8:F11) -> -3151.51 | G12: =SUM(G8:G11) -> -2365.22 | H12: =SUM(H8:H11) -> 0 | I12: =SUM(I8:I11) -> 0 | J12: =SUM(J8:J11) -> 0 | ... N12: =SUM(N8:N11) -> 0 | O12: =SUM(C12:N12) -> -15575.57 | P12: =O12/$O$7 -> -0.5865568
B13: MARGE BRUT TOTAL | C13: 2973.88 | D13: 3925.27 | E13: 4867.16 | F13: 3573.84 | G13: 3135.43 | O13: =SUM(C13:N13) -> 18475.58
B14: . SOUS I SALARIS | C14: -6277.45 | D14: -5122.38 | E14: -4631.43 | F14: -3719.69 | G14: -1931.52 | O14: =SUM(C14:N14) -> -21682.47
B15: . INDEMNITZACIONS | C15: 0 | D15: 0 | E15: 0 | F15: 0 | G15: 0 | O15: =SUM(C15:N15) -> 0
B16: . SEGURETAT SOCIAL | C16: -2327.7 | D16: -2085.12 | E16: -1909.98 | F16: -1966.14 | G16: -2099.85 | O16: =SUM(C16:N16) -> -10388.79
B17: . ALTRES DESPESES SOCIALS | C17: 0 | D17: 0 | E17: 0 | F17: -20.6 | G17: 0 | O17: =SUM(C17:N17) -> -20.6
B18: TOTAL COST SALARIAL | C18: =SUM(C14:C17) -> -8605.15 | D18: =SUM(D14:D17) -> -7207.5 | E18: =SUM(E14:E17) -> -6541.41 | F18: =SUM(F14:F17) -> -5706.43 | G18: =SUM(G14:G17) -> -4031.37 | H18: =SUM(H14:H17) -> 0 | I18: =SUM(I14:I17) -> 0 | J18: =SUM(J14:J17) -> 0 | ... N18: =SUM(N14:N17) -> 0 | O18: =SUM(C18:N18) -> -32091.86 | P18: =O18/$O$7 -> -1.20854
B19: . ARRENDAMENTS I CANONS | C19: -1729.9 | D19: -1729.9 | E19: -1729.9 | F19: -4069.1 | G19: -1729.9 | O19: =SUM(C19:N19) -> -10988.7
B20: . REPARACIONS I CONSERVACIO | C20: -249 | D20: -44 | E20: -44 | F20: -440.5 | G20: -44 | O20: =SUM(C20:N20) -> -821.5
B21: . SERVEIS PROFESSIONALS | C21: -92.86 | D21: -69.44 | E21: -89.28 | F21: -62 | G21: -62 | O21: =SUM(C21:N21) -> -375.58
B22: . TRANSPORTS | C22: 0 | D22: 0 | E22: 0 | F22: 0 | G22: 0 | O22: =SUM(C22:N22) -> 0
B23: . PRIMES D'ASSEGURANCES | C23: 0 | D23: -14.18 | E23: -14.18 | F23: -14.18 | G23: -14.18 | O23: =SUM(C23:N23) -> -56.72
B24: . SERVEIS BANCARIS | C24: -60.3 | D24: -52.93 | E24: -63.17 | F24: -39.91 | G24: -38.69 | O24: =SUM(C24:N24) -> -255
B25: . PUBLICITAT I PROPAGANDA | C25: 0 | D25: 0 | E25: 0 | F25: 0 | G25: 0 | O25: =SUM(C25:N25) -> 0
B26: . SUBMINISTRAMENTS | C26: -174.35 | D26: -2981.69 | E26: -3143.92 | F26: -2658.14 | G26: -1770 | O26: =SUM(C26:N26) -> -10728.1
B27: . ALTRES DESPESES | C27: -53.37 | D27: -42.8 | E27: -25.14 | F27: -142.71 | G27: 0 | O27: =SUM(C27:N27) -> -264.02
B28: . ALTRES TRIBUTS | C28: 0 | D28: -25.33 | E28: -25.33 | F28: -194.88 | G28: -25.33 | O28: =SUM(C28:N28) -> -270.87
B29: . DOTACIO PER INSOLVENCIA | C29: 0 | D29: 0 | E29: 0 | F29: 0 | G29: 0 | O29: =SUM(C29:N29) -> 0
B30: MOVIMENTS INTERNS | C30: 0 | D30: 0 | E30: 0 | F30: 0 | G30: 0 | O30: =SUM(C30:N30) -> 0
B31: TOTAL DESPESES GESTIO | C31: =SUM(C19:C30) -> -2359.78 | D31: =SUM(D19:D30) -> -4960.27 | E31: =SUM(E19:E30) -> -5134.92 | F31: =SUM(F19:F30) -> -7621.42 | G31: =SUM(G19:G30) -> -3684.1 | H31: =SUM(H19:H30) -> 0 | I31: =SUM(I19:I30) -> 0 | J31: =SUM(J19:J30) -> 0 | ... N31: =SUM(N19:N30) -> 0 | O31: =SUM(C31:N31) -> -23760.49 | P31: =O31/$O$7 -> -0.89479081
B32: TOTAL GESTIO + SALARIS | C32: =C31+C18 -> -10964.93 | D32: =D31+D18 -> -12167.77 | E32: =E31+E18 -> -11676.33 | F32: =F31+F18 -> -13327.85 | G32: =G31+G18 -> -7715.47 | H32: =H31+H18 -> 0 | I32: =I31+I18 -> 0 | J32: =J31+J18 -> 0 | ... N32: =N31+N18 -> 0 | O32: =SUM(C32:N32) -> -55852.35
B33: EBITDA | C33: =C7+(C12+C18+C31) -> -9240.75 | D33: =D7+(D12+D18+D31) -> -10379.97 | E33: =E7+(E12+E18+E31) -> -8038.61 | F33: =F7+(F12+F18+F31) -> -11508.66 | G33: =G7+(G12+G18+G31) -> -5705.69 | H33: =H7+(H12+H18+H31) -> 0 | I33: =I7+(I12+I18+I31) -> 0 | J33: =J7+(J12+J18+J31) -> 0 | ... N33: =N7+(N12+N18+N31) -> 0 | O33: =SUM(C33:N33) -> -44873.68 | P33: =O33/$O$7 -> -1.6898876
B34: EBITDA ACUMULAT | C34: =C33 -> -9240.75 | D34: =C34+D33 -> -19620.72 | E34: =D34+E33 -> -27659.33 | F34: =E34+F33 -> -39167.99 | G34: =F34+G33 -> -44873.68

Sheet Soliver
B1: SOLIVER | C1: Gener | D1: Febrer | E1: Març | F1: Abril | G1: Maig | H1: Juny | I1: Juliol | J1: Agost | K1: Setembre | L1: Octubre | M1: Novembre | N1: Desembre | O1: TOTAL | P1: %
C2: 0 | D2: 0 | E2: 0 | F2: 0 | G2: 0
B3: . VENDES | C3: 25536.29 | D3: 24602.78 | E3: 31685.85 | F3: 31597.1 | G3: 21145.92 | O3: =SUM(C3:N3) -> 134567.94
B4: . PRESTACIO DE SEVEIS | C4: 0 | D4: 0 | E4: 0 | F4: 0 | G4: 0 | O4: =SUM(C4:N4) -> 0
B5: . ALTRES INGRESSOS | C5: 0 | D5: 0 | E5: 0 | F5: 0 | G5: 0 | O5: =SUM(C5:N5) -> 0
B6: . VARIACIO EXISTENCIES | C6: 0 | D6: 0 | E6: 0 | F6: 0 | G6: 0 | O6: =SUM(C6:N6) -> 0
B7: TOTAL INGRESSOS EXPLOTACIO | C7: 25536.29 | D7: 24602.78 | E7: 31685.85 | F7: 31597.1 | G7: 21145.92 | O7: =SUM(C7:N7) -> 134567.94
B8: . COMPRES | C8: -4429.43 | D8: -4548.69 | E8: -4815.23 | F8: -5577.91 | G8: -4923.24 | O8: =SUM(C8:N8) -> -24294.5
B9: . ALTRES APROVISIONAMENTS | C9: -1560.42 | D9: -334.82 | E9: -655.7 | F9: -30.38 | G9: -564.51 | O9: =SUM(C9:N9) -> -3145.83
B10: . CONSUMS INTERNS | C10: -1475.24 | D10: -2567.52 | E10: -2968.66 | F10: -4577.52 | G10: -2829.74 | O10: =SUM(C10:N10) -> -14418.68
B11: . VARIACIO EXISTENICIES COMPRES | C11: 0 | D11: 0 | E11: 0 | F11: 0 | G11: 0 | O11: =SUM(C11:N11) -> 0
B12: TOTAL COMPRES | C12: =SUM(C8:C11) -> -7465.09 | D12: =SUM(D8:D11) -> -7451.03 | E12: =SUM(E8:E11) -> -8439.59 | F12: =SUM(F8:F11) -> -10185.81 | G12: =SUM(G8:G11) -> -8317.49 | H12: =SUM(H8:H11) -> 0 | I12: =SUM(I8:I11) -> 0 | J12: =SUM(J8:J11) -> 0 | ... N12: =SUM(N8:N11) -> 0 | O12: =SUM(C12:N12) -> -41859.01 | P12: =O12/$O$7 -> -0.31106228
B13: MARGE BRUT TOTAL | C13: 19546.44 | D13: 15995.27 | E13: 26214.92 | F13: 25964.81 | G13: 16115.78 | O13: =SUM(C13:N13) -> 103837.22
B14: . SOUS I SALARIS | C14: -23255.91 | D14: -19808.63 | E14: -21778.6 | F14: -22312.07 | G14: -16669.78 | O14: =SUM(C14:N14) -> -103824.99
B15: . INDEMNITZACIONS | C15: 0 | D15: 0 | E15: 0 | F15: 0 | G15: 0 | O15: =SUM(C15:N15) -> 0
B16: . SEGURETAT SOCIAL | C16: -7511.28 | D16: -6385.15 | E16: -6927.82 | F16: -7678.69 | G16: -6794.64 | O16: =SUM(C16:N16) -> -35297.58
B17: . ALTRES DESPESES SOCIALS | C17: 0 | D17: 0 | E17: 0 | F17: -105.91 | G17: 0 | O17: =SUM(C17:N17) -> -105.91
B18: TOTAL COST SALARIAL | C18: =SUM(C14:C17) -> -30767.19 | D18: =SUM(D14:D17) -> -26193.78 | E18: =SUM(E14:E17) -> -28706.42 | F18: =SUM(F14:F17) -> -30096.67 | G18: =SUM(G14:G17) -> -23464.42 | H18: =SUM(H14:H17) -> 0 | I18: =SUM(I14:I17) -> 0 | J18: =SUM(J14:J17) -> 0 | ... N18: =SUM(N14:N17) -> 0 | O18: =SUM(C18:N18) -> -139228.48 | P18: =O18/$O$7 -> -1.0346334
B19: . ARRENDAMENTS I CANONS | C19: -2766.67 | D19: -3270.48 | E19: -2846.9 | F19: -3190.24 | G19: -3190.24 | O19: =SUM(C19:N19) -> -15264.53
B20: . REPARACIONS I CONSERVACIO | C20: -1965.81 | D20: -1799.42 | E20: -4242.68 | F20: -2963.8 | G20: -1434.14 | O20: =SUM(C20:N20) -> -12405.85
B21: . SERVEIS PROFESSIONALS | C21: -100.05 | D21: -334.46 | E21: -93.22 | F21: -399.96 | G21: -3313.31 | O21: =SUM(C21:N21) -> -4241
B22: . TRANSPORTS | C22: 0 | D22: 0 | E22: 0 | F22: 0 | G22: 0 | O22: =SUM(C22:N22) -> 0
B23: . PRIMES D'ASSEGURANCES | C23: 0 | D23: -14.17 | E23: -14.17 | F23: -14.17 | G23: -14.17 | O23: =SUM(C23:N23) -> -56.68
B24: . SERVEIS BANCARIS | C24: -77.63 | D24: -72.45 | E24: -87.76 | F24: -298.35 | G24: -69.72 | O24: =SUM(C24:N24) -> -605.91
B25: . PUBLICITAT I PROPAGANDA | C25: -548.87 | D25: -155 | E25: -926 | F25: -742 | G25: -438 | O25: =SUM(C25:N25) -> -2809.87
B26: . SUBMINISTRAMENTS | C26: 0 | D26: -3646.23 | E26: -2353.08 | F26: -3900 | G26: -4361.43 | O26: =SUM(C26:N26) -> -14260.74
B27: . ALTRES DESPESES | C27: -2141 | D27: -542.87 | E27: -837 | F27: -614.72 | G27: -558.92 | O27: =SUM(C27:N27) -> -4694.51
B28: . ALTRES TRIBUTS | C28: 0 | D28: -25.33 | E28: -25.33 | F28: -25.33 | G28: -290.57 | O28: =SUM(C28:N28) -> -366.56
B29: . DOTACIO PER INSOLVENCIA | C29: 0 | D29: 0 | E29: 0 | F29: 0 | G29: 0 | O29: =SUM(C29:N29) -> 0
B30: MOVIMENTS INTERNS | C30: 0 | D30: 0 | E30: 0 | F30: 0 | G30: 0 | O30: =SUM(C30:N30) -> 0
B31: TOTAL DESPESES GESTIO | C31: =SUM(C19:C30) -> -7600.03 | D31: =SUM(D19:D30) -> -9860.41 | E31: =SUM(E19:E30) -> -11426.14 | F31: =SUM(F19:F30) -> -12148.57 | G31: =SUM(G19:G30) -> -13670.5 | H31: =SUM(H19:H30) -> 0 | I31: =SUM(I19:I30) -> 0 | J31: =SUM(J19:J30) -> 0 | ... N31: =SUM(N19:N30) -> 0 | O31: =SUM(C31:N31) -> -54705.65 | P31: =O31/$O$7 -> -0.40652811
B32: TOTAL GESTIO + SALARIS | C32: =C31+C18 -> -38367.22 | D32: =D31+D18 -> -36054.19 | E32: =E31+E18 -> -40132.56 | F32: =F31+F18 -> -42245.24 | G32: =G31+G18 -> -37134.92 | O32: =SUM(C32:N32) -> -193934.13
B33: EBITDA | C33: =C7+(C12+C18+C31) -> -20296.02 | D33: =D7+(D12+D18+D31) -> -18902.44 | E33: =E7+(E12+E18+E31) -> -16886.3 | F33: =F7+(F12+F18+F31) -> -20833.95 | G33: =G7+(G12+G18+G31) -> -24306.49 | H33: =H7+(H12+H18+H31) -> 0 | I33: =I7+(I12+I18+I31) -> 0 | J33: =J7+(J12+J18+J31) -> 0 | ... N33: =N7+(N12+N18+N31) -> 0 | O33: =SUM(C33:N33) -> -101225.2 | P33: =O33/$O$7 -> -0.75222375
B34: EBITDA ACUMULAT | C34: =C33 -> -20296.02 | D34: =C34+D33 -> -39198.46 | E34: =D34+E33 -> -56084.76 | F34: =E34+F33 -> -76918.71 | G34: =F34+G33 -> -101225.2

Sheet REST
B1: ORIGENS | C1: Gener | D1: Febrer | E1: Març | F1: Abril | G1: Maig | H1: Juny | I1: Juliol | J1: Agost | K1: Setembre | L1: Octubre | M1: Novembre | N1: Desembre | O1: TOTAL | P1: %
B3: . VENDES | C3: =Origens!C3+Nautic!C3+Masia!C3+'Camp Nou'!C3+Tarraco!C3+Mirador!C3+Juno!C3+Plural!C3+Soliver!C3 -> 388491.68 | D3: =Origens!D3+Nautic!D3+Masia!D3+'Camp Nou'!D3+Tarraco!D3+Mirador!D3+Juno!D3+Plural!D3+Soliver!D3 -> 469539.88 | E3: =Origens!E3+Nautic!E3+Masia!E3+'Camp Nou'!E3+Tarraco!E3+Mirador!E3+Juno!E3+Plural!E3+Soliver!E3 -> 584544.21 | F3: =Origens!F3+Nautic!F3+Masia!F3+'Camp Nou'!F3+Tarraco!F3+Mirador!F3+Juno!F3+Plural!F3+Soliver!F3 -> 588382.57 | G3: =Origens!G3+Nautic!G3+Masia!G3+'Camp Nou'!G3+Tarraco!G3+Mirador!G3+Juno!G3+Plural!G3+Soliver!G3 -> 642279.98 | H3: =Origens!H3+Nautic!H3+Masia!H3+'Camp Nou'!H3+Tarraco!H3+Mirador!H3+Juno!H3+Plural!H3+Soliver!H3 -> 0 | I3: =Origens!I3+Nautic!I3+Masia!I3+'Camp Nou'!I3+Tarraco!I3+Mirador!I3+Juno!I3+Plural!I3+Soliver!I3 -> 0 | J3: =Origens!J3+Nautic!J3+Masia!J3+'Camp Nou'!J3+Tarraco!J3+Mirador!J3+Juno!J3+Plural!J3+Soliver!J3 -> 0 | ... N3: =Origens!N3+Nautic!N3+Masia!N3+'Camp Nou'!N3+Tarraco!N3+Mirador!N3+Juno!N3+Plural!N3+Soliver!N3 -> 0 | O3: =SUM(C3:N3) -> 2673238.3
B4: . PRESTACIO DE SEVEIS | C4: =Origens!C4+Nautic!C4+Masia!C4+'Camp Nou'!C4+Tarraco!C4+Mirador!C4+Juno!C4+Plural!C4+Soliver!C4 -> 0 | D4: =Origens!D4+Nautic!D4+Masia!D4+'Camp Nou'!D4+Tarraco!D4+Mirador!D4+Juno!D4+Plural!D4+Soliver!D4 -> 0 | E4: =Origens!E4+Nautic!E4+Masia!E4+'Camp Nou'!E4+Tarraco!E4+Mirador!E4+Juno!E4+Plural!E4+Soliver!E4 -> 0 | F4: =Origens!F4+Nautic!F4+Masia!F4+'Camp Nou'!F4+Tarraco!F4+Mirador!F4+Juno!F4+Plural!F4+Soliver!F4 -> 0 | G4: =Origens!G4+Nautic!G4+Masia!G4+'Camp Nou'!G4+Tarraco!G4+Mirador!G4+Juno!G4+Plural!G4+Soliver!G4 -> 0 | H4: =Origens!H4+Nautic!H4+Masia!H4+'Camp Nou'!H4+Tarraco!H4+Mirador!H4+Juno!H4+Plural!H4+Soliver!H4 -> 0 | I4: =Origens!I4+Nautic!I4+Masia!I4+'Camp Nou'!I4+Tarraco!I4+Mirador!I4+Juno!I4+Plural!I4+Soliver!I4 -> 0 | J4: =Origens!J4+Nautic!J4+Masia!J4+'Camp Nou'!J4+Tarraco!J4+Mirador!J4+Juno!J4+Plural!J4+Soliver!J4 -> 0 | ... N4: =Origens!N4+Nautic!N4+Masia!N4+'Camp Nou'!N4+Tarraco!N4+Mirador!N4+Juno!N4+Plural!N4+Soliver!N4 -> 0 | O4: =SUM(C4:N4) -> 0
B5: . ALTRES INGRESSOS | C5: =Origens!C5+Nautic!C5+Masia!C5+'Camp Nou'!C5+Tarraco!C5+Mirador!C5+Juno!C5+Plural!C5+Soliver!C5 -> 4617.95 | D5: =Origens!D5+Nautic!D5+Masia!D5+'Camp Nou'!D5+Tarraco!D5+Mirador!D5+Juno!D5+Plural!D5+Soliver!D5 -> 4617.95 | E5: =Origens!E5+Nautic!E5+Masia!E5+'Camp Nou'!E5+Tarraco!E5+Mirador!E5+Juno!E5+Plural!E5+Soliver!E5 -> 4617.95 | F5: =Origens!F5+Nautic!F5+Masia!F5+'Camp Nou'!F5+Tarraco!F5+Mirador!F5+Juno!F5+Plural!F5+Soliver!F5 -> 4617.95 | G5: =Origens!G5+Nautic!G5+Masia!G5+'Camp Nou'!G5+Tarraco!G5+Mirador!G5+Juno!G5+Plural!G5+Soliver!G5 -> 4617.95 | H5: =Origens!H5+Nautic!H5+Masia!H5+'Camp Nou'!H5+Tarraco!H5+Mirador!H5+Juno!H5+Plural!H5+Soliver!H5 -> 0 | I5: =Origens!I5+Nautic!I5+Masia!I5+'Camp Nou'!I5+Tarraco!I5+Mirador!I5+Juno!I5+Plural!I5+Soliver!I5 -> 0 | J5: =Origens!J5+Nautic!J5+Masia!J5+'Camp Nou'!J5+Tarraco!J5+Mirador!J5+Juno!J5+Plural!J5+Soliver!J5 -> 0 | ... N5: =Origens!N5+Nautic!N5+Masia!N5+'Camp Nou'!N5+Tarraco!N5+Mirador!N5+Juno!N5+Plural!N5+Soliver!N5 -> 0 | O5: =SUM(C5:N5) -> 23089.75
B6: . VARIACIO EXISTENCIES | C6: =Origens!C6+Nautic!C6+Masia!C6+'Camp Nou'!C6+Tarraco!C6+Mirador!C6+Juno!C6+Plural!C6+Soliver!C6 -> 0 | D6: =Origens!D6+Nautic!D6+Masia!D6+'Camp Nou'!D6+Tarraco!D6+Mirador!D6+Juno!D6+Plural!D6+Soliver!D6 -> 0 | E6: =Origens!E6+Nautic!E6+Masia!E6+'Camp Nou'!E6+Tarraco!E6+Mirador!E6+Juno!E6+Plural!E6+Soliver!E6 -> 0 | F6: =Origens!F6+Nautic!F6+Masia!F6+'Camp Nou'!F6+Tarraco!F6+Mirador!F6+Juno!F6+Plural!F6+Soliver!F6 -> 0 | G6: =Origens!G6+Nautic!G6+Masia!G6+'Camp Nou'!G6+Tarraco!G6+Mirador!G6+Juno!G6+Plural!G6+Soliver!G6 -> 0 | H6: =Origens!H6+Nautic!H6+Masia!H6+'Camp Nou'!H6+Tarraco!H6+Mirador!H6+Juno!H6+Plural!H6+Soliver!H6 -> 0 | I6: =Origens!I6+Nautic!I6+Masia!I6+'Camp Nou'!I6+Tarraco!I6+Mirador!I6+Juno!I6+Plural!I6+Soliver!I6 -> 0 | J6: =Origens!J6+Nautic!J6+Masia!J6+'Camp Nou'!J6+Tarraco!J6+Mirador!J6+Juno!J6+Plural!J6+Soliver!J6 -> 0 | ... N6: =Origens!N6+Nautic!N6+Masia!N6+'Camp Nou'!N6+Tarraco!N6+Mirador!N6+Juno!N6+Plural!N6+Soliver!N6 -> 0 | O6: =SUM(C6:N6) -> 0
B7: TOTAL INGRESSOS EXPLOTACIO | C7: =Origens!C7+Nautic!C7+Masia!C7+'Camp Nou'!C7+Tarraco!C7+Mirador!C7+Juno!C7+Plural!C7+Soliver!C7 -> 393109.63 | D7: =Origens!D7+Nautic!D7+Masia!D7+'Camp Nou'!D7+Tarraco!D7+Mirador!D7+Juno!D7+Plural!D7+Soliver!D7 -> 474157.83 | E7: =Origens!E7+Nautic!E7+Masia!E7+'Camp Nou'!E7+Tarraco!E7+Mirador!E7+Juno!E7+Plural!E7+Soliver!E7 -> 589162.16 | F7: =Origens!F7+Nautic!F7+Masia!F7+'Camp Nou'!F7+Tarraco!F7+Mirador!F7+Juno!F7+Plural!F7+Soliver!F7 -> 593000.52 | G7: =Origens!G7+Nautic!G7+Masia!G7+'Camp Nou'!G7+Tarraco!G7+Mirador!G7+Juno!G7+Plural!G7+Soliver!G7 -> 646897.93 | H7: =Origens!H7+Nautic!H7+Masia!H7+'Camp Nou'!H7+Tarraco!H7+Mirador!H7+Juno!H7+Plural!H7+Soliver!H7 -> 0 | I7: =Origens!I7+Nautic!I7+Masia!I7+'Camp Nou'!I7+Tarraco!I7+Mirador!I7+Juno!I7+Plural!I7+Soliver!I7 -> 0 | J7: =Origens!J7+Nautic!J7+Masia!J7+'Camp Nou'!J7+Tarraco!J7+Mirador!J7+Juno!J7+Plural!J7+Soliver!J7 -> 0 | ... N7: =Origens!N7+Nautic!N7+Masia!N7+'Camp Nou'!N7+Tarraco!N7+Mirador!N7+Juno!N7+Plural!N7+Soliver!N7 -> 0 | O7: =SUM(C7:N7) -> 2696328.1
B8: . COMPRES | C8: =Origens!C8+Nautic!C8+Masia!C8+'Camp Nou'!C8+Tarraco!C8+Mirador!C8+Juno!C8+Plural!C8+Soliver!C8 -> -76365.01 | D8: =Origens!D8+Nautic!D8+Masia!D8+'Camp Nou'!D8+Tarraco!D8+Mirador!D8+Juno!D8+Plural!D8+Soliver!D8 -> -102000.38 | E8: =Origens!E8+Nautic!E8+Masia!E8+'Camp Nou'!E8+Tarraco!E8+Mirador!E8+Juno!E8+Plural!E8+Soliver!E8 -> -117868.81 | F8: =Origens!F8+Nautic!F8+Masia!F8+'Camp Nou'!F8+Tarraco!F8+Mirador!F8+Juno!F8+Plural!F8+Soliver!F8 -> -124716.13 | G8: =Origens!G8+Nautic!G8+Masia!G8+'Camp Nou'!G8+Tarraco!G8+Mirador!G8+Juno!G8+Plural!G8+Soliver!G8 -> -130129.79 | H8: =Origens!H8+Nautic!H8+Masia!H8+'Camp Nou'!H8+Tarraco!H8+Mirador!H8+Juno!H8+Plural!H8+Soliver!H8 -> 0 | I8: =Origens!I8+Nautic!I8+Masia!I8+'Camp Nou'!I8+Tarraco!I8+Mirador!I8+Juno!I8+Plural!I8+Soliver!I8 -> 0 | J8: =Origens!J8+Nautic!J8+Masia!J8+'Camp Nou'!J8+Tarraco!J8+Mirador!J8+Juno!J8+Plural!J8+Soliver!J8 -> 0 | ... N8: =Origens!N8+Nautic!N8+Masia!N8+'Camp Nou'!N8+Tarraco!N8+Mirador!N8+Juno!N8+Plural!N8+Soliver!N8 -> 0 | O8: =SUM(C8:N8) -> -551080.12
B9: . ALTRES APROVISIONAMENTS | C9: =Origens!C9+Nautic!C9+Masia!C9+'Camp Nou'!C9+Tarraco!C9+Mirador!C9+Juno!C9+Plural!C9+Soliver!C9 -> -8090 | D9: =Origens!D9+Nautic!D9+Masia!D9+'Camp Nou'!D9+Tarraco!D9+Mirador!D9+Juno!D9+Plural!D9+Soliver!D9 -> -8362.86 | E9: =Origens!E9+Nautic!E9+Masia!E9+'Camp Nou'!E9+Tarraco!E9+Mirador!E9+Juno!E9+Plural!E9+Soliver!E9 -> -8859.42 | F9: =Origens!F9+Nautic!F9+Masia!F9+'Camp Nou'!F9+Tarraco!F9+Mirador!F9+Juno!F9+Plural!F9+Soliver!F9 -> -5519.19 | G9: =Origens!G9+Nautic!G9+Masia!G9+'Camp Nou'!G9+Tarraco!G9+Mirador!G9+Juno!G9+Plural!G9+Soliver!G9 -> -8068.66 | H9: =Origens!H9+Nautic!H9+Masia!H9+'Camp Nou'!H9+Tarraco!H9+Mirador!H9+Juno!H9+Plural!H9+Soliver!H9 -> 0 | I9: =Origens!I9+Nautic!I9+Masia!I9+'Camp Nou'!I9+Tarraco!I9+Mirador!I9+Juno!I9+Plural!I9+Soliver!I9 -> 0 | J9: =Origens!J9+Nautic!J9+Masia!J9+'Camp Nou'!J9+Tarraco!J9+Mirador!J9+Juno!J9+Plural!J9+Soliver!J9 -> 0 | ... N9: =Origens!N9+Nautic!N9+Masia!N9+'Camp Nou'!N9+Tarraco!N9+Mirador!N9+Juno!N9+Plural!N9+Soliver!N9 -> 0 | O9: =SUM(C9:N9) -> -38900.13
B10: . CONSUMS INTERNS | C10: =Origens!C10+Nautic!C10+Masia!C10+'Camp Nou'!C10+Tarraco!C10+Mirador!C10+Juno!C10+Plural!C10+Soliver!C10 -> -34062.11 | D10: =Origens!D10+Nautic!D10+Masia!D10+'Camp Nou'!D10+Tarraco!D10+Mirador!D10+Juno!D10+Plural!D10+Soliver!D10 -> -37571.38 | E10: =Origens!E10+Nautic!E10+Masia!E10+'Camp Nou'!E10+Tarraco!E10+Mirador!E10+Juno!E10+Plural!E10+Soliver!E10 -> -53459.6 | F10: =Origens!F10+Nautic!F10+Masia!F10+'Camp Nou'!F10+Tarraco!F10+Mirador!F10+Juno!F10+Plural!F10+Soliver!F10 -> -68084.45 | G10: =Origens!G10+Nautic!G10+Masia!G10+'Camp Nou'!G10+Tarraco!G10+Mirador!G10+Juno!G10+Plural!G10+Soliver!G10 -> -69917.98 | H10: =Origens!H10+Nautic!H10+Masia!H10+'Camp Nou'!H10+Tarraco!H10+Mirador!H10+Juno!H10+Plural!H10+Soliver!H10 -> 0 | I10: =Origens!I10+Nautic!I10+Masia!I10+'Camp Nou'!I10+Tarraco!I10+Mirador!I10+Juno!I10+Plural!I10+Soliver!I10 -> 0 | J10: =Origens!J10+Nautic!J10+Masia!J10+'Camp Nou'!J10+Tarraco!J10+Mirador!J10+Juno!J10+Plural!J10+Soliver!J10 -> 0 | ... N10: =Origens!N10+Nautic!N10+Masia!N10+'Camp Nou'!N10+Tarraco!N10+Mirador!N10+Juno!N10+Plural!N10+Soliver!N10 -> 0 | O10: =SUM(C10:N10) -> -263095.52
B11: . VARIACIO EXISTENICIES COMPRES | C11: =Origens!C11+Nautic!C11+Masia!C11+'Camp Nou'!C11+Tarraco!C11+Mirador!C11+Juno!C11+Plural!C11+Soliver!C11 -> 0 | D11: =Origens!D11+Nautic!D11+Masia!D11+'Camp Nou'!D11+Tarraco!D11+Mirador!D11+Juno!D11+Plural!D11+Soliver!D11 -> 0 | E11: =Origens!E11+Nautic!E11+Masia!E11+'Camp Nou'!E11+Tarraco!E11+Mirador!E11+Juno!E11+Plural!E11+Soliver!E11 -> 0 | F11: =Origens!F11+Nautic!F11+Masia!F11+'Camp Nou'!F11+Tarraco!F11+Mirador!F11+Juno!F11+Plural!F11+Soliver!F11 -> 0 | G11: =Origens!G11+Nautic!G11+Masia!G11+'Camp Nou'!G11+Tarraco!G11+Mirador!G11+Juno!G11+Plural!G11+Soliver!G11 -> 0 | H11: =Origens!H11+Nautic!H11+Masia!H11+'Camp Nou'!H11+Tarraco!H11+Mirador!H11+Juno!H11+Plural!H11+Soliver!H11 -> 0 | I11: =Origens!I11+Nautic!I11+Masia!I11+'Camp Nou'!I11+Tarraco!I11+Mirador!I11+Juno!I11+Plural!I11+Soliver!I11 -> 0 | J11: =Origens!J11+Nautic!J11+Masia!J11+'Camp Nou'!J11+Tarraco!J11+Mirador!J11+Juno!J11+Plural!J11+Soliver!J11 -> 0 | ... N11: =Origens!N11+Nautic!N11+Masia!N11+'Camp Nou'!N11+Tarraco!N11+Mirador!N11+Juno!N11+Plural!N11+Soliver!N11 -> 0 | O11: =SUM(C11:N11) -> 0
B12: TOTAL COMPRES | C12: =Origens!C12+Nautic!C12+Masia!C12+'Camp Nou'!C12+Tarraco!C12+Mirador!C12+Juno!C12+Plural!C12+Soliver!C12 -> -118517.12 | D12: =Origens!D12+Nautic!D12+Masia!D12+'Camp Nou'!D12+Tarraco!D12+Mirador!D12+Juno!D12+Plural!D12+Soliver!D12 -> -147934.62 | E12: =Origens!E12+Nautic!E12+Masia!E12+'Camp Nou'!E12+Tarraco!E12+Mirador!E12+Juno!E12+Plural!E12+Soliver!E12 -> -180187.83 | F12: =Origens!F12+Nautic!F12+Masia!F12+'Camp Nou'!F12+Tarraco!F12+Mirador!F12+Juno!F12+Plural!F12+Soliver!F12 -> -198319.77 | G12: =Origens!G12+Nautic!G12+Masia!G12+'Camp Nou'!G12+Tarraco!G12+Mirador!G12+Juno!G12+Plural!G12+Soliver!G12 -> -208116.43 | H12: =Origens!H12+Nautic!H12+Masia!H12+'Camp Nou'!H12+Tarraco!H12+Mirador!H12+Juno!H12+Plural!H12+Soliver!H12 -> 0 | I12: =Origens!I12+Nautic!I12+Masia!I12+'Camp Nou'!I12+Tarraco!I12+Mirador!I12+Juno!I12+Plural!I12+Soliver!I12 -> 0 | J12: =Origens!J12+Nautic!J12+Masia!J12+'Camp Nou'!J12+Tarraco!J12+Mirador!J12+Juno!J12+Plural!J12+Soliver!J12 -> 0 | ... N12: =Origens!N12+Nautic!N12+Masia!N12+'Camp Nou'!N12+Tarraco!N12+Mirador!N12+Juno!N12+Plural!N12+Soliver!N12 -> 0 | O12: =SUM(C12:N12) -> -853075.77 | P12: =O12/$O$7 -> -0.31638426
B13: MARGE BRUT TOTAL | C13: =Origens!C13+Nautic!C13+Masia!C13+'Camp Nou'!C13+Tarraco!C13+Mirador!C13+Juno!C13+Plural!C13+Soliver!C13 -> 307585.62 | D13: =Origens!D13+Nautic!D13+Masia!D13+'Camp Nou'!D13+Tarraco!D13+Mirador!D13+Juno!D13+Plural!D13+Soliver!D13 -> 345605.59 | E13: =Origens!E13+Nautic!E13+Masia!E13+'Camp Nou'!E13+Tarraco!E13+Mirador!E13+Juno!E13+Plural!E13+Soliver!E13 -> 461333.93 | F13: =Origens!F13+Nautic!F13+Masia!F13+'Camp Nou'!F13+Tarraco!F13+Mirador!F13+Juno!F13+Plural!F13+Soliver!F13 -> 445673.2 | G13: =Origens!G13+Nautic!G13+Masia!G13+'Camp Nou'!G13+Tarraco!G13+Mirador!G13+Juno!G13+Plural!G13+Soliver!G13 -> 521786.53 | H13: =Origens!H13+Nautic!H13+Masia!H13+'Camp Nou'!H13+Tarraco!H13+Mirador!H13+Juno!H13+Plural!H13+Soliver!H13 -> 0 | I13: =Origens!I13+Nautic!I13+Masia!I13+'Camp Nou'!I13+Tarraco!I13+Mirador!I13+Juno!I13+Plural!I13+Soliver!I13 -> 0 | J13: =Origens!J13+Nautic!J13+Masia!J13+'Camp Nou'!J13+Tarraco!J13+Mirador!J13+Juno!J13+Plural!J13+Soliver!J13 -> 0 | ... N13: =Origens!N13+Nautic!N13+Masia!N13+'Camp Nou'!N13+Tarraco!N13+Mirador!N13+Juno!N13+Plural!N13+Soliver!N13 -> 0 | O13: =SUM(C13:N13) -> 2081984.9
