Workbook

Sheet Datos

Sheet Hipótesis
A1: HIPÓTESIS DE CUENTA DE RESULTADOS
A3: CONCEPTO | B3: X-2 | C3: X-1 | D3: X | E3: X+1 | F3: X+2 | G3: X+3 | H3: X+4 | I3: X+5 | J3: X+6
A4: Variación Importe neto de la cifra de negocio | C4: =('Cuentas de PyG'!C4-'Cuentas de PyG'!B4)/'Cuentas de PyG'!B4 -> 0.23383763 | D4: =('Cuentas de PyG'!D4-'Cuentas de PyG'!C4)/'Cuentas de PyG'!C4 -> 0.091271003 | E4: =+D4-(($D$4-$B$51)/6) -> 0.078892503 | F4: =+E4-(($D$4-$B$51)/6) -> 0.066514002 | G4: =+F4-(($D$4-$B$51)/6) -> 0.054135502 | H4: =+G4-(($D$4-$B$51)/6) -> 0.041757001 | I4: =+H4-(($D$4-$B$51)/6) -> 0.029378501 | J4: =+I4-(($D$4-$B$51)/6) -> 0.017
A5: Consumo de mercad./Imp. neto cifra de neg. | B5: =-'Cuentas de PyG'!B7/'Cuentas de PyG'!B4 -> 0.89551153 | C5: =-'Cuentas de PyG'!C7/'Cuentas de PyG'!C4 -> 0.88933301 | D5: =-'Cuentas de PyG'!D7/'Cuentas de PyG'!D4 -> 0.89083171 | E5: =+D5-($D$5-$K$5)/6 -> 0.88944309 | F5: =+E5-($D$5-$K$5)/6 -> 0.88805447 | G5: =+F5-($D$5-$K$5)/6 -> 0.88666585 | H5: =+G5-($D$5-$K$5)/6 -> 0.88527724 | I5: =+H5-($D$5-$K$5)/6 -> 0.88388862 | J5: =+I5-($D$5-$K$5)/6 -> 0.8825 | K5: 0.8825 | M5: dato anunciado
A6: Consumo de mat. prim./Imp. neto cifra de neg. | B6: =-'Cuentas de PyG'!B8/'Cuentas de PyG'!B4 -> 0.017837537 | C6: =-'Cuentas de PyG'!C8/'Cuentas de PyG'!C4 -> 0.012039208 | D6: =-'Cuentas de PyG'!D8/'Cuentas de PyG'!D4 -> 0.010630696 | E6: =D6 -> 0.010630696 | F6: =E6 -> 0.010630696 | G6: =F6 -> 0.010630696 | H6: =G6 -> 0.010630696 | I6: =H6 -> 0.010630696 | J6: =I6 -> 0.010630696
A7: Trabajos realiz. otras emp./Imp. neto cifra de neg. | B7: =-'Cuentas de PyG'!B9/'Cuentas de PyG'!B4 -> 0.0087567749 | C7: =-'Cuentas de PyG'!C9/'Cuentas de PyG'!C4 -> 0.01772647 | D7: =-'Cuentas de PyG'!D9/'Cuentas de PyG'!D4 -> 0.016314533 | E7: =D7 -> 0.016314533 | F7: =E7 -> 0.016314533 | G7: =F7 -> 0.016314533 | H7: =G7 -> 0.016314533 | I7: =H7 -> 0.016314533 | J7: =I7 -> 0.016314533
A8: Gastos de personal/Imp. neto cifra de negocio | B8: =-'Cuentas de PyG'!B13/'Cuentas de PyG'!B4 -> 0.030614602 | C8: =-'Cuentas de PyG'!C13/'Cuentas de PyG'!C4 -> 0.0287698 | D8: =-'Cuentas de PyG'!D13/'Cuentas de PyG'!D4 -> 0.028899141 | E8: =D8 -> 0.028899141 | F8: =E8 -> 0.028899141 | G8: =F8 -> 0.028899141 | H8: =G8 -> 0.028899141 | I8: =H8 -> 0.028899141 | J8: =I8 -> 0.028899141
A9: Servicios exteriores/Imp. neto cifra de negocio | B9: =-'Cuentas de PyG'!B17/'Cuentas de PyG'!B4 -> 0.022016152 | C9: =-'Cuentas de PyG'!C17/'Cuentas de PyG'!C4 -> 0.020055186 | D9: =-'Cuentas de PyG'!D17/'Cuentas de PyG'!D4 -> 0.023355677 | E9: =D9 -> 0.023355677 | F9: =E9 -> 0.023355677 | G9: =F9 -> 0.023355677 | H9: =G9 -> 0.023355677 | I9: =H9 -> 0.023355677 | J9: =I9 -> 0.023355677
A10: Tributos/Imp. neto cifra de negocio | B10: =-'Cuentas de PyG'!B18/'Cuentas de PyG'!B4 -> 0.00028833744 | C10: =-'Cuentas de PyG'!C18/'Cuentas de PyG'!C4 -> 0.00046909788 | D10: =-'Cuentas de PyG'!D18/'Cuentas de PyG'!D4 -> 0.00036514102 | E10: =D10 -> 0.00036514102 | F10: =E10 -> 0.00036514102 | G10: =F10 -> 0.00036514102 | H10: =G10 -> 0.00036514102 | I10: =H10 -> 0.00036514102 | J10: =I10 -> 0.00036514102
A11: Imputación subv. inmov./Subv. recibidas | C11: ='Cuentas de PyG'!C22/Balances!B49 -> 0.18868035 | D11: ='Cuentas de PyG'!D22/Balances!C49 -> 0.10435818 | E11: =D11 -> 0.10435818 | F11: =E11 -> 0.10435818 | G11: =F11 -> 0.10435818 | H11: =G11 -> 0.10435818 | I11: =H11 -> 0.10435818 | J11: =I11 -> 0.10435818
A12: Impuesto sobre beneficio/Result. antes de impuest. | B12: =-'Cuentas de PyG'!B37/'Cuentas de PyG'!B36 -> 0.31129148 | C12: =-'Cuentas de PyG'!C37/'Cuentas de PyG'!C36 -> 0.29417098 | D12: =-'Cuentas de PyG'!D37/'Cuentas de PyG'!D36 -> 0.30042962 | E12: =D12 -> 0.30042962 | F12: =E12 -> 0.30042962 | G12: =F12 -> 0.30042962 | H12: =G12 -> 0.30042962 | I12: =H12 -> 0.30042962 | J12: =I12 -> 0.30042962
A14: HIPÓTESIS DE ACTIVO FIJO
A16: CONCEPTO | B16: X-2 | C16: X-1 | D16: X | E16: X+1 | F16: X+2 | G16: X+3 | H16: X+4 | I16: X+5 | J16: X+6
A17: Activo fijo intangible/Imp. neto cifra neg. | B17: =Balances!B5/'Cuentas de PyG'!B4 -> 0.00087864229 | C17: =Balances!C5/'Cuentas de PyG'!C4 -> 0.00057501846 | D17: =Balances!D5/'Cuentas de PyG'!D4 -> 0.00092972434 | E17: =D17 -> 0.00092972434 | F17: =E17 -> 0.00092972434 | G17: =F17 -> 0.00092972434 | H17: =G17 -> 0.00092972434 | I17: =H17 -> 0.00092972434 | J17: =I17 -> 0.00092972434 | L17: datos lo dice
A18: Activo fijo material/Imp. neto cifra neg. | B18: =Balances!B10/'Cuentas de PyG'!B4 -> 0.057428685 | C18: =Balances!C10/'Cuentas de PyG'!C4 -> 0.089640497 | D18: =Balances!D10/'Cuentas de PyG'!D4 -> 0.13263347 | E18: =D18 -> 0.13263347 | F18: =E18 -> 0.13263347 | G18: =F18 -> 0.13263347 | H18: =G18 -> 0.13263347 | I18: =H18 -> 0.13263347 | J18: =I18 -> 0.13263347
A19: Dotación a la amort./Activo fijo intan. y material | C19: =-'Cuentas de PyG'!C21/(Balances!B5+Balances!B10) -> 0.10657134 | D19: =-'Cuentas de PyG'!D21/(Balances!C5+Balances!C10) -> 0.10507383 | E19: =D19 -> 0.10507383 | F19: =E19 -> 0.10507383 | G19: =F19 -> 0.10507383 | H19: =G19 -> 0.10507383 | I19: =H19 -> 0.10507383 | J19: =I19 -> 0.10507383
A20: Variación inmovilizado intangible | C20: =Balances!C5-Balances!B5 -> -26832.8 | D20: =Balances!D5-Balances!C5 -> 86028 | E20: =Balances!E5-Balances!D5 -> 15665.4 | F20: =Balances!F5-Balances!E5 -> 14249.414 | G20: =Balances!G5-Balances!F5 -> 12368.945 | H20: =Balances!H5-Balances!G5 -> 10057.18 | I20: =Balances!I5-Balances!H5 -> 7371.2814 | J20: =Balances!J5-Balances!I5 -> 4390.7366
A21: Variación inmovilizado material | C21: =Balances!C10-Balances!B10 -> 8434380.4 | D21: =Balances!D10-Balances!C10 -> 10783486 | E21: =Balances!E10-Balances!D10 -> 2234809 | F21: =Balances!F10-Balances!E10 -> 2032806 | G21: =Balances!G10-Balances!F10 -> 1764540.3 | H21: =Balances!H10-Balances!G10 -> 1434746.4 | I21: =Balances!I10-Balances!H10 -> 1051579 | J21: =Balances!J10-Balances!I10 -> 626377.72
A22: Dotación a la amortización | C22: =-'Cuentas de PyG'!C21 -> 985654 | D22: =-'Cuentas de PyG'!D21 -> 1855217.2 | E22: =-'Cuentas de PyG'!E21 -> 2997318.7 | F22: =-'Cuentas de PyG'!F21 -> 3233784.7 | G22: =-'Cuentas de PyG'!G21 -> 3448876.6 | H22: =-'Cuentas de PyG'!H21 -> 3635583.3 | I22: =-'Cuentas de PyG'!I21 -> 3787394.4 | J22: =-'Cuentas de PyG'!J21 -> 3898662.3
A23: CAPEX | C23: =C20+C21+C22 -> 9393201.6 | D23: =D20+D21+D22 -> 12724731 | E23: =E20+E21+E22 -> 5247793.1 | F23: =F20+F21+F22 -> 5280840.1 | G23: =G20+G21+G22 -> 5225785.9 | H23: =H20+H21+H22 -> 5080386.9 | I23: =I20+I21+I22 -> 4846344.7 | J23: =J20+J21+J22 -> 4529430.8 | L23: Incremento de inmoviliazados bnetos + amortizacin del ejercicio
A25: NECESIDADES OPERATIVAS DE FONDOS
A27: CONCEPTO | B27: X-2 | C27: X-1 | D27: X | E27: X+1 | F27: X+2 | G27: X+3 | H27: X+4 | I27: X+5 | J27: X+6
A28: Periodo medio de inventario | B28: =-Balances!B20/('Cuentas de PyG'!B7+'Cuentas de PyG'!B8)*365 -> 21.547183 | C28: =-Balances!C20/('Cuentas de PyG'!C7+'Cuentas de PyG'!C8)*365 -> 23.678502 | D28: =-Balances!D20/('Cuentas de PyG'!D7+'Cuentas de PyG'!D8)*365 -> 15.575743 | E28: =D28 -> 15.575743 | F28: =E28 -> 15.575743 | G28: =F28 -> 15.575743 | H28: =G28 -> 15.575743 | I28: =H28 -> 15.575743 | J28: =I28 -> 15.575743 | L28: datos lo dice | M28: se mantiene
A29: Periodo medio de cobro | B29: =(Balances!B25+Balances!B26+Balances!B27)/'Cuentas de PyG'!B4*365 -> 37.975654 | C29: =(Balances!C25+Balances!C26+Balances!C27)/'Cuentas de PyG'!C4*365 -> 55.353519 | D29: =(Balances!D25+Balances!D26+Balances!D27)/'Cuentas de PyG'!D4*365 -> 53.679532 | E29: =D29 -> 53.679532 | F29: =E29 -> 53.679532 | G29: =F29 -> 53.679532 | H29: =G29 -> 53.679532 | I29: =H29 -> 53.679532 | J29: =I29 -> 53.679532
A30: Periodo medio de pago | C30: =(Balances!C61+Balances!C62+Balances!C63)/(-'Cuentas de PyG'!C7+Balances!C20-Balances!B20)*365 -> 69.738491 | D30: =(Balances!D61+Balances!D62+Balances!D63)/(-'Cuentas de PyG'!D7+Balances!D20-Balances!C20)*365 -> 71.97294 | E30: =D30 -> 71.97294 | F30: =E30 -> 71.97294 | G30: =F30 -> 71.97294 | H30: =G30 -> 71.97294 | I30: =H30 -> 71.97294 | J30: =I30 -> 71.97294
A31: Activo circulante | B31: =Balances!B20+Balances!B24 -> 25407941 | C31: =Balances!C20+Balances!C24 -> 42315964 | D31: =Balances!D20+Balances!D24 -> 40009114 | E31: =Balances!E20+Balances!E24 -> 42738391 | F31: =Balances!F20+Balances!F24 -> 45566530 | G31: =Balances!G20+Balances!G24 -> 48017946 | H31: =Balances!H20+Balances!H24 -> 50007040 | I31: =Balances!I20+Balances!I24 -> 51459710 | J31: =Balances!J20+Balances!J24 -> 52317784 | L31: Manenemos las formulas
A32: Pasivo circulante | B32: =Balances!B60 -> 23266107 | C32: =Balances!C60 -> 34979187 | D32: =Balances!D60 -> 37705942 | E32: =Balances!E60 -> 40538415 | F32: =Balances!F60 -> 43147264 | G32: =Balances!G60 -> 45390371 | H32: =Balances!H60 -> 47188711 | I32: =Balances!I60 -> 48474673 | J32: =Balances!J60 -> 49196144
A33: Fondo de maniobra | B33: =B31-B32 -> 2141834 | C33: =C31-C32 -> 7336776.4 | D33: =D31-D32 -> 2303171.6 | E33: =E31-E32 -> 2199975.7 | F33: =F31-F32 -> 2419266.2 | G33: =G31-G32 -> 2627575.3 | H33: =H31-H32 -> 2818329.2 | I33: =I31-I32 -> 2985036.9 | J33: =J31-J32 -> 3121639.8
A34: Variación Necesidades operativas de fondos | C34: =C33-B33 -> 5194942.4 | D34: =D33-C33 -> -5033604.8 | E34: =E33-D33 -> -103195.9 | F34: =F33-E33 -> 219290.51 | G34: =G33-F33 -> 208309.13 | H34: =H33-G33 -> 190753.86 | I34: =I33-H33 -> 166707.72 | J34: =J33-I33 -> 136602.87
A36: ESTRUCTURA FINANCIERA
A38: CONCEPTO | B38: X-2 | C38: X-1 | D38: X | E38: X+1 | F38: X+2 | G38: X+3 | H38: X+4 | I38: X+5 | J38: X+6
A39: Deuda financiera/(Deuda fin. y fondos propios) | B39: =(Balances!B51+Balances!B57)/(Balances!B51+Balances!B57+Balances!B44) -> 0.56778289 | C39: =(Balances!C51+Balances!C57)/(Balances!C51+Balances!C57+Balances!C44) -> 0.64150641 | D39: =(Balances!D51+Balances!D57)/(Balances!D51+Balances!D57+Balances!D44) -> 0.38223532 | E39: =D39 -> 0.38223532 | F39: =E39 -> 0.38223532 | G39: =F39 -> 0.38223532 | H39: =G39 -> 0.38223532 | I39: =H39 -> 0.38223532 | J39: =I39 -> 0.38223532
A40: Deuda fin. largo plazo/Deuda financiera total | B40: =Balances!B51/(Balances!B51+Balances!B57) -> 0.10794462 | C40: =Balances!C51/(Balances!C51+Balances!C57) -> 0.23261894 | D40: =Balances!D51/(Balances!D51+Balances!D57) -> 0.39615701 | E40: =D40 -> 0.39615701 | F40: =E40 -> 0.39615701 | G40: =F40 -> 0.39615701 | H40: =G40 -> 0.39615701 | I40: =H40 -> 0.39615701 | J40: =I40 -> 0.39615701
A41: Coste efectivo de la deuda | C41: =-'Cuentas de PyG'!C31/((Balances!B51+Balances!B57+Balances!C51+Balances!C57)/2) -> 0.038990943 | D41: =-'Cuentas de PyG'!D31/((Balances!C51+Balances!C57+Balances!D51+Balances!D57)/2) -> 0.019724758 | E41: =+D41 -> 0.019724758 | F41: =E41 -> 0.019724758 | G41: =F41 -> 0.019724758 | H41: =G41 -> 0.019724758 | I41: =H41 -> 0.019724758 | J41: =I41 -> 0.019724758
A42: Variación fondos propios | D42: =Balances!D44-Balances!C44 -> 12459536 | E42: =Balances!E44-Balances!D44 -> 2858853.8 | F42: =Balances!F44-Balances!E44 -> 3236860.7 | G42: =Balances!G44-Balances!F44 -> 3608646.8 | H42: =Balances!H44-Balances!G44 -> 3961970.2 | I42: =Balances!I44-Balances!H44 -> 4284116.3 | J42: =Balances!J44-Balances!I44 -> 4562578.6
A43: Variación deuda financiera | E43: =+(1-E39)*E42 -> 1766098.9 | F43: =+(1-F39)*F42 -> 1999618.2 | G43: =+(1-G39)*G42 -> 2229294.6 | H43: =+(1-H39)*H42 -> 2447565.3 | I43: =+(1-I39)*I42 -> 2646575.7 | J43: =+(1-J39)*J42 -> 2818599.9
A45: OTRAS HIPÓTESIS
A47: Tipo sin riesgo | B47: 0.013 | D47: pablo ferndandez 2023
A48: Prima de mercado | B48: 0.063 | D48: pablo ferndandez 2023
A49: Beta desapalancada | B49: 0.58 | D49: sector procesado de alimentos, sector anticiclo menor de 1 damoradan | I49: unlevered beta
...

Sheet Balances
A1: ESTRUCTURA DEL ACTIVO
A3: CONCEPTO | B3: X-2 | C3: X-1 | D3: X | E3: X+1 | F3: X+2 | G3: X+3 | H3: X+4 | I3: X+5 | J3: X+6
A4: A) ACTIVO NO CORRIENTE | B4: =B5+B10+B14+B17 -> 10479595 | C4: =C5+C10+C14+C17 -> 20399036 | D4: =D5+D10+D14+D17 -> 33874956 | E4: =E5+E10+E14+E17 -> 36125431 | F4: =F5+F10+F14+F17 -> 38172486 | G4: =G5+G10+G14+G17 -> 39949395 | H4: =H5+H10+H14+H17 -> 41394199 | I4: =I5+I10+I14+I17 -> 42453149 | J4: =J5+J10+J14+J17 -> 43083918
A5: I Inmovilizado intangible | B5: =SUM(B6:B9) -> 139371.2 | C5: =SUM(C6:C9) -> 112538.4 | D5: =SUM(D6:D9) -> 198566.4 | E5: ='Cuentas de PyG'!E4*Hipótesis!E17 -> 214231.8 | F5: ='Cuentas de PyG'!F4*Hipótesis!F17 -> 228481.21 | G5: ='Cuentas de PyG'!G4*Hipótesis!G17 -> 240850.16 | H5: ='Cuentas de PyG'!H4*Hipótesis!H17 -> 250907.34 | I5: ='Cuentas de PyG'!I4*Hipótesis!I17 -> 258278.62 | J5: ='Cuentas de PyG'!J4*Hipótesis!J17 -> 262669.36 | K5: funcion de las ventas según los datos
A6: 2. Concesiones | B6: 61985.6 | C6: 50051.6 | D6: 38794
A7: 3. Patentes, licencias, marcas y similares | B7: 0 | C7: 0 | D7: 5008.8
A8: 5. Aplicaciones informáticas | B8: 61408 | C8: 49585.2 | D8: 142703.6
A9: 7. Otro inmovilizado intangible | B9: 15977.6 | C9: 12901.6 | D9: 12060
A10: II Inmovilizado material | B10: =SUM(B11:B13) -> 9109400.8 | C10: =SUM(C11:C13) -> 17543781 | D10: =SUM(D11:D13) -> 28327267 | E10: ='Cuentas de PyG'!E4*Hipótesis!E18 -> 30562076 | F10: ='Cuentas de PyG'!F4*Hipótesis!F18 -> 32594882 | G10: ='Cuentas de PyG'!G4*Hipótesis!G18 -> 34359423 | H10: ='Cuentas de PyG'!H4*Hipótesis!H18 -> 35794169 | I10: ='Cuentas de PyG'!I4*Hipótesis!I18 -> 36845748 | J10: ='Cuentas de PyG'!J4*Hipótesis!J18 -> 37472126 | K10: funcion de las ventas según los datos
A11: 1. Terrenos y construcciones | B11: 1359357.2 | C11: 2617984.4 | D11: 4450191.6
A12: 2. Inst. técnicas y otro inmovilizado material | B12: 2157804 | C12: 4155711.2 | D12: 19754065
A13: 3. Inmovilizado en curso y anticipos | B13: 5592239.6 | C13: 10770086 | D13: 4123010.8
A14: IV Inv. en emp. del grupo y asoc. a largo plazo | B14: =SUM(B15:B16) -> 1151975.6 | C14: =SUM(C15:C16) -> 2633535.6 | D14: =SUM(D15:D16) -> 5277009.2 | E14: =D14 -> 5277009.2 | F14: =E14 -> 5277009.2 | G14: =F14 -> 5277009.2 | H14: =G14 -> 5277009.2 | I14: =H14 -> 5277009.2 | J14: =I14 -> 5277009.2 | K14: Los mantenemos cosntantes y los umaraemos al final
A15: 1. Instrumentos de patrimonio | B15: 1151975.6 | C15: 2633535.6 | D15: 2870218.8
A16: 2. Créditos a empresas | B16: 0 | C16: 0 | D16: 2406790.4
A17: V Inversiones financieras a largo plazo | B17: =B18 -> 78847.2 | C17: =C18 -> 109180.8 | D17: =D18 -> 72113.6 | E17: =D17 -> 72113.6 | F17: =E17 -> 72113.6 | G17: =F17 -> 72113.6 | H17: =G17 -> 72113.6 | I17: =H17 -> 72113.6 | J17: =I17 -> 72113.6 | K17: Los mantenemos cosntantes y los umaraemos al final
A18: 5. Otros activos financieros | B18: 78847.2 | C18: 109180.8 | D18: 72113.6
A19: B) ACTIVO CORRIENTE | B19: =B20+B24+B30+B32+B35+B36 -> 35134642 | C19: =C20+C24+C30+C32+C35+C36 -> 53001727 | D19: =D20+D24+D30+D32+D35+D36 -> 48997554 | E19: =E20+E24+E30+E32+E35+E36 -> 53924927 | F19: =F20+F24+F30+F32+F35+F36 -> 59443620 | G19: =G20+G24+G30+G32+G35+G36 -> 65468180 | H19: =H20+H24+H30+H32+H35+H36 -> 71951673 | I19: =I20+I24+I30+I32+I35+I36 -> 78829799 | J19: =J20+J24+J30+J32+J35+J36 -> 86022101
A20: II Existencias | B20: =SUM(B21:B23) -> 8552544.8 | C20: =SUM(C21:C23) -> 11444174 | D20: =SUM(D21:D23) -> 8215899.2 | E20: =-('Cuentas de PyG'!E7+'Cuentas de PyG'!E8)/365*Hipótesis!E28 -> 8850417.8 | F20: =-('Cuentas de PyG'!F7+'Cuentas de PyG'!F8)/365*Hipótesis!F28 -> 9424532 | G20: =-('Cuentas de PyG'!G7+'Cuentas de PyG'!G8)/365*Hipótesis!G28 -> 9919383 | H20: =-('Cuentas de PyG'!H7+'Cuentas de PyG'!H8)/365*Hipótesis!H28 -> 10317595 | I20: =-('Cuentas de PyG'!I7+'Cuentas de PyG'!I8)/365*Hipótesis!I28 -> 10604249 | J20: =-('Cuentas de PyG'!J7+'Cuentas de PyG'!J8)/365*Hipótesis!J28 -> 10767779 | K20: consumo de mercaderias +
A21: 1. Comerciales | B21: 8281408.4 | C21: 11081366 | D21: 7498019.6
A22: 2. Materias primas y otros aprovisionamientos | B22: 188313.2 | C22: 251982 | D22: 333879.6
A23: 6. Anticipos a proveedores | B23: 82823.2 | C23: 110826 | D23: 384000
A24: III Deudores comerc. y otras cuentas a cobrar | B24: =SUM(B25:B29) -> 16855396 | C24: =SUM(C25:C29) -> 30871789 | D24: =SUM(D25:D29) -> 31793214 | E24: ='Cuentas de PyG'!E4/365*Hipótesis!E29 -> 33887973 | F24: ='Cuentas de PyG'!F4/365*Hipótesis!F29 -> 36141998 | G24: ='Cuentas de PyG'!G4/365*Hipótesis!G29 -> 38098563 | H24: ='Cuentas de PyG'!H4/365*Hipótesis!H29 -> 39689445 | I24: ='Cuentas de PyG'!I4/365*Hipótesis!I29 -> 40855461 | J24: ='Cuentas de PyG'!J4/365*Hipótesis!J29 -> 41550004
A25: 1. Clientes por ventas y prestaciones de serv. | B25: 14404848 | C25: 26260780 | D25: 26973485
A26: 2. Clientes empresas del grupo y asociadas | B26: 165100 | C26: 1756414.8 | D26: 4436478
A27: 3. Deudores varios | B27: 1933448.8 | C27: 1663312.8 | D27: 0
A28: 5. Activos por impuesto corriente | B28: 0 | C28: 0 | D28: 34366.8
A29: 6. Otros créditos con las Administ. Públicas | B29: 352000 | C29: 1191282 | D29: 348884.8
A30: IV Inv. en emp. del grupo y asoc. a corto plazo | B30: =B31 -> 1934336.4 | C30: =C31 -> 4514076 | D30: =D31 -> 4464669.2 | E30: =D30 -> 4464669.2 | F30: =E30 -> 4464669.2 | G30: =F30 -> 4464669.2 | H30: =G30 -> 4464669.2 | I30: =H30 -> 4464669.2 | J30: =I30 -> 4464669.2 | K30: Consatantes
A31: 2. Créditos a empresas | B31: 1934336.4 | C31: 4514076 | D31: 4464669.2
A32: V Inversiones financieras a corto plazo | B32: =SUM(B33:B34) -> 3531942 | C32: =SUM(C33:C34) -> 1905276 | D32: =SUM(D33:D34) -> 767224 | E32: =D32 -> 767224 | F32: =E32 -> 767224 | G32: =F32 -> 767224 | H32: =G32 -> 767224 | I32: =H32 -> 767224 | J32: =I32 -> 767224 | K32: Constantes
A33: 2. Créditos a empresas | B33: 2800000 | C33: 669.6 | D33: 0
A34: 5. Otros activos financieros | B34: 731942 | C34: 1904606.4 | D34: 767224
A35: VI Periodificaciones a corto plazo | B35: 775225.2 | C35: 659269.6 | D35: 561874.8 | E35: =D35 -> 561874.8 | F35: =E35 -> 561874.8 | G35: =F35 -> 561874.8 | H35: =G35 -> 561874.8 | I35: =H35 -> 561874.8 | J35: =I35 -> 561874.8
A36: VII Efectivo y otros activos líquidos equiv. | B36: =B37 -> 3485197.2 | C36: =C37 -> 3607141.6 | D36: =D37 -> 3194672 | E36: =E37 -> 5392767.4 | F36: =F37 -> 8083321.7 | G36: =G37 -> 11656466 | H36: =H37 -> 16150865 | I36: =I37 -> 21576320 | J36: =J37 -> 27910549
A37: 1. Tesorería | B37: 3485197.2 | C37: 3607141.6 | D37: 3194672 | E37: ='Flujos de caja'!B32 -> 5392767.4 | F37: ='Flujos de caja'!C32 -> 8083321.7 | G37: ='Flujos de caja'!D32 -> 11656466 | H37: ='Flujos de caja'!E32 -> 16150865 | I37: ='Flujos de caja'!F32 -> 21576320 | J37: ='Flujos de caja'!G32 -> 27910549 | K37: flujo de caja del accionista
A38: TOTAL ACTIVO | B38: =B4+B19 -> 45614237 | C38: =C4+C19 -> 73400763 | D38: =D4+D19 -> 82872510 | E38: =E4+E19 -> 90050357 | F38: =F4+F19 -> 97616106 | G38: =G4+G19 -> 1.0541758e+08 | H38: =H4+H19 -> 1.1334587e+08 | I38: =I4+I19 -> 1.2128295e+08 | J38: =J4+J19 -> 1.2910602e+08
A40: ESTRUCTURA DEL PASIVO
A42: CONCEPTO | B42: X-2 | C42: X-1 | D42: X | E42: X+1 | F42: X+2 | G42: X+3 | H42: X+4 | I42: X+5 | J42: X+6
A43: A) PATRIMONIO NETO | B43: =B44+B49 -> 10022119 | C43: =C44+C49 -> 15183295 | D43: =D44+D49 -> 27432942 | E43: =E44+E49 -> 30012217 | F43: =F44+F49 -> 32969499 | G43: =G44+G49 -> 36298567 | H43: =H44+H49 -> 39980959 | I43: =I44+I49 -> 43985496 | J43: =J44+J49 -> 48268496
...

Sheet Cuentas de PyG
A1: CUENTA DE RESULTADOS
A3: CONCEPTO | B3: X-2 | C3: X-1 | D3: X | E3: X+1 | F3: X+2 | G3: X+3 | H3: X+4 | I3: X+5 | J3: X+6
A4: 1. Importe neto de la cifra de negocios | B4: =B5 -> 158621092 | C4: =C5 -> 1.9571267e+08 | D4: =D5 -> 2.1357556e+08 | E4: =E5 -> 2.3042508e+08 | F4: =F5 -> 2.4575157e+08 | G4: =G5 -> 2.5905545e+08 | H4: =H5 -> 2.6987283e+08 | I4: =I5 -> 2.7780129e+08 | J4: =J5 -> 2.8252391e+08
A5: a) Ventas | B5: 158621092 | C5: 1.9571267e+08 | D5: 2.1357556e+08 | E5: =D5*(1+Hipótesis!E4) -> 2.3042508e+08 | F5: =E5*(1+Hipótesis!F4) -> 2.4575157e+08 | G5: =F5*(1+Hipótesis!G4) -> 2.5905545e+08 | H5: =G5*(1+Hipótesis!H4) -> 2.6987283e+08 | I5: =H5*(1+Hipótesis!I4) -> 2.7780129e+08 | J5: =I5*(1+Hipótesis!J4) -> 2.8252391e+08
A6: 4. Aprovisionamientos | B6: =SUM(B7:B9) -> -1.4626544e+08 | C6: =SUM(C7:C9) -> -1.7987926e+08 | D6: =SUM(D7:D9) -> -196014728 | E6: =SUM(E7:E9) -> -2.1115885e+08 | F6: =SUM(F7:F9) -> -2.2486261e+08 | G6: =SUM(G7:G9) -> -2.3667593e+08 | H6: =SUM(H7:H9) -> -2.4618406e+08 | I6: =SUM(I7:I9) -> -2.5303082e+08 | J6: =SUM(J7:J9) -> -2.5694003e+08
A7: a) Consumo de mercaderías | B7: -1.4204702e+08 | C7: -1.7405374e+08 | D7: -1.9025989e+08 | E7: =-E4*Hipótesis!E5 -> -2.0494999e+08 | F7: =-F4*Hipótesis!F5 -> -2.1824078e+08 | G7: =-G4*Hipótesis!G5 -> -2.2969563e+08 | H7: =-H4*Hipótesis!H5 -> -2.3891228e+08 | I7: =-I4*Hipótesis!I5 -> -2.455454e+08 | J7: =-J4*Hipótesis!J5 -> -2.4932735e+08
A8: b) Consumo de mat. primas y otras mat. cons. | B8: -2829409.6 | C8: -2356225.6 | D8: -2270456.8 | E8: =-E4*Hipótesis!E6 -> -2449578.8 | F8: =-F4*Hipótesis!F6 -> -2612510.1 | G8: =-G4*Hipótesis!G6 -> -2753939.7 | H8: =-H4*Hipótesis!H6 -> -2868935.9 | I8: =-I4*Hipótesis!I6 -> -2953221 | J8: =-J4*Hipótesis!J6 -> -3003425.7
A9: c) Trabajos realizados por otras empresas | B9: -1389009.2 | C9: -3469294.8 | D9: -3484385.6 | E9: =-E4*Hipótesis!E7 -> -3759277.5 | F9: =-F4*Hipótesis!F7 -> -4009322.1 | G9: =-G4*Hipótesis!G7 -> -4226368.8 | H9: =-H4*Hipótesis!H7 -> -4402849.2 | I9: =-I4*Hipótesis!I7 -> -4532198.3 | J9: =-J4*Hipótesis!J7 -> -4609245.7
A10: 5. Otros ingresos de explotación | B10: =SUM(B11:B12) -> 502573.6 | C10: =SUM(C11:C12) -> 92705.2 | D10: =SUM(D11:D12) -> 192742 | E10: =SUM(E11:E12) -> 0 | F10: =SUM(F11:F12) -> 0 | G10: =SUM(G11:G12) -> 0 | H10: =SUM(H11:H12) -> 0 | I10: =SUM(I11:I12) -> 0 | J10: =SUM(J11:J12) -> 0 | L10: desconocemos | M10: 0 o hacer un promedio de los 2 ultimos años
A11: a) Ingresos accesorios y otros de gest. corr. | B11: 502573.6 | C11: 79420.4 | D11: 148858
A12: b) Subvenc. de explot. incorpor. al result. del ej. | B12: 0 | C12: 13284.8 | D12: 43884
A13: 6. Gastos de personal | B13: =SUM(B14:B15) -> -4856121.6 | C13: =SUM(C14:C15) -> -5630614.4 | D13: =SUM(D14:D15) -> -6172150.4 | E13: =-E4*Hipótesis!E8 -> -6659086.8 | F13: =-F4*Hipótesis!F8 -> -7102009.3 | G13: =-G4*Hipótesis!G8 -> -7486480.1 | H13: =-H4*Hipótesis!H8 -> -7799093.1 | I13: =-I4*Hipótesis!I8 -> -8028218.8 | J13: =-J4*Hipótesis!J8 -> -8164698.5
A14: a) Sueldos, salarios y asimilados | B14: -3643630.4 | C14: -4224745.6 | D14: -4695406.8
A15: b) Cargas sociales | B15: -1212491.2 | C15: -1405868.8 | D15: -1476743.6
A16: 7. Otros gastos de explotación | B16: =SUM(B17:B20) -> -3578392 | C16: =SUM(C17:C20) -> -4043999.6 | D16: =SUM(D17:D20) -> -5257501.6 | E16: =SUM(E17:E20) -> -5465871.4 | F16: =SUM(F17:F20) -> -5829428.4 | G16: =SUM(G17:G20) -> -6145007.4 | H16: =SUM(H17:H20) -> -6401604.5 | I16: =SUM(I17:I20) -> -6589674 | J16: =SUM(J17:J20) -> -6701698.5
A17: a) Servicios exteriores | B17: -3492226 | C17: -3925054 | D17: -4988202 | E17: =-E4*Hipótesis!E9 -> -5381733.7 | F17: =-F4*Hipótesis!F9 -> -5739694.4 | G17: =-G4*Hipótesis!G9 -> -6050415.6 | H17: =-H4*Hipótesis!H9 -> -6303062.8 | I17: =-I4*Hipótesis!I9 -> -6488237.4 | J17: =-J4*Hipótesis!J9 -> -6598537.4
A18: b) Tributos | B18: -45736.4 | C18: -91808.4 | D18: -77985.2 | E18: =-E4*Hipótesis!E10 -> -84137.648 | F18: =-F4*Hipótesis!F10 -> -89733.979 | G18: =-G4*Hipótesis!G10 -> -94591.773 | H18: =-H4*Hipótesis!H10 -> -98541.642 | I18: =-I4*Hipótesis!I10 -> -101436.65 | J18: =-J4*Hipótesis!J10 -> -103161.07
A19: c) Pérd., deterioro y var. de prov. por op. com. | B19: 0 | C19: -4559.2 | D19: -191314.4 | L19: Considermos Extraordinarios
A20: d) Otros gastos de gestión corriente | B20: -40429.6 | C20: -22578 | D20: 0
A21: 8. Amortización del inmovilizado | B21: -785850.4 | C21: -985654 | D21: -1855217.2 | E21: =-(Balances!D5+Balances!D10)*Hipótesis!E19 -> -2997318.7 | F21: =-(Balances!E5+Balances!E10)*Hipótesis!F19 -> -3233784.7 | G21: =-(Balances!F5+Balances!F10)*Hipótesis!G19 -> -3448876.6 | H21: =-(Balances!G5+Balances!G10)*Hipótesis!H19 -> -3635583.3 | I21: =-(Balances!H5+Balances!H10)*Hipótesis!I19 -> -3787394.4 | J21: =-(Balances!I5+Balances!I10)*Hipótesis!J19 -> -3898662.3
A22: 9. Imputación de subvenc. de inmov. no financ. | B22: 0 | C22: 178314.4 | D22: 301482.4 | E22: =Balances!$D$49*Hipótesis!E11 -> 279578.74 | F22: =Balances!$D$49*Hipótesis!F11 -> 279578.74 | G22: =Balances!$D$49*Hipótesis!G11 -> 279578.74 | H22: =Balances!$D$49*Hipótesis!H11 -> 279578.74 | I22: =Balances!$D$49*Hipótesis!I11 -> 279578.74 | J22: =Balances!$D$49*Hipótesis!J11 -> 279578.74 | L22: No suma, no entra, la subvnecion entro en x-1 en balance, y lo que hace es salir cada año
A23: 11. Deterioro y resultado por enaj. del inmov. | B23: =B24 -> -7363.2 | C23: =C24 -> -5701.2 | D23: =D24 -> 11086.4 | E23: =E24 -> 0 | F23: =F24 -> 0 | G23: =G24 -> 0 | H23: =H24 -> 0 | I23: =I24 -> 0 | J23: =J24 -> 0
A24: b) Resultados por enajenaciones y otras | B24: -7363.2 | C24: -5701.2 | D24: 11086.4
A25: A1) RESULTADO DE EXPLOTACIÓN | B25: =B4+B6+B10+B13+B16+B21+B22+B23 -> 3630502.4 | C25: =C4+C6+C10+C13+C16+C21+C22+C23 -> 5438462.4 | D25: =D4+D6+D10+D13+D16+D21+D22+D23 -> 4781278.4 | E25: =E4+E6+E10+E13+E16+E21+E22+E23 -> 4423529.5 | F25: =F4+F6+F10+F13+F16+F21+F22+F23 -> 5003313.1 | G25: =G4+G6+G10+G13+G16+G21+G22+G23 -> 5578734.5 | H25: =H4+H6+H10+H13+H16+H21+H22+H23 -> 6132069.8 | I25: =I4+I6+I10+I13+I16+I21+I22+I23 -> 6644764.2 | J25: =J4+J6+J10+J13+J16+J21+J22+J23 -> 7098407.9
A26: 14. Ingresos financieros | B26: =B27+B30 -> 243585.2 | C26: =C27+C30 -> 148334.4 | D26: =D27+D30 -> 113532 | L26: No cocnocemo el dato, y no influye valoracion de la empresa, nos interesa resutlado de explotacion para arriba
A27: b) De valores negociables y otros instr. fin. | B27: =SUM(B28:B29) -> 68910 | C27: =SUM(C28:C29) -> 148334.4 | D27: =SUM(D28:D29) -> 113532
A28: a) De empresas del grupo y asociadas | B28: 55004.4 | C28: 0 | D28: 102932.4
A29: b) De terceros | B29: 13905.6 | C29: 148334.4 | D29: 10599.6
A30: c) Imputación de subv. y donac. de carácter fin. | B30: 174675.2 | C30: 0 | D30: 0
A31: 15. Gastos financieros | B31: =B32 -> -350600.4 | C31: =C32 -> -661369.6 | D31: =D32 -> -368028.4 | E31: =E32 -> -336944.6 | F31: =F32 -> -376386.58 | G31: =G32 -> -420358.88 | H31: =H32 -> -468636.51 | I31: =I32 -> -520839.58 | J31: =J32 -> -576435.78
A32: b) Por deudas con terceros | B32: -350600.4 | C32: -661369.6 | D32: -368028.4 | E32: =-Hipótesis!E41*(Balances!E51+Balances!E57) -> -336944.6 | F32: =-Hipótesis!F41*(Balances!F51+Balances!F57) -> -376386.58 | G32: =-Hipótesis!G41*(Balances!G51+Balances!G57) -> -420358.88 | H32: =-Hipótesis!H41*(Balances!H51+Balances!H57) -> -468636.51 | I32: =-Hipótesis!I41*(Balances!I51+Balances!I57) -> -520839.58 | J32: =-Hipótesis!J41*(Balances!J51+Balances!J57) -> -576435.78
A33: 16. Variación de valor razonable en instr. fin. | B33: =B34 -> 0 | C33: =C34 -> 0 | D33: =D34 -> -262280.4
A34: a) Cartera de negociación y otros | B34: 0 | C34: 0 | D34: -262280.4
A35: 17. Diferencias de cambio | B35: 111130.8 | C35: -367216.8 | D35: -39714.4
A36: A3) RESULTADO ANTES DE IMPUESTOS | B36: =B25+B26+B31+B33+B35 -> 3634618 | C36: =C25+C26+C31+C33+C35 -> 4558210.4 | D36: =D25+D26+D31+D33+D35 -> 4224787.2 | E36: =E25+E26+E31+E33+E35 -> 4086584.9 | F36: =F25+F26+F31+F33+F35 -> 4626926.5 | G36: =G25+G26+G31+G33+G35 -> 5158375.7 | H36: =H25+H26+H31+H33+H35 -> 5663433.3 | I36: =I25+I26+I31+I33+I35 -> 6123924.6 | J36: =J25+J26+J31+J33+J35 -> 6521972.1
A37: 19. Impuestos sobre beneficios | B37: -1131425.6 | C37: -1340893.2 | D37: -1269251.2 | E37: =-E36*Hipótesis!E12 -> -1227731.1 | F37: =-F36*Hipótesis!F12 -> -1390065.8 | G37: =-G36*Hipótesis!G12 -> -1549728.8 | H37: =-H36*Hipótesis!H12 -> -1701463.1 | I37: =-I36*Hipótesis!I12 -> -1839808.3 | J37: =-J36*Hipótesis!J12 -> -1959393.6
A38: A5) RESULTADO DEL EJERCICIO | B38: =B36+B37 -> 2503192.4 | C38: =C36+C37 -> 3217317.2 | D38: =D36+D37 -> 2955536 | E38: =E36+E37 -> 2858853.8 | F38: =F36+F37 -> 3236860.7 | G38: =G36+G37 -> 3608646.8 | H38: =H36+H37 -> 3961970.2 | I38: =I36+I37 -> 4284116.3 | J38: =J36+J37 -> 4562578.6
B40: =B25/B4 -> 0.022887892 | C40: =C25/C4 -> 0.027787993 | D40: =D25/D4 -> 0.022386823 | E40: =E25/E4 -> 0.019197257 | F40: =F25/F4 -> 0.020359231 | G40: =G25/G4 -> 0.021534905 | H40: =H25/H4 -> 0.022722072 | I40: =I25/I4 -> 0.023919126 | J40: =J25/J4 -> 0.025124981

Sheet Flujos de caja
A1: DESGLOSE DEL FLUJO DE CAJA LIBRE
A3: CONCEPTO | B3: X+1 | C3: X+2 | D3: X+3 | E3: X+4 | F3: X+5 | G3: X+6 | H3: Normalizado
A4: EBITDA | B4: ='Cuentas de PyG'!E25-'Cuentas de PyG'!E21-'Cuentas de PyG'!E22 -> 7141269.5 | C4: ='Cuentas de PyG'!F25-'Cuentas de PyG'!F21-'Cuentas de PyG'!F22 -> 7957519 | D4: ='Cuentas de PyG'!G25-'Cuentas de PyG'!G21-'Cuentas de PyG'!G22 -> 8748032.5 | E4: ='Cuentas de PyG'!H25-'Cuentas de PyG'!H21-'Cuentas de PyG'!H22 -> 9488074.4 | F4: ='Cuentas de PyG'!I25-'Cuentas de PyG'!I21-'Cuentas de PyG'!I22 -> 10152580 | G4: ='Cuentas de PyG'!J25-'Cuentas de PyG'!J21-'Cuentas de PyG'!J22 -> 10717492 | H4: =G4*(1+Hipótesis!B51) -> 10899689
A5: (-)Dotación a la amortización | B5: ='Cuentas de PyG'!E21 -> -2997318.7 | C5: ='Cuentas de PyG'!F21 -> -3233784.7 | D5: ='Cuentas de PyG'!G21 -> -3448876.6 | E5: ='Cuentas de PyG'!H21 -> -3635583.3 | F5: ='Cuentas de PyG'!I21 -> -3787394.4 | G5: ='Cuentas de PyG'!J21 -> -3898662.3 | H5: =-(Balances!J5+Balances!J10)*Hipótesis!J19 -> -3964939.6
A6: (+)Imputación de subvención por inmovilizado | B6: ='Cuentas de PyG'!E22 -> 279578.74 | C6: ='Cuentas de PyG'!F22 -> 279578.74 | D6: ='Cuentas de PyG'!G22 -> 279578.74 | E6: ='Cuentas de PyG'!H22 -> 279578.74 | F6: ='Cuentas de PyG'!I22 -> 279578.74 | G6: ='Cuentas de PyG'!J22 -> 279578.74 | H6: =+G6 -> 279578.74
A7: EBIT | B7: =B4+B5+B6 -> 4423529.5 | C7: =C4+C5+C6 -> 5003313.1 | D7: =D4+D5+D6 -> 5578734.5 | E7: =E4+E5+E6 -> 6132069.8 | F7: =F4+F5+F6 -> 6644764.2 | G7: =G4+G5+G6 -> 7098407.9 | H7: =H4+H5+H6 -> 7214328
A8: (-)Impuestos ajustados | B8: =-B7*Hipótesis!E12 -> -1328959.3 | C8: =-C7*Hipótesis!F12 -> -1503143.4 | D8: =-D7*Hipótesis!G12 -> -1676017.1 | E8: =-E7*Hipótesis!H12 -> -1842255.4 | F8: =-F7*Hipótesis!I12 -> -1996283.9 | G8: =-G7*Hipótesis!J12 -> -2132572 | H8: =-H7*Hipótesis!J12 -> -2167397.8
A9: NOPLAT | B9: =B7+B8 -> 3094570.2 | C9: =C7+C8 -> 3500169.6 | D9: =D7+D8 -> 3902717.5 | E9: =E7+E8 -> 4289814.4 | F9: =F7+F8 -> 4648480.2 | G9: =G7+G8 -> 4965836 | H9: =H7+H8 -> 5046930.2
A10: (+)Dotación a la amortización | B10: =-B5 -> 2997318.7 | C10: =-C5 -> 3233784.7 | D10: =-D5 -> 3448876.6 | E10: =-E5 -> 3635583.3 | F10: =-F5 -> 3787394.4 | G10: =-G5 -> 3898662.3 | H10: =-H5 -> 3964939.6
A11: (-)Imputación de subvención por inmovilizado | B11: =-B6 -> -279578.74 | C11: =-C6 -> -279578.74 | D11: =-D6 -> -279578.74 | E11: =-E6 -> -279578.74 | F11: =-F6 -> -279578.74 | G11: =-G6 -> -279578.74 | H11: =-H6 -> -279578.74
A12: (-)CAPEX | B12: =-Hipótesis!E23 -> -5247793.1 | C12: =-Hipótesis!F23 -> -5280840.1 | D12: =-Hipótesis!G23 -> -5225785.9 | E12: =-Hipótesis!H23 -> -5080386.9 | F12: =-Hipótesis!I23 -> -4846344.7 | G12: =-Hipótesis!J23 -> -4529430.8 | H12: =-(Balances!J5+Balances!J10)*Hipótesis!B51+'Flujos de caja'!H5 -> -4606431.1 | I12: CAPEX va en funconde las vaentas, premisa la equivalencia entre amortización y CAPEX en valor residual para evitar se nos disparen los inmovilizados en valor residual o que tiendan a 0. Entonces o hay que igualar G10 = G12 o que G12 va creciendo en funcion de las ventas
A13: (+/-)Necesidades op. de fondos | B13: =-Hipótesis!E34 -> 103195.9 | C13: =-Hipótesis!F34 -> -219290.51 | D13: =-Hipótesis!G34 -> -208309.13 | E13: =-Hipótesis!H34 -> -190753.86 | F13: =-Hipótesis!I34 -> -166707.72 | G13: =-Hipótesis!J34 -> -136602.87 | H13: =-Hipótesis!J33*Hipótesis!B51 -> -53067.876 | I13: Positivo es entrada negativo es salida, para normalizar ponemos un incremento igual que las ventas
A14: FLUJO DE CAJA LIBRE | B14: =B9+B10+B11+B12+B13 -> 667712.98 | C14: =C9+C10+C11+C12+C13 -> 954244.97 | D14: =D9+D10+D11+D12+D13 -> 1637920.3 | E14: =E9+E10+E11+E12+E13 -> 2374678.2 | F14: =F9+F10+F11+F12+F13 -> 3143243.4 | G14: =G9+G10+G11+G12+G13 -> 3918885.9 | H14: =H9+H10+H11+H12+H13 -> 4072792.1
A16: DESGLOSE DEL FLUJO DE CAJA LIBRE PARA EL ACCIONISTA
A18: CONCEPTO | B18: X+1 | C18: X+2 | D18: X+3 | E18: X+4 | F18: X+5 | G18: X+6
A19: FLUJO DE CAJA LIBRE | B19: =B14 -> 667712.98 | C19: =C14 -> 954244.97 | D19: =D14 -> 1637920.3 | E19: =E14 -> 2374678.2 | F19: =F14 -> 3143243.4 | G19: =G14 -> 3918885.9
A20: (-)Gastos financieros | B20: ='Cuentas de PyG'!E31 -> -336944.6 | C20: ='Cuentas de PyG'!F31 -> -376386.58 | D20: ='Cuentas de PyG'!G31 -> -420358.88 | E20: ='Cuentas de PyG'!H31 -> -468636.51 | F20: ='Cuentas de PyG'!I31 -> -520839.58 | G20: ='Cuentas de PyG'!J31 -> -576435.78
A21: (+)Escudo fiscal | B21: =-B20*Hipótesis!E12 -> 101228.14 | C21: =-C20*Hipótesis!F12 -> 113077.68 | D21: =-D20*Hipótesis!G12 -> 126288.26 | E21: =-E20*Hipótesis!H12 -> 140792.29 | F21: =-F20*Hipótesis!I12 -> 156475.64 | G21: =-G20*Hipótesis!J12 -> 173178.38 | H21: gastos financieros * impuesto de sociedades
A22: Incremento/amortización de Deuda | B22: =Hipótesis!E43 -> 1766098.9 | C22: =Hipótesis!F43 -> 1999618.2 | D22: =Hipótesis!G43 -> 2229294.6 | E22: =Hipótesis!H43 -> 2447565.3 | F22: =Hipótesis!I43 -> 2646575.7 | G22: =Hipótesis!J43 -> 2818599.9
A23: FLUJO PARA LOS ACCIONISTAS | B23: =B19+B20+B21+B22 -> 2198095.4 | C23: =C19+C20+C21+C22 -> 2690554.3 | D23: =D19+D20+D21+D22 -> 3573144.3 | E23: =E19+E20+E21+E22 -> 4494399.3 | F23: =F19+F20+F21+F22 -> 5425455.2 | G23: =G19+G20+G21+G22 -> 6334228.4
A25: SALDO CONTABLE DE CAJA
A27: CONCEPTO | B27: X+1 | C27: X+2 | D27: X+3 | E27: X+4 | F27: X+5 | G27: X+6
A28: Saldo de caja del ejercicio anterior | B28: =Balances!D36 -> 3194672 | C28: =Balances!E36 -> 5392767.4 | D28: =Balances!F36 -> 8083321.7 | E28: =Balances!G36 -> 11656466 | F28: =Balances!H36 -> 16150865 | G28: =Balances!I36 -> 21576320
A29: Flujo de caja libre para los accionistas | B29: =B23 -> 2198095.4 | C29: =C23 -> 2690554.3 | D29: =D23 -> 3573144.3 | E29: =E23 -> 4494399.3 | F29: =F23 -> 5425455.2 | G29: =G23 -> 6334228.4
A30: Aportaciones accionistas | B30: =IF(B28+B29<0,-(B28+B29),0) -> 0 | C30: =IF(C28+C29<0,-(C28+C29),0) -> 0 | D30: =IF(D28+D29<0,-(D28+D29),0) -> 0 | E30: =IF(E28+E29<0,-(E28+E29),0) -> 0 | F30: =IF(F28+F29<0,-(F28+F29),0) -> 0 | G30: =IF(G28+G29<0,-(G28+G29),0) -> 0
A31: Dividendos repartidos
A32: SALDO DE CAJA DEL EJERCICIO | B32: =B28+B29+B30+B31 -> 5392767.4 | C32: =C28+C29+C30+C31 -> 8083321.7 | D32: =D28+D29+D30+D31 -> 11656466 | E32: =E28+E29+E30+E31 -> 16150865 | F32: =F28+F29+F30+F31 -> 21576320 | G32: =G28+G29+G30+G31 -> 27910549

Sheet Valoración DCF
A1: ESTIMACIÓN DEL COSTE DEL CAPITAL MEDIO PONDERADO
O2: Ratio cobertura de interes | P2: =+'Cuentas de PyG'!D25/-'Cuentas de PyG'!D31 -> 12.991602
A3: COSTE DE LOS FONDOS PROPIOS | D3: COSTE DE LA DEUDA FINANCIERA | H3: COSTE DEL CAPITAL MEDIO PONDERADO
O4: Tasa libre de riesgo | P4: =+Hipótesis!B47 -> 0.013
A5: Tipo sin riesgo | B5: =Hipótesis!B47 -> 0.013 | D5: kd | F5: =+Hipótesis!D41 -> 0.019724758 | H5: DF/(DF+E) | J5: =(Balances!D51+Balances!D57)/(Balances!D51+Balances!D57+B30) -> 0.16349948 | O5: Spread default | P5: 0.0069
A6: Prima de mercado | B6: =Hipótesis!B48 -> 0.063 | D6: kd desp. impuestos | F6: =F5*(1-Hipótesis!D12) -> 0.013798857 | H6: DF/E | J6: =J5/(1-J5) -> 0.19545653 | O6: Coste de la deuda | P6: =+P4+P5 -> 0.0199
O7: Kd | P7: =+P6*(1-0.25) -> 0.014925
A8: Beta desapalancada | B8: =+Hipótesis!B49 -> 0.58 | H8: WACC | J8: =B13*(1-J5)+F6*J5 -> 0.056391507
A9: Beta reapalancada | B9: =B8*(1+J6*(1-Hipótesis!D12)) -> 0.65930665
H10: Crecimiento a perp. | J10: =Hipótesis!B51 -> 0.017
A11: Prima de liquidez | B11: 0.01
A13: ke | B13: =B5+B6*B9+B11 -> 0.064536319
A15: ESTIMACIÓN DEL VALOR DE LA EMPRESA
A17: CONCEPTO | B17: X | C17: X+1 | D17: X+2 | E17: X+3 | F17: X+4 | G17: X+5 | H17: X+6 | I17: Normalizado
A18: FLUJO DE CAJA LIBRE | C18: ='Flujos de caja'!B14 -> 667712.98 | D18: ='Flujos de caja'!C14 -> 954244.97 | E18: ='Flujos de caja'!D14 -> 1637920.3 | F18: ='Flujos de caja'!E14 -> 2374678.2 | G18: ='Flujos de caja'!F14 -> 3143243.4 | H18: ='Flujos de caja'!G14 -> 3918885.9 | I18: ='Flujos de caja'!H14 -> 4072792.1
A20: ENTERPRISE VALUE | B20: =(C18+C20)/(1+$J$8) -> 79901789 | C20: =(D18+D20)/(1+$J$8) -> 84538876 | D20: =(E18+E20)/(1+$J$8) -> 89197295 | E20: =(F18+F20)/(1+$J$8) -> 93481317 | F20: =(G18+G20)/(1+$J$8) -> 97313004 | G20: =(H18+H20)/(1+$J$8) -> 1.0063052e+08 | H20: =I18/(J8-J10) -> 1.0339264e+08
A22: ESTIMACIÓN DEL VALOR DE LOS FONDOS PROPIOS
A24: ENTERPRISE VALUE | B24: =B20 -> 79901789
A26: Deuda financiera | B26: =Balances!D51+Balances!D57-Balances!D36 -> 12121547
A27: Activos no operativos | B27: =-(Balances!D14+Balances!D17+Balances!D30+Balances!D32) -> -10581016
A28: Deuda fin. Neta | B28: =B26+B27 -> 1540531.2
A30: EQUITY VALUE | B30: =B24-B28 -> 78361258
A33: ANÁLISIS DE SENSIBILIDAD EV
A35: ENTERPRISE VALUE | H35: EQUITY VALUE
A37: =B24 -> 79901789 | B37: =+C37-0.5% -> 0.007 | C37: =+D37-0.5% -> 0.012 | D37: 0.017 | E37: =+D37+0.5% -> 0.022 | F37: =+E37+0.5% -> 0.027 | H37: =B30 -> 78361258 | I37: =+J37-0.5% -> 0.007 | J37: =+K37-0.5% -> 0.012 | K37: 0.017 | L37: =+K37+0.5% -> 0.022 | M37: =+L37*0.5% -> 0.00011
A38: =+A39-0.5% -> 0.046391507 | B38: 89174274 | C38: 1.0062527e+08 | D38: 1.1597228e+08 | E38: 1.3761125e+08 | F38: 1.7040921e+08 | H38: =+H39-0.5% -> 0.054265841 | I38: 78361258 | J38: 78361258 | K38: 78361258 | L38: 78361258 | M38: 78361258 | O38: Descuento flujo caja video
A39: =+A40-0.5% -> 0.051391507 | B39: 78119912 | C39: 86741216 | D39: 97869333 | E39: 1.1278362e+08 | F39: 1.3381244e+08 | H39: =+H40-0.5% -> 0.059265841 | I39: 78361258 | J39: 78361258 | K39: 78361258 | L39: 78361258 | M39: 78361258
A40: 0.056391507 | B40: 69324513 | C40: 76007347 | D40: 84386697 | E40: 95202507 | F40: 1.0969823e+08 | H40: 0.064265841 | I40: 78361258 | J40: 78361258 | K40: 78361258 | L40: 78361258 | M40: 78361258
A41: =+A40+0.5% -> 0.061391507 | B41: 62164555 | C41: 67466378 | D41: 73962534 | E41: 82107815 | F41: 92621496 | H41: =+H40+0.5% -> 0.069265841 | I41: 78361258 | J41: 78361258 | K41: 78361258 | L41: 78361258 | M41: 78361258
A42: =+A41+0.5% -> 0.066391507 | B42: 56226504 | C42: 60513042 | D42: 65667450 | E42: 71982983 | F42: 79901789 | H42: =+H41+0.5% -> 0.074265841 | I42: 78361258 | J42: 78361258 | K42: 78361258 | L42: 78361258 | M42: 78361258

Sheet Valoración múltiplo
A1: VALORACIÓN SEGÚN MÚLTIPLO EV/EBITDA
A3: Múltiplo EV/EBITDA | B3: 16.44 | D3: damoradan - data- ebit
A4: EBITDA | B4: ='Cuentas de PyG'!D25-'Cuentas de PyG'!D21-'Cuentas de PyG'!D22 -> 6335013.2
A6: ENTERPRISE VALUE | B6: =B3*B4 -> 1.0414762e+08
A8: Deuda financiera | B8: ='Valoración DCF'!B26 -> 12121547
A9: Activos no operativos | B9: ='Valoración DCF'!B27 -> -10581016
A10: Deuda fin. Neta | B10: =B8+B9 -> 1540531.2
A12: EQUITY VALUE | B12: =B6-B10 -> 1.0260709e+08
A14: MÚLTIPLO IMPLÍCITO
B16: X | C16: X+1
A17: EV/EBITDA | B17: ='Valoración DCF'!$B$20/('Cuentas de PyG'!D25-'Cuentas de PyG'!D21-'Cuentas de PyG'!D22) -> 12.612727 | C17: ='Valoración DCF'!$B$20/('Cuentas de PyG'!E25-'Cuentas de PyG'!E21-'Cuentas de PyG'!E22) -> 11.188737
