Workbook

Sheet Datos

Sheet Hipótesis
A1: HIPÓTESIS DE CUENTA RESULTADOS
E2: 1 | F2: 2 | G2: 3 | H2: 4 | I2: 5
A3: CONCEPTO | B3: X-2 | C3: X-1 | D3: X | E3: X+1 | F3: X+2 | G3: X+3 | H3: X+4 | I3: X+5
A4: Crec. Imp. neto de la cifra de negocios | C4: =('Cuentas PyG'!C4-'Cuentas PyG'!B4)/'Cuentas PyG'!B4 -> -0.23335122 | D4: =('Cuentas PyG'!D4-'Cuentas PyG'!C4)/'Cuentas PyG'!C4 -> 0.015460283 | E4: =+D4-(($D$4-$B$41)/5) -> 0.016368226 | F4: =+E4-(($D$4-$B$41)/5) -> 0.01727617 | G4: =+F4-(($D$4-$B$41)/5) -> 0.018184113 | H4: =+G4-(($D$4-$B$41)/5) -> 0.019092057 | I4: =+H4-(($D$4-$B$41)/5) -> 0.02
A5: Consumos totales/Imp. neto de la cifra de neg. | B5: =-('Cuentas PyG'!B8+'Cuentas PyG'!B5)/'Cuentas PyG'!B4 -> 0.41312568 | C5: =-('Cuentas PyG'!C8+'Cuentas PyG'!C5)/'Cuentas PyG'!C4 -> 0.32609163 | D5: =-('Cuentas PyG'!D8+'Cuentas PyG'!D5)/'Cuentas PyG'!D4 -> 0.2944947 | E5: 0.2944947 | F5: 0.2944947 | G5: 0.2944947 | H5: 0.2944947 | I5: 0.2944947
A6: Trab. realiz. emp. Para su activo/Imp. neto cifra de neg. | B6: ='Cuentas PyG'!B6/'Cuentas PyG'!B4 -> 0.1143984 | C6: ='Cuentas PyG'!C6/'Cuentas PyG'!C4 -> 0.18178861 | D6: ='Cuentas PyG'!D6/'Cuentas PyG'!D4 -> 0.17956046 | E6: 0.17956046 | F6: 0.17956046 | G6: 0.17956046 | H6: 0.17956046 | I6: 0.17956046
A7: Crec. Ingresos accesorios | C7: =('Cuentas PyG'!C12-'Cuentas PyG'!B12)/'Cuentas PyG'!B12 -> 9.8218776 | D7: =('Cuentas PyG'!D12-'Cuentas PyG'!C12)/'Cuentas PyG'!C12 -> -0.87797127
A8: Trab. realiz. por otras empresas /Imp. neto cifra de neg. | B8: =-'Cuentas PyG'!B9/'Cuentas PyG'!B4 -> 0.069028455 | C8: =-'Cuentas PyG'!C9/'Cuentas PyG'!C4 -> 0.049878802 | D8: =-'Cuentas PyG'!D9/'Cuentas PyG'!D4 -> 0.067456574 | E8: 0.067456574 | F8: 0.067456574 | G8: 0.067456574 | H8: 0.067456574 | I8: 0.067456574
A9: Gastos de personal/Imp. neto cifra de neg. | B9: =-'Cuentas PyG'!B14/'Cuentas PyG'!B4 -> 0.21974354 | C9: =-'Cuentas PyG'!C14/'Cuentas PyG'!C4 -> 0.30450156 | D9: =-'Cuentas PyG'!D14/'Cuentas PyG'!D4 -> 0.30623231 | E9: 0.30623231 | F9: 0.30623231 | G9: 0.30623231 | H9: 0.30623231 | I9: 0.30623231
A10: Gastos de explotación/Imp. Neto cifra de negocio | B10: =-'Cuentas PyG'!B17/'Cuentas PyG'!B4 -> 0.20727227 | C10: =-'Cuentas PyG'!C17/'Cuentas PyG'!C4 -> 0.26385543 | D10: =-'Cuentas PyG'!D17/'Cuentas PyG'!D4 -> 0.25109607 | E10: 0.25109607 | F10: 0.25109607 | G10: 0.25109607 | H10: 0.25109607 | I10: 0.25109607
A11: Dotación amort./Inmovilizado Neto | B11: =+'Cuentas PyG'!B21/(Balances!B9+Balances!B5) -> -0.58684942 | C11: =+'Cuentas PyG'!C21/(Balances!C9+Balances!C5) -> -0.58945554 | D11: =+'Cuentas PyG'!D21/(Balances!D9+Balances!D5) -> -0.61870444 | E11: -0.61870444 | F11: -0.61870444 | G11: -0.61870444 | H11: -0.61870444 | I11: -0.61870444
A12: Imputación de subv./Subvenciones | B12: =+'Cuentas PyG'!B22/Balances!B45 -> 0.3497693 | C12: =+'Cuentas PyG'!C22/Balances!C45 -> 0.10536409 | D12: =+'Cuentas PyG'!D22/Balances!D45 -> 0.12984146 | E12: 0.12984146 | F12: 0.12984146 | G12: 0.12984146 | H12: 0.12984146 | I12: 0.12984146
A13: Impuesto sobre beneficios/Result. antes imp. | B13: =-'Cuentas PyG'!B30/'Cuentas PyG'!B29 -> 0.17773561 | C13: =-'Cuentas PyG'!C30/'Cuentas PyG'!C29 -> 0.32547336 | D13: =-'Cuentas PyG'!D30/'Cuentas PyG'!D29 -> 0.27401021 | E13: =$B$44 -> 0.25 | F13: =$B$44 -> 0.25 | G13: =$B$44 -> 0.25 | H13: =$B$44 -> 0.25 | I13: =$B$44 -> 0.25
A15: HIPÓTESIS DE CAPITAL CIRCULANTE
A17: CONCEPTO | B17: X-2 | C17: X-1 | D17: X | E17: X+1 | F17: X+2 | G17: X+3 | H17: X+4 | I17: X+5
A18: Periodo medio de inventario | B18: =-Balances!B18/('Cuentas PyG'!B8+'Cuentas PyG'!B5)*365 -> 231.80612 | C18: =-Balances!C18/('Cuentas PyG'!C8+'Cuentas PyG'!C5)*365 -> 305.41719 | D18: =-Balances!D18/('Cuentas PyG'!D8+'Cuentas PyG'!D5)*365 -> 268.01517 | E18: 268.01517 | F18: 268.01517 | G18: 268.01517 | H18: 268.01517 | I18: 268.01517
A19: Periodo medio de cobro | B19: =(Balances!B24+Balances!B25+Balances!B26)/'Cuentas PyG'!B4*365 -> 152.7487 | C19: =(Balances!C24+Balances!C25+Balances!C26)/'Cuentas PyG'!C4*365 -> 266.03461 | D19: =(Balances!D24+Balances!D25+Balances!D26)/'Cuentas PyG'!D4*365 -> 316.84042 | E19: =D19-$C$42 -> 306.67926 | F19: =E19-$C$42 -> 296.51809 | G19: =F19-$C$42 -> 286.35693 | H19: =G19-$C$42 -> 276.19577 | I19: =H19-$C$42 -> 266.03461
A20: Periodo medio de pago | C20: =(Balances!C54+Balances!C18-Balances!B18)/(-'Cuentas PyG'!C8+'Cuentas PyG'!C5)*365 -> 178.3947 | D20: =(Balances!D54+Balances!D18-Balances!C18)/(-'Cuentas PyG'!D8+'Cuentas PyG'!D5)*365 -> 401.87638 | E20: =D20-$C$43 -> 357.18004 | F20: =E20-$C$43 -> 312.48371 | G20: =F20-$C$43 -> 267.78737 | H20: =G20-$C$43 -> 223.09104 | I20: =H20-$C$43 -> 178.3947
A21: Personal (activo)/Gastos de personal | B21: =-Balances!B27/'Cuentas PyG'!B14 -> 0.0077070393 | C21: =-Balances!C27/'Cuentas PyG'!C14 -> 0.0071010604 | D21: =-Balances!D27/'Cuentas PyG'!D14 -> 0.0079739036
A22: Personal (pasivo)/Gastos de personal | B22: =-Balances!B56/'Cuentas PyG'!B14 -> 0.0032857992 | C22: =-Balances!C56/'Cuentas PyG'!C14 -> 0.002636733 | D22: =-Balances!D56/'Cuentas PyG'!D14 -> 0.031714389
A23: Créditos adm. públicas/Imp. neto cifra de neg. | B23: =Balances!B28/'Cuentas PyG'!B4 -> 0.033839428 | C23: =Balances!C28/'Cuentas PyG'!C4 -> 0.047801839 | D23: =Balances!D28/'Cuentas PyG'!D4 -> 0.049281314
A24: Deudas adm. públicas/Imp. neto cifra de neg. | B24: =Balances!B58/'Cuentas PyG'!B4 -> 0.0093138905 | C24: =Balances!C58/'Cuentas PyG'!C4 -> 0.011367644 | D24: =Balances!D58/'Cuentas PyG'!D4 -> 0.01412398
A25: Anticipos de clientes/Clientes | B25: =Balances!B59/(Balances!B24+Balances!B25) -> 0.13731309 | C25: =Balances!C59/(Balances!C24+Balances!C25) -> 0.23931331 | D25: =Balances!D59/(Balances!D24+Balances!D25) -> 0.226426
A27: HIPÓTESIS DE INMOVILIZADO
A29: CONCEPTO | B29: X-2 | C29: X-1 | D29: X | E29: X+1 | F29: X+2 | G29: X+3 | H29: X+4 | I29: X+5
A30: Inmovilizado int. y mat./Imp. neto cifra de neg. | B30: =(Balances!B5+Balances!B9)/'Cuentas PyG'!B4 -> 0.24256775 | C30: =(Balances!C5+Balances!C9)/'Cuentas PyG'!C4 -> 0.32832126 | D30: =(Balances!D5+Balances!D9)/'Cuentas PyG'!D4 -> 0.33497974 | E30: =(Balances!E5+Balances!E9)/'Cuentas PyG'!E4 -> 0.33497974 | F30: =(Balances!F5+Balances!F9)/'Cuentas PyG'!F4 -> 0.33497974 | G30: =(Balances!G5+Balances!G9)/'Cuentas PyG'!G4 -> 0.33497974 | H30: =(Balances!H5+Balances!H9)/'Cuentas PyG'!H4 -> 0.33497974 | I30: =(Balances!I5+Balances!I9)/'Cuentas PyG'!I4 -> 0.33497974
A31: Inmovilizado int./Inmovilizado int. y mat. | B31: =Balances!B5/(Balances!B5+Balances!B9) -> 0.52003335 | C31: =Balances!C5/(Balances!C5+Balances!C9) -> 0.54617384 | D31: =Balances!D5/(Balances!D5+Balances!D9) -> 0.61696488 | E31: =Balances!E5/(Balances!E5+Balances!E9) -> 0.61696488 | F31: =Balances!F5/(Balances!F5+Balances!F9) -> 0.61696488 | G31: =Balances!G5/(Balances!G5+Balances!G9) -> 0.61696488 | H31: =Balances!H5/(Balances!H5+Balances!H9) -> 0.61696488 | I31: =Balances!I5/(Balances!I5+Balances!I9) -> 0.61696488
A33: HIPÓTESIS DE ESTRUCTURA FINANCIERA
A35: CONCEPTO | B35: X-2 | C35: X-1 | D35: X | E35: X+1 | F35: X+2 | G35: X+3 | H35: X+4 | I35: X+5
A36: Deuda fin./(Deuda fin.+Patr. neto objetivo) | B36: =(Balances!B47+Balances!B51+Balances!B52)/(Balances!B47+Balances!B51+Balances!B52+Balances!B36) -> 0.28021871 | C36: =(Balances!C47+Balances!C51+Balances!C52)/(Balances!C47+Balances!C51+Balances!C52+Balances!C36) -> 0.33097145 | D36: =(Balances!D47+Balances!D51+Balances!D52)/(Balances!D47+Balances!D51+Balances!D52+Balances!D36) -> 0.34399222 | E36: 0.34399222 | F36: 0.34399222 | G36: 0.34399222 | H36: 0.34399222 | I36: 0.34399222
A37: Deuda fin. l.p./Deuda fin. total | B37: =Balances!B47/(Balances!B47+Balances!B51+Balances!B52) -> 0.53135074 | C37: =Balances!C47/(Balances!C47+Balances!C51+Balances!C52) -> 0.33613677 | D37: =Balances!D47/(Balances!D47+Balances!D51+Balances!D52) -> 0.36189216 | E37: 0.36189216 | F37: 0.36189216 | G37: 0.36189216 | H37: 0.36189216 | I37: 0.36189216
A38: Deudas fin. a c.p./Deuda fin. total | B38: =Balances!B51/(Balances!B47+Balances!B51+Balances!B52) -> 0.46864926 | C38: =Balances!C51/(Balances!C47+Balances!C51+Balances!C52) -> 0.43720228 | D38: =Balances!D51/(Balances!D47+Balances!D51+Balances!D52) -> 0.41754879 | E38: 0.41754879 | F38: 0.41754879 | G38: 0.41754879 | H38: 0.41754879 | I38: 0.41754879
A39: Gastos financieros/Deuda financiera | C39: =-'Cuentas PyG'!C26/((Balances!B47+Balances!B51+Balances!C47+Balances!C51+Balances!B52+Balances!C52)/2) -> 0.080338928 | D39: =-'Cuentas PyG'!D26/((Balances!C47+Balances!C51+Balances!D47+Balances!D51+Balances!C52+Balances!D52)/2) -> 0.039861347
A41: Crecimiento ventas en X+5 | B41: 0.02
A42: Periodo medio de cobro | B42: =D19-C19 -> 50.805813 | C42: =B42/5 -> 10.161163
A43: Periodo medio de pago | B43: =D20-C20 -> 223.48168 | C43: =B43/5 -> 44.696336
A44: Impuesto sobre sociedades | B44: 0.25
A45: Coste efectvo de la deuda | D45: =-'Cuentas PyG'!D26/((Balances!C47+Balances!C50+Balances!D47+Balances!D50)/2) -> 0.066351907 | E45: 0.066351907 | F45: 0.066351907 | G45: 0.066351907 | H45: 0.066351907 | I45: 0.066351907
A47: CONCEPTO | B47: X-2 | C47: X-1 | D47: X | E47: X+1 | F47: X+2 | G47: X+3 | H47: X+4 | I47: X+5
A48: Activo fijo material/Imp. neto cifra neg. | B48: =Balances!B9/'Cuentas PyG'!B4 -> 0.11642443 | C48: =Balances!C9/'Cuentas PyG'!C4 -> 0.14900078 | D48: =Balances!D9/'Cuentas PyG'!D4 -> 0.12830901 | E48: 0.12830901 | F48: 0.12830901 | G48: 0.12830901 | H48: 0.12830901 | I48: 0.12830901
...

Sheet Balances
A1: ESTRUCTURA DEL ACTIVO
A3: CONCEPTO | B3: X-2 | C3: X-1 | D3: X | E3: X+1 | F3: X+2 | G3: X+3 | H3: X+4 | I3: X+5
A4: A) ACTIVO NO CORRIENTE | B4: =B5+B9+B12+B15+B16 -> 32397008 | C4: =C5+C9+C12+C15+C16 -> 33049388 | D4: =D5+D9+D12+D15+D16 -> 33764000 | E4: =E5+E9+E12+E15+E16 -> 34159194 | F4: =F5+F9+F12+F15+F16 -> 34583138 | G4: =G5+G9+G12+G15+G16 -> 35037070 | H4: =H5+H9+H12+H15+H16 -> 35522334 | I4: =I5+I9+I12+I15+I16 -> 36040381
A5: I Inmovilizado intangible | B5: =SUM(B6:B8) -> 11678728 | C5: =SUM(C6:C8) -> 12727926 | D5: =SUM(D6:D8) -> 14896000 | E5: ='Cuentas PyG'!E4*Hipótesis!E49 -> 15139821 | F5: ='Cuentas PyG'!F4*Hipótesis!F49 -> 15401379 | G5: ='Cuentas PyG'!G4*Hipótesis!G49 -> 15681440 | H5: ='Cuentas PyG'!H4*Hipótesis!H49 -> 15980831 | I5: ='Cuentas PyG'!I4*Hipótesis!I49 -> 16300447
A6: 1. Desarrollo | B6: 9386200 | C6: 9809882 | D6: 10342000
A7: 3. Patentes, licencias, marcas y similares | B7: 596012 | C7: 482900 | D7: 1694000
A8: 5. Aplicaciones informáticas | B8: 1696516 | C8: 2435144 | D8: 2860000
A9: II Inmovilizado material | B9: =SUM(B10:B11) -> 10778924 | C9: =SUM(C10:C11) -> 10575874 | D9: =SUM(D10:D11) -> 9248000 | E9: ='Cuentas PyG'!E4*Hipótesis!E48 -> 9399373.4 | F9: ='Cuentas PyG'!F4*Hipótesis!F48 -> 9561758.5 | G9: ='Cuentas PyG'!G4*Hipótesis!G48 -> 9735630.6 | H9: ='Cuentas PyG'!H4*Hipótesis!H48 -> 9921503.8 | I9: ='Cuentas PyG'!I4*Hipótesis!I48 -> 10119934
A10: 1. Terrenos y construcciones | B10: 4062970 | C10: 3939552 | D10: 3816000
A11: 2. Instalaciones técnicas y otro inmov. mat. | B11: 6715954 | C11: 6636322 | D11: 5432000
A12: IV Inversiones empr. del grupo y asoc. a l.p. | B12: =SUM(B13:B14) -> 960266 | C12: =SUM(C13:C14) -> 2146174 | D12: =SUM(D13:D14) -> 808000 | E12: 808000 | F12: 808000 | G12: 808000 | H12: 808000 | I12: 808000
A13: 1. Instrumentos de patrimonio | B13: 957418 | C13: 2143326 | D13: 806000
A14: 2. Créditos a empresas | B14: 2848 | C14: 2848 | D14: 2000
A15: V Inversiones financieras a largo plazo | B15: 15990 | C15: 21088 | D15: 12000 | E15: 12000 | F15: 12000 | G15: 12000 | H15: 12000 | I15: 12000
A16: VI Activos por impuesto diferido | B16: 8963100 | C16: 7578326 | D16: 8800000 | E16: 8800000 | F16: 8800000 | G16: 8800000 | H16: 8800000 | I16: 8800000
A17: B) ACTIVO CORRIENTE | B17: =B18+B23+B29+B30 -> 67240432 | C17: =C18+C23+C29+C30 -> 75282972 | D17: =D18+D23+D29+D30 -> 83152000 | E17: =E18+E23+E29+E30 -> 69494267 | F17: =F18+F23+F29+F30 -> 64133261 | G17: =G18+G23+G29+G30 -> 62373704 | H17: =H18+H23+H29+H30 -> 60724073 | I17: =I18+I23+I29+I30 -> 59186362
A18: II Existencias | B18: =SUM(B19:B22) -> 24291006 | C18: =SUM(C19:C22) -> 19367252 | D18: =SUM(D19:D22) -> 15586000 | E18: =-('Cuentas PyG'!E8+'Cuentas PyG'!E9)/365*Hipótesis!E18 -> 19411224 | F18: =-('Cuentas PyG'!F8+'Cuentas PyG'!F9)/365*Hipótesis!F18 -> 19684898 | G18: =-('Cuentas PyG'!G8+'Cuentas PyG'!G9)/365*Hipótesis!G18 -> 19977931 | H18: =-('Cuentas PyG'!H8+'Cuentas PyG'!H9)/365*Hipótesis!H18 -> 20291190 | I18: =-('Cuentas PyG'!I8+'Cuentas PyG'!I9)/365*Hipótesis!I18 -> 20625612
A19: 2. Materias primas y otros aprovisionamient. | B19: 11248112 | C19: 9180872 | D19: 7822000
A20: 3. Productos en curso | B20: 5583604 | C20: 4173512 | D20: 3318000
A21: 4. Productos terminados | B21: 7316234 | C21: 5847736 | D21: 4308000
A22: 6. Anticipos a proveedores | B22: 143056 | C22: 165132 | D22: 138000
A23: III Deudores com. y otras cuentas a cobrar | B23: =SUM(B24:B28) -> 42034778 | C23: =SUM(C24:C28) -> 55280022 | D23: =SUM(D24:D28) -> 66294000 | E23: ='Cuentas PyG'!E4/365*Hipótesis!E19 -> 61550742 | F23: ='Cuentas PyG'!F4/365*Hipótesis!F19 -> 60539518 | G23: ='Cuentas PyG'!G4/365*Hipótesis!G19 -> 59528067 | H23: ='Cuentas PyG'!H4/365*Hipótesis!H19 -> 58511942 | I23: ='Cuentas PyG'!I4/365*Hipótesis!I19 -> 57486491
A24: 1. Clientes por ventas y prest. de servicios | B24: 37583328 | C24: 50884334 | D24: 61866000
A25: 2. Clientes empresas del grupo y asociadas | B25: 1044920 | C25: 738486 | D25: 406000
A26: 3. Deudores varios | B26: 116778 | C26: 110816 | D26: 294000
A27: 4. Personal | B27: 156796 | C27: 153476 | D27: 176000
A28: 6. Otros créditos con las Adm. Públicas | B28: 3132956 | C28: 3392910 | D28: 3552000
A29: VI Periodificaciones a corto plazo | B29: 780900 | C29: 597492 | D29: 830000 | E29: 830000 | F29: 830000 | G29: 830000 | H29: 830000 | I29: 830000
A30: VII Efectivo y otros activos líquidos equiv. | B30: 133748 | C30: 38206 | D30: 442000 | E30: ='Flujos de caja'!B32 -> -12297699 | F30: ='Flujos de caja'!C32 -> -16921156 | G30: ='Flujos de caja'!D32 -> -17962294 | H30: ='Flujos de caja'!E32 -> -18909059 | I30: ='Flujos de caja'!F32 -> -19755741
A31: TOTAL ACTIVO | B31: =B4+B17 -> 99637440 | C31: =C4+C17 -> 108332360 | D31: =D4+D17 -> 116916000 | E31: =E4+E17 -> 1.0365346e+08 | F31: =F4+F17 -> 98716398 | G31: =G4+G17 -> 97410774 | H31: =H4+H17 -> 96246408 | I31: =I4+I17 -> 95226743
A33: ESTRUCTURA DEL PASIVO
A35: CONCEPTO | B35: X-2 | C35: X-1 | D35: X | E35: X+1 | F35: X+2 | G35: X+3 | H35: X+4 | I35: X+5
A36: A) PATRIMONIO NETO | B36: =B37+B44+B45 -> 46253699 | C36: =C37+C44+C45 -> 48682212 | D36: =D37+D44+D45 -> 46119915 | E36: =E37+E44+E45 -> 46538419 | F36: =F37+F44+F45 -> 47078644 | G36: =G37+G44+G45 -> 47747924 | H36: =H37+H44+H45 -> 48553899 | I36: =I37+I44+I45 -> 49504557
A37: A-1) Fondos propios | B37: =B38+B39+B40+B43 -> 46152701 | C37: =C38+C39+C40+C43 -> 48405534 | D37: =D38+D39+D40+D43 -> 45833915 | E37: =E38+E39+E40+E43 -> 46305654 | F37: =F38+F39+F40+F43 -> 46899114 | G37: =G38+G39+G40+G43 -> 47621629 | H37: =H38+H39+H40+H43 -> 48480839 | I37: =I38+I39+I40+I43 -> 49484732
A38: I Capital | B38: 493604 | C38: 493604 | D38: 494000 | E38: 494000 | F38: 494000 | G38: 494000 | H38: 494000 | I38: 494000
A39: II Prima de emisión | B39: 253326 | C39: 253326 | D39: 254000 | E39: 254000 | F39: 254000 | G39: 254000 | H39: 254000 | I39: 254000
A40: III Reservas | B40: =SUM(B41:B42) -> 41402488 | C40: =SUM(C41:C42) -> 44119016 | D40: =SUM(D41:D42) -> 44118000 | E40: =D40+D43 -> 45085915 | F40: =E40+E43 -> 45557654 | G40: =F40+F43 -> 46151114 | H40: =G40+G43 -> 46873629 | I40: =H40+H43 -> 47732839
A41: 1. Legal y estatutarias | B41: 98716 | C41: 98716 | D41: 98000
A42: 2. Otras reservas | B42: 41303772 | C42: 44020300 | D42: 44020000
A43: VII Resultado del ejercicio | B43: ='Cuentas PyG'!B31 -> 4003283 | C43: ='Cuentas PyG'!C31 -> 3539588 | D43: ='Cuentas PyG'!D31 -> 967915 | E43: ='Cuentas PyG'!E31 -> 471738.5 | F43: ='Cuentas PyG'!F31 -> 593460.95 | G43: ='Cuentas PyG'!G31 -> 722514.22 | H43: ='Cuentas PyG'!H31 -> 859210.79 | I43: ='Cuentas PyG'!I31 -> 1003892.8
...

Sheet Cuentas PyG
A1: CUENTAS DE RESULTADOS
A3: CONCEPTO | B3: X-2 | C3: X-1 | D3: X | E3: X+1 | F3: X+2 | G3: X+3 | H3: X+4 | I3: X+5
A4: 1. Importe neto de la cifra de negocios | B4: 92583008 | C4: 70978650 | D4: 72076000 | E4: =D4*(1+Hipótesis!E4) -> 73255756 | F4: =E4*(1+Hipótesis!F4) -> 74521335 | G4: =F4*(1+Hipótesis!G4) -> 75876440 | H4: =G4*(1+Hipótesis!H4) -> 77325077 | I4: =H4*(1+Hipótesis!I4) -> 78871578
A5: 2. Variación exist. de prod. term. y en curso | B5: 3646930 | C5: -1843676 | D5: -2354000 | E5: -2354000 | F5: -2354000 | G5: -2354000 | H5: -2354000 | I5: -2354000
A6: 3. Trabajos realiz. por la empr. para su activo | B6: 10591348 | C6: 12903110 | D6: 12942000 | E6: =E4*Hipótesis!E6 -> 13153838 | F6: =F4*Hipótesis!F6 -> 13381086 | G6: =G4*Hipótesis!G6 -> 13624409 | H6: =H4*Hipótesis!H6 -> 13884527 | I6: =I4*Hipótesis!I6 -> 14162217
A7: 4. Aprovisionamientos | B7: =SUM(B8:B10) -> -48967134 | C7: =SUM(C8:C10) -> -25126898 | D7: =SUM(D8:D10) -> -24022000 | E7: =SUM(E8:E10) -> -26723432 | F7: =SUM(F8:F10) -> -27096138 | G7: =SUM(G8:G10) -> -27495209 | H7: =SUM(H8:H10) -> -27921825 | I7: =SUM(I8:I10) -> -28377262
A8: b) Consumo de mat. prim. y otras mat. cons. | B8: -41895348 | C8: -21301868 | D8: -18872000 | E8: =-E4*Hipótesis!E5 -> -21573432 | F8: =-F4*Hipótesis!F5 -> -21946138 | G8: =-G4*Hipótesis!G5 -> -22345209 | H8: =-H4*Hipótesis!H5 -> -22771825 | I8: =-I4*Hipótesis!I5 -> -23227262
A9: c) Trabajos realizados por otras empresas | B9: -6390862 | C9: -3540330 | D9: -4862000 | E9: -4862000 | F9: -4862000 | G9: -4862000 | H9: -4862000 | I9: -4862000
A10: d) Deterioro merc., mat. prim. y otros aprov. | B10: -680924 | C10: -284700 | D10: -288000 | E10: -288000 | F10: -288000 | G10: -288000 | H10: -288000 | I10: -288000
A11: 5. Otros ingresos de explotación | B11: =SUM(B12:B13) -> 406658 | C11: =SUM(C12:C13) -> 2628682 | D11: =SUM(D12:D13) -> 426000 | E11: =SUM(E12:E13) -> 13800 | F11: =SUM(F12:F13) -> 12420 | G11: =SUM(G12:G13) -> 11178 | H11: =SUM(H12:H13) -> 10060.2 | I11: =SUM(I12:I13) -> 9054.18
A12: a) Ingresos accesorios y de gest. corriente | B12: 218086 | C12: 2360100 | D12: 288000
A13: b) Subv. de explot. incorporadas al result. | B13: 188572 | C13: 268582 | D13: 138000 | E13: =D13*10% -> 13800 | F13: =($D$13-E13)*10% -> 12420 | G13: =($D$13-(F13+E13))*10% -> 11178 | H13: =($D$13-(G13+F13+E13))*10% -> 10060.2 | I13: =($D$13-(E13+H13+G13+F13))*10% -> 9054.18
A14: 6. Gastos de personal | B14: =SUM(B15:B16) -> -20344518 | C14: =SUM(C15:C16) -> -21613110 | D14: =SUM(D15:D16) -> -22072000 | E14: =-E4*Hipótesis!E9 -> -22433279 | F14: =-F4*Hipótesis!F9 -> -22820841 | G14: =-G4*Hipótesis!G9 -> -23235817 | H14: =-H4*Hipótesis!H9 -> -23679437 | I14: =-I4*Hipótesis!I9 -> -24153026
A15: a) Sueldos, salarios y asimilados | B15: -15691594 | C15: -16719588 | D15: -17102000
A16: b) Cargas sociales | B16: -4652924 | C16: -4893522 | D16: -4970000
A17: 7. Otros gastos de explotación | B17: =SUM(B18:B20) -> -19189890 | C17: =SUM(C18:C20) -> -18728102 | D17: =SUM(D18:D20) -> -18098000 | E17: =-E4*Hipótesis!E10 -> -18394232 | F17: =-F4*Hipótesis!F10 -> -18712014 | G17: =-G4*Hipótesis!G10 -> -19052275 | H17: =-H4*Hipótesis!H10 -> -19416023 | I17: =-I4*Hipótesis!I10 -> -19804343
A18: a) Servicios exteriores | B18: -15508874 | C18: -18688772 | D18: -17304000
A19: b) Tributos | B19: -56920 | C19: -60148 | D19: -58000
A20: c) Pérd., deterioro y var. prov. por op. com. | B20: -3624096 | C20: 20818 | D20: -736000
A21: 8. Amortización del inmovilizado | B21: -13179260 | C21: -13736554 | D21: -14938000 | E21: =-(Balances!D5+Balances!D9)*-Hipótesis!E11 -> -14938000 | F21: =-(Balances!E5+Balances!E9)*-Hipótesis!F11 -> -15182509 | G21: =-(Balances!F5+Balances!F9)*-Hipótesis!G11 -> -15444804 | H21: =-(Balances!G5+Balances!G9)*-Hipótesis!H11 -> -15725654 | I21: =-(Balances!H5+Balances!H9)*-Hipótesis!I11 -> -16025889
A22: 9. Imputación de subv. de inmov. no financiero | B22: 35326 | C22: 62852 | D22: 53235 | E22: =Balances!$D$45*Hipótesis!E12 -> 53235 | F22: =Balances!$D$45*Hipótesis!F12 -> 53235 | G22: =Balances!$D$45*Hipótesis!G12 -> 53235 | H22: =Balances!$D$45*Hipótesis!H12 -> 53235 | I22: =Balances!$D$45*Hipótesis!I12 -> 53235
A23: 11. Deterioro y result. por enaj. inmovilizado | B23: -314 | C23: -52466 | D23: -6000
A24: A1) RESULTADO DE EXPLOTACIÓN | B24: =B4+B5+B6+B7+B11+B14+B17+B21+B22+B23 -> 5582154 | C24: =C4+C5+C6+C7+C11+C14+C17+C21+C22+C23 -> 5472488 | D24: =D4+D5+D6+D7+D11+D14+D17+D21+D22+D23 -> 4007235 | E24: =E4+E5+E6+E7+E11+E14+E17+E21+E22+E23 -> 1633685.2 | F24: =F4+F5+F6+F7+F11+F14+F17+F21+F22+F23 -> 1802574.2 | G24: =G4+G5+G6+G7+G11+G14+G17+G21+G22+G23 -> 1983155 | H24: =H4+H5+H6+H7+H11+H14+H17+H21+H22+H23 -> 2175959.7 | I24: =I4+I5+I6+I7+I11+I14+I17+I21+I22+I23 -> 2381565
A25: 14. Ingresos financieros | B25: 43812 | C25: 544428 | D25: 832000
A26: 15. Gastos financieros | B26: -915068 | C26: -1690748 | D26: -962000 | E26: =-(Balances!D47+Balances!D50)*Hipótesis!E45 -> -1004700.6 | F26: =-(Balances!E47+Balances!E50)*Hipótesis!F45 -> -1011292.9 | G26: =-(Balances!F47+Balances!F50)*Hipótesis!G45 -> -1019802.7 | H26: =-(Balances!G47+Balances!G50)*Hipótesis!H45 -> -1030345.3 | I26: =-(Balances!H47+Balances!H50)*Hipótesis!I45 -> -1043041.2
A27: 17. Diferencias de cambio | B27: 235282 | C27: -134794 | D27: -530000
A28: 18. Deterioro y resultado por enaj. de instr. fin. | B28: -77572 | C28: 1056140 | D28: -2014000
A29: A3) RESULTADO ANTES DE IMPUESTOS | B29: =SUM(B24:B28) -> 4868608 | C29: =SUM(C24:C28) -> 5247514 | D29: =SUM(D24:D28) -> 1333235 | E29: =SUM(E24:E28) -> 628984.67 | F29: =SUM(F24:F28) -> 791281.26 | G29: =SUM(G24:G28) -> 963352.29 | H29: =SUM(H24:H28) -> 1145614.4 | I29: =SUM(I24:I28) -> 1338523.8
A30: 19. Impuestos sobre beneficios | B30: -865325 | C30: -1707926 | D30: -365320 | E30: =-E29*Hipótesis!$B$44 -> -157246.17 | F30: =-F29*Hipótesis!$B$44 -> -197820.32 | G30: =-G29*Hipótesis!$B$44 -> -240838.07 | H30: =-H29*Hipótesis!$B$44 -> -286403.6 | I30: =-I29*Hipótesis!$B$44 -> -334630.94
A31: A5) Resultado del ejercicio | B31: =SUM(B29:B30) -> 4003283 | C31: =SUM(C29:C30) -> 3539588 | D31: =SUM(D29:D30) -> 967915 | E31: =SUM(E29:E30) -> 471738.5 | F31: =SUM(F29:F30) -> 593460.95 | G31: =SUM(G29:G30) -> 722514.22 | H31: =SUM(H29:H30) -> 859210.79 | I31: =SUM(I29:I30) -> 1003892.8

Sheet Flujos de caja
A1: DESGLOSE DEL FLUJO DE CAJA LIBRE
A3: CONCEPTO | B3: X+1 | C3: X+2 | D3: X+3 | E3: X+4 | F3: X+5
A4: EBITDA | B4: ='Cuentas PyG'!E24-'Cuentas PyG'!E21-'Cuentas PyG'!E22 -> 16518450 | C4: ='Cuentas PyG'!F24-'Cuentas PyG'!F21-'Cuentas PyG'!F22 -> 16931848 | D4: ='Cuentas PyG'!G24-'Cuentas PyG'!G21-'Cuentas PyG'!G22 -> 17374724 | E4: ='Cuentas PyG'!H24-'Cuentas PyG'!H21-'Cuentas PyG'!H22 -> 17848379 | F4: ='Cuentas PyG'!I24-'Cuentas PyG'!I21-'Cuentas PyG'!I22 -> 18354219
A5: Dotación a la amortización | B5: ='Cuentas PyG'!E21 -> -14938000 | C5: ='Cuentas PyG'!F21 -> -15182509 | D5: ='Cuentas PyG'!G21 -> -15444804 | E5: ='Cuentas PyG'!H21 -> -15725654 | F5: ='Cuentas PyG'!I21 -> -16025889
A6: Provisiones del tráfico | B6: ='Cuentas PyG'!E22 -> 53235 | C6: ='Cuentas PyG'!F22 -> 53235 | D6: ='Cuentas PyG'!G22 -> 53235 | E6: ='Cuentas PyG'!H22 -> 53235 | F6: ='Cuentas PyG'!I22 -> 53235
A7: EBIT | B7: =B4+B5+B6 -> 1633685.2 | C7: =C4+C5+C6 -> 1802574.2 | D7: =D4+D5+D6 -> 1983155 | E7: =E4+E5+E6 -> 2175959.7 | F7: =F4+F5+F6 -> 2381565
A8: Impuestos ajustados | B8: =-Hipótesis!E13*'Flujos de caja'!B7 -> -408421.31 | C8: =-Hipótesis!F13*'Flujos de caja'!C7 -> -450643.55 | D8: =-Hipótesis!G13*'Flujos de caja'!D7 -> -495788.74 | E8: =-Hipótesis!H13*'Flujos de caja'!E7 -> -543989.93 | F8: =-Hipótesis!I13*'Flujos de caja'!F7 -> -595391.24
A9: NOPLAT | B9: =B7+B8 -> 1225263.9 | C9: =C7+C8 -> 1351930.6 | D9: =D7+D8 -> 1487366.2 | E9: =E7+E8 -> 1631969.8 | F9: =F7+F8 -> 1786173.7
A10: Dotación a la amortización | B10: =-B5 -> 14938000 | C10: =-C5 -> 15182509 | D10: =-D5 -> 15444804 | E10: =-E5 -> 15725654 | F10: =-F5 -> 16025889
A11: Imputación de subvención por inmovilizado | B11: =-B6 -> -53235 | C11: =-C6 -> -53235 | D11: =-D6 -> -53235 | E11: =-E6 -> -53235 | F11: =-F6 -> -53235
A12: CAPEX | B12: =-Balances!E80 -> -15333194 | C12: =-Balances!F80 -> -15606452 | D12: =-Balances!G80 -> -15898737 | E12: =-Balances!H80 -> -16210918 | F12: =-Balances!I80 -> -16543936
A13: Var. Fondo de maniobra necesario | B13: =-Balances!E71 -> -13037549 | C13: =-Balances!F71 -> -5094131.9 | D13: =-Balances!G71 -> -1695537.1 | E13: =-Balances!H71 -> -1796203.5 | F13: =-Balances!I71 -> -1902931.7
A14: FLUJO DE CAJA LIBRE | B14: =B9+B10+B11+B12+B13 -> -12260715 | C14: =C9+C10+C11+C12+C13 -> -4219379.6 | D14: =D9+D10+D11+D12+D13 -> -715338.36 | E14: =E9+E10+E11+E12+E13 -> -702732.83 | F14: =F9+F10+F11+F12+F13 -> -688039.68
A16: DESGLOSE DEL FLUJO DE CAJA LIBRE PARA EL ACCIONISTA
A18: CONCEPTO | B18: X+1 | C18: X+2 | D18: X+3 | E18: X+4 | F18: X+5
A19: FLUJO DE CAJA LIBRE | B19: =B14 -> -12260715 | C19: =C14 -> -4219379.6 | D19: =D14 -> -715338.36 | E19: =E14 -> -702732.83 | F19: =F14 -> -688039.68
A20: Gastos financieros | B20: ='Cuentas PyG'!E26 -> -1004700.6 | C20: ='Cuentas PyG'!F26 -> -1011292.9 | D20: ='Cuentas PyG'!G26 -> -1019802.7 | E20: ='Cuentas PyG'!H26 -> -1030345.3 | F20: ='Cuentas PyG'!I26 -> -1043041.2
A21: Escudo fiscal | B21: =-B20*Hipótesis!E13 -> 251175.14 | C21: =-C20*Hipótesis!F13 -> 252823.23 | D21: =-D20*Hipótesis!G13 -> 254950.67 | E21: =-E20*Hipótesis!H13 -> 257586.33 | F21: =-F20*Hipótesis!I13 -> 260760.3
A22: Incremento/amortización de Deuda | B22: =Balances!E87 -> 274541.55 | C22: =Balances!F87 -> 354392.42 | D22: =Balances!G87 -> 439052.37 | E22: =Balances!H87 -> 528726.39 | F22: =Balances!I87 -> 623638.93
A23: FLUJO PARA LOS ACCIONISTAS | B23: =B19+B20+B21+B22 -> -12739699 | C23: =C19+C20+C21+C22 -> -4623456.8 | D23: =D19+D20+D21+D22 -> -1041138 | E23: =E19+E20+E21+E22 -> -946765.43 | F23: =F19+F20+F21+F22 -> -846681.66
A25: SALDO CONTABLE DE CAJA
A27: CONCEPTO | B27: X+1 | C27: X+2 | D27: X+3 | E27: X+4 | F27: X+5
A28: Saldo de caja del ejercicio anterior | B28: =Balances!D30 -> 442000 | C28: =Balances!E30 -> -12297699 | D28: =Balances!F30 -> -16921156 | E28: =Balances!G30 -> -17962294 | F28: =Balances!H30 -> -18909059
A29: Flujo de caja libre para los accionistas | B29: =B23 -> -12739699 | C29: =C23 -> -4623456.8 | D29: =D23 -> -1041138 | E29: =E23 -> -946765.43 | F29: =F23 -> -846681.66
A30: Aportaciones accionistas | B30: =IF(B28+B29<0,-(B28+B29),0) -> 12297699
A31: Dividendos repartidos
A32: SALDO DE CAJA DEL EJERCICIO | B32: =B28+B29 -> -12297699 | C32: =C28+C29 -> -16921156 | D32: =D28+D29 -> -17962294 | E32: =E28+E29 -> -18909059 | F32: =F28+F29 -> -19755741
