Workbook

Sheet Proyecto
B2: CONTROL A | H2: CONTROL B
B3: Inmovilizado material | C3: 4000000 | E3: Capital Social | F3: 6000 | H3: Inmovilizado material | I3: 28000 | K3: Capital Social | L3: 10000
B4: Inversiones inmobiliarias | C4: 470000 | E4: Reservas | F4: =3142245.33-('Sprint 1'!F33-C10) -> 3135125.3 | H4: Inversiones financieras a largo plazo | I4: 75000 | K4: Reservas | L4: =122125-('Sprint 1'!L33-I10) -> 109485.19
B5: Inversiones financieras a largo plazo, empresas del grupo | C5: =+L3 -> 10000 | E5: Resultado del ejericio | F5: =1047375+60000 -> 1107375 | H5: Activo no corriente | I5: =+SUM(I3:I4) -> 103000 | K5: Resultado del ejericio | L5: =157875-60000 -> 97875
B6: Activo no corriente | C6: =+SUM(C3:C5) -> 4480000 | E6: Patrimonio Neto | F6: =+SUM(F3:F5) -> 4248500.3 | K6: Patrimonio Neto | L6: =+SUM(L3:L5) -> 217360.19
E8: Deudas a largo plazo | F8: =500000/15*12.5 -> 416666.67 | K8: Deudas a largo plazo | L8: 50000
E9: Pasivo no corriente | F9: =+F8 -> 416666.67 | K9: Pasivo no corriente | L9: =+L8 -> 50000
B10: Existencias | C10: ='Sprint 1'!F42 -> 70000 | H10: Existencias | I10: ='Sprint 1'!L42 -> 63875
B11: Deudores | C11: 350000 | E11: Deudas a corto plazo | F11: 33333 | H11: Deudores | I11: 460000 | K11: Deudas a corto plazo | L11: 10000
B12: Inversiones financieras a corto plazo | C12: 150000 | E12: Deudas a corto plazo, empresas del Grupo | F12: =+I13 -> 38000 | H12: Inversiones finaniceras a corto plazo | I12: 21000 | K12: Proveedores | L12: 350000
B13: Clientes empresas del grupo | C13: =+L13 -> 10000 | E13: Proveedores | F13: 460000 | H13: Inversiones finaniceras a corto plazo empresas del grupo | I13: 38000 | K13: Proveedores , empresas del grupo | L13: 10000
B14: Tesorería | C14: =150000+'Sprint 2'!G41 -> 210000 | E14: Personal | F14: 73500 | H14: Tesorería | I14: =22000-'Sprint 2'!G41 -> -38000 | K14: Personal | L14: 10000
B15: Activo corriente | C15: =+SUM(C10:C14) -> 790000 | E15: Pasivo corriente | F15: =+SUM(F11:F14) -> 604833 | H15: Activo corriente | I15: =+SUM(I10:I14) -> 544875 | K15: Pasivo corriente | L15: =+SUM(L11:L14) -> 380000
B16: TOTAL ACTIVO | C16: =+C15+C6 -> 5270000 | E16: TOTAL PASIVO Y PATRIMONIO NETO | F16: =+F6+F9+F15 -> 5270000 | H16: TOTAL ACTIVO | I16: =+I15+I5 -> 647875 | K16: TOTAL PASIVO Y PATRIMONIO NETO | L16: =+L6+L9+L15 -> 647360.19
B19: CONTROL A | C19: CONTROL B | D19: AGREGADO | E19: Eliminiación Patrimonial | F19: Eliminacion de Saldos | G19: CONSOLIDADO
A20: Inmovilizado material | B20: 4000000 | C20: 28000 | D20: =SUM(B20:C20) -> 4028000 | G20: =D20+E20+F20 -> 4028000
A21: Inversiones inmobiliarias | B21: 470000 | C21: 0 | D21: =SUM(B21:C21) -> 470000 | G21: =D21+E21+F21 -> 470000
A22: Inversiones fiancieras a l.p | B22: 0 | C22: 75000 | D22: =SUM(B22:C22) -> 75000 | G22: =D22+E22+F22 -> 75000
A23: Inversiones financieras a l.p., empresas del grupo | B23: 10000 | C23: 0 | D23: =SUM(B23:C23) -> 10000 | E23: -10000 | G23: =D23+E23+F23 -> 0
A24: ACTIVO NO CORRIENTE | B24: =SUM(B20:B23) -> 4480000 | C24: =SUM(C20:C23) -> 103000 | D24: =SUM(D20:D23) -> 4583000 | E24: =+SUM(E20:E23) -> -10000 | F24: =+SUM(F20:F23) -> 0 | G24: =SUM(G20:G23) -> 4573000
A26: Existencias | B26: =C10 -> 70000 | C26: =I10 -> 63875 | D26: =SUM(B26:C26) -> 133875 | G26: =D26+E26+F26 -> 133875
A27: Deudores | B27: 350000 | C27: 460000 | D27: =SUM(B27:C27) -> 810000 | G27: =D27+E27+F27 -> 810000
A28: Inversiones financieras a c.p. | B28: 150000 | C28: 21000 | D28: =SUM(B28:C28) -> 171000 | G28: =D28+E28+F28 -> 171000
A29: Inversiones financieras a c.p. empresas del grupo | B29: 0 | C29: 38000 | D29: =SUM(B29:C29) -> 38000 | F29: -38000 | G29: =D29+E29+F29 -> 0
A30: Clientes empresas del grupo | B30: 10000 | C30: 0 | D30: =SUM(B30:C30) -> 10000 | F30: -10000 | G30: =D30+E30+F30 -> 0
A31: Tesoreira | B31: =C14 -> 210000 | C31: =I14 -> -38000 | D31: =SUM(B31:C31) -> 172000 | G31: =D31+E31+F31 -> 172000
A32: ACTIVO CORRIENTE | B32: =SUM(B26:B31) -> 790000 | C32: =SUM(C26:C31) -> 544875 | D32: =SUM(D26:D31) -> 1334875 | E32: =+SUM(E26:E31) -> 0 | F32: =+SUM(F26:F31) -> -48000 | G32: =SUM(G26:G31) -> 1286875
A33: TOTAL ACTIVO | B33: =B24+B32 -> 5270000 | C33: =C32+C24 -> 647875 | D33: =D32+D24 -> 5917875 | E33: =+E24+E32 -> -10000 | F33: =+F24+F32 -> -48000 | G33: =G32+G24 -> 5859875
A35: Capital Social | B35: 6000 | C35: 10000 | D35: =SUM(B35:C35) -> 16000 | E35: -10000 | G35: =D35+E35+F35 -> 6000
A36: Reservas | B36: =F4 -> 3135125.3 | C36: =L4 -> 109485.19 | D36: =SUM(B36:C36) -> 3244610.5 | E36: =-C36 -> -109485.19 | G36: =D36+E36+F36 -> 3135125.3
A38: Reservas en sociedades consolidadas | B38: 0 | C38: 0 | D38: 0 | E38: =-E36 -> 109485.19 | G38: =D38+E38+F38 -> 109485.19
A39: Resultado del ejercio | B39: =F5 -> 1107375 | C39: =L5 -> 97875 | D39: =SUM(B39:C39) -> 1205250 | G39: =D39+E38+F39 -> 1314735.2
A40: Patrimonio Neto | B40: =SUM(B35:B39) -> 4248500.3 | C40: =SUM(C35:C39) -> 217360.19 | D40: =SUM(D35:D39) -> 4465860.5 | E40: =+SUM(E35:E39) -> -10000 | F40: =+SUM(F35:F39) -> 0 | G40: =D40+E40+F40 -> 4455860.5
A42: Deudas a l.p | B42: 416666.67 | C42: 50000 | D42: =SUM(B42:C42) -> 466666.67 | G42: =D42+E42+F42 -> 466666.67
A43: PASIVO NO CORRIENTE | B43: =B42 -> 416666.67 | C43: =C42 -> 50000 | D43: =D42 -> 466666.67 | E43: =+E42 -> 0 | F43: =+F42 -> 0 | G43: =D43+E43+F43 -> 466666.67
A45: Deudas a c.p | B45: 33333 | C45: 10000 | D45: =SUM(B45:C45) -> 43333 | G45: =D45+E45+F45 -> 43333
A46: Deudas a c.p, empresas del grupo | B46: 38000 | C46: 0 | D46: =SUM(B46:C46) -> 38000 | F46: -38000 | G46: =D46+E46+F46 -> 0
A47: Proveedores | B47: 460000 | C47: 350000 | D47: =SUM(B47:C47) -> 810000 | G47: =D47+E47+F47 -> 810000
A48: Proveedores, empresas del grupo | B48: 0 | C48: 10000 | D48: =SUM(B48:C48) -> 10000 | F48: -10000 | G48: =D48+E48+F48 -> 0
A49: Personal | B49: 73500 | C49: 10000 | D49: =SUM(B49:C49) -> 83500 | G49: =D49+E49+F49 -> 83500
...

Sheet Sprint 1
B4: 1 | C4: Valores de los inventarios de cada empresa a 31.10
C6: CONTROL A | I6: CONTROL B
D7: Mes | E7: Unidades | F7: Precio | J7: Mes | K7: Unidades | L7: Precio
C8: Compra | D8: Enero | E8: 7000 | F8: 10 | I8: Compra | J8: Marzo | K8: 3500 | L8: 11
C9: Venta | D9: Marzo | E9: -5000 | F9: 13 | I9: Venta | J9: Abril y Mayo | K9: -2700 | L9: 13
C10: Compra | D10: Mayo | E10: 18000 | F10: 9.5 | I10: Compra | J10: Junio | K10: 7000 | L10: 10
C11: Venta | D11: Junio | E11: -12000 | F11: 13 | I11: Venta | J11: Julio y Agosto | K11: -3500 | L11: 13
I12: Compra | J12: Septiembre | K12: 3000 | L12: 11
D14: Precio medio: | J14: FIFO:
D15: Precio | E15: Unidades | F15: Valor | J15: Precio | K15: Unidades | L15: Valor
C16: Octubre | D16: =+((E8*F8)+(E10*F10))/(E8+E10) -> 9.64 | E16: =+SUM($E$8:$E$11) -> 8000 | F16: =+D16*E16 -> 77120 | I16: Compra sept | J16: =+K12 -> 3000 | K16: =+L12 -> 11 | L16: =+J16*K16 -> 33000
I17: Compra julio | J17: =+SUM(K8:K11) -> 4300 | K17: =+L10 -> 10 | L17: =+J17*K17 -> 43000
I18: Octubre | L18: =+SUM(L16:L17) -> 76000
C21: INVENTARIO 31 OCTUBRE
C23: CONTROL A | I23: CONTROL B
D24: Mes | E24: Unidades | F24: Precio | J24: Mes | K24: Unidades | L24: Precio
C25: Compra | D25: Enero | E25: 7000 | F25: 10 | I25: Compra | J25: Marzo | K25: 3500 | L25: 11
C26: Venta | D26: Marzo | E26: -5000 | F26: 13 | I26: Venta | J26: Abril y Mayo | K26: -2700 | L26: 13
C27: Compra | D27: Mayo | E27: 18000 | F27: 9.5 | I27: Compra | J27: Junio | K27: 7000 | L27: 10
C28: Venta | D28: Junio | E28: -12000 | F28: 13 | I28: Venta | J28: Julio y Agosto | K28: -3500 | L28: 13
I29: Compra | J29: Septiembre | K29: 3000 | L29: 11
D31: Precio medio: | J31: Precio medio:
D32: Precio | E32: Unidades | F32: Valor | J32: Precio | K32: Unidades | L32: Valor
C33: Octubre | D33: =+((E25*F25)+(E27*F27))/(E25+E27) -> 9.64 | E33: =+SUM(E25:E28) -> 8000 | F33: =+D33*E33 -> 77120 | I33: Octubre | J33: =+((K25*L25)+(K27*L27)+(K29*L29))/(K25+K27+K29) -> 10.481481 | K33: =+SUM($K$25:$K$29) -> 7300 | L33: =+J33*K33 -> 76514.815
E35: Unidades | F35: Valor
C36: Inventario consolidado | E36: =+E33+K33 -> 15300 | F36: =+F33+L33 -> 153634.81
B39: 4 | C39: En noviembre ha aparecido una nueva legislación por la cual se ha limitado el precio de venta a 8,75 euros que afecta a las ventas del grupo. Se pide: calcular el valor del inventario del grupo, así como el posible deterioro a 31 de diciembre.
C41: CONROL A | D41: Nuevo precio | E41: Unidades | F41: Valor Inventario (Existencias) | I41: CONROL B | J41: Nuevo precio | K41: Unidades | L41: Valor Inventario (Existencias)
D42: 8.75 | E42: =+SUM($E$8:$E$11) -> 8000 | F42: =D42*E42 -> 70000 | J42: 8.75 | K42: =+SUM($K$25:$K$29) -> 7300 | L42: =J42*K42 -> 63875

Sheet Sprint 2
B4: 1- Registrar las operaciones que han ocurrido desde el año de la adquisición hasta el 31 de diciembre de este año.
B6: Hace 2 años y medio:
B8: 500000 | C8: Inmovilizado material
D9: a | E9: Proveedores de inmovilizado | F9: =+B8 -> 500000
B11: 500000 | C11: Proveedores de inmovilizado
D12: a | E12: Préstamo | F12: =+B11 -> 500000
B15: A final de año de hace 2 años:
B17: =+B11*0.03/2 -> 7500 | C17: Gasto por amortización
D18: a | E18: Amortización acumulada | F18: =+B17 -> 7500
B20: A final de año de hace 1 año:
B22: =+B11*0.03 -> 15000 | C22: Gasto por amortización
D23: a | E23: Amortización acumulada | F23: =+B22 -> 15000
B25: Hace 6 meses | C25: CONTROL A
B27: =+B11*0.03/2 -> 7500 | C27: Gasto por amortización
D28: a | E28: Amortización acumulada | F28: =+B27 -> 7500
B30: =+B11-F18-F23-F28 -> 470000 | C30: Inversiones inmobiliarias
D31: a | E31: Inmovilizado material | F31: =+B30 -> 470000
B33: 60000 | C33: Ingreso por alquiler
B37: Si el alquiler del local se le realiza a la sociedad CONTROL B por importe de 10.000 euros, ¿cómo influiría a efectos del grupo?
B40: meses | C40: € | E40: CONTROL A | F40: Ingresos explotacion | G40: 60000
B41: 6 | C41: 10000 | D41: =60000 -> 60000 | E41: CONTROL B | F41: Pago de | G41: 60000

Sheet Sprint3
C1: 1
B2: CONTROL A | C2: CONTROL B | D2: AGREGADO | E2: Eliminiación patrimonial | F2: Eliminacion de Saldos
A3: Inmovilizado material | B3: 4000000 | C3: 28000 | D3: =SUM(B3:C3) -> 4028000 | G3: =D3+E3+F3 -> 4028000
A4: Inversiones inmobiliarias | B4: 470000 | C4: 0 | D4: =SUM(B4:C4) -> 470000 | G4: =D4+E4+F4 -> 470000
A5: Inversiones fiancieras a l.p | B5: 0 | C5: 75000 | D5: =SUM(B5:C5) -> 75000 | G5: =D5+E5+F5 -> 75000
A6: Inversiones financieras a l.p., empresas del grupo | B6: 10000 | C6: 0 | D6: =SUM(B6:C6) -> 10000 | E6: -10000 | G6: =D6+E6+F6 -> 0
A7: ACTIVO NO CORRIENTE | B7: =SUM(B3:B6) -> 4480000 | C7: =SUM(C3:C6) -> 103000 | D7: =SUM(D3:D6) -> 4583000 | E7: =+SUM(E3:E6) -> -10000 | F7: =+SUM(F3:F6) -> 0 | G7: =SUM(G3:G6) -> 4573000
A9: Existencias | B9: 77120 | C9: 76000 | D9: =SUM(B9:C9) -> 153120 | G9: =D9+E9+F9 -> 153120
A10: Deudores | B10: 350000 | C10: 460000 | D10: =SUM(B10:C10) -> 810000 | G10: =D10+E10+F10 -> 810000
A11: Inversiones financieras a c.p. | B11: 150000 | C11: 21000 | D11: =SUM(B11:C11) -> 171000 | G11: =D11+E11+F11 -> 171000
A12: Inversiones financieras a c.p. empresas del grupo | B12: 0 | C12: 38000 | D12: =SUM(B12:C12) -> 38000 | F12: -38000 | G12: =D12+E12+F12 -> 0
A13: Clientes empresas del grupo | B13: 10000 | C13: 0 | D13: =SUM(B13:C13) -> 10000 | F13: -10000 | G13: =D13+E13+F13 -> 0
A14: Tesoreira | B14: 150000 | C14: 22000 | D14: =SUM(B14:C14) -> 172000 | G14: =D14+E14+F14 -> 172000
A15: ACTIVO CORRIENTE | B15: =SUM(B9:B14) -> 737120 | C15: =SUM(C9:C14) -> 617000 | D15: =SUM(D9:D14) -> 1354120 | E15: =+SUM(E9:E14) -> 0 | F15: =+SUM(F9:F14) -> -48000 | G15: =SUM(G9:G14) -> 1306120
A16: TOTAL ACTIVO | B16: =B7+B15 -> 5217120 | C16: =C15+C7 -> 720000 | D16: =D15+D7 -> 5937120 | E16: =+E7+E15 -> -10000 | F16: =+F7+F15 -> -48000 | G16: =G15+G7 -> 5879120
A18: Capital Social | B18: 6000 | C18: 10000 | D18: =SUM(B18:C18) -> 16000 | E18: -10000 | G18: =D18+E18+F18 -> 6000
A19: Reservas | B19: 3142245.3 | C19: 122125 | D19: =SUM(B19:C19) -> 3264370.3 | E19: =-C19 -> -122125 | G19: =D19+E19+F19 -> 3142245.3
A21: Reservas en sociedades consolidadas | B21: 0 | C21: 0 | D21: 0 | E21: =-E19 -> 122125 | G21: =D21+E21+F21 -> 122125
A22: Resultado del ejercio | B22: 1047375 | C22: 157875 | D22: =SUM(B22:C22) -> 1205250 | G22: =D22+E21+F22 -> 1327375
A23: Patrimonio Neto | B23: =SUM(B18:B22) -> 4195620.3 | C23: =SUM(C18:C22) -> 290000 | D23: =SUM(D18:D22) -> 4485620.3 | E23: =+SUM(E18:E22) -> -10000 | F23: =+SUM(F18:F22) -> 0 | G23: =D23+E23+F23 -> 4475620.3
A25: Deudas a l.p | B25: 416666.67 | C25: 50000 | D25: =SUM(B25:C25) -> 466666.67 | G25: =D25+E25+F25 -> 466666.67
A26: PASIVO NO CORRIENTE | B26: =B25 -> 416666.67 | C26: =C25 -> 50000 | D26: =D25 -> 466666.67 | E26: =+E25 -> 0 | F26: =+F25 -> 0 | G26: =D26+E26+F26 -> 466666.67
A28: Deudas a c.p | B28: 33333 | C28: 10000 | D28: =SUM(B28:C28) -> 43333 | G28: =D28+E28+F28 -> 43333
A29: Deudas a c.p, empresas del grupo | B29: 38000 | C29: 0 | D29: =SUM(B29:C29) -> 38000 | F29: -38000 | G29: =D29+E29+F29 -> 0
A30: Proveedores | B30: 460000 | C30: 350000 | D30: =SUM(B30:C30) -> 810000 | G30: =D30+E30+F30 -> 810000
A31: Proveedores, empresas del grupo | B31: 0 | C31: 10000 | D31: =SUM(B31:C31) -> 10000 | F31: -10000 | G31: =D31+E31+F31 -> 0
A32: Personal | B32: 73500 | C32: 10000 | D32: =SUM(B32:C32) -> 83500 | G32: =D32+E32+F32 -> 83500
A33: PASIVO CORRIENTE | B33: =SUM(B28:B32) -> 604833 | C33: =SUM(C28:C32) -> 380000 | D33: =SUM(D28:D32) -> 984833 | F33: =+SUM(F28:F32) -> -48000 | G33: =SUM(G28:G32) -> 936833
A34: TOTAL PASIVO y PATRIMONIO NETO | B34: =B23+B26+B33 -> 5217120 | C34: =C23+C26+C33 -> 720000 | D34: =D23+D26+D33 -> 5937120 | E34: =+E23+E26+E33 -> -10000 | F34: =+F23+F26+F33 -> -48000 | G34: =+G23+G26+G33 -> 5879120
