Workbook

Sheet Balances
A1: ESTRUCTURA DEL ACTIVO SOCIETARIO
A3: CONCEPTO | B3: 2018 | C3: 2019 | D3: 2020 | E3: 2021 | F3: 2022
A4: A) ACTIVO NO CORRIENTE | B4: =B5+B6+B7+B8+B9+B10 -> 356716 | C4: =C5+C6+C7+C8+C9+C10 -> 355524 | D4: =D5+D6+D7+D8+D9+D10 -> 365722 | E4: =E5+E6+E7+E8+E9+E10 -> 161719 | F4: =F5+F6+F7+F8+F9+F10 -> 71342
A5: I Inmovilizado intangible | B5: 2550 | C5: 2736 | D5: 1726 | E5: 823 | F5: 54
A6: II Inmovilizado material | B6: 126615 | C6: 91906 | D6: 73644 | E6: 43963 | F6: 30324
A7: III Inv. Inmobiliarias | J7: Activo no operativo que sumaria en CAESA, estimar
A8: IV Inv. en empr. del grupo y asociadas a l.p.
A9: V Inversiones financieras a largo plazo | B9: 26584 | C9: 27466 | D9: 27466 | E9: 27466 | F9: 20584
A10: VI Activos por impuesto diferido | B10: 200967 | C10: 233416 | D10: 262886 | E10: 89467 | F10: 20380 | J10: Informe de gestion para proyeccion de ventas, estimacion de crecimineto o descecimiento, junto con el margen marque descuento flujo de caja
A11: B) ACTIVO CORRIENTE | B11: =B12+B13+B14+B15+B16+B17 -> 6314583 | C11: =C12+C13+C14+C15+C16+C17 -> 6444984 | D11: =D12+D13+D14+D15+D16+D17 -> 4900360 | E11: =E12+E13+E14+E15+E16+E17 -> 3073693 | F11: =F12+F13+F14+F15+F16+F17 -> 3866439
A12: II Existencias
A13: III Deudores comerc. y otras cuentas a cobr. | B13: 4633105 | C13: 3910982 | D13: 1803038 | E13: 2625957 | F13: 3627776 | J13: Multiplos Sprint 1, EBITA
A14: IV Inv. en empr. del grupo y asociadas a c.p.
A15: V Inversiones financieras a corto plazo
A16: VI Periodificaciones a corto plazo | J16: Coste de la deuda considerar toto negocio se financia con fondos propios
A17: VII Efectivo y otros activos líquidos equiv. | B17: =+B18 -> 1681478 | C17: =+C18 -> 2534002 | D17: =+D18 -> 3097322 | E17: =+E18 -> 447736 | F17: =+F18 -> 238663
A18: 1. Tesorería | B18: 1681478 | C18: 2534002 | D18: 3097322 | E18: 447736 | F18: 238663
A19: TOTAL ACTIVO | B19: =B4+B11 -> 6671299 | C19: =C4+C11 -> 6800508 | D19: =D4+D11 -> 5266082 | E19: =E4+E11 -> 3235412 | F19: =F4+F11 -> 3937781 | J19: Centrarse en Perdidas y Ganancias
A21: ESTRUCTURA DEL PASIVO SOCIETARIO | J21: Mantener un margen similar
A23: CONCEPTO | B23: 2018 | C23: 2019 | D23: 2020 | E23: 2021 | F23: 2022 | J23: Reducir la primera parte, importante hacer la proyeccion, descuento de flujo de cajas, todo lo que estamos proyectando y descontando sea coherente, saldo cliente, saldo proveedores, …...
A24: A) PATRIMONIO NETO | B24: =+B25+B31 -> 950602 | C24: =+C25+C31 -> 1192014 | D24: =+D25+D31 -> 1212634 | E24: =+E25+E31 -> 1087424 | F24: =+F25+F31 -> 1346800
A25: A-1) Fondos propios | B25: =B26+B27+B28+B29+B30 -> 943935 | C25: =C26+C27+C28+C29+C30 -> 1186947 | D25: =D26+D27+D28+D29+D30 -> 1209167 | E25: =E26+E27+E28+E29+E30 -> 1085557 | F25: =F26+F27+F28+F29+F30 -> 1346800
A26: I Capital | B26: 180000 | C26: 180000 | D26: 180000 | E26: 180000 | F26: 180000 | J26: Gasto0s financieros, P y Ganancias no reflejan la realidad, habria que etimalarlos con Demoraran Interest and
A27: II Prima de emisión | J27: funcion de ratio de interese, mirar la tabla sumarle la proima sin riesgo el euribor.
A28: III Reservas | B28: 503684 | C28: 503684 | D28: 746696 | E28: 58221 | F28: 905557
A29: V Resultados de ejercicios anteriores | C29: 260251 | D29: 260251 | J29: Waac sectorial, sino suponer que no hay deuda WACC = Ksue Kd= 0
A30: VII Resultado del ejercicio | B30: =+'Cuentas PyG'!B22 -> 260251 | C30: =+'Cuentas PyG'!C22 -> 243012 | D30: =+'Cuentas PyG'!D22 -> 22220 | E30: =+'Cuentas PyG'!E22 -> 847336 | F30: =+'Cuentas PyG'!F22 -> 261243
A31: A-2) Subvenciones, donac. y legados recib. | B31: 6667 | C31: 5067 | D31: 3467 | E31: 1867 | J31: üna vez calclualdao, su equity subir a la valoracion de Equety va
A32: B) PASIVO NO CORRIENTE | B32: =B33+B34+B35+B36+B37 -> 0 | C32: =C33+C34+C35+C36+C37 -> 0 | D32: =D33+D34+D35+D36+D37 -> 0 | E32: =E33+E34+E35+E36+E37 -> 0 | F32: =F33+F34+F35+F36+F37 -> 0
A33: I Provisiones a largo plazo
A34: II Deudas a largo plazo | L34: Entrepaise a Equety tienens que sumar todos los activos no oeprativos, seria valor
A35: III Deudas con empr. del grupo y asoc. a l.p.
A36: IV Pasivos por impuesto diferido | K36: mucho mayor a 180mil
A37: V Periodificaciones a largo plazo
A38: C) PASIVO CORRIENTE | B38: =B39+B40+B41+B42+B43 -> 5720697 | C38: =C39+C40+C41+C42+C43 -> 5608494 | D38: =D39+D40+D41+D42+D43 -> 4053448 | E38: =E39+E40+E41+E42+E43 -> 2147988 | F38: =F39+F40+F41+F42+F43 -> 2590981 | K38: Participaciones empresa del grupo
A39: II Provisiones a corto plazo
A40: III Deudas a corto plazo
A41: IV Deudas empr. del grupo y asoc. a c.p. | B41: 918747 | C41: 1032055 | D41: 1069071 | J41: Hay que hacer por flujos de caja.
A42: V Acreed. comerc.y otras cuentas a pagar | B42: 4801950 | C42: 4576439 | D42: 2984377 | E42: 2147988 | F42: 2590981
A43: VI Periodificaciones a corto plazo
...

Sheet Cuentas PyG
A1: ESTUCTURA DE LA CUENTA DE RESULTADOS
A3: CONCEPTO | B3: 2018 | C3: 2019 | D3: 2020 | E3: 2021 | F3: 2022
A4: 1. Importe neto de la cifra de negocios | B4: 14175032 | C4: 15084250 | D4: 10507821 | E4: 9339767 | F4: 7225733 | H4: =(F4-E4)/E4 -> -0.22634762
A5: 3. Trabajos realiz. por la empr para su activo
A6: 4. Aprovisionamientos | B6: -3078853 | C6: -2774939 | D6: -907800 | E6: -1244850 | F6: -2212833
A7: 5. Otros ingresos de explotación | D7: 520147
A8: 6. Gastos de personal | B8: -6498849 | C8: -7549155 | D8: -6752584 | E8: -4186778 | F8: -2784096 | G8: =E8/$E$4 -> -0.44827435 | H8: =F8/$F$4 -> -0.38530292
A9: 7. Otros gastos de explotación | B9: -4197927 | C9: -4422426 | D9: -3308146 | E9: -3521544 | F9: -1855704 | G9: =E9/$E$4 -> -0.37704838 | H9: =F9/$F$4 -> -0.25681879
A10: 8. Amortización del inmovilizado | B10: -39922 | C10: -35544 | D10: -34474 | E10: -35202 | F10: -16687
A11: 9. Imputación de subv. de inmov. no financ. | B11: 1333 | C11: 1600 | D11: 1600 | E11: 1600 | F11: 1867
A12: 10. Exceso de provisiones | E12: 773114
A13: 11. Deterioro y result. por enaj. del inmovilizado | B13: 2956
A14: 13. Otros resultados
A15: A1) RESULTADO DE EXPLOTACIÓN | B15: =B4+B5+B6+B7+B8+B9+B10+B11+B12+B13+B14 -> 363770 | C15: =C4+C5+C6+C7+C8+C9+C10+C11+C12+C13+C14 -> 303786 | D15: =D4+D5+D6+D7+D8+D9+D10+D11+D12+D13+D14 -> 26564 | E15: =E4+E5+E6+E7+E8+E9+E10+E11+E12+E13+E14 -> 1126107 | F15: =F4+F5+F6+F7+F8+F9+F10+F11+F12+F13+F14 -> 358280
A16: 14. Ingresos financieros | B16: 2411 | C16: 21462 | D16: 33506 | E16: 19412 | F16: 82
A17: 15. Gastos financieros | B17: -18275 | C17: -730 | D17: -25448 | E17: -20034 | F17: -4866
A18: 17. Diferencias de cambio | D18: -4856 | F18: -4
A19: 18. Deterioro y result. por enaj. de instr. financ.
A20: A3) RESULTADO ANTES DE IMPUESTOS | B20: =B15+B16+B17+B18+B19 -> 347906 | C20: =C15+C16+C17+C18+C19 -> 324518 | D20: =D15+D16+D17+D18+D19 -> 29766 | E20: =E15+E16+E17+E18+E19 -> 1125485 | F20: =F15+F16+F17+F18+F19 -> 353492
A21: 19. Impuestos sobre beneficios | B21: -87655 | C21: -81506 | D21: -7546 | E21: -278149 | F21: -92249
A22: A5) Resultado del ejercicio | B22: =B20+B21 -> 260251 | C22: =C20+C21 -> 243012 | D22: =D20+D21 -> 22220 | E22: =E20+E21 -> 847336 | F22: =F20+F21 -> 261243
A27: EBITDA | B27: =F15-F10 -> 374967 | I27: Ticker | J27: Company Name | K27: Global Region | L27: Country | M27: Industry | N27: Trailing TEV/EBITDA (2022)
A28: EV/EBITDA | B28: =N48 -> 8.14 | I28: ALA | J28: A.L.A. società per azioni | K28: Europe | L28: ITA | M28: Air Freight and Logistics | N28: 10.7
A29: EV BODEGA | B29: =+B27*B28 -> 3052231.4 | I29: ALCLA | J29: Clasquin SA | K29: Europe | L29: FRA | M29: Air Freight and Logistics | N29: 5.82
A30: DEUDA FINANCIERA | B30: 0 | I30: AQ | J30: Aquila Part Prod Com S.A. | K30: Europe | L30: ROU | M30: Air Freight and Logistics | N30: 8.08
A31: TESORERIA | B31: =Balances!F30 -> 261243 | I31: BPOST | J31: bpost NV/SA | K31: Europe | L31: BEL | M31: Air Freight and Logistics | N31: 3.26
A32: ACTIVOS NO OPERATIVOS | B32: =+Balances!B7 -> 0 | I32: CTT | J32: CTT - Correios De Portugal, S.A. | K32: Europe | L32: PRT | M32: Air Freight and Logistics | N32: 1.69
A33: EQUITY VALUE BODEGA | B33: =SUM(B29:B32) -> 3313474.4 | I33: DE1 | J33: Deufol SE | K33: Europe | L33: DEU | M33: Air Freight and Logistics | N33: 9.08
A34: Participación 100% HOLDING | B34: =+B33 -> 3313474.4 | I34: DPW | J34: Deutsche Post AG | K34: Europe | L34: DEU | M34: Air Freight and Logistics | N34: 6.98
A35: Valor contable | B35: 0 | I35: IDS | J35: International Distributions Services plc | K35: Europe | L35: GBR | M35: Air Freight and Logistics | N35: 2.97
A36: Plusvalía participación | B36: =+B34-B35 -> 3313474.4 | C36: Inversion en empresas | I36: IEKG | J36: Intereuropa, d. d. | K36: Europe | L36: SVN | M36: Air Freight and Logistics | N36: 6.15
I37: JETPAK | J37: Jetpak Top Holding AB (publ) | K37: Europe | L37: SWE | M37: Air Freight and Logistics | N37: 10.4
I38: LOG | J38: Compañía de Distribución Integral Logista Holdings, S.A. | K38: Europe | L38: ESP | M38: Air Freight and Logistics | N38: 4.52
I39: MTP | J39: MaltaPost p.l.c. | K39: Europe | L39: MLT | M39: Air Freight and Logistics | N39: 8.2
I40: NLG1V | J40: Nurminen Logistics Oyj | K40: Europe | L40: FIN | M40: Air Freight and Logistics | N40: 8.73
I41: PNL | J41: PostNL N.V. | K41: Europe | L41: NLD | M41: Air Freight and Logistics | N41: 3.52
I42: POST | J42: Österreichische Post AG | K42: Europe | L42: AUT | M42: Air Freight and Logistics | N42: 10.32
I43: SPDY | J43: Speedy AD | K43: Europe | L43: BGR | M43: Air Freight and Logistics | N43: 9.19
I44: TGHN | J44: Logwin AG | K44: Europe | L44: DEU | M44: Air Freight and Logistics | N44: 4.58
I45: WIN | J45: Wincanton plc | K45: Europe | L45: GBR | M45: Air Freight and Logistics | N45: 8.28
...
