Workbook

Sheet Hipotésis
A1: HIPÓTESIS DE CUENTA RESULTADOS
E2: 1 | F2: 2 | G2: 3 | H2: 4 | I2: 5
A3: CONCEPTO | B3: X-2 | C3: X-1 | D3: X | E3: X+1 | F3: X+2 | G3: X+3 | H3: X+4 | I3: X+5
A4: Crec. Imp. neto de la cifra de negocios | B4: =('Proyeccion PYG'!D4-'Proyeccion PYG'!C4)/'Proyeccion PYG'!C4 -> 0.73494188 | C4: =('Proyeccion PYG'!E4-'Proyeccion PYG'!D4)/'Proyeccion PYG'!D4 -> -0.09525511 | D4: =('Proyeccion PYG'!F4-'Proyeccion PYG'!E4)/'Proyeccion PYG'!E4 -> -0.11436948 | E4: =+D4-(($D$4-$B$31)/5) -> -0.071495582 | F4: =+E4-(($D$4-$B$31)/5) -> -0.028621687 | G4: =+F4-(($D$4-$B$31)/5) -> 0.014252209 | H4: =+G4-(($D$4-$B$31)/5) -> 0.057126104 | I4: =+H4-(($D$4-$B$31)/5) -> 0.1
A5: Aprovisionamientos | B5: ='Proyeccion PYG'!D6/'Proyeccion PYG'!D4 -> -0.81997553 | C5: ='Proyeccion PYG'!E6/'Proyeccion PYG'!E4 -> -0.6382394 | D5: ='Proyeccion PYG'!F6/'Proyeccion PYG'!F4 -> -0.58864069 | E5: =+D5-(($D$5-$B$32)/5) -> -0.58091255 | F5: =+E5-(($D$5-$B$32)/5) -> -0.57318441 | G5: =+F5-(($D$5-$B$32)/5) -> -0.56545628 | H5: =+G5-(($D$5-$B$32)/5) -> -0.55772814 | I5: =+H5-(($D$5-$B$32)/5) -> -0.55
A6: Gastos de personal/Imp. neto cifra de neg. | B6: =-'Proyeccion PYG'!D8/'Proyeccion PYG'!D4 -> 0.07313762 | C6: =-'Proyeccion PYG'!E8/'Proyeccion PYG'!E4 -> 0.13328201 | D6: =-'Proyeccion PYG'!F8/'Proyeccion PYG'!F4 -> 0.16101541 | E6: =+D6-(($D$6-$B$33)/5) -> 0.15481233 | F6: =+E6-(($D$6-$B$33)/5) -> 0.14860924 | G6: =+F6-(($D$6-$B$33)/5) -> 0.14240616 | H6: =+G6-(($D$6-$B$33)/5) -> 0.13620308 | I6: =+H6-(($D$6-$B$33)/5) -> 0.13
A7: Dotación amort./Inmovilizado Neto | B7: ='Proyeccion PYG'!D10/('PROYECCION BALANCE'!D6+'PROYECCION BALANCE'!D5) -> -0.11308743 | C7: ='Proyeccion PYG'!E10/('PROYECCION BALANCE'!E6+'PROYECCION BALANCE'!E5) -> -0.11654557 | D7: ='Proyeccion PYG'!F10/('PROYECCION BALANCE'!F6+'PROYECCION BALANCE'!F5) -> -0.18377236 | E7: ='Proyeccion PYG'!F10/('PROYECCION BALANCE'!G6+'PROYECCION BALANCE'!G5) -> -0.19792298 | F7: ='Proyeccion PYG'!H10/('PROYECCION BALANCE'!H6+'PROYECCION BALANCE'!H5) -> -0.20375478 | G7: ='Proyeccion PYG'!I10/('PROYECCION BALANCE'!I6+'PROYECCION BALANCE'!I5) -> -0.20089163 | H7: ='Proyeccion PYG'!J10/('PROYECCION BALANCE'!J6+'PROYECCION BALANCE'!J5) -> -0.19003564 | I7: ='Proyeccion PYG'!K10/('PROYECCION BALANCE'!K6+'PROYECCION BALANCE'!K5) -> -0.17275967
A8: Impuesto sobre beneficios/Result. antes imp. | B8: =-'Proyeccion PYG'!D21/'Proyeccion PYG'!D20 -> 0.25096057 | C8: =-'Proyeccion PYG'!E21/'Proyeccion PYG'!E20 -> 0.21979768 | D8: =-'Proyeccion PYG'!F21/'Proyeccion PYG'!F20 -> 0.26505712 | E8: =$B$35 -> 0.25 | F8: =$B$35 -> 0.25 | G8: =$B$35 -> 0.25 | H8: =$B$35 -> 0.25 | I8: =$B$35 -> 0.25
A10: HIPÓTESIS DE CAPITAL CIRCULANTE
A12: CONCEPTO | B12: X-2 | C12: X-1 | D12: X | E12: X+1 | F12: X+2 | G12: X+3 | H12: X+4 | I12: X+5
A13: Periodo medio de inventario | C13: 120 | D13: =-'PROYECCION BALANCE'!F12/('Proyeccion PYG'!F6)*365 -> 100 | E13: =$D$13 -> 100 | F13: =$D$13 -> 100 | G13: =$D$13 -> 100 | H13: =$D$13 -> 100 | I13: =$D$13 -> 100 | L13: E$xistencias
A14: Periodo medio de cobro | B14: =(-'PROYECCION BALANCE'!D13/'Proyeccion PYG'!D6)*365 -> 107.03009 | C14: =(-'PROYECCION BALANCE'!E13/'Proyeccion PYG'!E6)*365 -> 139.64945 | D14: =(-'PROYECCION BALANCE'!F13/'Proyeccion PYG'!F6)*365 -> 144.2327 | E14: =$D$14+($C$14-$D$14)*(E2)/($I$2) -> 143.31605 | F14: =$D$14+($C$14-$D$14)*(F2)/($I$2) -> 142.3994 | G14: =$D$14+($C$14-$D$14)*(G2)/($I$2) -> 141.48275 | H14: =$D$14+($C$14-$D$14)*(H2)/($I$2) -> 140.5661 | I14: =$D$14+($C$14-$D$14)*(I2)/($I$2) -> 139.64945
A15: Periodo medio de pago | B15: ='PROYECCION BALANCE'!D42/(-'Cuentas PyG'!D6-'Cuentas PyG'!C6)*365 -> 61.396625 | C15: ='PROYECCION BALANCE'!E42/(-'Cuentas PyG'!E6-'Cuentas PyG'!D6)*365 -> 53.33214 | D15: ='PROYECCION BALANCE'!F42/(-'Cuentas PyG'!F6-'Cuentas PyG'!E6)*365 -> 77.712405 | E15: =$D$15+($C$15-$D$15)*(E2)/($I$2) -> 72.836352 | F15: =$D$15+($C$15-$D$15)*(F2)/($I$2) -> 67.960299 | G15: =$D$15+($C$15-$D$15)*(G2)/($I$2) -> 63.084246 | H15: =$D$15+($C$15-$D$15)*(H2)/($I$2) -> 58.208193 | I15: =$D$15+($C$15-$D$15)*(I2)/($I$2) -> 53.33214
A16: Deudas Acreed. comerc.y otras cuentas a pagar | B16: ='PROYECCION BALANCE'!D42/'Proyeccion PYG'!D4 -> 0.2125165 | C16: ='PROYECCION BALANCE'!E42/'Proyeccion PYG'!E4 -> 0.22568192 | D16: ='PROYECCION BALANCE'!F42/'Proyeccion PYG'!F4 -> 0.27876434 | E16: ='PROYECCION BALANCE'!G42/'Proyeccion PYG'!G4 -> 0.2024522 | F16: ='PROYECCION BALANCE'!H42/'Proyeccion PYG'!H4 -> 0.10799007 | G16: ='PROYECCION BALANCE'!I42/'Proyeccion PYG'!I4 -> 0.097714369 | H16: ='PROYECCION BALANCE'!J42/'Proyeccion PYG'!J4 -> 0.087945998 | I16: ='PROYECCION BALANCE'!K42/'Proyeccion PYG'!K4 -> 0.078643162 | J16: 42
A18: HIPÓTESIS DE INMOVILIZADO
A20: CONCEPTO | B20: X-2 | C20: X-1 | D20: X | E20: X+1 | F20: X+2 | G20: X+3 | H20: X+4 | I20: X+5
A21: Inmovilizado int./Inmovilizado int. y mat. | B21: ='PROYECCION BALANCE'!D5/('PROYECCION BALANCE'!D5+'PROYECCION BALANCE'!D6) -> 0.035281766 | C21: ='PROYECCION BALANCE'!E5/('PROYECCION BALANCE'!E5+'PROYECCION BALANCE'!E6) -> 0.060722661 | D21: ='PROYECCION BALANCE'!F5/('PROYECCION BALANCE'!F5+'PROYECCION BALANCE'!F6) -> 0.1084259 | E21: ='PROYECCION BALANCE'!G5/('PROYECCION BALANCE'!G5+'PROYECCION BALANCE'!G6) -> 0.1084259 | F21: ='PROYECCION BALANCE'!H5/('PROYECCION BALANCE'!H5+'PROYECCION BALANCE'!H6) -> 0.1084259 | G21: ='PROYECCION BALANCE'!I5/('PROYECCION BALANCE'!I5+'PROYECCION BALANCE'!I6) -> 0.1084259 | H21: ='PROYECCION BALANCE'!J5/('PROYECCION BALANCE'!J5+'PROYECCION BALANCE'!J6) -> 0.1084259 | I21: ='PROYECCION BALANCE'!K5/('PROYECCION BALANCE'!K5+'PROYECCION BALANCE'!K6) -> 0.1084259
A23: HIPÓTESIS DE ESTRUCTURA FINANCIERA
A25: CONCEPTO | B25: X-2 | C25: X-1 | D25: X | E25: X+1 | F25: X+2 | G25: X+3 | H25: X+4 | I25: X+5
A26: Deuda fin./(Deuda fin.+Patr. neto objetivo) | B26: =('PROYECCION BALANCE'!D34+'PROYECCION BALANCE'!D39+'PROYECCION BALANCE'!D40)/('PROYECCION BALANCE'!D34+'PROYECCION BALANCE'!D39+'PROYECCION BALANCE'!D40+'PROYECCION BALANCE'!D25) -> 0.021049231 | C26: =('PROYECCION BALANCE'!E34+'PROYECCION BALANCE'!E39+'PROYECCION BALANCE'!E40)/('PROYECCION BALANCE'!E34+'PROYECCION BALANCE'!E39+'PROYECCION BALANCE'!E40+'PROYECCION BALANCE'!E25) -> 0.060134841 | D26: =('PROYECCION BALANCE'!F33+'PROYECCION BALANCE'!F39+'PROYECCION BALANCE'!F40)/('PROYECCION BALANCE'!G33+'PROYECCION BALANCE'!G39+'PROYECCION BALANCE'!F24) -> 0.017815195 | E26: =$D$26 -> 0.017815195 | F26: =$D$26 -> 0.017815195 | G26: =$D$26 -> 0.017815195 | H26: =$D$26 -> 0.017815195 | I26: =$D$26 -> 0.017815195 | K26: deuda largo plazo | M26: Provisiones corto plzo | O26: deudas corto plazo | R26: deuda largo plazo+provis cp+deuda cp+ | V26: Patrimonio neto
A27: Deuda fin. l.p./Deuda fin. total | B27: ='PROYECCION BALANCE'!D34/('PROYECCION BALANCE'!D39+'PROYECCION BALANCE'!D40+'PROYECCION BALANCE'!D34) -> 0.75466805 | C27: ='PROYECCION BALANCE'!E34/('PROYECCION BALANCE'!E39+'PROYECCION BALANCE'!E40+'PROYECCION BALANCE'!E34) -> 0.27447425 | D27: ='PROYECCION BALANCE'!F34/('PROYECCION BALANCE'!F39+'PROYECCION BALANCE'!F40+'PROYECCION BALANCE'!F34) -> 0.56097383 | E27: =$D$27 -> 0.56097383 | F27: =$D$27 -> 0.56097383 | G27: =$D$27 -> 0.56097383 | H27: =$D$27 -> 0.56097383 | I27: =$D$27 -> 0.56097383
A28: Deudas fin. a c.p./Deuda fin. total | B28: ='PROYECCION BALANCE'!D39/('PROYECCION BALANCE'!D39+'PROYECCION BALANCE'!D40+'PROYECCION BALANCE'!D34) -> 0.24533195 | C28: ='PROYECCION BALANCE'!E39/('PROYECCION BALANCE'!E39+'PROYECCION BALANCE'!E40+'PROYECCION BALANCE'!E34) -> 0.10255055 | D28: ='PROYECCION BALANCE'!F39/('PROYECCION BALANCE'!F39+'PROYECCION BALANCE'!F40+'PROYECCION BALANCE'!F34) -> 0.43902617 | E28: =$D$28 -> 0.43902617 | F28: =$D$28 -> 0.43902617 | G28: =$D$28 -> 0.43902617 | H28: =$D$28 -> 0.43902617 | I28: =$D$28 -> 0.43902617
A29: Gastos financieros/Deuda financiera | B29: =-'Proyeccion PYG'!D17/('PROYECCION BALANCE'!C33+'PROYECCION BALANCE'!C39+'PROYECCION BALANCE'!D33+'PROYECCION BALANCE'!D39)/2 -> 0.1260039 | C29: =-'Proyeccion PYG'!E17/('PROYECCION BALANCE'!D33+'PROYECCION BALANCE'!D39+'PROYECCION BALANCE'!E33+'PROYECCION BALANCE'!E39)/2 -> 0.044750453 | D29: =-'Proyeccion PYG'!F17/('PROYECCION BALANCE'!E33+'PROYECCION BALANCE'!E39+'PROYECCION BALANCE'!F33+'PROYECCION BALANCE'!F39)/2 -> 0.2401421 | E29: =$D$29 -> 0.2401421 | F29: =$D$29 -> 0.2401421 | G29: =$D$29 -> 0.2401421 | H29: =$D$29 -> 0.2401421 | I29: =$D$29 -> 0.2401421
A31: Crecimiento ventas en X+5 | B31: 0.1
A32: Aprovionamiento | B32: -0.55
A33: Gasto personal en x+5 vba ser el mismo x-2 | B33: 0.13
A34: Otros Gastos de expl. van mantenerse según las ventas | B34: =-'Proyeccion PYG'!F9/'Proyeccion PYG'!F4 -> 0.14859324
A35: Impuesto sobre sociedades | B35: 0.25
A36: Promedio medio de cobro volver x-1 | B36: =C14 -> 139.64945
A37: Promedio medio de pago igualar al a x-1 al x+5 | B37: 53.33
A44: Coste efectvo de la deuda | D44: =-'Proyeccion PYG'!F17/('PROYECCION BALANCE'!E33+'PROYECCION BALANCE'!E40+'PROYECCION BALANCE'!F33+'PROYECCION BALANCE'!F40)/2 -> 0.16040846 | E44: =-'Proyeccion PYG'!G17/('PROYECCION BALANCE'!F33+'PROYECCION BALANCE'!F40+'PROYECCION BALANCE'!G33+'PROYECCION BALANCE'!G40)/2 -> 0.036063413 | F44: =-'Proyeccion PYG'!H17/('PROYECCION BALANCE'!G33+'PROYECCION BALANCE'!G40+'PROYECCION BALANCE'!H33+'PROYECCION BALANCE'!H40)/2 -> 0.0085714874 | G44: =-'Proyeccion PYG'!I17/('PROYECCION BALANCE'!H33+'PROYECCION BALANCE'!H40+'PROYECCION BALANCE'!I33+'PROYECCION BALANCE'!I40)/2 -> 0.0021414407 | H44: =-'Proyeccion PYG'!J17/('PROYECCION BALANCE'!I33+'PROYECCION BALANCE'!I40+'PROYECCION BALANCE'!J33+'PROYECCION BALANCE'!J40)/2 -> 0.0005842447 | I44: =-'Proyeccion PYG'!K17/('PROYECCION BALANCE'!J33+'PROYECCION BALANCE'!J40+'PROYECCION BALANCE'!K33+'PROYECCION BALANCE'!K40)/2 -> 0.00018166212
A46: CONCEPTO | B46: X-2 | C46: X-1 | D46: X | E46: X+1 | F46: X+2 | G46: X+3 | H46: X+4 | I46: X+5
A47: Activo fijo material/Imp. neto cifra neg. | B47: ='PROYECCION BALANCE'!D6/'Proyeccion PYG'!D4 -> 0.011023232 | C47: ='PROYECCION BALANCE'!E6/'Proyeccion PYG'!E4 -> 0.019428913 | D47: ='PROYECCION BALANCE'!E6/'Proyeccion PYG'!E4 -> 0.019428913 | E47: ='PROYECCION BALANCE'!F6/'Proyeccion PYG'!F4 -> 0.02234974 | F47: ='PROYECCION BALANCE'!G6/'Proyeccion PYG'!G4 -> 0.02234974 | G47: ='PROYECCION BALANCE'!H6/'Proyeccion PYG'!H4 -> 0.02234974 | H47: ='PROYECCION BALANCE'!I6/'Proyeccion PYG'!I4 -> 0.02234974 | I47: ='PROYECCION BALANCE'!J6/'Proyeccion PYG'!J4 -> 0.02234974
A48: Activo fijo intangible/Imp. neto cifra neg. | B48: ='PROYECCION BALANCE'!D5/'Proyeccion PYG'!D4 -> 0.0004031427 | C48: ='PROYECCION BALANCE'!E5/'Proyeccion PYG'!E4 -> 0.0012560458 | D48: ='PROYECCION BALANCE'!E5/'Proyeccion PYG'!E4 -> 0.0012560458 | E48: ='PROYECCION BALANCE'!F5/'Proyeccion PYG'!F4 -> 0.0027179914 | F48: ='PROYECCION BALANCE'!G5/'Proyeccion PYG'!G4 -> 0.0027179914 | G48: ='PROYECCION BALANCE'!H5/'Proyeccion PYG'!H4 -> 0.0027179914 | H48: ='PROYECCION BALANCE'!I5/'Proyeccion PYG'!I4 -> 0.0027179914 | I48: ='PROYECCION BALANCE'!J5/'Proyeccion PYG'!J4 -> 0.0027179914
A51: Mantener la inversion a corto plazo

Sheet PROYECCION BALANCE
A1: ESTRUCTURA DEL ACTIVO SOCIETARIO
A3: CONCEPTO | B3: 2018 | C3: 2019 | D3: 2020 | E3: 2021 | F3: 2022 | G3: X+1 | H3: X+2 | I3: X+3 | J3: X+4 | K3: X+5
A4: A) ACTIVO NO CORRIENTE | B4: =B5+B6+B7+B8+B9+B10 -> 859099 | C4: =C5+C6+C7+C8+C9+C10 -> 1556623 | D4: =D5+D6+D7+D8+D9+D10 -> 1403778 | E4: =E5+E6+E7+E8+E9+E10 -> 2730187 | F4: =F5+F6+F7+F8+F9+F10 -> 2700262.5 | G4: =G5+G6+G7+G8+G9+G10 -> 2609883.3 | H4: =H5+H6+H7+H8+H9+H10 -> 2576288.7 | I4: =I5+I6+I7+I8+I9+I10 -> 2592538.4 | ... K4: =K5+K6+K7+K8+K9+K10 -> 2780845
A5: I Inmovilizado intangible | B5: 55358 | C5: 38181 | D5: 25372 | E5: 71520 | F5: 137063.78 | G5: ='Proyeccion PYG'!G4*Hipotésis!E48 -> 127264.33 | H5: ='Proyeccion PYG'!H4*Hipotésis!F48 -> 123621.81 | I5: ='Proyeccion PYG'!I4*Hipotésis!G48 -> 125383.69 | J5: ='Proyeccion PYG'!J4*Hipotésis!H48 -> 132546.37 | K5: ='Proyeccion PYG'!K4*Hipotésis!I48 -> 145801.01
A6: II Inmovilizado material | B6: 306410 | C6: 353563 | D6: 693753 | E6: 1106294 | F6: 1127060.2 | G6: ='Proyeccion PYG'!G4*Hipotésis!E47 -> 1046480.4 | H6: ='Proyeccion PYG'!H4*Hipotésis!F47 -> 1016528.3 | I6: ='Proyeccion PYG'!I4*Hipotésis!G47 -> 1031016.1 | J6: ='Proyeccion PYG'!J4*Hipotésis!H47 -> 1089914 | K6: ='Proyeccion PYG'!K4*Hipotésis!I47 -> 1198905.4
A7: III Inv. Inmobiliarias | B7: 0 | C7: 0 | D7: 0 | E7: 0 | F7: 0
A8: IV Inv. en empr. del grupo y asociadas a l.p. | B8: 180000 | C8: 180000 | D8: 180000 | E8: 180000 | F8: 180000 | G8: 180000 | H8: 180000 | I8: 180000 | J8: 180000 | K8: 180000
A9: V Inversiones financieras a largo plazo | B9: 130945 | C9: 658072 | D9: 236958 | E9: 1073260 | F9: 967272.43 | G9: 967272.43 | H9: 967272.43 | I9: 967272.43 | J9: 967272.43 | K9: 967272.43
A10: VI Activos por impuesto diferido | B10: 186386 | C10: 326807 | D10: 267695 | E10: 299113 | F10: 288866.14 | G10: 288866.14 | H10: 288866.14 | I10: 288866.14 | J10: 288866.14 | K10: 288866.14
A11: B) ACTIVO CORRIENTE | B11: =B12+B13+B14+B15+B16+B17 -> 15752844 | C11: =C12+C13+C14+C15+C16+C17 -> 15603138 | D11: =D12+D13+D14+D15+D16+D17 -> 23948930 | E11: =E12+E13+E14+E15+E16+E17 -> 30338643 | F11: =F12+F13+F14+F15+F16+F17 -> 31075471 | G11: =G12+G13+G14+G15+G16+G17 -> 30852725 | H11: =H12+H13+H14+H15+H16+H17 -> 30915575 | I11: =I12+I13+I14+I15+I16+I17 -> 35639283 | ... K11: =K12+K13+K14+K15+K16+K17 -> 48226481
A12: II Existencias | E12: =-'Proyeccion PYG'!E6/365*Hipotésis!C13 -> 11947968 | F12: =-'Proyeccion PYG'!F6/365*Hipotésis!D13 -> 8132649.2 | G12: =-'Proyeccion PYG'!G6/365*Hipotésis!E13 -> 7452062.6 | H12: =-'Proyeccion PYG'!H6/365*Hipotésis!F13 -> 7142471.4 | I12: =-'Proyeccion PYG'!I6/365*Hipotésis!G13 -> 7146594.3 | J12: =-'Proyeccion PYG'!J6/365*Hipotésis!H13 -> 7451598.6 | K12: =-'Proyeccion PYG'!K6/365*Hipotésis!I13 -> 8083180.4
A13: III Deudores comerc. y otras cuentas a cobr. | B13: 7499543 | C13: 9085867 | D13: 15132470 | E13: 13904393 | F13: 11729940 | G13: =('Proyeccion PYG'!G4/365)*Hipotésis!E14 -> 18384870 | H13: ='Proyeccion PYG'!H4/365*Hipotésis!E14 -> 17858664 | I13: ='Proyeccion PYG'!I4/365*Hipotésis!F14 -> 17997338 | J13: ='Proyeccion PYG'!J4/365*Hipotésis!G14 -> 18902985 | K13: ='Proyeccion PYG'!K4/365*Hipotésis!H14 -> 20658567
A14: IV Inv. en empr. del grupo y asociadas a c.p. | F14: 3913618.7 | G14: 3913618.7 | H14: 3913618.7 | I14: 3913618.7 | J14: 3913618.7 | K14: 3913618.7
A15: V Inversiones financieras a corto plazo | B15: 778610 | C15: 494474 | D15: 2859350 | E15: 250703 | F15: 335009.77 | G15: 335009.77 | H15: 335009.77 | I15: 335009.77 | J15: 335009.77 | K15: 335009.77
A16: VI Periodificaciones a corto plazo
A17: VII Efectivo y otros activos líquidos equiv. | B17: =SUM(B18:B18) -> 7474691 | C17: =SUM(C18:C18) -> 6022797 | D17: =SUM(D18:D18) -> 5957110 | E17: =SUM(E18:E18) -> 4235579 | F17: =SUM(F18:F18) -> 6964253.9 | G17: =SUM(G18:G18) -> 767163.39 | H17: =SUM(H18:H18) -> 1665810.7 | I17: =SUM(I18:I18) -> 6246722.4 | ... K17: =SUM(K18:K18) -> 15236106
A18: 1. Tesorería | B18: 7474691 | C18: 6022797 | D18: 5957110 | E18: 4235579 | F18: 6964253.9 | G18: ='Flujos de Caja'!B32 -> 767163.39 | H18: ='Flujos de Caja'!C32 -> 1665810.7 | I18: ='Flujos de Caja'!D32 -> 6246722.4 | J18: ='Flujos de Caja'!E32 -> 10704414 | K18: ='Flujos de Caja'!F32 -> 15236106
A19: TOTAL ACTIVO | B19: =B4+B11 -> 16611943 | C19: =C4+C11 -> 17159761 | D19: =D4+D11 -> 25352708 | E19: =E4+E11 -> 33068830 | F19: =F4+F11 -> 33775734 | G19: =G4+G11 -> 33462608 | H19: =H4+H11 -> 33491863 | I19: =I4+I11 -> 38231821 | ... K19: =K4+K11 -> 51007326
A21: ESTRUCTURA DEL PASIVO SOCIETARIO
A23: CONCEPTO | B23: 2018 | C23: 2019 | D23: 2020 | E23: 2021 | F23: 2022 | G23: X+1 | H23: X+2 | I23: X+3 | J23: X+4 | K23: X+5
A24: A) PATRIMONIO NETO | B24: =+B25+B31 -> 4745015 | C24: =+C25+C31 -> 5994774 | D24: =+D25+D31 -> 9487240 | E24: =+E25+E31 -> 7627299 | F24: =+F25+F31 -> 11316385 | G24: =+G25+G31 -> 15407944 | H24: =+H25+H31 -> 17302037 | I24: =+I25+I31 -> 19141521 | ... K24: =+K25+K31 -> 25686652
A25: A-1) Fondos propios | B25: =B26+B27+B28+B29+B30 -> 4745015 | C25: =C26+C27+C28+C29+C30 -> 5994774 | D25: =D26+D27+D28+D29+D30 -> 9487240 | E25: =E26+E27+E28+E29+E30 -> 7627299 | F25: =F26+F27+F28+F29+F30 -> 11316385 | G25: =G26+G27+G28+G29+G30 -> 15407944 | H25: =H26+H27+H28+H29+H30 -> 17302037 | I25: =I26+I27+I28+I29+I30 -> 19141521 | ... K25: =K26+K27+K28+K29+K30 -> 25686652
A26: I Capital | B26: 192320 | C26: 192320 | D26: 192320 | E26: 192320 | F26: 192320 | G26: 192320 | H26: 192320 | I26: 192320 | J26: 192320 | K26: 192320
A27: II Prima de emisión
A28: III Reservas | B28: 4074938 | C28: 4074937 | D28: 5802454 | E28: 2194921 | F28: 7434979.3 | G28: =F28 -> 7434979.3 | H28: =H29+H30 -> 8554858.5 | I28: =I29+I30 -> 9474600.7 | J28: =J29+J30 -> 10816568 | K28: =K29+K30 -> 12747166
A29: V Resultados de ejercicios anteriores | B29: 0 | G29: =F30 -> 3689085.3 | H29: =G30 -> 4091559.1 | I29: =H30 -> 4463299.4 | J29: =I30 -> 5011301.3 | K29: =J30 -> 5805266.4
A30: VII Resultado del ejercicio | B30: =+'Cuentas PyG'!B22 -> 477757 | C30: =+'Cuentas PyG'!C22 -> 1727517 | D30: =+'Cuentas PyG'!D22 -> 3492466 | E30: =+'Cuentas PyG'!E22 -> 5240058 | F30: 3689085.3 | G30: ='Proyeccion PYG'!G22 -> 4091559.1 | H30: ='Proyeccion PYG'!H22 -> 4463299.4 | I30: ='Proyeccion PYG'!I22 -> 5011301.3 | J30: ='Proyeccion PYG'!J22 -> 5805266.4 | K30: ='Proyeccion PYG'!K22 -> 6941899.6
A31: A-2) Subvenciones, donac. y legados recib.
A32: B) PASIVO NO CORRIENTE | B32: =B33+B34+B35+B36+B37 -> 479567 | C32: =C33+C34+C35+C36+C37 -> 477567 | D32: =D33+D34+D35+D36+D37 -> 309033 | E32: =E33+E34+E35+E36+E37 -> 289033 | F32: =F33+F34+F35+F36+F37 -> 219032.59 | G32: =G33+G34+G35+G36+G37 -> 251614.5 | H32: =H33+H34+H35+H36+H37 -> 266697.55 | I32: =I33+I34+I35+I36+I37 -> 281345.74 | ... K32: =K33+K34+K35+K36+K37 -> 333465.94
A33: I Provisiones a largo plazo | B33: 373620 | C33: 373620 | D33: 155086 | E33: 155086 | F33: 155085.54 | G33: 155085.54 | H33: 155085.54 | I33: 155085.54 | J33: 155085.54 | K33: 155085.54
A34: II Deudas a largo plazo | B34: 105947 | C34: 103947 | D34: 153947 | E34: 133947 | F34: 63947.05 | G34: =F34+G71*Hipotésis!E28 -> 96528.964 | H34: =G34+H71*Hipotésis!F28 -> 111612.01 | I34: =H34+I71*Hipotésis!G28 -> 126260.2 | J34: =I34+J71*Hipotésis!H28 -> 147632.91 | K34: =J34+K71*Hipotésis!I28 -> 178380.4
A35: III Deudas con empr. del grupo y asoc. a l.p.
A36: IV Pasivos por impuesto diferido
A37: V Periodificaciones a largo plazo
A38: C) PASIVO CORRIENTE | B38: =B39+B40+B41+B42+B43 -> 11387361 | C38: =C39+C40+C41+C42+C43 -> 10687420 | D38: =D39+D40+D41+D42+D43 -> 15556435 | E38: =E39+E40+E41+E42+E43 -> 13204530 | F38: =F39+F40+F41+F42+F43 -> 14107667 | G38: =G39+G40+G41+G42+G43 -> 9522343.2 | H38: =H39+H40+H41+H42+H43 -> 4947518.3 | I38: =I39+I40+I41+I42+I43 -> 4536384.3 | ... K38: =K39+K40+K41+K42+K43 -> 4233154.9
A39: II Provisiones a corto plazo | B39: 50046 | C39: 50046 | D39: 50046 | E39: 50046 | F39: 50045.88 | G39: =F39-('Proyeccion PYG'!G13) -> 42937.84 | H39: =G39-('Proyeccion PYG'!H13) -> 35829.8 | I39: =H39-('Proyeccion PYG'!I13) -> 28721.76 | J39: =I39-('Proyeccion PYG'!J13) -> 21613.72 | K39: =J39-('Proyeccion PYG'!K13) -> 14505.68
A40: III Deudas a corto plazo | E40: 304020
A41: IV Deudas empr. del grupo y asoc. a c.p. | B41: 422750 | C41: 1150016 | D41: 2131550 | E41: 0
A42: V Acreed. comerc.y otras cuentas a pagar | B42: 10914565 | C42: 9487358 | D42: 13374839 | E42: 12850464 | F42: 14057622 | G42: =('Proyeccion PYG'!G4+'PROYECCION BALANCE'!F12-G12)/365*Hipotésis!E15 -> 9479405.3 | H42: =(-'Proyeccion PYG'!H6+'PROYECCION BALANCE'!G12-H12)/365*Hipotésis!F15 -> 4911688.5 | I42: =(-'Proyeccion PYG'!I6+'PROYECCION BALANCE'!H12-I12)/365*Hipotésis!G15 -> 4507662.5 | J42: =(-'Proyeccion PYG'!J6+'PROYECCION BALANCE'!I12-J12)/365*Hipotésis!H15 -> 4288800.5 | K42: =(-'Proyeccion PYG'!K6+'PROYECCION BALANCE'!J12-K12)/365*Hipotésis!I15 -> 4218649.2
A43: VI Periodificaciones a corto plazo
...

Sheet Proyeccion PYG
A1: CUENTAS DE RESULTADOS
A3: CONCEPTO | B3: 2018 | C3: 2019 | D3: 2020 | E3: 2021 | F3: 2022 | G3: X+1 | H3: X+2 | I3: X+3 | J3: X+4 | K3: X+5
A4: 1. Importe neto de la cifra de negocios | B4: 30591119 | C4: 36275297 | D4: 62935532 | E4: 56940601 | F4: 50428334 | G4: =F4*(1+Hipotésis!E4) -> 46822931 | H4: =G4*(1+Hipotésis!F4) -> 45482780 | I4: =H4*(1+Hipotésis!G4) -> 46131010 | J4: =I4*(1+Hipotésis!H4) -> 48766295 | K4: =J4*(1+Hipotésis!I4) -> 53642924
A5: 3. Trabajos realiz. por la empr para su activo
A6: 4. Aprovisionamientos | B6: -24505756 | C6: -27907182 | D6: -51605596 | E6: -36341735 | F6: -29684170 | G6: =G4*Hipotésis!E5 -> -27200028 | H6: =H4*Hipotésis!F5 -> -26070021 | I6: =I4*Hipotésis!G5 -> -26085069 | J6: =J4*Hipotésis!H5 -> -27198335 | K6: =K4*Hipotésis!I5 -> -29503608
A7: 5. Otros ingresos de explotación | B7: 698523 | C7: 649332 | D7: 494498 | E7: 375024 | F7: 425953.06 | G7: 425953.06 | H7: 425953.06 | I7: 425953.06 | J7: 425953.06 | K7: 425953.06
A8: 6. Gastos de personal | B8: -4285464 | C8: -4848498 | D8: -4602955 | E8: -7589158 | F8: -8119738.8 | G8: =-G4*Hipotésis!E6 -> -7248766.8 | H8: =-H4*Hipotésis!F6 -> -6759161.5 | I8: =-I4*Hipotésis!G6 -> -6569340.1 | J8: =-J4*Hipotésis!H6 -> -6642119.6 | K8: =-K4*Hipotésis!I6 -> -6973580.2
A9: 7. Otros gastos de explotación | B9: -1804614 | C9: -1911955 | D9: -3014003 | E9: -7510299 | F9: -7493309.6 | G9: =-G4*Hipotésis!$B$34 -> -6957571.1 | H9: =-H4*Hipotésis!$B$34 -> -6758433.6 | I9: =-I4*Hipotésis!$B$34 -> -6854756.3 | J9: =-J4*Hipotésis!$B$34 -> -7246341.8 | K9: =-K4*Hipotésis!$B$34 -> -7970976
A10: 8. Amortización del inmovilizado | B10: -120233 | C10: -85764 | D10: -81324 | E10: -137269 | F10: -232311.04 | G10: =-('PROYECCION BALANCE'!G5+'PROYECCION BALANCE'!G6)*-Hipotésis!E7 -> -232311.04 | H10: =-('PROYECCION BALANCE'!H5+'PROYECCION BALANCE'!H6)*-Hipotésis!F7 -> -232311.04 | I10: =-('PROYECCION BALANCE'!I5+'PROYECCION BALANCE'!I6)*-Hipotésis!G7 -> -232311.04 | J10: =-('PROYECCION BALANCE'!J5+'PROYECCION BALANCE'!J6)*-Hipotésis!H7 -> -232311.04 | K10: =-('PROYECCION BALANCE'!K5+'PROYECCION BALANCE'!K6)*-Hipotésis!I7 -> -232311.04
A11: 9. Imputación de subv. de inmov. no financ.
A12: 10. Exceso de provisiones | D12: 498315
A13: 11. Deterioro y result. por enaj. del inmovilizado | B13: 3495 | C13: 6400 | D13: 5100 | E13: 17327 | F13: 7108.04 | G13: 7108.04 | H13: 7108.04 | I13: 7108.04 | J13: 7108.04 | K13: 7108.04
A14: 13. Otros resultados
A15: A1) RESULTADO DE EXPLOTACIÓN | B15: =B4+B5+B6+B7+B8+B9+B10+B11+B12+B13+B14 -> 577070 | C15: =C4+C5+C6+C7+C8+C9+C10+C11+C12+C13+C14 -> 2177630 | D15: =D4+D5+D6+D7+D8+D9+D10+D11+D12+D13+D14 -> 4629567 | E15: =E4+E5+E6+E7+E8+E9+E10+E11+E12+E13+E14 -> 5754491 | F15: =F4+F5+F6+F7+F8+F9+F10+F11+F12+F13+F14 -> 5331866.4 | G15: =G4+G5+G6+G7+G8+G9+G10+G11+G12+G13+G14 -> 5617314.8 | H15: =H4+H5+H6+H7+H8+H9+H10+H11+H12+H13+H14 -> 6095914.2 | I15: =I4+I5+I6+I7+I8+I9+I10+I11+I12+I13+I14 -> 6822594.5 | ... K15: =K4+K5+K6+K7+K8+K9+K10+K11+K12+K13+K14 -> 9395509.9
A16: 14. Ingresos financieros | B16: 153234 | C16: 149305 | D16: 180876 | E16: 1047640 | F16: 24261.41
A17: 15. Gastos financieros | B17: -184081 | C17: -19413 | D17: -158462 | E17: -36719 | F17: -197043.04 | G17: =-('PROYECCION BALANCE'!G34+'PROYECCION BALANCE'!G39)*Hipotésis!D44 -> -22371.656 | H17: =-('PROYECCION BALANCE'!H34+'PROYECCION BALANCE'!H39)*Hipotésis!E44 -> -5317.255 | I17: =-('PROYECCION BALANCE'!I34+'PROYECCION BALANCE'!I39)*Hipotésis!F44 -> -1328.4259 | J17: =-('PROYECCION BALANCE'!J34+'PROYECCION BALANCE'!J39)*Hipotésis!G44 -> -362.43162 | K17: =-('PROYECCION BALANCE'!K34+'PROYECCION BALANCE'!K39)*Hipotésis!H44 -> -112.69267
A18: 17. Diferencias de cambio | B18: 52992 | C18: 9423 | D18: 10612 | E18: -49131 | F18: -139531.05 | G18: -139531.05 | H18: -139531.05 | I18: -139531.05 | J18: -139531.05 | K18: -139531.05
A19: 18. Deterioro y result. por enaj. de instr. financ.
A20: A3) RESULTADO ANTES DE IMPUESTOS | B20: =B15+B16+B17+B18+B19 -> 599215 | C20: =C15+C16+C17+C18+C19 -> 2316945 | D20: =D15+D16+D17+D18+D19 -> 4662593 | E20: =E15+E16+E17+E18+E19 -> 6716281 | F20: =F15+F16+F17+F18+F19 -> 5019553.7 | G20: =G15+G16+G17+G18+G19 -> 5455412.1 | H20: =H15+H16+H17+H18+H19 -> 5951065.9 | I20: =I15+I16+I17+I18+I19 -> 6681735 | ... K20: =K15+K16+K17+K18+K19 -> 9255866.1
A21: 19. Impuestos sobre beneficios | B21: -121458 | C21: -589428 | D21: -1170127 | E21: -1476223 | F21: -1330468.4 | G21: =-MAX(0,G20)*Hipotésis!E8 -> -1363853 | H21: =-MAX(0,H20)*Hipotésis!F8 -> -1487766.5 | I21: =-MAX(0,I20)*Hipotésis!G8 -> -1670433.8 | J21: =-MAX(0,J20)*Hipotésis!H8 -> -1935088.8 | K21: =-MAX(0,K20)*Hipotésis!I8 -> -2313966.5
A22: A5) Resultado del ejercicio | B22: =B20+B21 -> 477757 | C22: =C20+C21 -> 1727517 | D22: =D20+D21 -> 3492466 | E22: =E20+E21 -> 5240058 | F22: =F20+F21 -> 3689085.3 | G22: =G20+G21 -> 4091559.1 | H22: =H20+H21 -> 4463299.4 | I22: =I20+I21 -> 5011301.3 | ... K22: =K20+K21 -> 6941899.6

Sheet Flujos de Caja
A1: DESGLOSE DEL FLUJO DE CAJA LIBRE
A3: CONCEPTO | B3: X+1 | C3: X+2 | D3: X+3 | E3: X+4 | F3: X+5
A4: EBITDA | B4: ='Proyeccion PYG'!G15-'Proyeccion PYG'!G13-'Proyeccion PYG'!G10 -> 5842517.8 | C4: ='Proyeccion PYG'!H15-'Proyeccion PYG'!H13-'Proyeccion PYG'!H10 -> 6321117.2 | D4: ='Proyeccion PYG'!I15-'Proyeccion PYG'!I13-'Proyeccion PYG'!I10 -> 7047797.5 | E4: ='Proyeccion PYG'!J15-'Proyeccion PYG'!J13-'Proyeccion PYG'!J10 -> 8105451.7 | F4: ='Proyeccion PYG'!K15-'Proyeccion PYG'!K13-'Proyeccion PYG'!K10 -> 9620712.9
A5: Dotación a la amortización | B5: ='Proyeccion PYG'!G10 -> -232311.04 | C5: ='Proyeccion PYG'!H10 -> -232311.04 | D5: ='Proyeccion PYG'!I10 -> -232311.04 | E5: ='Proyeccion PYG'!J10 -> -232311.04 | F5: ='Proyeccion PYG'!K10 -> -232311.04
A6: Imputación de subvención por inmovilizado
A7: EBIT | B7: =SUM(B4:B6) -> 5610206.7 | C7: =SUM(C4:C6) -> 6088806.1 | D7: =SUM(D4:D6) -> 6815486.5 | E7: =SUM(E4:E6) -> 7873140.6 | F7: =SUM(F4:F6) -> 9388401.8
A8: Impuestos ajustados | B8: =-MAX(0,B7)*Hipotésis!E8 -> -1402551.7 | C8: =-MAX(0,C7)*Hipotésis!F8 -> -1522201.5 | D8: =-MAX(0,D7)*Hipotésis!G8 -> -1703871.6 | E8: =-MAX(0,E7)*Hipotésis!H8 -> -1968285.2 | F8: =-MAX(0,F7)*Hipotésis!I8 -> -2347100.5
A9: NOPLAT | B9: =SUM(B7:B8) -> 4207655.1 | C9: =SUM(C7:C8) -> 4566604.6 | D9: =SUM(D7:D8) -> 5111614.9 | E9: =SUM(E7:E8) -> 5904855.5 | F9: =SUM(F7:F8) -> 7041301.4
A10: Dotación a la amortización | B10: =-B5 -> 232311.04 | C10: =-C5 -> 232311.04 | D10: =-D5 -> 232311.04 | E10: =-E5 -> 232311.04 | F10: =-F5 -> 232311.04
A11: Imputación de subvención por inmovilizado | B11: =-B6 -> 0 | C11: =-C6 -> 0 | D11: =-D6 -> 0 | E11: =-E6 -> 0 | F11: =-F6 -> 0
A12: CAPEX | B12: =-'PROYECCION BALANCE'!G64 -> -141931.76 | C12: =-'PROYECCION BALANCE'!H64 -> -198716.49 | D12: =-'PROYECCION BALANCE'!I64 -> -248560.7 | E12: =-'PROYECCION BALANCE'!J64 -> -298371.66 | F12: =-'PROYECCION BALANCE'!K64 -> -354557.08
A13: Var. Fondo de maniobra necesario | B13: =-'PROYECCION BALANCE'!G55 -> -10552560 | C13: =-'PROYECCION BALANCE'!H55 -> -3731919.6 | D13: =-'PROYECCION BALANCE'!I55 -> -546822.29 | E13: =-'PROYECCION BALANCE'!J55 -> -1429514 | F13: =-'PROYECCION BALANCE'!K55 -> -2457314.4
A14: FLUJO DE CAJA LIBRE | B14: =SUM(B9:B13) -> -6254525.8 | C14: =SUM(C9:C13) -> 868279.53 | D14: =SUM(D9:D13) -> 4548542.9 | E14: =SUM(E9:E13) -> 4409280.8 | F14: =SUM(F9:F13) -> 4461740.9
A16: DESGLOSE DEL FLUJO DE CAJA LIBRE PARA EL ACCIONISTA
A18: CONCEPTO | B18: X+1 | C18: X+2 | D18: X+3 | E18: X+4 | F18: X+5
A19: FLUJO DE CAJA LIBRE | B19: =B14 -> -6254525.8 | C19: =C14 -> 868279.53 | D19: =D14 -> 4548542.9 | E19: =E14 -> 4409280.8 | F19: =F14 -> 4461740.9
A20: Gastos financieros | B20: ='Proyeccion PYG'!G17 -> -22371.656 | C20: ='Proyeccion PYG'!H17 -> -5317.255 | D20: ='Proyeccion PYG'!I17 -> -1328.4259 | E20: ='Proyeccion PYG'!J17 -> -362.43162 | F20: ='Proyeccion PYG'!K17 -> -112.69267
A21: Escudo fiscal | B21: =MAX(0,MIN(-B20,B7))*[1]Hipótesis!E13 -> 5592.9139 | C21: =MAX(0,MIN(-C20,C7))*[1]Hipótesis!F13 -> 1329.3138 | D21: =MAX(0,MIN(-D20,D7))*[1]Hipótesis!G13 -> 332.10648 | E21: =MAX(0,MIN(-E20,E7))*[1]Hipótesis!H13 -> 90.607904 | F21: =MAX(0,MIN(-F20,F7))*[1]Hipótesis!I13 -> 28.173168
A22: Incremento/amortización de Deuda | B22: ='PROYECCION BALANCE'!G71 -> 74214.059 | C22: ='PROYECCION BALANCE'!H71 -> 34355.693 | D22: ='PROYECCION BALANCE'!I71 -> 33365.18 | E22: ='PROYECCION BALANCE'!J71 -> 48682.087 | F22: ='PROYECCION BALANCE'!K71 -> 70035.669
A23: FLUJO PARA LOS ACCIONISTAS | B23: =SUM(B19:B22) -> -6197090.5 | C23: =SUM(C19:C22) -> 898647.28 | D23: =SUM(D19:D22) -> 4580911.8 | E23: =SUM(E19:E22) -> 4457691.1 | F23: =SUM(F19:F22) -> 4531692.1
A25: SALDO CONTABLE DE CAJA
A27: CONCEPTO | B27: X+1 | C27: X+2 | D27: X+3 | E27: X+4 | F27: X+5
A28: Saldo de caja del ejercicio anterior | B28: ='PROYECCION BALANCE'!F17 -> 6964253.9 | C28: ='PROYECCION BALANCE'!G17 -> 767163.39 | D28: ='PROYECCION BALANCE'!H17 -> 1665810.7 | E28: ='PROYECCION BALANCE'!I17 -> 6246722.4 | F28: ='PROYECCION BALANCE'!J17 -> 10704414
A29: Flujo de caja libre para los accionistas | B29: =B23 -> -6197090.5 | C29: =C23 -> 898647.28 | D29: =D23 -> 4580911.8 | E29: =E23 -> 4457691.1 | F29: =F23 -> 4531692.1
A30: Aportaciones accionistas
A31: Dividendos repartidos
A32: SALDO DE CAJA DEL EJERCICIO | B32: =SUM(B28:B31) -> 767163.39 | C32: =SUM(C28:C31) -> 1665810.7 | D32: =SUM(D28:D31) -> 6246722.4 | E32: =SUM(E28:E31) -> 10704414 | F32: =SUM(F28:F31) -> 15236106

Sheet Balances
A1: ESTRUCTURA DEL ACTIVO SOCIETARIO
G2: Ajuste
A3: CONCEPTO | B3: 2018 | C3: 2019 | D3: 2020 | E3: 2021 | F3: 2022
A4: A) ACTIVO NO CORRIENTE | B4: =B5+B6+B7+B8+B9+B10 -> 859099 | C4: =C5+C6+C7+C8+C9+C10 -> 1556623 | D4: =D5+D6+D7+D8+D9+D10 -> 1403778 | E4: =E5+E6+E7+E8+E9+E10 -> 2730187 | F4: =F5+F6+F7+F8+F9+F10 -> 2700262.5 | G4: =G5+G6+G7+G8+G9+G10 -> 6014559.9 | K4: ESTIMACIÓN DEL COSTE DEL CAPITAL MEDIO PONDERADO
A5: I Inmovilizado intangible | B5: 55358 | C5: 38181 | D5: 25372 | E5: 71520 | F5: 137063.78 | G5: =137063.78+823 -> 137886.78
A6: II Inmovilizado material | B6: 306410 | C6: 353563 | D6: 693753 | E6: 1106294 | F6: 1127060.2 | G6: 1127060.2 | K6: COSTE DE LOS FONDOS PROPIOS CAESA | N6: COSTE DE LA DEUDA FINANCIERA | R6: COSTE DEL CAPITAL MEDIO PONDERADO
A7: III Inv. Inmobiliarias | B7: 0 | C7: 0 | D7: 0 | E7: 0 | F7: 0 | G7: 0
A8: IV Inv. en empr. del grupo y asociadas a l.p. | B8: 180000 | C8: 180000 | D8: 180000 | E8: 180000 | F8: 180000 | G8: =3313474.38+F8 -> 3493474.4 | K8: Tipo sin riesgo | L8: 0.035 | N8: kd | P8: 0 | R8: DF/(DF+E) | T8: =G34/(G34+G24) -> 0.0043519732
A9: V Inversiones financieras a largo plazo | B9: 130945 | C9: 658072 | D9: 236958 | E9: 1073260 | F9: 967272.43 | G9: 967272.43 | K9: Prima de mercado | L9: 0.066 | N9: kd desp. impuestos | P9: =P8*(1-P12) -> 0 | R9: DF/E | T9: =T8/(1-T8) -> 0.0043709956
A10: VI Activos por impuesto diferido | B10: 186386 | C10: 326807 | D10: 267695 | E10: 299113 | F10: 288866.14 | G10: 288866.14
A11: B) ACTIVO CORRIENTE | B11: =B12+B13+B14+B15+B16+B17 -> 15752844 | C11: =C12+C13+C14+C15+C16+C17 -> 15603138 | D11: =D12+D13+D14+D15+D16+D17 -> 23948930 | E11: =E12+E13+E14+E15+E16+E17 -> 18390675 | F11: =F12+F13+F14+F15+F16+F17 -> 22942822 | G11: =G12+G13+G14+G15+G16+G17 -> 22942822 | K11: Beta desapalancada | L11: =P72 -> 0.79 | R11: WACC | T11: =L16*(1-T8)+P9*T8 -> 0.10684391
A12: II Existencias | K12: Beta reapalancada | L12: =L11*(1+T9*(1-P12)) -> 0.79258981 | N12: Tipo impositivo | P12: 0.25
A13: III Deudores comerc. y otras cuentas a cobr. | B13: 7499543 | C13: 9085867 | D13: 15132470 | E13: 13904393 | F13: 11729940 | G13: 11729940
A14: IV Inv. en empr. del grupo y asociadas a c.p. | F14: 3913618.7 | G14: 3913618.7 | K14: Prima de liquidez | L14: 0.02
A15: V Inversiones financieras a corto plazo | B15: 778610 | C15: 494474 | D15: 2859350 | E15: 250703 | F15: 335009.77 | G15: 335009.77
A16: VI Periodificaciones a corto plazo | K16: ke | L16: =L8+L9*L12+L14 -> 0.10731093
A17: VII Efectivo y otros activos líquidos equiv. | B17: =SUM(B18:B18) -> 7474691 | C17: =SUM(C18:C18) -> 6022797 | D17: =SUM(D18:D18) -> 5957110 | E17: =SUM(E18:E18) -> 4235579 | F17: =SUM(F18:F18) -> 6964253.9 | G17: =SUM(G18:G18) -> 6964253.9
A18: 1. Tesorería | B18: 7474691 | C18: 6022797 | D18: 5957110 | E18: 4235579 | F18: 6964253.9 | G18: 6964253.9 | K18: Kd | L18: considermaos que todo se fiancia con fondos propios, deuda es minima.
A19: TOTAL ACTIVO | B19: =B4+B11 -> 16611943 | C19: =C4+C11 -> 17159761 | D19: =D4+D11 -> 25352708 | E19: =E4+E11 -> 21120862 | F19: =F4+F11 -> 25643085 | G19: =G4+G11 -> 28957382
A21: ESTRUCTURA DEL PASIVO SOCIETARIO
A23: CONCEPTO | B23: 2018 | C23: 2019 | D23: 2020 | E23: 2021 | F23: 2022 | G23: Ajuste
A24: A) PATRIMONIO NETO | B24: =+B25+B31 -> 4745015 | C24: =+C25+C31 -> 5994774 | D24: =+D25+D31 -> 9487240 | E24: =+E25+E31 -> 7627299 | F24: =+F25+F31 -> 11316385 | G24: =+G25+G31 -> 14629859
A25: A-1) Fondos propios | B25: =B26+B27+B28+B29+B30 -> 4745015 | C25: =C26+C27+C28+C29+C30 -> 5994774 | D25: =D26+D27+D28+D29+D30 -> 9487240 | E25: =E26+E27+E28+E29+E30 -> 7627299 | F25: =F26+F27+F28+F29+F30 -> 11316385 | G25: =G26+G27+G28+G29+G30 -> 14629859
A26: I Capital | B26: 192320 | C26: 192320 | D26: 192320 | E26: 192320 | F26: 192320 | G26: ='PyG ALAER'!B36+F26 -> 3505794.4
A27: II Prima de emisión
A28: III Reservas | B28: 4074938 | C28: 4074937 | D28: 5802454 | E28: 2194921 | F28: 7434979.3 | G28: 7434979.3
A29: V Resultados de ejercicios anteriores | B29: 0
A30: VII Resultado del ejercicio | B30: =+'Cuentas PyG'!B22 -> 477757 | C30: =+'Cuentas PyG'!C22 -> 1727517 | D30: =+'Cuentas PyG'!D22 -> 3492466 | E30: =+'Cuentas PyG'!E22 -> 5240058 | F30: 3689085.3 | G30: 3689085.3
A31: A-2) Subvenciones, donac. y legados recib.
A32: B) PASIVO NO CORRIENTE | B32: =B33+B34+B35+B36+B37 -> 479567 | C32: =C33+C34+C35+C36+C37 -> 477567 | D32: =D33+D34+D35+D36+D37 -> 309033 | E32: =E33+E34+E35+E36+E37 -> 289033 | F32: =F33+F34+F35+F36+F37 -> 219032.59 | G32: =G33+G34+G35+G36+G37 -> 219032.59
A33: I Provisiones a largo plazo | B33: 373620 | C33: 373620 | D33: 155086 | E33: 155086 | F33: 155085.54 | G33: 155085.54
A34: II Deudas a largo plazo | B34: 105947 | C34: 103947 | D34: 153947 | E34: 133947 | F34: 63947.05 | G34: 63947.05
A35: III Deudas con empr. del grupo y asoc. a l.p.
A36: IV Pasivos por impuesto diferido
A37: V Periodificaciones a largo plazo
A38: C) PASIVO CORRIENTE | B38: =B39+B40+B41+B42+B43 -> 11387361 | C38: =C39+C40+C41+C42+C43 -> 10687420 | D38: =D39+D40+D41+D42+D43 -> 15556435 | E38: =E39+E40+E41+E42+E43 -> 13204530 | F38: =F39+F40+F41+F42+F43 -> 14107667 | G38: =G39+G40+G41+G42+G43 -> 14107667
A39: II Provisiones a corto plazo | B39: 50046 | C39: 50046 | D39: 50046 | E39: 50046 | F39: 50045.88 | G39: 50045.88
A40: III Deudas a corto plazo | E40: 304020
A41: IV Deudas empr. del grupo y asoc. a c.p. | B41: 422750 | C41: 1150016 | D41: 2131550 | E41: 0
A42: V Acreed. comerc.y otras cuentas a pagar | B42: 10914565 | C42: 9487358 | D42: 13374839 | E42: 12850464 | F42: 14057622 | G42: 14057622
...

Sheet Cuentas PyG
A1: ESTUCTURA DE LA CUENTA DE RESULTADOS
A3: CONCEPTO | B3: 2018 | C3: 2019 | D3: 2020 | E3: 2021 | F3: 2022
A4: 1. Importe neto de la cifra de negocios | B4: 30591119 | C4: 36275297 | D4: 62935532 | E4: 56940601 | F4: 50428334
A5: 3. Trabajos realiz. por la empr para su activo
A6: 4. Aprovisionamientos | B6: -24505756 | C6: -27907182 | D6: -51605596 | E6: -36341735 | F6: -29684170 | G6: =D6/D4 -> -0.81997553 | H6: =E6/E4 -> -0.6382394 | I6: =F6/F4 -> -0.58864069
A7: 5. Otros ingresos de explotación | B7: 698523 | C7: 649332 | D7: 494498 | E7: 375024 | F7: 425953.06
A8: 6. Gastos de personal | B8: -4285464 | C8: -4848498 | D8: -4602955 | E8: -7589158 | F8: -8119738.8
A9: 7. Otros gastos de explotación | B9: -1804614 | C9: -1911955 | D9: -3014003 | E9: -7510299 | F9: -7493309.6 | G9: =D9/D4 -> -0.047890324 | H9: =E9/E4 -> -0.13189708 | I9: =F9/F4 -> -0.14859324
A10: 8. Amortización del inmovilizado | B10: -120233 | C10: -85764 | D10: -81324 | E10: -137269 | F10: -232311.04
A11: 9. Imputación de subv. de inmov. no financ.
A12: 10. Exceso de provisiones | D12: 498315 | H12: y otros
A13: 11. Deterioro y result. por enaj. del inmovilizado | B13: 3495 | C13: 6400 | D13: 5100 | E13: 17327 | F13: 7108.04
A14: 13. Otros resultados
A15: A1) RESULTADO DE EXPLOTACIÓN | B15: =B4+B5+B6+B7+B8+B9+B10+B11+B12+B13+B14 -> 577070 | C15: =C4+C5+C6+C7+C8+C9+C10+C11+C12+C13+C14 -> 2177630 | D15: =D4+D5+D6+D7+D8+D9+D10+D11+D12+D13+D14 -> 4629567 | E15: =E4+E5+E6+E7+E8+E9+E10+E11+E12+E13+E14 -> 5754491 | F15: =F4+F5+F6+F7+F8+F9+F10+F11+F12+F13+F14 -> 5331866.4
A16: 14. Ingresos financieros | B16: 153234 | C16: 149305 | D16: 180876 | E16: 1047640 | F16: 24261.41
A17: 15. Gastos financieros | B17: -184081 | C17: -19413 | D17: -158462 | E17: -36719 | F17: -197043.04
A18: 17. Diferencias de cambio | B18: 52992 | C18: 9423 | D18: 10612 | E18: -49131 | F18: -139531.05
A19: 18. Deterioro y result. por enaj. de instr. financ.
A20: A3) RESULTADO ANTES DE IMPUESTOS | B20: =B15+B16+B17+B18+B19 -> 599215 | C20: =C15+C16+C17+C18+C19 -> 2316945 | D20: =D15+D16+D17+D18+D19 -> 4662593 | E20: =E15+E16+E17+E18+E19 -> 6716281 | F20: =F15+F16+F17+F18+F19 -> 5019553.7
A21: 19. Impuestos sobre beneficios | B21: -121458 | C21: -589428 | D21: -1170127 | E21: -1476223 | F21: -1330468.4
A22: A5) Resultado del ejercicio | B22: =B20+B21 -> 477757 | C22: =C20+C21 -> 1727517 | D22: =D20+D21 -> 3492466 | E22: =E20+E21 -> 5240058 | F22: =F20+F21 -> 3689085.3

Sheet PyG ALAER
A1: ESTUCTURA DE LA CUENTA DE RESULTADOS
A3: CONCEPTO | B3: 2018 | C3: 2019 | D3: 2020 | E3: 2021 | F3: 2022
A4: 1. Importe neto de la cifra de negocios | B4: 14175032 | C4: 15084250 | D4: 10507821 | E4: 9339767 | F4: 7225733 | H4: =(F4-E4)/E4 -> -0.22634762
A5: 3. Trabajos realiz. por la empr para su activo
A6: 4. Aprovisionamientos | B6: -3078853 | C6: -2774939 | D6: -907800 | E6: -1244850 | F6: -2212833
A7: 5. Otros ingresos de explotación | D7: 520147
A8: 6. Gastos de personal | B8: -6498849 | C8: -7549155 | D8: -6752584 | E8: -4186778 | F8: -2784096 | G8: =E8/$E$4 -> -0.44827435 | H8: =F8/$F$4 -> -0.38530292
A9: 7. Otros gastos de explotación | B9: -4197927 | C9: -4422426 | D9: -3308146 | E9: -3521544 | F9: -1855704 | G9: =E9/$E$4 -> -0.37704838 | H9: =F9/$F$4 -> -0.25681879
A10: 8. Amortización del inmovilizado | B10: -39922 | C10: -35544 | D10: -34474 | E10: -35202 | F10: -16687
A11: 9. Imputación de subv. de inmov. no financ. | B11: 1333 | C11: 1600 | D11: 1600 | E11: 1600 | F11: 1867
A12: 10. Exceso de provisiones | E12: 773114
A13: 11. Deterioro y result. por enaj. del inmovilizado | B13: 2956
A14: 13. Otros resultados
A15: A1) RESULTADO DE EXPLOTACIÓN | B15: =B4+B5+B6+B7+B8+B9+B10+B11+B12+B13+B14 -> 363770 | C15: =C4+C5+C6+C7+C8+C9+C10+C11+C12+C13+C14 -> 303786 | D15: =D4+D5+D6+D7+D8+D9+D10+D11+D12+D13+D14 -> 26564 | E15: =E4+E5+E6+E7+E8+E9+E10+E11+E12+E13+E14 -> 1126107 | F15: =F4+F5+F6+F7+F8+F9+F10+F11+F12+F13+F14 -> 358280
A16: 14. Ingresos financieros | B16: 2411 | C16: 21462 | D16: 33506 | E16: 19412 | F16: 82
A17: 15. Gastos financieros | B17: -18275 | C17: -730 | D17: -25448 | E17: -20034 | F17: -4866
A18: 17. Diferencias de cambio | D18: -4856 | F18: -4
A19: 18. Deterioro y result. por enaj. de instr. financ.
A20: A3) RESULTADO ANTES DE IMPUESTOS | B20: =B15+B16+B17+B18+B19 -> 347906 | C20: =C15+C16+C17+C18+C19 -> 324518 | D20: =D15+D16+D17+D18+D19 -> 29766 | E20: =E15+E16+E17+E18+E19 -> 1125485 | F20: =F15+F16+F17+F18+F19 -> 353492
A21: 19. Impuestos sobre beneficios | B21: -87655 | C21: -81506 | D21: -7546 | E21: -278149 | F21: -92249
A22: A5) Resultado del ejercicio | B22: =B20+B21 -> 260251 | C22: =C20+C21 -> 243012 | D22: =D20+D21 -> 22220 | E22: =E20+E21 -> 847336 | F22: =F20+F21 -> 261243
A27: EBITDA | B27: =F15-F10 -> 374967 | I27: Ticker | J27: Company Name | K27: Global Region | L27: Country | M27: Industry | N27: Trailing TEV/EBITDA (2022)
A28: EV/EBITDA | B28: =N48 -> 8.14 | I28: ALA | J28: A.L.A. società per azioni | K28: Europe | L28: ITA | M28: Air Freight and Logistics | N28: 10.7
A29: EV BODEGA | B29: =+B27*B28 -> 3052231.4 | I29: ALCLA | J29: Clasquin SA | K29: Europe | L29: FRA | M29: Air Freight and Logistics | N29: 5.82
A30: DEUDA FINANCIERA | B30: 0 | I30: AQ | J30: Aquila Part Prod Com S.A. | K30: Europe | L30: ROU | M30: Air Freight and Logistics | N30: 8.08
A31: TESORERIA | B31: =[2]Balances!F30 -> 261243 | I31: BPOST | J31: bpost NV/SA | K31: Europe | L31: BEL | M31: Air Freight and Logistics | N31: 3.26
A32: ACTIVOS NO OPERATIVOS | B32: =+[2]Balances!B7 -> 0 | I32: CTT | J32: CTT - Correios De Portugal, S.A. | K32: Europe | L32: PRT | M32: Air Freight and Logistics | N32: 1.69
A33: EQUITY VALUE BODEGA | B33: =SUM(B29:B32) -> 3313474.4 | I33: DE1 | J33: Deufol SE | K33: Europe | L33: DEU | M33: Air Freight and Logistics | N33: 9.08
A34: Participación 100% HOLDING | B34: =+B33 -> 3313474.4 | I34: DPW | J34: Deutsche Post AG | K34: Europe | L34: DEU | M34: Air Freight and Logistics | N34: 6.98
A35: Valor contable | B35: 0 | I35: IDS | J35: International Distributions Services plc | K35: Europe | L35: GBR | M35: Air Freight and Logistics | N35: 2.97
A36: Plusvalía participación | B36: =+B34-B35 -> 3313474.4 | C36: Inversion en empresas | I36: IEKG | J36: Intereuropa, d. d. | K36: Europe | L36: SVN | M36: Air Freight and Logistics | N36: 6.15
I37: JETPAK | J37: Jetpak Top Holding AB (publ) | K37: Europe | L37: SWE | M37: Air Freight and Logistics | N37: 10.4
I38: LOG | J38: Compañía de Distribución Integral Logista Holdings, S.A. | K38: Europe | L38: ESP | M38: Air Freight and Logistics | N38: 4.52
I39: MTP | J39: MaltaPost p.l.c. | K39: Europe | L39: MLT | M39: Air Freight and Logistics | N39: 8.2
I40: NLG1V | J40: Nurminen Logistics Oyj | K40: Europe | L40: FIN | M40: Air Freight and Logistics | N40: 8.73
I41: PNL | J41: PostNL N.V. | K41: Europe | L41: NLD | M41: Air Freight and Logistics | N41: 3.52
I42: POST | J42: Österreichische Post AG | K42: Europe | L42: AUT | M42: Air Freight and Logistics | N42: 10.32
I43: SPDY | J43: Speedy AD | K43: Europe | L43: BGR | M43: Air Freight and Logistics | N43: 9.19
I44: TGHN | J44: Logwin AG | K44: Europe | L44: DEU | M44: Air Freight and Logistics | N44: 4.58
I45: WIN | J45: Wincanton plc | K45: Europe | L45: GBR | M45: Air Freight and Logistics | N45: 8.28
...

Sheet Balance ALAER
A2: ESTRUCTURA DEL PASIVO SOCIETARIO
A4: CONCEPTO | B4: 2018 | C4: 2019 | D4: 2020 | E4: 2021 | F4: 2022
A5: A) PATRIMONIO NETO | B5: =+B6+B12 -> 692369 | C5: =+C6+C12 -> 951021 | D5: =+D6+D12 -> 1192434 | E5: =+E6+E12 -> 242109 | F5: =+F6+F12 -> 1087579
A6: A-1) Fondos propios | B6: =B7+B8+B9+B10+B11 -> 685702 | C6: =C7+C8+C9+C10+C11 -> 945954 | D6: =D7+D8+D9+D10+D11 -> 1188967 | E6: =E7+E8+E9+E10+E11 -> 240242 | F6: =F7+F8+F9+F10+F11 -> 1087579
A7: I Capital | B7: 180000 | C7: 180000 | D7: 180000 | E7: 180000 | F7: 180000
A8: II Prima de emisión
A9: III Reservas | B9: 503684 | C9: 503684 | D9: 746696 | E9: 58221 | F9: 905557
A10: V Resultados de ejercicios anteriores | C10: 260251 | D10: 260251
A11: VII Resultado del ejercicio | B11: =+'[2]Cuentas PyG'!B3 -> 2018 | C11: =+'[2]Cuentas PyG'!C3 -> 2019 | D11: =+'[2]Cuentas PyG'!D3 -> 2020 | E11: =+'[2]Cuentas PyG'!E3 -> 2021 | F11: =+'[2]Cuentas PyG'!F3 -> 2022
A12: A-2) Subvenciones, donac. y legados recib. | B12: 6667 | C12: 5067 | D12: 3467 | E12: 1867
A13: B) PASIVO NO CORRIENTE | B13: =B14+B15+B16+B17+B18 -> 0 | C13: =C14+C15+C16+C17+C18 -> 0 | D13: =D14+D15+D16+D17+D18 -> 0 | E13: =E14+E15+E16+E17+E18 -> 0 | F13: =F14+F15+F16+F17+F18 -> 0
A14: I Provisiones a largo plazo
A15: II Deudas a largo plazo
A16: III Deudas con empr. del grupo y asoc. a l.p.
A17: IV Pasivos por impuesto diferido
A18: V Periodificaciones a largo plazo
A19: C) PASIVO CORRIENTE | B19: =B20+B21+B22+B23+B24 -> 5720697 | C19: =C20+C21+C22+C23+C24 -> 5608494 | D19: =D20+D21+D22+D23+D24 -> 4053448 | E19: =E20+E21+E22+E23+E24 -> 2147988 | F19: =F20+F21+F22+F23+F24 -> 2590981
A20: II Provisiones a corto plazo
A21: III Deudas a corto plazo
A22: IV Deudas empr. del grupo y asoc. a c.p. | B22: 918747 | C22: 1032055 | D22: 1069071
A23: V Acreed. comerc.y otras cuentas a pagar | B23: 4801950 | C23: 4576439 | D23: 2984377 | E23: 2147988 | F23: 2590981
A24: VI Periodificaciones a corto plazo
A25: TOTAL PATRIMONIO NETO Y PASIVO | B25: =B5+B13+B19 -> 6413066 | C25: =C5+C13+C19 -> 6559515 | D25: =D5+D13+D19 -> 5245882 | E25: =E5+E13+E19 -> 2390097 | F25: =F5+F13+F19 -> 3678560
