Workbook
Name DEUDA_INI: [1]Cuadro_vencimientos_y_devengos!$I$5
Name INTERÉS: [1]Cuadro_vencimientos_y_devengos!$J$5
Name IVA: 'Cuenta de Resultados'!#REF!
Name RET_TRABAJO: 'Cuenta de Resultados'!#REF!
Name RETENCIÓN: 'Cuenta de Resultados'!#REF!
Name SS_EMPRESA: 'Cuenta de Resultados'!#REF!
Name SS_TRABAJADOR: 'Cuenta de Resultados'!#REF!

Sheet Cuenta de Resultados
A1: CUENTA DE RESULTADOS
B4: CUENTA DE RESULTADOS DE EXPLOTACIÓN | C4: NOV A-1 | D4: DIC A-1 | E4: ENE | F4: FEB | G4: MAR | H4: ABR | I4: MAY | J4: JUN | K4: JUL | L4: AGO | M4: SEP | N4: OCT | O4: NOV | P4: DIC | R4: FY
B5: INGRESOS POR VENTAS | C5: 383000 | D5: 229000 | E5: 252000 | F5: 258000 | G5: 312000 | H5: 299000 | I5: 313000 | J5: 236000 | K5: 325000 | L5: 266000 | M5: 359000 | N5: 265000 | O5: 317000 | P5: 282000 | R5: =+SUM(E5:P5) -> 3484000
B6: Sueldos y Salarios | C6: -42500 | D6: -42500 | E6: -57500 | F6: -57500 | G6: -57500 | H6: -57500 | I6: -57500 | J6: -57500 | K6: -57500 | L6: -57500 | M6: -57500 | N6: -57500 | O6: -57500 | P6: -57500 | R6: =+SUM(E6:P6) -> -690000 | T6: El salario anual se divide en 14 pagas, teniendo paga extra los meses de julio y diciembre.
B7: Bonus e Incentivos | C7: =+C6*0.2 -> -8500 | D7: =+D6*0.2 -> -8500 | E7: =+E6*0.2 -> -11500 | F7: =+F6*0.2 -> -11500 | G7: =+G6*0.2 -> -11500 | H7: =+H6*0.2 -> -11500 | I7: =+I6*0.2 -> -11500 | J7: =+J6*0.2 -> -11500 | ... P7: =+P6*0.2 -> -11500 | R7: =+SUM(E7:P7) -> -138000 | T7: Los bonus e incentivos por objetivos se cobran en el mes de febrero.
B8: Seguridad Social Empresa | C8: =+(C7+C6*0.3) -> -21250 | D8: =+(D7+D6*0.3) -> -21250 | E8: =+(E7+E6*0.3) -> -28750 | F8: =+(F7+F6*0.3) -> -28750 | G8: =+(G7+G6*0.3) -> -28750 | H8: =+(H7+H6*0.3) -> -28750 | I8: =+(I7+I6*0.3) -> -28750 | J8: =+(J7+J6*0.3) -> -28750 | ... P8: =+(P7+P6*0.3) -> -28750 | R8: =+SUM(E8:P8) -> -345000
B9: COSTES DE PERSONAL | C9: =SUM(C6:C8) -> -72250 | D9: =SUM(D6:D8) -> -72250 | E9: =SUM(E6:E8) -> -97750 | F9: =SUM(F6:F8) -> -97750 | G9: =SUM(G6:G8) -> -97750 | H9: =SUM(H6:H8) -> -97750 | I9: =SUM(I6:I8) -> -97750 | J9: =SUM(J6:J8) -> -97750 | ... P9: =SUM(P6:P8) -> -97750 | R9: =+SUM(E9:P9) -> -1173000
B10: Compra de materias primas | C10: -54000 | D10: -49000 | E10: -48000 | F10: -56000 | G10: -47500 | H10: -58000 | I10: -56000 | J10: -62000 | K10: -47000 | L10: -35000 | M10: -42000 | N10: -38000 | O10: -41000 | P10: -47000 | R10: =+SUM(E10:P10) -> -577500 | T10: Un tercio de nuestros proveedores son empresas cuyos plazos de pago están amparados por la legislación comercial de protección a pequeñas empresas por lo que son a 30 días. Todos aplican un 21% de IVA. El resto de los proveedores tiene plazos de pago entre 45 y 90 días.
B11: Compra de otros materiales para producción | C11: -32000 | D11: -29000 | E11: -28000 | F11: -26000 | G11: -24000 | H11: -25000 | I11: -23000 | J11: -19000 | K11: -21000 | L11: -17000 | M11: -12000 | N11: -16000 | O11: -17000 | P11: -19000 | R11: =+SUM(E11:P11) -> -247000
B12: COMPRAS A PROVEEDORES | C12: =SUM(C10:C11) -> -86000 | D12: =SUM(D10:D11) -> -78000 | E12: =SUM(E10:E11) -> -76000 | F12: =SUM(F10:F11) -> -82000 | G12: =SUM(G10:G11) -> -71500 | H12: =SUM(H10:H11) -> -83000 | I12: =SUM(I10:I11) -> -79000 | J12: =SUM(J10:J11) -> -81000 | ... P12: =SUM(P10:P11) -> -66000 | R12: =+SUM(E12:P12) -> -824500
B13: Alquileres | C13: -16500 | D13: -16500 | E13: -18000 | F13: -18000 | G13: -18000 | H13: -18000 | I13: -18000 | J13: -18000 | K13: -18000 | L13: -18000 | M13: -18000 | N13: -18000 | O13: -18000 | P13: -18000 | R13: =+SUM(E13:P13) -> -216000 | T13: Se pagan por anticipado entre el 1 y el 5 de cada mes.
B14: Serv. Profesionales Independientes | C14: -4000 | D14: -4000 | E14: -16000 | F14: -4000 | G14: -4000 | H14: -6000 | I14: -4000 | J14: -4000 | K14: -6000 | L14: -4000 | M14: -4000 | N14: -6000 | O14: -4000 | P14: -4000 | R14: =+SUM(E14:P14) -> -66000 | T14: Se pagan a 30 días
B15: Transporte | C15: -19150 | D15: -11450 | E15: -12600 | F15: -12900 | G15: -15600 | H15: -14950 | I15: -15650 | J15: -11800 | K15: -16250 | L15: -13300 | M15: -17950 | N15: -13250 | O15: -15850 | P15: -14100 | R15: =+SUM(E15:P15) -> -174200 | T15: Se pagan a 30 días
B16: Seguros | C16: -3750 | D16: -3750 | E16: -3750 | F16: -3750 | G16: -3750 | H16: -3750 | I16: -3750 | J16: -3750 | K16: -3750 | L16: -3750 | M16: -3750 | N16: -3750 | O16: -3750 | P16: -3750 | R16: =+SUM(E16:P16) -> -45000 | T16: La póliza anual de seguros se renueva en febrero
B17: Publicidad y Márketing | C17: -2500 | D17: -7500 | E17: -2500 | F17: -2500 | G17: -2500 | H17: -2500 | I17: -2500 | J17: -2500 | K17: -2500 | L17: -2500 | M17: -2500 | N17: -2500 | O17: -2500 | P17: -7500 | R17: =+SUM(E17:P17) -> -35000 | T17: Se pagan a 30 días
B18: Suministros | C18: -4500 | D18: -4500 | E18: -4500 | F18: -4500 | G18: -4500 | H18: -4500 | I18: -4500 | J18: -4500 | K18: -4500 | L18: -4500 | M18: -4500 | N18: -4500 | O18: -4500 | P18: -4500 | R18: =+SUM(E18:P18) -> -54000 | T18: Se pagan a mes vencido.
B19: SERVICIOS EXTERIORES | C19: =SUM(C13:C18) -> -50400 | D19: =SUM(D13:D18) -> -47700 | E19: =SUM(E13:E18) -> -57350 | F19: =SUM(F13:F18) -> -45650 | G19: =SUM(G13:G18) -> -48350 | H19: =SUM(H13:H18) -> -49700 | I19: =SUM(I13:I18) -> -48400 | J19: =SUM(J13:J18) -> -44550 | ... P19: =SUM(P13:P18) -> -51850 | R19: =+SUM(E19:P19) -> -590200
B20: H. Pública por Impuesto de Sociedades | C20: -35248.5 | D20: -5155.5 | E20: -3024 | F20: -5481 | G20: -18459 | H20: -13030.5 | I20: -17083.5 | J20: -1302 | K20: -21367.5 | L20: -9177 | M20: -30040.5 | N20: -7507.5 | O20: -18091.5 | P20: -11109 | R20: =+SUM(E20:P20) -> -155673 | T20: Se hacen pagos a cuenta en abril, octubre y diciembre y el pago de la liquidación es en Julio.
B21: IAE y otros tributos locales | C21: -3000 | D21: -3000 | E21: -3000 | F21: -3000 | G21: -3000 | H21: -3000 | I21: -3000 | J21: -3000 | K21: -3000 | L21: -3000 | M21: -3000 | N21: -3000 | O21: -3000 | P21: -3000 | R21: =+SUM(E21:P21) -> -36000 | T21: El IAE supone un 80% de este epígrafe y se paga en enero, el resto se paga mensualmente.
B22: IMPUESTOS Y TRIBUTOS | C22: =SUM(C20:C21) -> -38248.5 | D22: =SUM(D20:D21) -> -8155.5 | E22: =SUM(E20:E21) -> -6024 | F22: =SUM(F20:F21) -> -8481 | G22: =SUM(G20:G21) -> -21459 | H22: =SUM(H20:H21) -> -16030.5 | I22: =SUM(I20:I21) -> -20083.5 | J22: =SUM(J20:J21) -> -4302 | ... P22: =SUM(P20:P21) -> -14109 | R22: =+SUM(E22:P22) -> -191673
B23: Gastos Bancarios | C23: -1000 | D23: -1000 | E23: -1000 | F23: -1000 | G23: -1000 | H23: -1000 | I23: -1000 | J23: -1000 | K23: -1000 | L23: -1000 | M23: -1000 | N23: -1000 | O23: -1000 | P23: -1000 | R23: =+SUM(E23:P23) -> -12000
B24: Otros Gastos | C24: -2500 | D24: -2500 | E24: -2500 | F24: -2500 | G24: -2500 | H24: -2500 | I24: -2500 | J24: -2500 | K24: -2500 | L24: -2500 | M24: -2500 | N24: -2500 | O24: -2500 | P24: -2500 | R24: =+SUM(E24:P24) -> -30000
B25: TOTAL GASTOS EXPLOTACIÓN | C25: =+C9+C12+C19+C22+C23+C24 -> -250398.5 | D25: =+D9+D12+D19+D22+D23+D24 -> -209605.5 | E25: =+E9+E12+E19+E22+E23+E24 -> -240624 | F25: =+F9+F12+F19+F22+F23+F24 -> -237381 | G25: =+G9+G12+G19+G22+G23+G24 -> -242559 | H25: =+H9+H12+H19+H22+H23+H24 -> -249980.5 | I25: =+I9+I12+I19+I22+I23+I24 -> -248733.5 | J25: =+J9+J12+J19+J22+J23+J24 -> -231102 | ... P25: =+P9+P12+P19+P22+P23+P24 -> -233209 | R25: =+SUM(E25:P25) -> -2821373
B27: MARGEN DE EXPLOTACIÓN | C27: =+C5+C25 -> 132601.5 | D27: =+D5+D25 -> 19394.5 | E27: =+E5+E25 -> 11376 | F27: =+F5+F25 -> 20619 | G27: =+G5+G25 -> 69441 | H27: =+H5+H25 -> 49019.5 | I27: =+I5+I25 -> 64266.5 | J27: =+J5+J25 -> 4898 | ... P27: =+P5+P25 -> 48791 | R27: =+SUM(E27:P27) -> 662627
B30: Presupuesto de Capital:
B31: Elabora el cuadro de operaciones financieras que incluya, al menos, dos líneas de financiación a corto plazo, un préstamo a largo plazo y varios depósitos a corto plazo en función de la liquidez obtenida.
B33: La compra de activos fijos se prevé según la periodificación adjunta:
B34: Compra de Activos Fijos | E34: -70000 | F34: -50000 | G34: -15000 | H34: -5000 | I34: -2000 | J34: -12000 | K34: -2000 | L34: -2000 | M34: -9000 | N34: -8500 | O34: -2000 | P34: -2000 | R34: =+SUM(E34:P34) -> -179500

Sheet Traslación_Cobros
A1: TRASLACIÓN DE COBROS DE CUENTA DE RESULTADOS A PRESUPUESTO DE TESORERÍA
B4: CUENTA DE RESULTADOS | C4: NOV A-1 | D4: DIC A-1 | E4: ENE | F4: FEB | G4: MAR | H4: ABR | I4: MAY | J4: JUN | K4: JUL | L4: AGO | M4: SEP | N4: OCT | O4: NOV | P4: DIC | R4: FY | T4: CONDICIONES | V4: IMPUESTO
B5: Cliente TOP 1 | C5: 54000 | D5: 21000 | E5: 32000 | F5: 34000 | G5: 21000 | H5: 25000 | I5: 45000 | J5: 10000 | K5: 45000 | L5: 28000 | M5: 32000 | N5: 38000 | O5: 17000 | P5: 48000 | R5: =+SUM(E5:P5) -> 375000 | T5: PAGO 30 DÍAS | V5: 0.21
B6: Cliente TOP 2 | C6: 26000 | D6: 6000 | E6: 4000 | F6: 50000 | G6: 59000 | H6: 10000 | I6: 37000 | J6: 12000 | K6: 54000 | L6: 35000 | M6: 43000 | N6: 30000 | O6: 11000 | P6: 48000 | R6: =+SUM(E6:P6) -> 393000 | T6: PAGO 60 DÍAS | V6: 0.21
B7: Cliente TOP 3 | C7: 32000 | D7: 7000 | E7: 32000 | F7: 41000 | G7: 44000 | H7: 37000 | I7: 45000 | J7: 21000 | K7: 55000 | L7: 7000 | M7: 11000 | N7: 46000 | O7: 33000 | P7: 31000 | R7: =+SUM(E7:P7) -> 403000 | T7: 40% CONTADO, 60% 60 DÍAS | V7: 0.21
B8: Cliente TOP 4 | C8: 37000 | D8: 33000 | E8: 19000 | F8: 33000 | G8: 15000 | H8: 60000 | I8: 13000 | J8: 20000 | K8: 7000 | L8: 48000 | M8: 48000 | N8: 10000 | O8: 45000 | P8: 18000 | R8: =+SUM(E8:P8) -> 336000 | T8: PAGO 45 DÍAS | V8: 0.21
B9: Cliente TOP 5 | C9: 18000 | D9: 45000 | E9: 41000 | F9: 5000 | G9: 46000 | H9: 45000 | I9: 0 | J9: 21000 | K9: 31000 | L9: 38000 | M9: 18000 | N9: 19000 | O9: 44000 | P9: 16000 | R9: =+SUM(E9:P9) -> 324000 | T9: PAGO 60 DÍAS | W9: Exportación, no aplica IVA
B10: Cliente TOP 6 | C10: 24000 | D10: 15000 | E10: 4000 | F10: 23000 | G10: 27000 | H10: 30000 | I10: 42000 | J10: 42000 | K10: 14000 | L10: 41000 | M10: 57000 | N10: 28000 | O10: 32000 | P10: 17000 | R10: =+SUM(E10:P10) -> 357000 | T10: 50% CONTADO, 50% 30 DÍAS | V10: 0.21
B11: Cliente TOP 7 | C11: 29000 | D11: 0 | E11: 5000 | F11: 31000 | G11: 23000 | H11: 26000 | I11: 41000 | J11: 31000 | K11: 15000 | L11: 26000 | M11: 33000 | N11: 35000 | O11: 0 | P11: 45000 | R11: =+SUM(E11:P11) -> 311000 | T11: PAGO 30 DÍAS | V11: 0.21
B12: Cliente TOP 8 | C12: 44000 | D12: 39000 | E12: 50000 | F12: 13000 | G12: 0 | H12: 4000 | I12: 15000 | J12: 28000 | K12: 39000 | L12: 0 | M12: 25000 | N12: 30000 | O12: 55000 | P12: 4000 | R12: =+SUM(E12:P12) -> 263000 | T12: PAGO 15 DÍAS | V12: 0.21
B13: Cliente TOP 9 | C13: 36000 | D13: 41000 | E13: 12000 | F13: 0 | G13: 23000 | H13: 28000 | I13: 25000 | J13: 24000 | K13: 18000 | L13: 14000 | M13: 22000 | N13: 0 | O13: 8000 | P13: 9000 | R13: =+SUM(E13:P13) -> 183000 | T13: PAGO 60 DÍAS | V13: 0.21
B14: Cliente TOP 10 | C14: 42000 | D14: 0 | E14: 18000 | F14: 0 | G14: 5000 | H14: 0 | I14: 29000 | J14: 0 | K14: 17000 | L14: 0 | M14: 52000 | N14: 0 | O14: 13000 | P14: 0 | R14: =+SUM(E14:P14) -> 134000 | T14: PAGO 30 DÍAS | V14: 0.21
B15: Resto Clientes | C15: 41000 | D15: 22000 | E15: 35000 | F15: 28000 | G15: 49000 | H15: 34000 | I15: 21000 | J15: 27000 | K15: 30000 | L15: 29000 | M15: 18000 | N15: 29000 | O15: 59000 | P15: 46000 | R15: =+SUM(E15:P15) -> 405000 | T15: PROMEDIO 45 DÍAS | V15: 0.21
B16: INGRESOS POR VENTAS | C16: =SUM(C5:C15) -> 383000 | D16: =SUM(D5:D15) -> 229000 | E16: =SUM(E5:E15) -> 252000 | F16: =SUM(F5:F15) -> 258000 | G16: =SUM(G5:G15) -> 312000 | H16: =SUM(H5:H15) -> 299000 | I16: =SUM(I5:I15) -> 313000 | J16: =SUM(J5:J15) -> 236000 | ... P16: =SUM(P5:P15) -> 282000 | R16: =SUM(R5:R15) -> 3484000
B20: PRESUPUESTO TESORERÍA | E20: ENE | F20: FEB | G20: MAR | H20: ABR | I20: MAY | J20: JUN | K20: JUL | L20: AGO | M20: SEP | N20: OCT | O20: NOV | P20: DIC | R20: DIC
B21: Cliente TOP 1 | E21: =+D5*(1+$V5) -> 25410 | F21: =+E5*(1+$V5) -> 38720 | G21: =+F5*(1+$V5) -> 41140 | H21: =+G5*(1+$V5) -> 25410 | I21: =+H5*(1+$V5) -> 30250 | J21: =+I5*(1+$V5) -> 54450 | K21: =+J5*(1+$V5) -> 12100 | L21: =+K5*(1+$V5) -> 54450 | ... P21: =+O5*(1+$V5) -> 20570 | R21: =+SUM(E21:P21) -> 421080 | T21: PAGO 30 DÍAS
B22: Cliente TOP 2 | E22: =+C6*(1+$V6) -> 31460 | F22: =+D6*(1+$V6) -> 7260 | G22: =+E6*(1+$V6) -> 4840 | H22: =+F6*(1+$V6) -> 60500 | I22: =+G6*(1+$V6) -> 71390 | J22: =+H6*(1+$V6) -> 12100 | K22: =+I6*(1+$V6) -> 44770 | L22: =+J6*(1+$V6) -> 14520 | ... P22: =+N6*(1+$V6) -> 36300 | R22: =+SUM(E22:P22) -> 442860 | T22: PAGO 60 DÍAS
B23: Cliente TOP 3 | E23: =+(C7*0.6+E7*0.4)*(1+$V7) -> 38720 | F23: =+(D7*0.6+F7*0.4)*(1+$V7) -> 24926 | G23: =+(E7*0.6+G7*0.4)*(1+$V7) -> 44528 | H23: =+(F7*0.6+H7*0.4)*(1+$V7) -> 47674 | I23: =+(G7*0.6+I7*0.4)*(1+$V7) -> 53724 | J23: =+(H7*0.6+J7*0.4)*(1+$V7) -> 37026 | K23: =+(I7*0.6+K7*0.4)*(1+$V7) -> 59290 | L23: =+(J7*0.6+L7*0.4)*(1+$V7) -> 18634 | ... P23: =+(N7*0.6+P7*0.4)*(1+$V7) -> 48400 | R23: =+SUM(E23:P23) -> 469480 | T23: 40% CONTADO, 60% 60 DÍAS
B24: Cliente TOP 4 | E24: =+(C8/2+D8/2)*(1+$V8) -> 42350 | F24: =+(D8/2+E8/2)*(1+$V8) -> 31460 | G24: =+(E8/2+F8/2)*(1+$V8) -> 31460 | H24: =+(F8/2+G8/2)*(1+$V8) -> 29040 | I24: =+(G8/2+H8/2)*(1+$V8) -> 45375 | J24: =+(H8/2+I8/2)*(1+$V8) -> 44165 | K24: =+(I8/2+J8/2)*(1+$V8) -> 19965 | L24: =+(J8/2+K8/2)*(1+$V8) -> 16335 | ... P24: =+(N8/2+O8/2)*(1+$V8) -> 33275 | R24: =+SUM(E24:P24) -> 419870 | T24: PAGO 45 DÍAS
B25: Cliente TOP 5 | E25: =+C9*(1+$V9) -> 18000 | F25: =+D9*(1+$V9) -> 45000 | G25: =+E9*(1+$V9) -> 41000 | H25: =+F9*(1+$V9) -> 5000 | I25: =+G9*(1+$V9) -> 46000 | J25: =+H9*(1+$V9) -> 45000 | K25: =+I9*(1+$V9) -> 0 | L25: =+J9*(1+$V9) -> 21000 | ... P25: =+N9*(1+$V9) -> 19000 | R25: =+SUM(E25:P25) -> 327000 | T25: PAGO 60 DÍAS
B26: Cliente TOP 6 | E26: =+(D10*0.5+E10*0.5)*(1+$V10) -> 11495 | F26: =+(E10*0.5+F10*0.5)*(1+$V10) -> 16335 | G26: =+(F10*0.5+G10*0.5)*(1+$V10) -> 30250 | H26: =+(G10*0.5+H10*0.5)*(1+$V10) -> 34485 | I26: =+(H10*0.5+I10*0.5)*(1+$V10) -> 43560 | J26: =+(I10*0.5+J10*0.5)*(1+$V10) -> 50820 | K26: =+(J10*0.5+K10*0.5)*(1+$V10) -> 33880 | L26: =+(K10*0.5+L10*0.5)*(1+$V10) -> 33275 | ... P26: =+(O10*0.5+P10*0.5)*(1+$V10) -> 29645 | R26: =+SUM(E26:P26) -> 430760 | T26: 50% CONTADO, 50% 30 DÍAS
B27: Cliente TOP 7 | E27: =+D11*(1+$V11) -> 0 | F27: =+E11*(1+$V11) -> 6050 | G27: =+F11*(1+$V11) -> 37510 | H27: =+G11*(1+$V11) -> 27830 | I27: =+H11*(1+$V11) -> 31460 | J27: =+I11*(1+$V11) -> 49610 | K27: =+J11*(1+$V11) -> 37510 | L27: =+K11*(1+$V11) -> 18150 | ... P27: =+O11*(1+$V11) -> 0 | R27: =+SUM(E27:P27) -> 321860 | T27: PAGO 30 DÍAS
B28: Cliente TOP 8 | E28: =+(D12/2+E12/2)*(1+$V12) -> 53845 | F28: =+(E12/2+F12/2)*(1+$V12) -> 38115 | G28: =+(F12/2+G12/2)*(1+$V12) -> 7865 | H28: =+(G12/2+H12/2)*(1+$V12) -> 2420 | I28: =+(H12/2+I12/2)*(1+$V12) -> 11495 | J28: =+(I12/2+J12/2)*(1+$V12) -> 26015 | K28: =+(J12/2+K12/2)*(1+$V12) -> 40535 | L28: =+(K12/2+L12/2)*(1+$V12) -> 23595 | ... P28: =+(O12/2+P12/2)*(1+$V12) -> 35695 | R28: =+SUM(E28:P28) -> 339405 | T28: PAGO 15 DÍAS
B29: Cliente TOP 9 | E29: =+C13*(1+$V13) -> 43560 | F29: =+D13*(1+$V13) -> 49610 | G29: =+E13*(1+$V13) -> 14520 | H29: =+F13*(1+$V13) -> 0 | I29: =+G13*(1+$V13) -> 27830 | J29: =+H13*(1+$V13) -> 33880 | K29: =+I13*(1+$V13) -> 30250 | L29: =+J13*(1+$V13) -> 29040 | ... P29: =+N13*(1+$V13) -> 0 | R29: =+SUM(E29:P29) -> 294030 | T29: PAGO 60 DÍAS
B30: Cliente TOP 10 | E30: =+D14*(1+$V14) -> 0 | F30: =+E14*(1+$V14) -> 21780 | G30: =+F14*(1+$V14) -> 0 | H30: =+G14*(1+$V14) -> 6050 | I30: =+H14*(1+$V14) -> 0 | J30: =+I14*(1+$V14) -> 35090 | K30: =+J14*(1+$V14) -> 0 | L30: =+K14*(1+$V14) -> 20570 | ... P30: =+O14*(1+$V14) -> 15730 | R30: =+SUM(E30:P30) -> 162140 | T30: PAGO 30 DÍAS
B31: Resto Clientes | E31: =+(C15/2+D15/2)*(1+$V15) -> 38115 | F31: =+(D15/2+E15/2)*(1+$V15) -> 34485 | G31: =+(E15/2+F15/2)*(1+$V15) -> 38115 | H31: =+(F15/2+G15/2)*(1+$V15) -> 46585 | I31: =+(G15/2+H15/2)*(1+$V15) -> 50215 | J31: =+(H15/2+I15/2)*(1+$V15) -> 33275 | K31: =+(I15/2+J15/2)*(1+$V15) -> 29040 | L31: =+(J15/2+K15/2)*(1+$V15) -> 34485 | ... P31: =+(N15/2+O15/2)*(1+$V15) -> 53240 | R31: =+SUM(E31:P31) -> 450120 | T31: PROMEDIO 45 DÍAS
B32: INGRESOS POR VENTAS | E32: =SUM(E21:E31) -> 302955 | F32: =SUM(F21:F31) -> 313741 | G32: =SUM(G21:G31) -> 291228 | H32: =SUM(H21:H31) -> 284994 | I32: =SUM(I21:I31) -> 411299 | J32: =SUM(J21:J31) -> 421431 | K32: =SUM(K21:K31) -> 307340 | L32: =SUM(L21:L31) -> 284054 | ... P32: =SUM(P21:P31) -> 291855 | R32: =SUM(R21:R31) -> 4078605

Sheet Traslación_Pagos_1
A1: CUENTA DE RESULTADOS
B4: CUENTA DE RESULTADOS DE EXPLOTACIÓN | C4: NOV A-1 | D4: DIC A-1 | E4: ENE | F4: FEB | G4: MAR | H4: ABR | I4: MAY | J4: JUN | K4: JUL | L4: AGO | M4: SEP | N4: OCT | O4: NOV | P4: DIC | R4: FY
B5: INGRESOS POR VENTAS | C5: 383000 | D5: 229000 | E5: 252000 | F5: 258000 | G5: 312000 | H5: 299000 | I5: 313000 | J5: 236000 | K5: 325000 | L5: 266000 | M5: 359000 | N5: 265000 | O5: 317000 | P5: 282000 | R5: =+SUM(E5:P5) -> 3484000
B6: Sueldos y Salarios | C6: -42500 | D6: -42500 | E6: -57500 | F6: -57500 | G6: -57500 | H6: -57500 | I6: -57500 | J6: -57500 | K6: -57500 | L6: -57500 | M6: -57500 | N6: -57500 | O6: -57500 | P6: -57500 | R6: =+SUM(E6:P6) -> -690000 | T6: El salario anual se divide en 14 pagas, teniendo paga extra los meses de julio y diciembre.
B7: Bonus e Incentivos | C7: =+C6*0.2 -> -8500 | D7: =+D6*0.2 -> -8500 | E7: =+E6*0.2 -> -11500 | F7: =+F6*0.2 -> -11500 | G7: =+G6*0.2 -> -11500 | H7: =+H6*0.2 -> -11500 | I7: =+I6*0.2 -> -11500 | J7: =+J6*0.2 -> -11500 | ... P7: =+P6*0.2 -> -11500 | R7: =+SUM(E7:P7) -> -138000 | T7: Los bonus e incentivos por objetivos se cobran en el mes de febrero.
B8: Seguridad Social Empresa | C8: =+(C7+C6*0.3) -> -21250 | D8: =+(D7+D6*0.3) -> -21250 | E8: =+(E7+E6*0.3) -> -28750 | F8: =+(F7+F6*0.3) -> -28750 | G8: =+(G7+G6*0.3) -> -28750 | H8: =+(H7+H6*0.3) -> -28750 | I8: =+(I7+I6*0.3) -> -28750 | J8: =+(J7+J6*0.3) -> -28750 | ... P8: =+(P7+P6*0.3) -> -28750 | R8: =+SUM(E8:P8) -> -345000
B9: COSTES DE PERSONAL | C9: =SUM(C6:C8) -> -72250 | D9: =SUM(D6:D8) -> -72250 | E9: =SUM(E6:E8) -> -97750 | F9: =SUM(F6:F8) -> -97750 | G9: =SUM(G6:G8) -> -97750 | H9: =SUM(H6:H8) -> -97750 | I9: =SUM(I6:I8) -> -97750 | J9: =SUM(J6:J8) -> -97750 | ... P9: =SUM(P6:P8) -> -97750 | R9: =+SUM(E9:P9) -> -1173000
B10: Compra de materias primas | C10: -54000 | D10: -49000 | E10: -48000 | F10: -56000 | G10: -47500 | H10: -58000 | I10: -56000 | J10: -62000 | K10: -47000 | L10: -35000 | M10: -42000 | N10: -38000 | O10: -41000 | P10: -47000 | R10: =+SUM(E10:P10) -> -577500 | T10: Un tercio de nuestros proveedores son empresas cuyos plazos de pago están amparados por la legislación comercial de protección a pequeñas empresas por lo que son a 30 días. Todos aplican un 21% de IVA. El resto de los proveedores tiene plazos de pago entre 45 y 90 días.
B11: Compra de otros materiales para producción | C11: -32000 | D11: -29000 | E11: -28000 | F11: -26000 | G11: -24000 | H11: -25000 | I11: -23000 | J11: -19000 | K11: -21000 | L11: -17000 | M11: -12000 | N11: -16000 | O11: -17000 | P11: -19000 | R11: =+SUM(E11:P11) -> -247000
B12: COMPRAS A PROVEEDORES | C12: =SUM(C10:C11) -> -86000 | D12: =SUM(D10:D11) -> -78000 | E12: =SUM(E10:E11) -> -76000 | F12: =SUM(F10:F11) -> -82000 | G12: =SUM(G10:G11) -> -71500 | H12: =SUM(H10:H11) -> -83000 | I12: =SUM(I10:I11) -> -79000 | J12: =SUM(J10:J11) -> -81000 | ... P12: =SUM(P10:P11) -> -66000 | R12: =+SUM(E12:P12) -> -824500
B13: Alquileres | C13: -16500 | D13: -16500 | E13: -18000 | F13: -18000 | G13: -18000 | H13: -18000 | I13: -18000 | J13: -18000 | K13: -18000 | L13: -18000 | M13: -18000 | N13: -18000 | O13: -18000 | P13: -18000 | R13: =+SUM(E13:P13) -> -216000 | T13: Se pagan por anticipado entre el 1 y el 5 de cada mes.
B14: Serv. Profesionales Independientes | C14: -4000 | D14: -4000 | E14: -16000 | F14: -4000 | G14: -4000 | H14: -6000 | I14: -4000 | J14: -4000 | K14: -6000 | L14: -4000 | M14: -4000 | N14: -6000 | O14: -4000 | P14: -4000 | R14: =+SUM(E14:P14) -> -66000 | T14: Se pagan a 30 días
B15: Transporte | C15: -19150 | D15: -11450 | E15: -12600 | F15: -12900 | G15: -15600 | H15: -14950 | I15: -15650 | J15: -11800 | K15: -16250 | L15: -13300 | M15: -17950 | N15: -13250 | O15: -15850 | P15: -14100 | R15: =+SUM(E15:P15) -> -174200 | T15: Se pagan a 30 días
B16: Seguros | C16: -3750 | D16: -3750 | E16: -3750 | F16: -3750 | G16: -3750 | H16: -3750 | I16: -3750 | J16: -3750 | K16: -3750 | L16: -3750 | M16: -3750 | N16: -3750 | O16: -3750 | P16: -3750 | R16: =+SUM(E16:P16) -> -45000 | T16: La póliza anual de seguros se renueva en febrero
B17: Publicidad y Márketing | C17: -2500 | D17: -7500 | E17: -2500 | F17: -2500 | G17: -2500 | H17: -2500 | I17: -2500 | J17: -2500 | K17: -2500 | L17: -2500 | M17: -2500 | N17: -2500 | O17: -2500 | P17: -7500 | R17: =+SUM(E17:P17) -> -35000 | T17: Se pagan a 30 días
B18: Suministros | C18: -4500 | D18: -4500 | E18: -4500 | F18: -4500 | G18: -4500 | H18: -4500 | I18: -4500 | J18: -4500 | K18: -4500 | L18: -4500 | M18: -4500 | N18: -4500 | O18: -4500 | P18: -4500 | R18: =+SUM(E18:P18) -> -54000 | T18: Se pagan a mes vencido.
B19: SERVICIOS EXTERIORES | C19: =SUM(C13:C18) -> -50400 | D19: =SUM(D13:D18) -> -47700 | E19: =SUM(E13:E18) -> -57350 | F19: =SUM(F13:F18) -> -45650 | G19: =SUM(G13:G18) -> -48350 | H19: =SUM(H13:H18) -> -49700 | I19: =SUM(I13:I18) -> -48400 | J19: =SUM(J13:J18) -> -44550 | ... P19: =SUM(P13:P18) -> -51850 | R19: =+SUM(E19:P19) -> -590200
B20: H. Pública por Impuesto de Sociedades | C20: -35248.5 | D20: -5155.5 | E20: -3024 | F20: -5481 | G20: -18459 | H20: -13030.5 | I20: -17083.5 | J20: -1302 | K20: -21367.5 | L20: -9177 | M20: -30040.5 | N20: -7507.5 | O20: -18091.5 | P20: -11109 | R20: =+SUM(E20:P20) -> -155673 | T20: Se hacen pagos a cuenta en abril, octubre y diciembre y el pago de la liquidación es en Julio.
B21: IAE y otros tributos locales | C21: -3000 | D21: -3000 | E21: -3000 | F21: -3000 | G21: -3000 | H21: -3000 | I21: -3000 | J21: -3000 | K21: -3000 | L21: -3000 | M21: -3000 | N21: -3000 | O21: -3000 | P21: -3000 | R21: =+SUM(E21:P21) -> -36000 | T21: El IAE supone un 80% de este epígrafe y se paga en enero, el resto se paga mensualmente.
B22: IMPUESTOS Y TRIBUTOS | C22: =SUM(C20:C21) -> -38248.5 | D22: =SUM(D20:D21) -> -8155.5 | E22: =SUM(E20:E21) -> -6024 | F22: =SUM(F20:F21) -> -8481 | G22: =SUM(G20:G21) -> -21459 | H22: =SUM(H20:H21) -> -16030.5 | I22: =SUM(I20:I21) -> -20083.5 | J22: =SUM(J20:J21) -> -4302 | ... P22: =SUM(P20:P21) -> -14109 | R22: =+SUM(E22:P22) -> -191673
B23: Gastos Bancarios | C23: -1000 | D23: -1000 | E23: -1000 | F23: -1000 | G23: -1000 | H23: -1000 | I23: -1000 | J23: -1000 | K23: -1000 | L23: -1000 | M23: -1000 | N23: -1000 | O23: -1000 | P23: -1000 | R23: =+SUM(E23:P23) -> -12000
B24: Otros Gastos | C24: -2500 | D24: -2500 | E24: -2500 | F24: -2500 | G24: -2500 | H24: -2500 | I24: -2500 | J24: -2500 | K24: -2500 | L24: -2500 | M24: -2500 | N24: -2500 | O24: -2500 | P24: -2500 | R24: =+SUM(E24:P24) -> -30000
B25: TOTAL GASTOS EXPLOTACIÓN | C25: =+C9+C12+C19+C22+C23+C24 -> -250398.5 | D25: =+D9+D12+D19+D22+D23+D24 -> -209605.5 | E25: =+E9+E12+E19+E22+E23+E24 -> -240624 | F25: =+F9+F12+F19+F22+F23+F24 -> -237381 | G25: =+G9+G12+G19+G22+G23+G24 -> -242559 | H25: =+H9+H12+H19+H22+H23+H24 -> -249980.5 | I25: =+I9+I12+I19+I22+I23+I24 -> -248733.5 | J25: =+J9+J12+J19+J22+J23+J24 -> -231102 | ... P25: =+P9+P12+P19+P22+P23+P24 -> -233209 | R25: =+SUM(E25:P25) -> -2821373
B27: MARGEN DE EXPLOTACIÓN | C27: =+C5+C25 -> 132601.5 | D27: =+D5+D25 -> 19394.5 | E27: =+E5+E25 -> 11376 | F27: =+F5+F25 -> 20619 | G27: =+G5+G25 -> 69441 | H27: =+H5+H25 -> 49019.5 | I27: =+I5+I25 -> 64266.5 | J27: =+J5+J25 -> 4898 | ... P27: =+P5+P25 -> 48791 | R27: =+SUM(E27:P27) -> 662627
B30: Presupuesto de Capital:
B31: Elabora el cuadro de operaciones financieras que incluya, al menos, dos líneas de financiación a corto plazo, un préstamo a largo plazo y varios depósitos a corto plazo en función de la liquidez obtenida.
B33: La compra de activos fijos se prevé según la periodificación adjunta:
B34: Compra de Activos Fijos | E34: -70000 | F34: -50000 | G34: -15000 | H34: -5000 | I34: -2000 | J34: -12000 | K34: -2000 | L34: -2000 | M34: -9000 | N34: -8500 | O34: -2000 | P34: -2000 | R34: =+SUM(E34:P34) -> -179500
B35: Tipo IVA | C35: 0.21
B36: Tipo Seguridad Social Trabajador | C36: 0.06
B37: Tipo Seguridad Social Empresa | C37: 0.33
B38: Tipo Retención Trabajadores | C38: 0.16
B39: Tipo Retención Alquileres y Profesionales | C39: 0.19
B43: PRESUPUESTO DE TESORERÍA | C43: ENE | D43: FEB | E43: MAR | F43: ABR | G43: MAY | H43: JUN | I43: JUL | J43: AGO | K43: SEP | L43: OCT | M43: NOV | N43: DIC
B44: Nómina mensual | C44: =$R$6/14 -> -49285.714 | D44: =$R$6/14 -> -49285.714 | E44: =$R$6/14 -> -49285.714 | F44: =$R$6/14 -> -49285.714 | G44: =$R$6/14 -> -49285.714 | H44: =$R$6/14 -> -49285.714 | I44: =$R$6/14 -> -49285.714 | J44: =$R$6/14 -> -49285.714 | ... N44: =$R$6/14 -> -49285.714
B45: Pagas Extras | I45: =+I44 -> -49285.714 | N45: =+N44 -> -49285.714
B46: Retenciones a trabajadores | C46: =D6*12/14*2*C38*2+C6*12/14*C38 -> -29142.857 | F46: =+E6*12/14*C38+F6*12/14*C38+D47/(1-C36-C38)*C38+G6*12/14*C36 -> -40808.571 | I46: =H6*12/14*C38+I6*12/14*C38+J6*12/14*2*C38 -> -31542.857 | L46: =K6*12/14*C38+L6*12/14*C38+M6*12/14*C38 -> -23657.143
B47: Bonus e Incentivos | D47: =$R$7*(1-$C$36-$C$38) -> -107640 | N47: =AB7*(1-M36-M38) -> 0
B48: Seguridad Social | C48: =D6*$C$36+D8 -> -23800 | D48: =E6*$C$36+E8 -> -32200 | E48: =F6*C38+F13+D47/(1-C36-C38)*39% -> -81020 | F48: =G6*$C$36+G8 -> -32200 | G48: =H6*$C$36+H8 -> -32200 | H48: =I6*$C$36+I8 -> -32200 | I48: =J6*$C$36+J8 -> -32200 | J48: =K6*$C$36+K8 -> -32200 | K48: =L6*$C$36+L8 -> -32200 | L48: =M6*$C$36+M8 -> -32200 | M48: =N6*$C$36+N8 -> -32200 | N48: =O6*$C$36+O8 -> -32200
B49: COSTES DE PERSONAL | C49: =SUM(C44:C48) -> -102228.57 | D49: =SUM(D44:D48) -> -189125.71 | E49: =SUM(E44:E48) -> -130305.71 | F49: =SUM(F44:F48) -> -122294.29 | G49: =SUM(G44:G48) -> -81485.714 | H49: =SUM(H44:H48) -> -81485.714 | I49: =SUM(I44:I48) -> -162314.29 | J49: =SUM(J44:J48) -> -81485.714 | ... N49: =SUM(N44:N48) -> -130771.43
...

Sheet Presupuesto_Tesoreria_1
A1: CONSOLIDACIÓN Y ANÁLISIS
B3: PRESUPUESTO DE TESORERÍA | D3: ENE | E3: FEB | F3: MAR | G3: ABR | H3: MAY | I3: JUN | J3: JUL | K3: AGO | L3: SEP | M3: OCT | N3: NOV | O3: DIC | Q3: TOTAL
B4: SALDO INICIAL | D4: 45000 | E4: =+D47 -> -8221.4048 | F4: =+E47 -> -134730 | G4: =+F47 -> -133861.26 | H4: =+G47 -> -170087.09 | I4: =+H47 -> 11378.818 | J4: =+I47 -> 186506.39 | K4: =+J47 -> 163119.89 | L4: =+K47 -> 214154.47 | ... O4: =+N47 -> 685276.21 | Q4: =+D4 -> 45000
C5: Cliente TOP 1 | D5: =Traslación_Cobros!E21 -> 25410 | E5: =Traslación_Cobros!F21 -> 38720 | F5: =Traslación_Cobros!G21 -> 41140 | G5: =Traslación_Cobros!H21 -> 25410 | H5: =Traslación_Cobros!I21 -> 30250 | I5: =Traslación_Cobros!J21 -> 54450 | J5: =Traslación_Cobros!K21 -> 12100 | K5: =Traslación_Cobros!L21 -> 54450 | ... O5: =Traslación_Cobros!P21 -> 20570 | Q5: =SUM(D5:O5) -> 421080
C6: Cliente TOP 2 | D6: =Traslación_Cobros!E22 -> 31460 | E6: =Traslación_Cobros!F22 -> 7260 | F6: =Traslación_Cobros!G22 -> 4840 | G6: =Traslación_Cobros!H22 -> 60500 | H6: =Traslación_Cobros!I22 -> 71390 | I6: =Traslación_Cobros!J22 -> 12100 | J6: =Traslación_Cobros!K22 -> 44770 | K6: =Traslación_Cobros!L22 -> 14520 | ... O6: =Traslación_Cobros!P22 -> 36300 | Q6: =SUM(D6:O6) -> 442860
C7: Cliente TOP 3 | D7: =Traslación_Cobros!E23 -> 38720 | E7: =Traslación_Cobros!F23 -> 24926 | F7: =Traslación_Cobros!G23 -> 44528 | G7: =Traslación_Cobros!H23 -> 47674 | H7: =Traslación_Cobros!I23 -> 53724 | I7: =Traslación_Cobros!J23 -> 37026 | J7: =Traslación_Cobros!K23 -> 59290 | K7: =Traslación_Cobros!L23 -> 18634 | ... O7: =Traslación_Cobros!P23 -> 48400 | Q7: =SUM(D7:O7) -> 469480
C8: Cliente TOP 4 | D8: =Traslación_Cobros!E24 -> 42350 | E8: =Traslación_Cobros!F24 -> 31460 | F8: =Traslación_Cobros!G24 -> 31460 | G8: =Traslación_Cobros!H24 -> 29040 | H8: =Traslación_Cobros!I24 -> 45375 | I8: =Traslación_Cobros!J24 -> 44165 | J8: =Traslación_Cobros!K24 -> 19965 | K8: =Traslación_Cobros!L24 -> 16335 | ... O8: =Traslación_Cobros!P24 -> 33275 | Q8: =SUM(D8:O8) -> 419870
C9: Cliente TOP 5 | D9: =Traslación_Cobros!E25 -> 18000 | E9: =Traslación_Cobros!F25 -> 45000 | F9: =Traslación_Cobros!G25 -> 41000 | G9: =Traslación_Cobros!H25 -> 5000 | H9: =Traslación_Cobros!I25 -> 46000 | I9: =Traslación_Cobros!J25 -> 45000 | J9: =Traslación_Cobros!K25 -> 0 | K9: =Traslación_Cobros!L25 -> 21000 | ... O9: =Traslación_Cobros!P25 -> 19000 | Q9: =SUM(D9:O9) -> 327000
C10: Cliente TOP 6 | D10: =Traslación_Cobros!E26 -> 11495 | E10: =Traslación_Cobros!F26 -> 16335 | F10: =Traslación_Cobros!G26 -> 30250 | G10: =Traslación_Cobros!H26 -> 34485 | H10: =Traslación_Cobros!I26 -> 43560 | I10: =Traslación_Cobros!J26 -> 50820 | J10: =Traslación_Cobros!K26 -> 33880 | K10: =Traslación_Cobros!L26 -> 33275 | ... O10: =Traslación_Cobros!P26 -> 29645 | Q10: =SUM(D10:O10) -> 430760
C11: Cliente TOP 7 | D11: =Traslación_Cobros!E27 -> 0 | E11: =Traslación_Cobros!F27 -> 6050 | F11: =Traslación_Cobros!G27 -> 37510 | G11: =Traslación_Cobros!H27 -> 27830 | H11: =Traslación_Cobros!I27 -> 31460 | I11: =Traslación_Cobros!J27 -> 49610 | J11: =Traslación_Cobros!K27 -> 37510 | K11: =Traslación_Cobros!L27 -> 18150 | ... O11: =Traslación_Cobros!P27 -> 0 | Q11: =SUM(D11:O11) -> 321860
C12: Cliente TOP 8 | D12: =Traslación_Cobros!E28 -> 53845 | E12: =Traslación_Cobros!F28 -> 38115 | F12: =Traslación_Cobros!G28 -> 7865 | G12: =Traslación_Cobros!H28 -> 2420 | H12: =Traslación_Cobros!I28 -> 11495 | I12: =Traslación_Cobros!J28 -> 26015 | J12: =Traslación_Cobros!K28 -> 40535 | K12: =Traslación_Cobros!L28 -> 23595 | ... O12: =Traslación_Cobros!P28 -> 35695 | Q12: =SUM(D12:O12) -> 339405
C13: Cliente TOP 9 | D13: =Traslación_Cobros!E29 -> 43560 | E13: =Traslación_Cobros!F29 -> 49610 | F13: =Traslación_Cobros!G29 -> 14520 | G13: =Traslación_Cobros!H29 -> 0 | H13: =Traslación_Cobros!I29 -> 27830 | I13: =Traslación_Cobros!J29 -> 33880 | J13: =Traslación_Cobros!K29 -> 30250 | K13: =Traslación_Cobros!L29 -> 29040 | ... O13: =Traslación_Cobros!P29 -> 0 | Q13: =SUM(D13:O13) -> 294030
C14: Cliente TOP 10 | D14: =Traslación_Cobros!E30 -> 0 | E14: =Traslación_Cobros!F30 -> 21780 | F14: =Traslación_Cobros!G30 -> 0 | G14: =Traslación_Cobros!H30 -> 6050 | H14: =Traslación_Cobros!I30 -> 0 | I14: =Traslación_Cobros!J30 -> 35090 | J14: =Traslación_Cobros!K30 -> 0 | K14: =Traslación_Cobros!L30 -> 20570 | ... O14: =Traslación_Cobros!P30 -> 15730 | Q14: =SUM(D14:O14) -> 162140
C15: Resto Clientes | D15: =Traslación_Cobros!E31 -> 38115 | E15: =Traslación_Cobros!F31 -> 34485 | F15: =Traslación_Cobros!G31 -> 38115 | G15: =Traslación_Cobros!H31 -> 46585 | H15: =Traslación_Cobros!I31 -> 50215 | I15: =Traslación_Cobros!J31 -> 33275 | J15: =Traslación_Cobros!K31 -> 29040 | K15: =Traslación_Cobros!L31 -> 34485 | ... O15: =Traslación_Cobros!P31 -> 53240 | Q15: =SUM(D15:O15) -> 450120
C16: COBROS EXPLOTACIÓN | D16: =SUM(D5:D15) -> 302955 | E16: =SUM(E5:E15) -> 313741 | F16: =SUM(F5:F15) -> 291228 | G16: =SUM(G5:G15) -> 284994 | H16: =SUM(H5:H15) -> 411299 | I16: =SUM(I5:I15) -> 421431 | J16: =SUM(J5:J15) -> 307340 | K16: =SUM(K5:K15) -> 284054 | ... O16: =SUM(O5:O15) -> 291855 | Q16: =SUM(Q5:Q15) -> 4078605
C17: Nómina mensual | D17: =Traslación_Pagos_1!C44 -> -49285.714 | E17: =Traslación_Pagos_1!D44 -> -49285.714 | F17: =Traslación_Pagos_1!E44 -> -49285.714 | G17: =Traslación_Pagos_1!F44 -> -49285.714 | H17: =Traslación_Pagos_1!G44 -> -49285.714 | I17: =Traslación_Pagos_1!H44 -> -49285.714 | J17: =Traslación_Pagos_1!I44 -> -49285.714 | K17: =Traslación_Pagos_1!J44 -> -49285.714 | ... O17: =Traslación_Pagos_1!N44 -> -49285.714 | Q17: =SUM(D17:O17) -> -591428.57
C18: Pagas Extras | D18: =Traslación_Pagos_1!C45 -> 0 | E18: =Traslación_Pagos_1!D45 -> 0 | F18: =Traslación_Pagos_1!E45 -> 0 | G18: =Traslación_Pagos_1!F45 -> 0 | H18: =Traslación_Pagos_1!G45 -> 0 | I18: =Traslación_Pagos_1!H45 -> 0 | J18: =Traslación_Pagos_1!I45 -> -49285.714 | K18: =Traslación_Pagos_1!J45 -> 0 | ... O18: =Traslación_Pagos_1!N45 -> -49285.714 | Q18: =SUM(D18:O18) -> -98571.429
C19: Retenciones a trabajadores | D19: =Traslación_Pagos_1!C46 -> -29142.857 | E19: =Traslación_Pagos_1!D46 -> 0 | F19: =Traslación_Pagos_1!E46 -> 0 | G19: =Traslación_Pagos_1!F46 -> -40808.571 | H19: =Traslación_Pagos_1!G46 -> 0 | I19: =Traslación_Pagos_1!H46 -> 0 | J19: =Traslación_Pagos_1!I46 -> -31542.857 | K19: =Traslación_Pagos_1!J46 -> 0 | ... O19: =Traslación_Pagos_1!N46 -> 0 | Q19: =SUM(D19:O19) -> -125151.43
C20: Bonus e Incentivos | D20: =Traslación_Pagos_1!C47 -> 0 | E20: =Traslación_Pagos_1!D47 -> -107640 | F20: =Traslación_Pagos_1!E47 -> 0 | G20: =Traslación_Pagos_1!F47 -> 0 | H20: =Traslación_Pagos_1!G47 -> 0 | I20: =Traslación_Pagos_1!H47 -> 0 | J20: =Traslación_Pagos_1!I47 -> 0 | K20: =Traslación_Pagos_1!J47 -> 0 | ... O20: =Traslación_Pagos_1!N47 -> 0 | Q20: =SUM(D20:O20) -> -107640
C21: Seguridad Social | D21: =Traslación_Pagos_1!C48 -> -23800 | E21: =Traslación_Pagos_1!D48 -> -32200 | F21: =Traslación_Pagos_1!E48 -> -81020 | G21: =Traslación_Pagos_1!F48 -> -32200 | H21: =Traslación_Pagos_1!G48 -> -32200 | I21: =Traslación_Pagos_1!H48 -> -32200 | J21: =Traslación_Pagos_1!I48 -> -32200 | K21: =Traslación_Pagos_1!J48 -> -32200 | ... O21: =Traslación_Pagos_1!N48 -> -32200 | Q21: =SUM(D21:O21) -> -426820
C22: COSTES DE PERSONAL | D22: =SUM(D17:D21) -> -102228.57 | E22: =SUM(E17:E21) -> -189125.71 | F22: =SUM(F17:F21) -> -130305.71 | G22: =SUM(G17:G21) -> -122294.29 | H22: =SUM(H17:H21) -> -81485.714 | I22: =SUM(I17:I21) -> -81485.714 | J22: =SUM(J17:J21) -> -162314.29 | K22: =SUM(K17:K21) -> -81485.714 | ... O22: =SUM(O17:O21) -> -130771.43 | Q22: =SUM(Q17:Q21) -> -1349611.4
C23: Compra de materias primas | D23: =Traslación_Pagos_1!C50 -> -63323.333 | E23: =Traslación_Pagos_1!D50 -> -58886.667 | F23: =Traslación_Pagos_1!E50 -> -61306.667 | G23: =Traslación_Pagos_1!F50 -> -64331.667 | H23: =Traslación_Pagos_1!G50 -> -61710 | I23: =Traslación_Pagos_1!H50 -> -69373.333 | J23: =Traslación_Pagos_1!I50 -> -70180 | K23: =Traslación_Pagos_1!J50 -> -68970 | ... O23: =Traslación_Pagos_1!N50 -> -47190 | Q23: =SUM(D23:O23) -> -711681.67
C24: Compra de otros materiales para producción | D24: =Traslación_Pagos_1!C51 -> -37510 | E24: =Traslación_Pagos_1!D51 -> -34686.667 | F24: =Traslación_Pagos_1!E51 -> -33073.333 | G24: =Traslación_Pagos_1!F51 -> -30653.333 | H24: =Traslación_Pagos_1!G51 -> -29443.333 | I24: =Traslación_Pagos_1!H51 -> -29443.333 | J24: =Traslación_Pagos_1!I51 -> -26216.667 | K24: =Traslación_Pagos_1!J51 -> -23796.667 | ... O24: =Traslación_Pagos_1!N51 -> -19763.333 | Q24: =SUM(D24:O24) -> -323070
C25: COMPRAS A PROVEEDORES | D25: =SUM(D23:D24) -> -100833.33 | E25: =SUM(E23:E24) -> -93573.333 | F25: =SUM(F23:F24) -> -94380 | G25: =SUM(G23:G24) -> -94985 | H25: =SUM(H23:H24) -> -91153.333 | I25: =SUM(I23:I24) -> -98816.667 | J25: =SUM(J23:J24) -> -96396.667 | K25: =SUM(K23:K24) -> -92766.667 | ... O25: =SUM(O23:O24) -> -66953.333 | Q25: =SUM(Q23:Q24) -> -1034751.7
C26: Alquileres | D26: =Traslación_Pagos_1!C53 -> -18360 | E26: =Traslación_Pagos_1!D53 -> -18360 | F26: =Traslación_Pagos_1!E53 -> -18360 | G26: =Traslación_Pagos_1!F53 -> -18360 | H26: =Traslación_Pagos_1!G53 -> -18360 | I26: =Traslación_Pagos_1!H53 -> -18360 | J26: =Traslación_Pagos_1!I53 -> -18360 | K26: =Traslación_Pagos_1!J53 -> -18360 | ... O26: =Traslación_Pagos_1!N53 -> -18360 | Q26: =SUM(D26:O26) -> -220320
C27: Serv. Profesionales Independientes | D27: =Traslación_Pagos_1!C54 -> -4080 | E27: =Traslación_Pagos_1!D54 -> -16320 | F27: =Traslación_Pagos_1!E54 -> -4080 | G27: =Traslación_Pagos_1!F54 -> -4080 | H27: =Traslación_Pagos_1!G54 -> -6120 | I27: =Traslación_Pagos_1!H54 -> -4080 | J27: =Traslación_Pagos_1!I54 -> -4080 | K27: =Traslación_Pagos_1!J54 -> -6120 | ... O27: =Traslación_Pagos_1!N54 -> -4080 | Q27: =SUM(D27:O27) -> -67320
C28: Transporte | D28: =Traslación_Pagos_1!C55 -> -13854.5 | E28: =Traslación_Pagos_1!D55 -> -15246 | F28: =Traslación_Pagos_1!E55 -> -15609 | G28: =Traslación_Pagos_1!F55 -> -18876 | H28: =Traslación_Pagos_1!G55 -> -18089.5 | I28: =Traslación_Pagos_1!H55 -> -18936.5 | J28: =Traslación_Pagos_1!I55 -> -14278 | K28: =Traslación_Pagos_1!J55 -> -19662.5 | ... O28: =Traslación_Pagos_1!N55 -> -19178.5 | Q28: =SUM(D28:O28) -> -207575.5
C29: Seguros | D29: =Traslación_Pagos_1!C56 -> 0 | E29: =Traslación_Pagos_1!D56 -> -45000 | F29: =Traslación_Pagos_1!E56 -> 0 | G29: =Traslación_Pagos_1!F56 -> 0 | H29: =Traslación_Pagos_1!G56 -> 0 | I29: =Traslación_Pagos_1!H56 -> 0 | J29: =Traslación_Pagos_1!I56 -> 0 | K29: =Traslación_Pagos_1!J56 -> 0 | ... O29: =Traslación_Pagos_1!N56 -> 0 | Q29: =SUM(D29:O29) -> -45000
C30: Publicidad y Márketing | D30: =Traslación_Pagos_1!C57 -> -9075 | E30: =Traslación_Pagos_1!D57 -> -3025 | F30: =Traslación_Pagos_1!E57 -> -3025 | G30: =Traslación_Pagos_1!F57 -> -3025 | H30: =Traslación_Pagos_1!G57 -> -3025 | I30: =Traslación_Pagos_1!H57 -> -3025 | J30: =Traslación_Pagos_1!I57 -> -3025 | K30: =Traslación_Pagos_1!J57 -> -3025 | ... O30: =Traslación_Pagos_1!N57 -> -3025 | Q30: =SUM(D30:O30) -> -42350
C31: Suministros | D31: =Traslación_Pagos_1!C58 -> -5445 | E31: =Traslación_Pagos_1!D58 -> -5445 | F31: =Traslación_Pagos_1!E58 -> -5445 | G31: =Traslación_Pagos_1!F58 -> -5445 | H31: =Traslación_Pagos_1!G58 -> -5445 | I31: =Traslación_Pagos_1!H58 -> -5445 | J31: =Traslación_Pagos_1!I58 -> -5445 | K31: =Traslación_Pagos_1!J58 -> -5445 | ... O31: =Traslación_Pagos_1!N58 -> -5445 | Q31: =SUM(D31:O31) -> -65340
C32: SERVICIOS EXTERIORES | D32: =SUM(D26:D31) -> -50814.5 | E32: =SUM(E26:E31) -> -103396 | F32: =SUM(F26:F31) -> -46519 | G32: =SUM(G26:G31) -> -49786 | H32: =SUM(H26:H31) -> -51039.5 | I32: =SUM(I26:I31) -> -49846.5 | J32: =SUM(J26:J31) -> -45188 | K32: =SUM(K26:K31) -> -52612.5 | ... O32: =SUM(O26:O31) -> -50088.5 | Q32: =SUM(Q26:Q31) -> -647905.5
C33: H. Pública por Impuesto de Sociedades | D33: =Traslación_Pagos_1!C60 -> 0 | E33: =Traslación_Pagos_1!D60 -> 0 | F33: =Traslación_Pagos_1!E60 -> 0 | G33: =Traslación_Pagos_1!F60 -> -45000 | H33: =Traslación_Pagos_1!G60 -> 0 | I33: =Traslación_Pagos_1!H60 -> 0 | J33: =Traslación_Pagos_1!I60 -> -20673 | K33: =Traslación_Pagos_1!J60 -> 0 | ... O33: =Traslación_Pagos_1!N60 -> -45000 | Q33: =SUM(D33:O33) -> -155673
C34: IAE y otros tributos locales | D34: =Traslación_Pagos_1!C61 -> -28800 | E34: =Traslación_Pagos_1!D61 -> -654.54545 | F34: =Traslación_Pagos_1!E61 -> -654.54545 | G34: =Traslación_Pagos_1!F61 -> -654.54545 | H34: =Traslación_Pagos_1!G61 -> -654.54545 | I34: =Traslación_Pagos_1!H61 -> -654.54545 | J34: =Traslación_Pagos_1!I61 -> -654.54545 | K34: =Traslación_Pagos_1!J61 -> -654.54545 | ... O34: =Traslación_Pagos_1!N61 -> -654.54545 | Q34: =SUM(D34:O34) -> -36000
C35: IMPUESTOS Y TRIBUTOS | D35: =SUM(D33:D34) -> -28800 | E35: =SUM(E33:E34) -> -654.54545 | F35: =SUM(F33:F34) -> -654.54545 | G35: =SUM(G33:G34) -> -45654.545 | H35: =SUM(H33:H34) -> -654.54545 | I35: =SUM(I33:I34) -> -654.54545 | J35: =SUM(J33:J34) -> -21327.545 | K35: =SUM(K33:K34) -> -654.54545 | ... O35: =SUM(O33:O34) -> -45654.545 | Q35: =SUM(Q33:Q34) -> -191673
C36: Gastos Bancarios | D36: =Traslación_Pagos_1!C63 -> -1000 | E36: =Traslación_Pagos_1!D63 -> -1000 | F36: =Traslación_Pagos_1!E63 -> -1000 | G36: =Traslación_Pagos_1!F63 -> -1000 | H36: =Traslación_Pagos_1!G63 -> -1000 | I36: =Traslación_Pagos_1!H63 -> -1000 | J36: =Traslación_Pagos_1!I63 -> -1000 | K36: =Traslación_Pagos_1!J63 -> -1000 | ... O36: =Traslación_Pagos_1!N63 -> -1000 | Q36: =SUM(D36:O36) -> -12000
C37: Otros Gastos | D37: =Traslación_Pagos_1!C64 -> -2500 | E37: =Traslación_Pagos_1!D64 -> -2500 | F37: =Traslación_Pagos_1!E64 -> -2500 | G37: =Traslación_Pagos_1!F64 -> -2500 | H37: =Traslación_Pagos_1!G64 -> -2500 | I37: =Traslación_Pagos_1!H64 -> -2500 | J37: =Traslación_Pagos_1!I64 -> -2500 | K37: =Traslación_Pagos_1!J64 -> -2500 | ... O37: =Traslación_Pagos_1!N64 -> -2500 | Q37: =SUM(D37:O37) -> -30000
C38: PAGOS EXPLOTACIÓN (OPEX) | D38: =+D22+D25+D32+D35+D36+D37 -> -286176.4 | E38: =+E22+E25+E32+E35+E36+E37 -> -390249.59 | F38: =+F22+F25+F32+F35+F36+F37 -> -275359.26 | G38: =+G22+G25+G32+G35+G36+G37 -> -316219.83 | H38: =+H22+H25+H32+H35+H36+H37 -> -227833.09 | I38: =+I22+I25+I32+I35+I36+I37 -> -234303.43 | J38: =+J22+J25+J32+J35+J36+J37 -> -328726.5 | K38: =+K22+K25+K32+K35+K36+K37 -> -231019.43 | ... O38: =+O22+O25+O32+O35+O36+O37 -> -296967.81 | Q38: =+Q22+Q25+Q32+Q35+Q36+Q37 -> -3265941.6
B39: FLUJO CAJA EXPLOTACIÓN | D39: =+D16+D38 -> 16778.595 | E39: =+E16+E38 -> -76508.593 | F39: =+F16+F38 -> 15868.74 | G39: =+G16+G38 -> -31225.831 | H39: =+H16+H38 -> 183465.91 | I39: =+I16+I38 -> 187127.57 | J39: =+J16+J38 -> -21386.498 | K39: =+K16+K38 -> 53034.574 | ... O39: =+O16+O38 -> -5112.8074 | Q39: =+Q16+Q38 -> 812663.4
C40: (-) Compra de Activos Fijos | D40: =Traslación_Pagos_1!E34 -> -70000 | E40: =Traslación_Pagos_1!F34 -> -50000 | F40: =Traslación_Pagos_1!G34 -> -15000 | G40: =Traslación_Pagos_1!H34 -> -5000 | H40: =Traslación_Pagos_1!I34 -> -2000 | I40: =Traslación_Pagos_1!J34 -> -12000 | J40: =Traslación_Pagos_1!K34 -> -2000 | K40: =Traslación_Pagos_1!L34 -> -2000 | ... O40: =Traslación_Pagos_1!P34 -> -2000 | Q40: =SUM(D40:O40) -> -179500
C41: (+) Enajenación de Activos Fijos | Q41: =SUM(D41:O41) -> 0
...

Sheet Traslación_Pagos_2
A1: CUENTA DE RESULTADOS
B4: CUENTA DE RESULTADOS DE EXPLOTACIÓN | C4: NOV A-1 | D4: DIC A-1 | E4: ENE | F4: FEB | G4: MAR | H4: ABR | I4: MAY | J4: JUN | K4: JUL | L4: AGO | M4: SEP | N4: OCT | O4: NOV | P4: DIC | R4: FY
B5: INGRESOS POR VENTAS | C5: 383000 | D5: 229000 | E5: 252000 | F5: 258000 | G5: 312000 | H5: 299000 | I5: 313000 | J5: 236000 | K5: 325000 | L5: 266000 | M5: 359000 | N5: 265000 | O5: 317000 | P5: 282000 | R5: =+SUM(E5:P5) -> 3484000
B6: Sueldos y Salarios | C6: -42500 | D6: -42500 | E6: -57500 | F6: -57500 | G6: -57500 | H6: -57500 | I6: -57500 | J6: -57500 | K6: -57500 | L6: -57500 | M6: -57500 | N6: -57500 | O6: -57500 | P6: -57500 | R6: =+SUM(E6:P6) -> -690000 | T6: El salario anual se divide en 14 pagas, teniendo paga extra los meses de julio y diciembre.
B7: Bonus e Incentivos | C7: =+C6*0.2 -> -8500 | D7: =+D6*0.2 -> -8500 | E7: =+E6*0.2 -> -11500 | F7: =+F6*0.2 -> -11500 | G7: =+G6*0.2 -> -11500 | H7: =+H6*0.2 -> -11500 | I7: =+I6*0.2 -> -11500 | J7: =+J6*0.2 -> -11500 | ... P7: =+P6*0.2 -> -11500 | R7: =+SUM(E7:P7) -> -138000 | T7: Los bonus se pagan a final de año.
B8: Seguridad Social Empresa | C8: =+(C7+C6*0.3) -> -21250 | D8: =+(D7+D6*0.3) -> -21250 | E8: =+(E7+E6*0.3) -> -28750 | F8: =+(F7+F6*0.3) -> -28750 | G8: =+(G7+G6*0.3) -> -28750 | H8: =+(H7+H6*0.3) -> -28750 | I8: =+(I7+I6*0.3) -> -28750 | J8: =+(J7+J6*0.3) -> -28750 | ... P8: =+(P7+P6*0.3) -> -28750 | R8: =+SUM(E8:P8) -> -345000
B9: COSTES DE PERSONAL | C9: =SUM(C6:C8) -> -72250 | D9: =SUM(D6:D8) -> -72250 | E9: =SUM(E6:E8) -> -97750 | F9: =SUM(F6:F8) -> -97750 | G9: =SUM(G6:G8) -> -97750 | H9: =SUM(H6:H8) -> -97750 | I9: =SUM(I6:I8) -> -97750 | J9: =SUM(J6:J8) -> -97750 | ... P9: =SUM(P6:P8) -> -97750 | R9: =+SUM(E9:P9) -> -1173000
B10: Compra de materias primas | C10: -54000 | D10: -49000 | E10: -48000 | F10: -56000 | G10: -47500 | H10: -58000 | I10: -56000 | J10: -62000 | K10: -47000 | L10: -35000 | M10: -42000 | N10: -38000 | O10: -41000 | P10: -47000 | R10: =+SUM(E10:P10) -> -577500 | T10: Un tercio de nuestros proveedores son empresas cuyos plazos de pago están amparados por la legislación comercial de protección a pequeñas empresas por lo que son a 30 días. Todos aplican un 21% de IVA. El resto de los proveedores tiene plazos de pago entre 45 y 90 días.
B11: Compra de otros materiales para producción | C11: -32000 | D11: -29000 | E11: -28000 | F11: -26000 | G11: -24000 | H11: -25000 | I11: -23000 | J11: -19000 | K11: -21000 | L11: -17000 | M11: -12000 | N11: -16000 | O11: -17000 | P11: -19000 | R11: =+SUM(E11:P11) -> -247000
B12: COMPRAS A PROVEEDORES | C12: =SUM(C10:C11) -> -86000 | D12: =SUM(D10:D11) -> -78000 | E12: =SUM(E10:E11) -> -76000 | F12: =SUM(F10:F11) -> -82000 | G12: =SUM(G10:G11) -> -71500 | H12: =SUM(H10:H11) -> -83000 | I12: =SUM(I10:I11) -> -79000 | J12: =SUM(J10:J11) -> -81000 | ... P12: =SUM(P10:P11) -> -66000 | R12: =+SUM(E12:P12) -> -824500
B13: Alquileres | C13: -16500 | D13: -16500 | E13: -18000 | F13: -18000 | G13: -18000 | H13: -18000 | I13: -18000 | J13: -18000 | K13: -18000 | L13: -18000 | M13: -18000 | N13: -18000 | O13: -18000 | P13: -18000 | R13: =+SUM(E13:P13) -> -216000 | T13: Negociar para relaizar dos paganos anuales
B14: Serv. Profesionales Independientes | C14: -4000 | D14: -4000 | E14: -16000 | F14: -4000 | G14: -4000 | H14: -6000 | I14: -4000 | J14: -4000 | K14: -6000 | L14: -4000 | M14: -4000 | N14: -6000 | O14: -4000 | P14: -4000 | R14: =+SUM(E14:P14) -> -66000 | T14: Se pagan a 30 días
B15: Transporte | C15: -19150 | D15: -11450 | E15: -12600 | F15: -12900 | G15: -15600 | H15: -14950 | I15: -15650 | J15: -11800 | K15: -16250 | L15: -13300 | M15: -17950 | N15: -13250 | O15: -15850 | P15: -14100 | R15: =+SUM(E15:P15) -> -174200 | T15: Se pagan a 30 días
B16: Seguros | C16: -3750 | D16: -3750 | E16: -3750 | F16: -3750 | G16: -3750 | H16: -3750 | I16: -3750 | J16: -3750 | K16: -3750 | L16: -3750 | M16: -3750 | N16: -3750 | O16: -3750 | P16: -3750 | R16: =+SUM(E16:P16) -> -45000 | T16: La póliza anual de seguros se renueva en febrero
B17: Publicidad y Márketing | C17: -2500 | D17: -7500 | E17: -2500 | F17: -2500 | G17: -2500 | H17: -2500 | I17: -2500 | J17: -2500 | K17: -2500 | L17: -2500 | M17: -2500 | N17: -2500 | O17: -2500 | P17: -7500 | R17: =+SUM(E17:P17) -> -35000 | T17: Se pagan a 30 días
B18: Suministros | C18: -4500 | D18: -4500 | E18: -4500 | F18: -4500 | G18: -4500 | H18: -4500 | I18: -4500 | J18: -4500 | K18: -4500 | L18: -4500 | M18: -4500 | N18: -4500 | O18: -4500 | P18: -4500 | R18: =+SUM(E18:P18) -> -54000 | T18: Se pagan a mes vencido.
B19: SERVICIOS EXTERIORES | C19: =SUM(C13:C18) -> -50400 | D19: =SUM(D13:D18) -> -47700 | E19: =SUM(E13:E18) -> -57350 | F19: =SUM(F13:F18) -> -45650 | G19: =SUM(G13:G18) -> -48350 | H19: =SUM(H13:H18) -> -49700 | I19: =SUM(I13:I18) -> -48400 | J19: =SUM(J13:J18) -> -44550 | ... P19: =SUM(P13:P18) -> -51850 | R19: =+SUM(E19:P19) -> -590200
B20: H. Pública por Impuesto de Sociedades | C20: -35248.5 | D20: -5155.5 | E20: -3024 | F20: -5481 | G20: -18459 | H20: -13030.5 | I20: -17083.5 | J20: -1302 | K20: -21367.5 | L20: -9177 | M20: -30040.5 | N20: -7507.5 | O20: -18091.5 | P20: -11109 | R20: =+SUM(E20:P20) -> -155673 | T20: Se hacen pagos a cuenta en abril, octubre y diciembre y el pago de la liquidación es en Julio.
B21: IAE y otros tributos locales | C21: -3000 | D21: -3000 | E21: -3000 | F21: -3000 | G21: -3000 | H21: -3000 | I21: -3000 | J21: -3000 | K21: -3000 | L21: -3000 | M21: -3000 | N21: -3000 | O21: -3000 | P21: -3000 | R21: =+SUM(E21:P21) -> -36000 | T21: El IAE supone un 80% de este epígrafe y se paga en enero, el resto se paga mensualmente.
B22: IMPUESTOS Y TRIBUTOS | C22: =SUM(C20:C21) -> -38248.5 | D22: =SUM(D20:D21) -> -8155.5 | E22: =SUM(E20:E21) -> -6024 | F22: =SUM(F20:F21) -> -8481 | G22: =SUM(G20:G21) -> -21459 | H22: =SUM(H20:H21) -> -16030.5 | I22: =SUM(I20:I21) -> -20083.5 | J22: =SUM(J20:J21) -> -4302 | ... P22: =SUM(P20:P21) -> -14109 | R22: =+SUM(E22:P22) -> -191673
B23: Gastos Bancarios | C23: -1000 | D23: -1000 | E23: -1000 | F23: -1000 | G23: -1000 | H23: -1000 | I23: -1000 | J23: -1000 | K23: -1000 | L23: -1000 | M23: -1000 | N23: -1000 | O23: -1000 | P23: -1000 | R23: =+SUM(E23:P23) -> -12000
B24: Otros Gastos | C24: -2500 | D24: -2500 | E24: -2500 | F24: -2500 | G24: -2500 | H24: -2500 | I24: -2500 | J24: -2500 | K24: -2500 | L24: -2500 | M24: -2500 | N24: -2500 | O24: -2500 | P24: -2500 | R24: =+SUM(E24:P24) -> -30000
B25: TOTAL GASTOS EXPLOTACIÓN | C25: =+C9+C12+C19+C22+C23+C24 -> -250398.5 | D25: =+D9+D12+D19+D22+D23+D24 -> -209605.5 | E25: =+E9+E12+E19+E22+E23+E24 -> -240624 | F25: =+F9+F12+F19+F22+F23+F24 -> -237381 | G25: =+G9+G12+G19+G22+G23+G24 -> -242559 | H25: =+H9+H12+H19+H22+H23+H24 -> -249980.5 | I25: =+I9+I12+I19+I22+I23+I24 -> -248733.5 | J25: =+J9+J12+J19+J22+J23+J24 -> -231102 | ... P25: =+P9+P12+P19+P22+P23+P24 -> -233209 | R25: =+SUM(E25:P25) -> -2821373
B27: MARGEN DE EXPLOTACIÓN | C27: =+C5+C25 -> 132601.5 | D27: =+D5+D25 -> 19394.5 | E27: =+E5+E25 -> 11376 | F27: =+F5+F25 -> 20619 | G27: =+G5+G25 -> 69441 | H27: =+H5+H25 -> 49019.5 | I27: =+I5+I25 -> 64266.5 | J27: =+J5+J25 -> 4898 | ... P27: =+P5+P25 -> 48791 | R27: =+SUM(E27:P27) -> 662627
B30: Presupuesto de Capital:
B31: Elabora el cuadro de operaciones financieras que incluya, al menos, dos líneas de financiación a corto plazo, un préstamo a largo plazo y varios depósitos a corto plazo en función de la liquidez obtenida.
B33: La compra de activos fijos se prevé según la periodificación adjunta:
B34: Compra de Activos Fijos | E34: -70000 | F34: -50000 | G34: -15000 | H34: -5000 | I34: -2000 | J34: -12000 | K34: -2000 | L34: -2000 | M34: -9000 | N34: -8500 | O34: -2000 | P34: -2000 | R34: =+SUM(E34:P34) -> -179500
B36: Tipo IVA | C36: 0.21
B37: Tipo Seguridad Social Trabajador | C37: 0.06
B38: Tipo Seguridad Social Empresa | C38: 0.33
B39: Tipo Retención Trabajadores | C39: 0.16
B40: Tipo Retención Alquileres y Profesionales | C40: 0.19
B43: PRESUPUESTO DE TESORERÍA | C43: ENE | D43: FEB | E43: MAR | F43: ABR | G43: MAY | H43: JUN | I43: JUL | J43: AGO | K43: SEP | L43: OCT | M43: NOV | N43: DIC
B44: Nómina mensual | C44: =$R$6/14 -> -49285.714 | D44: =$R$6/14 -> -49285.714 | E44: =$R$6/14 -> -49285.714 | F44: =$R$6/14 -> -49285.714 | G44: =$R$6/14 -> -49285.714 | H44: =$R$6/14 -> -49285.714 | I44: =$R$6/14 -> -49285.714 | J44: =$R$6/14 -> -49285.714 | ... N44: =$R$6/14 -> -49285.714
B45: Pagas Extras | I45: =+I44 -> -49285.714 | N45: =+N44 -> -49285.714
B46: Retenciones a trabajadores | C46: =D6*12/14*2*C39*2+C6*12/14*C39 -> -29142.857 | F46: =+E6*12/14*C39+F6*12/14*C39+D47/(1-C37-C39)*C39+G6*12/14*C37 -> -18728.571 | I46: =H6*12/14*C39+I6*12/14*C39+J6*12/14*2*C39 -> -31542.857 | L46: =K6*12/14*C39+L6*12/14*C39+M6*12/14*C39 -> -23657.143
B47: Bonus e Incentivos | N47: =$R$7*(1-$C$37-$C$39) -> -107640
B48: Seguridad Social | C48: =D6*$C$37+D8 -> -23800 | D48: =E6*$C$37+E8 -> -32200 | E48: =F6*C39+F13+D47/(1-C37-C39)*39% -> -27200 | F48: =G6*$C$37+G8 -> -32200 | G48: =H6*$C$37+H8 -> -32200 | H48: =I6*$C$37+I8 -> -32200 | I48: =J6*$C$37+J8 -> -32200 | J48: =K6*$C$37+K8 -> -32200 | K48: =L6*$C$37+L8 -> -32200 | L48: =M6*$C$37+M8 -> -32200 | M48: =N6*$C$37+N8 -> -32200 | N48: =O6*$C$37+O8 -> -32200
B49: COSTES DE PERSONAL | C49: =SUM(C44:C48) -> -102228.57 | D49: =SUM(D44:D48) -> -81485.714 | E49: =SUM(E44:E48) -> -76485.714 | F49: =SUM(F44:F48) -> -100214.29 | G49: =SUM(G44:G48) -> -81485.714 | H49: =SUM(H44:H48) -> -81485.714 | I49: =SUM(I44:I48) -> -162314.29 | J49: =SUM(J44:J48) -> -81485.714 | ... N49: =SUM(N44:N48) -> -238411.43
...

Sheet Presupuesto_Tesoreria_2
A1: CONSOLIDACIÓN Y ANÁLISIS
B3: PRESUPUESTO DE TESORERÍA | D3: ENE | E3: FEB | F3: MAR | G3: ABR | H3: MAY | I3: JUN | J3: JUL | K3: AGO | L3: SEP | M3: OCT | N3: NOV | O3: DIC | Q3: TOTAL
B4: SALDO INICIAL | D4: 45000 | E4: =+D47 -> 10138.595 | F4: =+E47 -> 9630.0022 | G4: =+F47 -> 28858.742 | H4: =+G47 -> 10992.911 | I4: =+H47 -> 210818.82 | J4: =+I47 -> 294146.39 | K4: =+J47 -> 289119.89 | L4: =+K47 -> 358514.47 | ... O4: =+N47 -> 884716.21 | Q4: =+D4 -> 45000
C5: Cliente TOP 1 | D5: =Traslación_Cobros!E21 -> 25410 | E5: =Traslación_Cobros!F21 -> 38720 | F5: =Traslación_Cobros!G21 -> 41140 | G5: =Traslación_Cobros!H21 -> 25410 | H5: =Traslación_Cobros!I21 -> 30250 | I5: =Traslación_Cobros!J21 -> 54450 | J5: =Traslación_Cobros!K21 -> 12100 | K5: =Traslación_Cobros!L21 -> 54450 | ... O5: =Traslación_Cobros!P21 -> 20570 | Q5: =SUM(D5:O5) -> 421080
C6: Cliente TOP 2 | D6: =Traslación_Cobros!E22 -> 31460 | E6: =Traslación_Cobros!F22 -> 7260 | F6: =Traslación_Cobros!G22 -> 4840 | G6: =Traslación_Cobros!H22 -> 60500 | H6: =Traslación_Cobros!I22 -> 71390 | I6: =Traslación_Cobros!J22 -> 12100 | J6: =Traslación_Cobros!K22 -> 44770 | K6: =Traslación_Cobros!L22 -> 14520 | ... O6: =Traslación_Cobros!P22 -> 36300 | Q6: =SUM(D6:O6) -> 442860
C7: Cliente TOP 3 | D7: =Traslación_Cobros!E23 -> 38720 | E7: =Traslación_Cobros!F23 -> 24926 | F7: =Traslación_Cobros!G23 -> 44528 | G7: =Traslación_Cobros!H23 -> 47674 | H7: =Traslación_Cobros!I23 -> 53724 | I7: =Traslación_Cobros!J23 -> 37026 | J7: =Traslación_Cobros!K23 -> 59290 | K7: =Traslación_Cobros!L23 -> 18634 | ... O7: =Traslación_Cobros!P23 -> 48400 | Q7: =SUM(D7:O7) -> 469480
C8: Cliente TOP 4 | D8: =Traslación_Cobros!E24 -> 42350 | E8: =Traslación_Cobros!F24 -> 31460 | F8: =Traslación_Cobros!G24 -> 31460 | G8: =Traslación_Cobros!H24 -> 29040 | H8: =Traslación_Cobros!I24 -> 45375 | I8: =Traslación_Cobros!J24 -> 44165 | J8: =Traslación_Cobros!K24 -> 19965 | K8: =Traslación_Cobros!L24 -> 16335 | ... O8: =Traslación_Cobros!P24 -> 33275 | Q8: =SUM(D8:O8) -> 419870
C9: Cliente TOP 5 | D9: =Traslación_Cobros!E25 -> 18000 | E9: =Traslación_Cobros!F25 -> 45000 | F9: =Traslación_Cobros!G25 -> 41000 | G9: =Traslación_Cobros!H25 -> 5000 | H9: =Traslación_Cobros!I25 -> 46000 | I9: =Traslación_Cobros!J25 -> 45000 | J9: =Traslación_Cobros!K25 -> 0 | K9: =Traslación_Cobros!L25 -> 21000 | ... O9: =Traslación_Cobros!P25 -> 19000 | Q9: =SUM(D9:O9) -> 327000
C10: Cliente TOP 6 | D10: =Traslación_Cobros!E26 -> 11495 | E10: =Traslación_Cobros!F26 -> 16335 | F10: =Traslación_Cobros!G26 -> 30250 | G10: =Traslación_Cobros!H26 -> 34485 | H10: =Traslación_Cobros!I26 -> 43560 | I10: =Traslación_Cobros!J26 -> 50820 | J10: =Traslación_Cobros!K26 -> 33880 | K10: =Traslación_Cobros!L26 -> 33275 | ... O10: =Traslación_Cobros!P26 -> 29645 | Q10: =SUM(D10:O10) -> 430760
C11: Cliente TOP 7 | D11: =Traslación_Cobros!E27 -> 0 | E11: =Traslación_Cobros!F27 -> 6050 | F11: =Traslación_Cobros!G27 -> 37510 | G11: =Traslación_Cobros!H27 -> 27830 | H11: =Traslación_Cobros!I27 -> 31460 | I11: =Traslación_Cobros!J27 -> 49610 | J11: =Traslación_Cobros!K27 -> 37510 | K11: =Traslación_Cobros!L27 -> 18150 | ... O11: =Traslación_Cobros!P27 -> 0 | Q11: =SUM(D11:O11) -> 321860
C12: Cliente TOP 8 | D12: =Traslación_Cobros!E28 -> 53845 | E12: =Traslación_Cobros!F28 -> 38115 | F12: =Traslación_Cobros!G28 -> 7865 | G12: =Traslación_Cobros!H28 -> 2420 | H12: =Traslación_Cobros!I28 -> 11495 | I12: =Traslación_Cobros!J28 -> 26015 | J12: =Traslación_Cobros!K28 -> 40535 | K12: =Traslación_Cobros!L28 -> 23595 | ... O12: =Traslación_Cobros!P28 -> 35695 | Q12: =SUM(D12:O12) -> 339405
C13: Cliente TOP 9 | D13: =Traslación_Cobros!E29 -> 43560 | E13: =Traslación_Cobros!F29 -> 49610 | F13: =Traslación_Cobros!G29 -> 14520 | G13: =Traslación_Cobros!H29 -> 0 | H13: =Traslación_Cobros!I29 -> 27830 | I13: =Traslación_Cobros!J29 -> 33880 | J13: =Traslación_Cobros!K29 -> 30250 | K13: =Traslación_Cobros!L29 -> 29040 | ... O13: =Traslación_Cobros!P29 -> 0 | Q13: =SUM(D13:O13) -> 294030
C14: Cliente TOP 10 | D14: =Traslación_Cobros!E30 -> 0 | E14: =Traslación_Cobros!F30 -> 21780 | F14: =Traslación_Cobros!G30 -> 0 | G14: =Traslación_Cobros!H30 -> 6050 | H14: =Traslación_Cobros!I30 -> 0 | I14: =Traslación_Cobros!J30 -> 35090 | J14: =Traslación_Cobros!K30 -> 0 | K14: =Traslación_Cobros!L30 -> 20570 | ... O14: =Traslación_Cobros!P30 -> 15730 | Q14: =SUM(D14:O14) -> 162140
C15: Resto Clientes | D15: =Traslación_Cobros!E31 -> 38115 | E15: =Traslación_Cobros!F31 -> 34485 | F15: =Traslación_Cobros!G31 -> 38115 | G15: =Traslación_Cobros!H31 -> 46585 | H15: =Traslación_Cobros!I31 -> 50215 | I15: =Traslación_Cobros!J31 -> 33275 | J15: =Traslación_Cobros!K31 -> 29040 | K15: =Traslación_Cobros!L31 -> 34485 | ... O15: =Traslación_Cobros!P31 -> 53240 | Q15: =SUM(D15:O15) -> 450120
C16: COBROS EXPLOTACIÓN | D16: =SUM(D5:D15) -> 302955 | E16: =SUM(E5:E15) -> 313741 | F16: =SUM(F5:F15) -> 291228 | G16: =SUM(G5:G15) -> 284994 | H16: =SUM(H5:H15) -> 411299 | I16: =SUM(I5:I15) -> 421431 | J16: =SUM(J5:J15) -> 307340 | K16: =SUM(K5:K15) -> 284054 | ... O16: =SUM(O5:O15) -> 291855 | Q16: =SUM(Q5:Q15) -> 4078605
C17: Nómina mensual | D17: =Traslación_Pagos_1!C44 -> -49285.714 | E17: =Traslación_Pagos_1!D44 -> -49285.714 | F17: =Traslación_Pagos_1!E44 -> -49285.714 | G17: =Traslación_Pagos_1!F44 -> -49285.714 | H17: =Traslación_Pagos_1!G44 -> -49285.714 | I17: =Traslación_Pagos_1!H44 -> -49285.714 | J17: =Traslación_Pagos_1!I44 -> -49285.714 | K17: =Traslación_Pagos_1!J44 -> -49285.714 | ... O17: =Traslación_Pagos_1!N44 -> -49285.714 | Q17: =SUM(D17:O17) -> -591428.57
C18: Pagas Extras | D18: =Traslación_Pagos_1!C45 -> 0 | E18: =Traslación_Pagos_1!D45 -> 0 | F18: =Traslación_Pagos_1!E45 -> 0 | G18: =Traslación_Pagos_1!F45 -> 0 | H18: =Traslación_Pagos_1!G45 -> 0 | I18: =Traslación_Pagos_1!H45 -> 0 | J18: =Traslación_Pagos_1!I45 -> -49285.714 | K18: =Traslación_Pagos_1!J45 -> 0 | ... O18: =Traslación_Pagos_1!N45 -> -49285.714 | Q18: =SUM(D18:O18) -> -98571.429
C19: Retenciones a trabajadores | D19: =Traslación_Pagos_1!C46 -> -29142.857 | E19: =Traslación_Pagos_1!D46 -> 0 | F19: =Traslación_Pagos_1!E46 -> 0 | G19: =Traslación_Pagos_1!F46 -> -40808.571 | H19: =Traslación_Pagos_1!G46 -> 0 | I19: =Traslación_Pagos_1!H46 -> 0 | J19: =Traslación_Pagos_1!I46 -> -31542.857 | K19: =Traslación_Pagos_1!J46 -> 0 | ... O19: =Traslación_Pagos_1!N46 -> 0 | Q19: =SUM(D19:O19) -> -125151.43
C20: Bonus e Incentivos | D20: =Traslación_Pagos_2!C47 -> 0 | E20: =Traslación_Pagos_2!D47 -> 0 | F20: =Traslación_Pagos_2!E47 -> 0 | G20: =Traslación_Pagos_2!F47 -> 0 | H20: =Traslación_Pagos_2!G47 -> 0 | I20: =Traslación_Pagos_2!H47 -> 0 | J20: =Traslación_Pagos_2!I47 -> 0 | K20: =Traslación_Pagos_2!J47 -> 0 | ... O20: =Traslación_Pagos_2!N47 -> -107640 | Q20: =SUM(D20:O20) -> -107640
C21: Seguridad Social | D21: =Traslación_Pagos_1!C48 -> -23800 | E21: =Traslación_Pagos_1!D48 -> -32200 | F21: =Traslación_Pagos_1!E48 -> -81020 | G21: =Traslación_Pagos_1!F48 -> -32200 | H21: =Traslación_Pagos_1!G48 -> -32200 | I21: =Traslación_Pagos_1!H48 -> -32200 | J21: =Traslación_Pagos_1!I48 -> -32200 | K21: =Traslación_Pagos_1!J48 -> -32200 | ... O21: =Traslación_Pagos_1!N48 -> -32200 | Q21: =SUM(D21:O21) -> -426820
C22: COSTES DE PERSONAL | D22: =SUM(D17:D21) -> -102228.57 | E22: =SUM(E17:E21) -> -81485.714 | F22: =SUM(F17:F21) -> -130305.71 | G22: =SUM(G17:G21) -> -122294.29 | H22: =SUM(H17:H21) -> -81485.714 | I22: =SUM(I17:I21) -> -81485.714 | J22: =SUM(J17:J21) -> -162314.29 | K22: =SUM(K17:K21) -> -81485.714 | ... O22: =SUM(O17:O21) -> -238411.43 | Q22: =SUM(Q17:Q21) -> -1349611.4
C23: Compra de materias primas | D23: =Traslación_Pagos_1!C50 -> -63323.333 | E23: =Traslación_Pagos_1!D50 -> -58886.667 | F23: =Traslación_Pagos_1!E50 -> -61306.667 | G23: =Traslación_Pagos_1!F50 -> -64331.667 | H23: =Traslación_Pagos_1!G50 -> -61710 | I23: =Traslación_Pagos_1!H50 -> -69373.333 | J23: =Traslación_Pagos_1!I50 -> -70180 | K23: =Traslación_Pagos_1!J50 -> -68970 | ... O23: =Traslación_Pagos_1!N50 -> -47190 | Q23: =SUM(D23:O23) -> -711681.67
C24: Compra de otros materiales para producción | D24: =Traslación_Pagos_1!C51 -> -37510 | E24: =Traslación_Pagos_1!D51 -> -34686.667 | F24: =Traslación_Pagos_1!E51 -> -33073.333 | G24: =Traslación_Pagos_1!F51 -> -30653.333 | H24: =Traslación_Pagos_1!G51 -> -29443.333 | I24: =Traslación_Pagos_1!H51 -> -29443.333 | J24: =Traslación_Pagos_1!I51 -> -26216.667 | K24: =Traslación_Pagos_1!J51 -> -23796.667 | ... O24: =Traslación_Pagos_1!N51 -> -19763.333 | Q24: =SUM(D24:O24) -> -323070
C25: COMPRAS A PROVEEDORES | D25: =SUM(D23:D24) -> -100833.33 | E25: =SUM(E23:E24) -> -93573.333 | F25: =SUM(F23:F24) -> -94380 | G25: =SUM(G23:G24) -> -94985 | H25: =SUM(H23:H24) -> -91153.333 | I25: =SUM(I23:I24) -> -98816.667 | J25: =SUM(J23:J24) -> -96396.667 | K25: =SUM(K23:K24) -> -92766.667 | ... O25: =SUM(O23:O24) -> -66953.333 | Q25: =SUM(Q23:Q24) -> -1034751.7
