Workbook

Sheet Datos Estructurados
C4: ACTIVO | D4: Año 5 | E4: Año 6 | F4: Año 7 | J4: ACTIVO | K4: Año 5 | L4: Año 6 | M4: Año 7
C5: Inmovilizado material bruto | D5: 7500 | E5: 175000 | F5: 250000 | J5: ACTIVO NO CORRIENTE | K5: =SUM(K6:K9) -> 90000 | L5: =SUM(L6:L9) -> 179000 | M5: =SUM(M6:M9) -> 234000
C6: Clientes y deudores | D6: 38000 | E6: 108000 | F6: 206000 | J6: Inmovilizado inmaterial | K6: 3000 | L6: 5000 | M6: 8000
C7: Inmovilizado inmaterial | D7: 3000 | E7: 5000 | F7: 8000 | J7: Tesorería | K7: 27000 | L7: 19000 | M7: 6000
C8: Existencias | D8: 123000 | E8: 162000 | F8: 203500 | J8: Inmovilizado material bruto | K8: 75000 | L8: 175000 | M8: 250000
C9: Amortizacion acumulada | D9: -15000 | E9: -20000 | F9: -30000 | J9: Amortizacion acumulada | K9: -15000 | L9: -20000 | M9: -30000
C10: Tesorería | D10: 27000 | E10: 19000 | F10: 6000 | J10: ACTIVO CORRIENTE | K10: =SUM(K11:K12) -> 161000 | L10: =SUM(L11:L12) -> 270000 | M10: =SUM(M11:M12) -> 409500
J11: Existencias | K11: 123000 | L11: 162000 | M11: 203500
J12: Clientes y deudores | K12: 38000 | L12: 108000 | M12: 206000
C13: PASIVO | D13: Año 5 | E13: Año 6 | F13: Año 7 | J13: TOTAL ACTIVO | K13: =K5+K10 -> 251000 | L13: =L5+L10 -> 449000 | M13: =M5+M10 -> 643500
C14: Capital social | D14: 25000 | E14: 25000 | F14: 65000 | J14: PASIVO | K14: Año 5 | L14: Año 6 | M14: Año 7
C15: Deudas bancarias a L.P. | D15: 42000 | E15: 136931 | F15: 209356 | J15: PATRIMONIO NETO | K15: =SUM(K16:K18) -> 188675 | L15: =SUM(L16:L18) -> 204425 | M15: =SUM(M16:M18) -> 176644
C16: Pérdidas y ganancias | D16: 76125 | E16: 61425 | F16: -52425 | J16: Capital social | K16: 25000 | L16: 25000 | M16: 65000
C17: Otros acreedores | D17: 5000 | E17: 3000 | F17: 18000 | J17: Reservas | K17: 87550 | L17: 118000 | M17: 164069
C18: Reservas | D18: 87550 | E18: 118000 | F18: 164069 | J18: Pérdidas y ganancias | K18: 76125 | L18: 61425 | M18: -52425
C19: Deudas bancarias a C.P. | D19: 7000 | E19: 21000 | F19: 41000 | J19: PASIVO CORRIENTE | K19: =SUM(K20:K22) -> 66000 | L19: =SUM(L20:L22) -> 123000 | M19: =SUM(M20:M22) -> 257500
C20: Proveedores | D20: 54000 | E20: 99000 | F20: 198500 | J20: Deudas bancarias a C.P. | K20: 7000 | L20: 21000 | M20: 41000
C21: Dividendo a cuenta | D21: -45675 | E21: -15356 | F21: 0 | J21: Proveedores | K21: 54000 | L21: 99000 | M21: 198500
J22: Otros acreedores | K22: 5000 | L22: 3000 | M22: 18000
J23: PASIVO NO CORRIENTE | K23: =SUM(K24:K25) -> -3675 | L23: =SUM(L24:L25) -> 121575 | M23: =SUM(M24:M25) -> 209356
C24: CUENTA DE RESULTADOS | D24: Año 5 | E24: Año 6 | F24: Año 7 | J24: Deudas bancarias a L.P. | K24: 42000 | L24: 136931 | M24: 209356
C25: Amortizaciones | D25: 1500 | E25: 5000 | F25: 10000 | J25: Dividendo a cuenta | K25: -45675 | L25: -15356
C26: Gastos financieros | D26: 12000 | E26: 67000 | F26: 132000 | J26: TOTAL PASIVO Y PN | K26: =K15+K19+K23 -> 251000 | L26: =L15+L19+L23 -> 449000 | M26: =M15+M19+M23 -> 643500
C27: Costes de personal | D27: 210000 | E27: 364000 | F27: 618800
C28: Ventas netas | D28: 750000 | E28: 1250000 | F28: 2300000 | J28: CUENTA DE RESULTADOS | K28: Año 5 | L28: Año 6 | M28: Año 7
C29: Otros gastos de explotación | D29: 18000 | E29: 21600 | F29: 36600 | J29: Ventas netas | K29: 750000 | L29: 1250000 | M29: 2300000
C30: Ingresos Financieros | D30: 3000 | E30: 7000 | F30: 6000 | J30: TOTAL INGRESOS | K30: =K29 -> 750000 | L30: =L29 -> 1250000 | M30: =M29 -> 2300000
C31: Aprovisionamientos | D31: 410000 | E31: 717500 | F31: 1578500 | J31: Costes de personal | K31: 210000 | L31: 364000 | M31: 618800
C32: Resultados extraordinarios | D32: 0 | E32: 0 | F32: 0 | J32: Aprovisionamientos | K32: 410000 | L32: 717500 | M32: 1578500
C33: Impuesto de Sociedades | D33: 25375 | E33: 20475 | F33: -17475 | J33: Otros gastos de explotación | K33: 18000 | L33: 21600 | M33: 36600
C34: Beneficio neto | D34: 76125 | E34: 61425 | F34: -52425 | J34: EBITDA | K34: =K30-(K31+K32+K33) -> 112000 | L34: =L30-(L31+L32+L33) -> 146900 | M34: =M30-(M31+M32+M33) -> 66100
J35: Amortizaciones | K35: 1500 | L35: 5000 | M35: 10000
J36: EBIT | K36: =K34-K35 -> 110500 | L36: =L34-L35 -> 141900 | M36: =M34-M35 -> 56100
C37: Distribución de resultados | J37: Ingresos Financieros | K37: 3000 | L37: 7000 | M37: 6000
C38: A reservas | D38: 30450 | E38: 46069 | F38: -52425 | J38: Gastos financieros | K38: 12000 | L38: 67000 | M38: 132000
C39: A dividendo | D39: 45675 | E39: 15356 | F39: 0 | J39: BAI | K39: =(K37-K38)+K36 -> 101500 | L39: =(L37-L38)+L36 -> 81900 | M39: =(M37-M38)+M36 -> -69900
J40: Impuesto de Sociedades | K40: 25375 | L40: 20475 | M40: -17475
J41: BENEFICIO NETO | K41: 76125 | L41: 61425 | M41: -52425

Sheet Full3

Sheet Analisis vertical y horizontal
B2: VERTICAL | J2: HORITZONTAL
B3: ACTIVO | C3: Año 5 | D3: % | E3: Año 6 | F3: % | G3: Año 7 | H3: % | J3: ACTIVO | K3: Año 5 | L3: % | M3: Año 6 | N3: % Respecto año anterior | O3: Año 7 | P3: % Respecto año anterior
B4: ACTIVO NO CORRIENTE | C4: =SUM(C5:C7) -> 90000 | D4: =C4/C13 -> 0.35856574 | E4: =SUM(E5:E7) -> 179000 | F4: =E4/E13 -> 0.3986637 | G4: =SUM(G5:G7) -> 234000 | H4: =G4/G13 -> 0.36363636 | J4: ACTIVO NO CORRIENTE | K4: =SUM(K5:K7) -> 90000 | M4: =SUM(M5:M7) -> 179000 | N4: =(M4-K4)/K4 -> 0.98888889 | O4: =SUM(O5:O7) -> 234000 | P4: =(O4-M4)/M4 -> 0.30726257
B5: Inmovilizado inmaterial | C5: 3000 | D5: =C5/$C$4 -> 0.033333333 | E5: 5000 | F5: =E5/$E$4 -> 0.027932961 | G5: 8000 | H5: =G5/$G$4 -> 0.034188034 | J5: Inmovilizado inmaterial | K5: 3000 | M5: 5000 | N5: =(M5-K5)/K5 -> 0.66666667 | O5: 8000 | P5: =(O5-M5)/M5 -> 0.6
B6: Tesorería | C6: 27000 | D6: =C6/$C$4 -> 0.3 | E6: 19000 | F6: =E6/$E$4 -> 0.10614525 | G6: 6000 | H6: =G6/$G$4 -> 0.025641026 | J6: Tesorería | K6: 27000 | M6: 19000 | N6: =(M6-K6)/K6 -> -0.2962963 | O6: 6000 | P6: =(O6-M6)/M6 -> -0.68421053
B7: Inmovilizado material | C7: =C8+C9 -> 60000 | D7: =C7/$C$4 -> 0.66666667 | E7: =E8+E9 -> 155000 | F7: =E7/$E$4 -> 0.86592179 | G7: =G8+G9 -> 220000 | H7: =G7/$G$4 -> 0.94017094 | J7: Inmovilizado material | K7: =K8+K9 -> 60000 | M7: =M8+M9 -> 155000 | N7: =(M7-K7)/K7 -> 1.5833333 | O7: =O8+O9 -> 220000 | P7: =(O7-M7)/M7 -> 0.41935484
B8: Inmovilizado material bruto | C8: 75000 | E8: 175000 | G8: 250000 | J8: Inmovilizado material bruto | K8: 75000 | M8: 175000 | O8: 250000
B9: Amortizacion acumulada | C9: -15000 | E9: -20000 | G9: -30000 | J9: Amortizacion acumulada | K9: -15000 | M9: -20000 | O9: -30000
B10: ACTIVO CORRIENTE | C10: =SUM(C11:C12) -> 161000 | D10: =C10/C13 -> 0.64143426 | E10: =SUM(E11:E12) -> 270000 | F10: =E10/E13 -> 0.6013363 | G10: =SUM(G11:G12) -> 409500 | H10: =G10/G13 -> 0.63636364 | J10: ACTIVO CORRIENTE | K10: =SUM(K11:K12) -> 161000 | M10: =SUM(M11:M12) -> 270000 | N10: =(M10-K10)/K10 -> 0.67701863 | O10: =SUM(O11:O12) -> 409500 | P10: =(O10-M10)/M10 -> 0.51666667
B11: Existencias | C11: 123000 | D11: =C11/$C$10 -> 0.76397516 | E11: 162000 | F11: =E11/$E$10 -> 0.6 | G11: 203500 | H11: =G11/$G$10 -> 0.4969475 | J11: Existencias | K11: 123000 | M11: 162000 | N11: =(M11-K11)/K11 -> 0.31707317 | O11: 203500 | P11: =(O11-M11)/M11 -> 0.25617284
B12: Clientes y deudores | C12: 38000 | D12: =C12/$C$10 -> 0.23602484 | E12: 108000 | F12: =E12/$E$10 -> 0.4 | G12: 206000 | H12: =G12/$G$10 -> 0.5030525 | J12: Clientes y deudores | K12: 38000 | M12: 108000 | N12: =(M12-K12)/K12 -> 1.8421053 | O12: 206000 | P12: =(O12-M12)/M12 -> 0.90740741
B13: TOTAL ACTIVO | C13: =C4+C10 -> 251000 | E13: =E4+E10 -> 449000 | G13: =G4+G10 -> 643500 | J13: TOTAL ACTIVO | K13: =K4+K10 -> 251000 | M13: =M4+M10 -> 449000 | N13: =(M13-K13)/K13 -> 0.78884462 | O13: =O4+O10 -> 643500 | P13: =(O13-M13)/M13 -> 0.43318486
B14: PASIVO | C14: Año 5 | E14: Año 6 | G14: Año 7 | J14: PASIVO | K14: Año 5 | M14: Año 6 | O14: Año 7
B15: PATRIMONIO NETO | C15: =SUM(C16:C18) -> 188675 | D15: =C15/C26 -> 0.75169323 | E15: =SUM(E16:E18) -> 204425 | F15: =E15/E26 -> 0.45528953 | G15: =SUM(G16:G18) -> 176644 | H15: =G15/G26 -> 0.27450505 | J15: PATRIMONIO NETO | K15: =SUM(K16:K18) -> 188675 | M15: =SUM(M16:M18) -> 204425 | N15: =(M15-K15)/K15 -> 0.083476878 | O15: =SUM(O16:O18) -> 176644 | P15: =(O15-M15)/M15 -> -0.13589825
B16: Capital social | C16: 25000 | D16: =C16/$C$15 -> 0.13250298 | E16: 25000 | F16: =E16/$E$15 -> 0.12229424 | G16: 65000 | H16: =G16/$G$15 -> 0.36797174 | J16: Capital social | K16: 25000 | M16: 25000 | N16: =(M16-K16)/K16 -> 0 | O16: 65000 | P16: =(O16-M16)/M16 -> 1.6
B17: Reservas | C17: 87550 | D17: =C17/$C$15 -> 0.46402544 | E17: 118000 | F17: =E17/$E$15 -> 0.57722881 | G17: 164069 | H17: =G17/$G$15 -> 0.92881162 | J17: Reservas | K17: 87550 | M17: 118000 | N17: =(M17-K17)/K17 -> 0.34780126 | O17: 164069 | P17: =(O17-M17)/M17 -> 0.39041525
B18: Pérdidas y ganancias | C18: 76125 | D18: =C18/$C$15 -> 0.40347158 | E18: 61425 | F18: =E18/$E$15 -> 0.30047695 | G18: -52425 | H18: =G18/$G$15 -> -0.29678336 | J18: Pérdidas y ganancias | K18: 76125 | M18: 61425 | N18: =(M18-K18)/K18 -> -0.19310345 | O18: -52425 | P18: =(O18-M18)/M18 -> -1.8534799
B19: PASIVO CORRIENTE | C19: =SUM(C20:C23) -> 20325 | D19: =C19/C26 -> 0.080976096 | E19: =SUM(E20:E23) -> 107644 | F19: =E19/E26 -> 0.23974165 | G19: =SUM(G20:G23) -> 257500 | H19: =G19/G26 -> 0.4001554 | J19: PASIVO CORRIENTE | K19: =SUM(K20:K23) -> 20325 | M19: =SUM(M20:M23) -> 107644 | N19: =(M19-K19)/K19 -> 4.2961378 | O19: =SUM(O20:O23) -> 257500 | P19: =(O19-M19)/M19 -> 1.3921445
B20: Deudas bancarias a C.P. | C20: 7000 | D20: =C20/$C$19 -> 0.34440344 | E20: 21000 | F20: =E20/$E$19 -> 0.19508751 | G20: 41000 | H20: =G20/$G$19 -> 0.1592233 | J20: Deudas bancarias a C.P. | K20: 7000 | M20: 21000 | N20: =(M20-K20)/K20 -> 2 | O20: 41000 | P20: =(O20-M20)/M20 -> 0.95238095
B21: Proveedores | C21: 54000 | D21: =C21/$C$19 -> 2.6568266 | E21: 99000 | F21: =E21/$E$19 -> 0.91969826 | G21: 198500 | H21: =G21/$G$19 -> 0.77087379 | J21: Proveedores | K21: 54000 | M21: 99000 | N21: =(M21-K21)/K21 -> 0.83333333 | O21: 198500 | P21: =(O21-M21)/M21 -> 1.0050505
B22: Otros acreedores | C22: 5000 | D22: =C22/$C$19 -> 0.24600246 | E22: 3000 | F22: =E22/$E$19 -> 0.027869644 | G22: 18000 | H22: =G22/$G$19 -> 0.069902913 | J22: Otros acreedores | K22: 5000 | M22: 3000 | N22: =(M22-K22)/K22 -> -0.4 | O22: 18000 | P22: =(O22-M22)/M22 -> 5
B23: Dividendo a cuenta | C23: -45675 | D23: =C23/$C$19 -> -2.2472325 | E23: -15356 | F23: =E23/$E$19 -> -0.14265542 | H23: =G23/$G$19 -> 0 | J23: Dividendo a cuenta | K23: -45675 | M23: -15356 | N23: =(M23-K23)/K23 -> -0.66379858 | P23: =(O23-M23)/M23 -> -1
B24: PASIVO NO CORRIENTE | C24: =SUM(C25:C25) -> 42000 | D24: =C24/C26 -> 0.16733068 | E24: =SUM(E25:E25) -> 136931 | F24: =E24/E26 -> 0.30496882 | G24: =SUM(G25:G25) -> 209356 | H24: =G24/G26 -> 0.32533955 | J24: PASIVO NO CORRIENTE | K24: =SUM(K25:K25) -> 42000 | M24: =SUM(M25:M25) -> 136931 | N24: =(M24-K24)/K24 -> 2.2602619 | O24: =SUM(O25:O25) -> 209356 | P24: =(O24-M24)/M24 -> 0.52891602
B25: Deudas bancarias a L.P. | C25: 42000 | D25: =C25/C24 -> 1 | E25: 136931 | F25: =E25/E24 -> 1 | G25: 209356 | H25: =G25/G24 -> 1 | J25: Deudas bancarias a L.P. | K25: 42000 | M25: 136931 | N25: =(M25-K25)/K25 -> 2.2602619 | O25: 209356 | P25: =(O25-M25)/M25 -> 0.52891602
B26: TOTAL PASIVO Y PN | C26: =C15+C19+C24 -> 251000 | E26: =E15+E19+E24 -> 449000 | G26: =G15+G19+G24 -> 643500 | J26: TOTAL PASIVO Y PN | K26: =K15+K19+K24 -> 251000 | M26: =M15+M19+M24 -> 449000 | N26: =(M26-K26)/K26 -> 0.78884462 | O26: =O15+O19+O24 -> 643500 | P26: =(O26-M26)/M26 -> 0.43318486
B28: CUENTA DE RESULTADOS | C28: Año 5 | D28: Vertical | E28: Año 6 | G28: Año 7 | J28: CUENTA DE RESULTADOS | K28: Año 5 | M28: Año 6 | N28: % Respecto año anterior | O28: Año 7 | P28: % Respecto año anterior
B29: Ventas netas | C29: 750000 | E29: 1250000 | G29: 2300000 | J29: Ventas netas | K29: 750000 | M29: 1250000 | O29: 2300000
B30: TOTAL INGRESOS | C30: =C29 -> 750000 | D30: =C30/C29 -> 1 | E30: =E29 -> 1250000 | F30: =E30/E29 -> 1 | G30: =G29 -> 2300000 | H30: =G30/G29 -> 1 | J30: TOTAL INGRESOS | K30: =K29 -> 750000 | M30: =M29 -> 1250000 | N30: =(M30-K30)/K30 -> 0.66666667 | O30: =O29 -> 2300000 | P30: =(O30-M30)/M30 -> 0.84
B31: Costes de personal | C31: 210000 | D31: =C31/$C$30 -> 0.28 | E31: 364000 | F31: =E31/$E$30 -> 0.2912 | G31: 618800 | H31: =G31/$G$30 -> 0.26904348 | J31: Costes de personal | K31: 210000 | M31: 364000 | N31: =(M31-K31)/K31 -> 0.73333333 | O31: 618800 | P31: =(O31-M31)/M31 -> 0.7
B32: Aprovisionamientos | C32: 410000 | D32: =C32/$C$30 -> 0.54666667 | E32: 717500 | F32: =E32/$E$30 -> 0.574 | G32: 1578500 | H32: =G32/$G$30 -> 0.68630435 | J32: Aprovisionamientos | K32: 410000 | M32: 717500 | N32: =(M32-K32)/K32 -> 0.75 | O32: 1578500 | P32: =(O32-M32)/M32 -> 1.2
B33: Otros gastos de explotación | C33: 18000 | D33: =C33/$C$30 -> 0.024 | E33: 21600 | F33: =E33/$E$30 -> 0.01728 | G33: 36600 | H33: =G33/$G$30 -> 0.015913043 | J33: Otros gastos de explotación | K33: 18000 | M33: 21600 | N33: =(M33-K33)/K33 -> 0.2 | O33: 36600 | P33: =(O33-M33)/M33 -> 0.69444444
B34: EBITDA | C34: =C30-(C31+C32+C33) -> 112000 | D34: =C34/$C$30 -> 0.14933333 | E34: =E30-(E31+E32+E33) -> 146900 | F34: =E34/$E$30 -> 0.11752 | G34: =G30-(G31+G32+G33) -> 66100 | H34: =G34/$G$30 -> 0.02873913 | J34: EBITDA | K34: =K30-(K31+K32+K33) -> 112000 | M34: =M30-(M31+M32+M33) -> 146900 | N34: =(M34-K34)/K34 -> 0.31160714 | O34: =O30-(O31+O32+O33) -> 66100 | P34: =(O34-M34)/M34 -> -0.55003404
B35: Amortizaciones | C35: 1500 | D35: =C35/$C$30 -> 0.002 | E35: 5000 | F35: =E35/$E$30 -> 0.004 | G35: 10000 | H35: =G35/$G$30 -> 0.0043478261 | J35: Amortizaciones | K35: 1500 | M35: 5000 | N35: =(M35-K35)/K35 -> 2.3333333 | O35: 10000 | P35: =(O35-M35)/M35 -> 1
B36: EBIT | C36: =C34-C35 -> 110500 | D36: =C36/$C$30 -> 0.14733333 | E36: =E34-E35 -> 141900 | F36: =E36/$E$30 -> 0.11352 | G36: =G34-G35 -> 56100 | H36: =G36/$G$30 -> 0.024391304 | J36: EBIT | K36: =K34-K35 -> 110500 | M36: =M34-M35 -> 141900 | N36: =(M36-K36)/K36 -> 0.2841629 | O36: =O34-O35 -> 56100 | P36: =(O36-M36)/M36 -> -0.60465116
B37: Ingresos Financieros | C37: 3000 | D37: =C37/$C$30 -> 0.004 | E37: 7000 | F37: =E37/$E$30 -> 0.0056 | G37: 6000 | H37: =G37/$G$30 -> 0.0026086957 | J37: Ingresos Financieros | K37: 3000 | M37: 7000 | N37: =(M37-K37)/K37 -> 1.3333333 | O37: 6000 | P37: =(O37-M37)/M37 -> -0.14285714
B38: Gastos financieros | C38: 12000 | D38: =C38/$C$30 -> 0.016 | E38: 67000 | F38: =E38/$E$30 -> 0.0536 | G38: 132000 | H38: =G38/$G$30 -> 0.057391304 | J38: Gastos financieros | K38: 12000 | M38: 67000 | N38: =(M38-K38)/K38 -> 4.5833333 | O38: 132000 | P38: =(O38-M38)/M38 -> 0.97014925
B39: BAI | C39: =(C37-C38)+C36 -> 101500 | D39: =C39/$C$30 -> 0.13533333 | E39: =(E37-E38)+E36 -> 81900 | F39: =E39/$E$30 -> 0.06552 | G39: =(G37-G38)+G36 -> -69900 | H39: =G39/$G$30 -> -0.030391304 | J39: BAI | K39: =(K37-K38)+K36 -> 101500 | M39: =(M37-M38)+M36 -> 81900 | N39: =(M39-K39)/K39 -> -0.19310345 | O39: =(O37-O38)+O36 -> -69900 | P39: =(O39-M39)/M39 -> -1.8534799
B40: Impuesto de Sociedades | C40: 25375 | D40: =C40/$C$30 -> 0.033833333 | E40: 20475 | F40: =E40/$E$30 -> 0.01638 | G40: -17475 | H40: =G40/$G$30 -> -0.0075978261 | J40: Impuesto de Sociedades | K40: 25375 | M40: 20475 | N40: =(M40-K40)/K40 -> -0.19310345 | O40: -17475 | P40: =(O40-M40)/M40 -> -1.8534799
B41: BENEFICIO NETO | C41: 76125 | D41: =C41/$C$30 -> 0.1015 | E41: 61425 | F41: =E41/$E$30 -> 0.04914 | G41: -52425 | H41: =G41/$G$30 -> -0.022793478 | J41: BENEFICIO NETO | K41: 76125 | M41: 61425 | N41: =(M41-K41)/K41 -> -0.19310345 | O41: -52425 | P41: =(O41-M41)/M41 -> -1.8534799

Sheet Consolidació
B2: BALANCE DE SITUACION ANALISIS VERTICAL& HORITZONTAL | N2: CUENTA DE RESULTADOS
B3: ACTIVO | C3: Año 5 | D3: % V | E3: % H | F3: Año 6 | G3: % V | H3: % H | I3: Año 7 | J3: % V | K3: % H | O3: Año 5 | P3: % V | Q3: % H | R3: Año 6 | S3: % V | T3: % H | U3: Año 7 | V3: % V | W3: % H
B4: ACTIVO NO CORRIENTE | C4: =SUM(C5:C7) -> 63000 | D4: =C4/C12 -> 0.25099602 | F4: =SUM(F5:F7) -> 160000 | G4: =F4/F12 -> 0.35634744 | H4: 0.98888889 | I4: =SUM(I5:I7) -> 228000 | J4: =I4/I12 -> 0.35431235 | K4: 0.30726257 | N4: Ventas netas | O4: 750000 | R4: 1250000 | U4: 2300000
B5: Inmovilizado inmaterial | C5: 3000 | D5: =C5/$C$12 -> 0.011952191 | F5: 5000 | G5: =F5/$F$12 -> 0.011135857 | H5: 0.66666667 | I5: 8000 | J5: =I5/$I$12 -> 0.012432012 | K5: 0.6 | N5: TOTAL INGRESOS | O5: =O4 -> 750000 | P5: 1 | R5: =R4 -> 1250000 | S5: 1 | T5: 0.66666667 | U5: =U4 -> 2300000 | V5: 1 | W5: 0.84
B6: Inmovilizado material bruto | C6: 75000 | D6: =C6/$C$12 -> 0.29880478 | F6: 175000 | G6: =F6/$F$12 -> 0.38975501 | H6: 0.66666667 | I6: 250000 | J6: =I6/$I$12 -> 0.38850039 | N6: Costes de personal | O6: 210000 | P6: 0.28 | R6: 364000 | S6: 0.2912 | T6: 0.73333333 | U6: 618800 | V6: 0.26904348 | W6: 0.7
B7: Amortizacion acumulada | C7: -15000 | D7: =C7/$C$12 -> -0.059760956 | F7: -20000 | G7: =F7/$F$12 -> -0.04454343 | H7: 0.66666667 | I7: -30000 | J7: =I7/$I$12 -> -0.046620047 | N7: Aprovisionamientos | O7: 410000 | P7: 0.54666667 | R7: 717500 | S7: 0.574 | T7: 0.75 | U7: 1578500 | V7: 0.68630435 | W7: 1.2
B8: ACTIVO CORRIENTE | C8: =SUM(C9:C11) -> 188000 | D8: =C8/$C$12 -> 0.74900398 | F8: =SUM(F9:F11) -> 289000 | G8: =F8/$F$12 -> 0.64365256 | H8: 0.66666667 | I8: =SUM(I9:I11) -> 415500 | J8: =I8/$I$12 -> 0.64568765 | K8: 0.51666667 | N8: Amortizaciones | O8: 1500 | P8: 0.002 | R8: 5000 | S8: 0.004 | T8: 2.3333333 | U8: 10000 | V8: 0.0043478261 | W8: 1
B9: Existencias | C9: 123000 | D9: =C9/$C$12 -> 0.49003984 | F9: 162000 | G9: =F9/$F$12 -> 0.36080178 | H9: 0.66666667 | I9: 203500 | J9: =I9/$I$12 -> 0.31623932 | K9: 0.25617284 | N9: Otros gastos de explotación | O9: 18000 | P9: 0.024 | R9: 21600 | S9: 0.01728 | T9: 0.2 | U9: 36600 | V9: 0.015913043 | W9: 0.69444444
B10: Tesorería | C10: 27000 | D10: =C10/$C$12 -> 0.10756972 | F10: 19000 | G10: =F10/$F$12 -> 0.042316258 | H10: 0.66666667 | I10: 6000 | J10: =I10/$I$12 -> 0.0093240093 | K10: -0.68421053 | N10: Resultado de Explotación | O10: =O5-(O6+O7+O9+O8) -> 110500 | P10: 0.14933333 | R10: =R5-(R6+R7+R9) -> 146900 | S10: 0.11752 | T10: 0.31160714 | U10: =U5-(U6+U7+U9) -> 66100 | V10: 0.02873913 | W10: -0.55003404
B11: Clientes y deudores | C11: 38000 | D11: =C11/$C$12 -> 0.15139442 | F11: 108000 | G11: =F11/$F$12 -> 0.24053452 | H11: 0.66666667 | I11: 206000 | J11: =I11/$I$12 -> 0.32012432 | K11: 0.90740741 | N11: Ingresos Financieros | O11: 3000 | P11: 0.004 | R11: 7000 | S11: 0.0056 | T11: 1.3333333 | U11: 6000 | V11: 0.0026086957 | W11: -0.14285714
B12: TOTAL ACTIVO | C12: =C4+C8 -> 251000 | F12: =F4+F8 -> 449000 | H12: 0.78884462 | I12: =I4+I8 -> 643500 | K12: 0.43318486 | N12: Gastos financieros | O12: 12000 | P12: 0.016 | R12: 67000 | S12: 0.0536 | T12: 4.5833333 | U12: 132000 | V12: 0.057391304 | W12: 0.97014925
N13: Resultado Financiero | O13: =O11-O12 -> -9000 | P13: 0.14933333 | R13: =R11-R12 -> -60000 | S13: 0.11752 | T13: 0.31160714 | U13: =U11-U12 -> -126000 | V13: 0.02873913 | W13: -0.55003404
N14: Resultado Antes de impuestos | O14: =O10+O13 -> 101500 | P14: 0.13533333 | R14: =R10+R13 -> 86900 | S14: 0.06552 | T14: -0.19310345 | U14: =U10+U13 -> -59900 | V14: -0.030391304 | W14: -1.8534799
B15: PASIVO | C15: Año 5 | F15: Año 6 | I15: Año 7 | N15: Impuesto de Sociedades | O15: 25375 | P15: 0.033833333 | R15: 20475 | S15: 0.01638 | T15: -0.19310345 | U15: -17475 | V15: -0.0075978261 | W15: -1.8534799
B16: PATRIMONIO NETO | C16: =SUM(C17:C20) -> 143000 | D16: =C16/C27 -> 0.56972112 | F16: =SUM(F17:F20) -> 189069 | G16: =F16/F27 -> 0.42108909 | H16: 0.083476878 | I16: =SUM(I17:I20) -> 176644 | J16: =I16/I27 -> 0.27450505 | K16: -0.13589825 | N16: BENEFICIO NETO | O16: 76125 | P16: 0.1015 | R16: 61425 | S16: 0.04914 | T16: -0.19310345 | U16: -52425 | V16: -0.022793478 | W16: -1.8534799
B17: Capital social | C17: 25000 | D17: =C17/$C$27 -> 0.099601594 | F17: 25000 | G17: =F17/$F$27 -> 0.055679287 | H17: 0 | I17: 65000 | J17: =I17/$I$27 -> 0.1010101 | K17: 1.6
B18: Reservas | C18: 87550 | D18: =C18/$C$27 -> 0.34880478 | F18: 118000 | G18: =F18/$F$27 -> 0.26280624 | H18: 0.34780126 | I18: 164069 | J18: =I18/$I$27 -> 0.25496348 | K18: 0.39041525
B19: Pérdidas y ganancias | C19: 76125 | D19: =C19/$C$27 -> 0.30328685 | F19: 61425 | G19: =F19/$F$27 -> 0.13680401 | H19: -0.19310345 | I19: -52425 | J19: =I19/$I$27 -> -0.081468531 | K19: -1.8534799
B20: Dividendo a cuenta | C20: -45675 | D20: =C20/$C$27 -> -0.18197211 | F20: -15356 | G20: =F20/$F$27 -> -0.034200445 | H20: -0.66379858 | J20: =I20/$I$27 -> 0 | K20: -1 | N20: Fuerte crecimiento del balance con importantes incrementos en inmovilizado, clientes y existencias, debido al mayor volumen de producción que requiere la nueva línea de negocio en la que están entrando Este crecimiento se ha financiado con de deuda a largo plazo (€209M Año 7 vs €42M Año 5) y con proveedores (€199M Año 7 vs €54M Año 5); si bien la compañía ha realizado una ampliación de capital en el Año 7 por valor de €40M La apertura de la nueva línea de negocio provoca aumentos en ventas (+200% Año 7 vs Año 5) si bien esos mayores ingresos no se reflejan en un mayor “Resultado de Explotación”, puesto que los aprovisionamientos crecen más rápido que las ventas (+285% Año 7 vs Año 5). Esto implica que están instalando un mayor volumen de ventanas pero con un menor margen que cuando operaban únicamente el canal minorista El análisis vertical nos muestra como el “Resultado de Explotación” pasa de suponer un 14,7% (Año 5) a un 2,4% (Año 7) Los gastos financieros reflejan el incremento de la financiación a largo plazo que soporta el crecimiento de la compañía, y junto al empeoramiento del “Resultado de Explotación” provocan un deterioro financiero que lleva a la compañía a registrar pérdidas en el últim
B21: PASIVO NO CORRIENTE | C21: =SUM(C22:C22) -> 42000 | D21: =C21/$C$27 -> 0.16733068 | F21: =SUM(F22:F22) -> 136931 | G21: =F21/$F$27 -> 0.30496882 | H21: 2.2602619 | I21: =SUM(I22:I22) -> 209356 | J21: =I21/$I$27 -> 0.32533955 | K21: 0.52891602
B22: Deudas bancarias a L.P. | C22: 42000 | D22: =C22/$C$27 -> 0.16733068 | F22: 136931 | G22: =F22/$F$27 -> 0.30496882 | H22: 2.2602619 | I22: 209356 | J22: =I22/$I$27 -> 0.32533955 | K22: 0.52891602
B23: PASIVO CORRIENTE | C23: =SUM(C24:C26) -> 66000 | D23: =C23/$C$27 -> 0.26294821 | F23: =SUM(F24:F26) -> 123000 | G23: =F23/$F$27 -> 0.27394209 | H23: 4.2961378 | I23: =SUM(I24:I26) -> 257500 | J23: =I23/$I$27 -> 0.4001554 | K23: 1.3921445
B24: Deudas bancarias a C.P. | C24: 7000 | D24: =C24/$C$27 -> 0.027888446 | F24: 21000 | G24: =F24/$F$27 -> 0.046770601 | H24: 2 | I24: 41000 | J24: =I24/$I$27 -> 0.063714064 | K24: 0.95238095
B25: Proveedores | C25: 54000 | D25: =C25/$C$27 -> 0.21513944 | F25: 99000 | G25: =F25/$F$27 -> 0.22048998 | H25: 0.83333333 | I25: 198500 | J25: =I25/$I$27 -> 0.30846931 | K25: 1.0050505
B26: Otros acreedores | C26: 5000 | D26: =C26/$C$27 -> 0.019920319 | F26: 3000 | G26: =F26/$F$27 -> 0.0066815145 | H26: -0.4 | I26: 18000 | J26: =I26/$I$27 -> 0.027972028 | K26: 5
B27: TOTAL PASIVO Y PN | C27: =C16+C23+C21 -> 251000 | F27: =F16+F23+F21 -> 449000 | I27: =I16+I23+I21 -> 643500 | K27: 0.43318486
B30: Activo no corriente vemos que tenemos problemas de tesoreria | N30: Tenemos un crecimiento de la ventas.
B31: Aumento del inmovilizado material (maquinaria) | N31: Tenemos una aumento mu significativo de costes de fabricacion
B32: Una de las causas podria ser el aumento de deudores, vemos el gran incremento en el Año 6 | N32: Cuanto mas vendemos mas costes tenemos.
B33: Pasivo vemos una disminución del ^Patrimonio neto | N33: Los intereses de los creditos pedidos ghace que entremos en perdidas al año 7
B34: Ampliacion de capital en año 7 por falta de tesoreria y compensar las perdidas seguramente para mejorar el ratio de edeundamiento.
B35: Aumento del credito a CP para hacer frente a los problemas de tesoreria
B36: Nos cuesta hacer frente al pago de proveedores va en aumento la deuda.
B37: Para el aumento del inmovilizado aumento cdreditos L:P

Sheet SPRINT2
B4: BALANCE DE SITUACION ANALISIS VERTICAL& HORITZONTAL | G4: CUENTA DE RESULTADOS
B5: ACTIVO | C5: Año 5 | D5: Año 6 | E5: Año 7 | H5: Año 5 | I5: Año 6 | J5: Año 7
B6: ACTIVO NO CORRIENTE | C6: =SUM(C7:C9) -> 63000 | D6: =SUM(D7:D9) -> 160000 | E6: =SUM(E7:E9) -> 228000 | G6: Ventas netas | H6: 750000 | I6: 1250000 | J6: 2300000
B7: Inmovilizado inmaterial | C7: 3000 | D7: 5000 | E7: 8000 | G7: TOTAL INGRESOS | H7: =H6 -> 750000 | I7: =I6 -> 1250000 | J7: =J6 -> 2300000
B8: Inmovilizado material bruto | C8: 75000 | D8: 175000 | E8: 250000 | G8: Costes de personal | H8: 210000 | I8: 364000 | J8: 618800
B9: Amortizacion acumulada | C9: -15000 | D9: -20000 | E9: -30000 | G9: Aprovisionamientos | H9: 410000 | I9: 717500 | J9: 1578500
B10: ACTIVO CORRIENTE | C10: =SUM(C11:C13) -> 188000 | D10: =SUM(D11:D13) -> 289000 | E10: =SUM(E11:E13) -> 415500 | G10: Amortizaciones | H10: 1500 | I10: 5000 | J10: 10000
B11: Existencias | C11: 123000 | D11: 162000 | E11: 203500 | G11: Otros gastos de explotación | H11: 18000 | I11: 21600 | J11: 36600
B12: Tesorería | C12: 27000 | D12: 19000 | E12: 6000 | G12: Resultado de Explotación | H12: =H7-(H8+H9+H11+H10) -> 110500 | I12: =I7-(I8+I9+I11) -> 146900 | J12: =J7-(J8+J9+J11) -> 66100
B13: Clientes y deudores | C13: 38000 | D13: 108000 | E13: 206000 | G13: Ingresos Financieros | H13: 3000 | I13: 7000 | J13: 6000
B14: TOTAL ACTIVO | C14: =C6+C10 -> 251000 | D14: =D6+D10 -> 449000 | E14: =E6+E10 -> 643500 | G14: Gastos financieros | H14: 12000 | I14: 67000 | J14: 132000
G15: Resultado Financiero | H15: =H13-H14 -> -9000 | I15: =I13-I14 -> -60000 | J15: =J13-J14 -> -126000
G16: Resultado Antes de impuestos | H16: =H12+H15 -> 101500 | I16: =I12+I15 -> 86900 | J16: =J12+J15 -> -59900
B17: PASIVO | C17: Año 5 | D17: Año 6 | E17: Año 7 | G17: Impuesto de Sociedades | H17: 25375 | I17: 20475 | J17: -17475
B18: PATRIMONIO NETO | C18: =SUM(C19:C22) -> 143000 | D18: =SUM(D19:D22) -> 189069 | E18: =SUM(E19:E22) -> 176644 | G18: BENEFICIO NETO | H18: 76125 | I18: 61425 | J18: -52425
B19: Capital social | C19: 25000 | D19: 25000 | E19: 65000
B20: Reservas | C20: 87550 | D20: 118000 | E20: 164069
B21: Pérdidas y ganancias | C21: 76125 | D21: 61425 | E21: -52425
B22: Dividendo a cuenta | C22: -45675 | D22: -15356
B23: PASIVO NO CORRIENTE | C23: =SUM(C24:C24) -> 42000 | D23: =SUM(D24:D24) -> 136931 | E23: =SUM(E24:E24) -> 209356
B24: Deudas bancarias a L.P. | C24: 42000 | D24: 136931 | E24: 209356
B25: PASIVO CORRIENTE | C25: =SUM(C26:C28) -> 66000 | D25: =SUM(D26:D28) -> 123000 | E25: =SUM(E26:E28) -> 257500
B26: Deudas bancarias a C.P. | C26: 7000 | D26: 21000 | E26: 41000
B27: Proveedores | C27: 54000 | D27: 99000 | E27: 198500
B28: Otros acreedores | C28: 5000 | D28: 3000 | E28: 18000
B29: TOTAL PASIVO Y PN | C29: =C18+C25+C23 -> 251000 | D29: =D18+D25+D23 -> 449000 | E29: =E18+E25+E23 -> 643500
G32: Ratio /Periodo | H32: Año 5 | I32: Año 6 | J32: Año 7
G33: Rotacion Productos terminados | H33: =(H8+H9+H10+H11)/C11 -> 5.199187 | I33: =(I8+I9+I10+I11)/D11 -> 6.8401235 | J33: =(J8+J9+J10+J11)/E11 -> 11.026536
G34: Periodo PT | H34: =C11/((H8+H9+H10+H11)/360) -> 69.241595 | I34: =D11/((I8+I9+I10+I11)/360) -> 52.630629 | J34: =E11/((J8+J9+J10+J11)/360) -> 32.648514
G35: NOF | H35: =(C11+C13)-C27 -> 107000 | I35: =(D11+D13)-D27 -> 171000 | J35: =(E11+E13)-E27 -> 211000 | M35: Son las inversiones en circulante que la empresa necesita para su funcionamiento | N35: somos menos eficientes
G37: Endeudamineto | H37: =(C23+C25)/C18 -> 0.75524476 | I37: =(D23+D25)/D18 -> 1.3747944 | J37: =(E23+E25)/E18 -> 2.6429202 | M37: Ratio de endeudamiento se dispara siendo 3,5 veces mayor
G38: Endeudamiento a C.P | H38: =C25/C18 -> 0.46153846 | I38: =D25/D18 -> 0.65055615 | J38: =E25/E18 -> 1.4577342 | M38: Emperoa el ratio endeudamiento a cp
G40: Ratio estructura economica | H40: =C10/C14 -> 0.74900398 | I40: =D10/D14 -> 0.64365256 | J40: =E10/E14 -> 0.64568765 | N40: =25596/129773 -> 0.19723671
G41: Liquidez | H41: =C10/C25 -> 2.8484848 | I41: =D10/D25 -> 2.3495935 | J41: =E10/E25 -> 1.6135922 | M41: 1,5 - 2 | N41: Perdida de liquidez pero aun dentro del margen estándar
G42: Acid test | H42: =(C10-C11)/C25 -> 0.98484848 | I42: =(D10-D11)/D25 -> 1.0325203 | J42: =(E10-E11)/E25 -> 0.82330097 | M42: 1 | N42: año 7 estamos en mala posicion | Q42: Un valor de 0,82 podría sugerir que la empresa puede tener dificultades para cubrir completamente sus pasivos corrientes con sus activos líquidos.
G43: Tesoreria | H43: =C12/C25 -> 0.40909091 | I43: =D12/D25 -> 0.15447154 | J43: =E12/E25 -> 0.023300971 | M43: Grave problema deberia estar alrededor del 0,3 esta en riesgo serio de suspension de pagos
G45: ROE | H45: =H18/C19 -> 3.045 | I45: =I18/D19 -> 2.457 | J45: =J18/E19 -> -0.80653846 | M45: Benefecio obtenido en relacion capital aportado por los socios.
G46: ROA | H46: =H18/C14 -> 0.30328685 | I46: =I18/D14 -> 0.13680401 | J46: =J18/E14 -> -0.081468531 | M46: correlacion entre beneficio i el activo empleado para generarlo
G47: Payaout | H47: =-C22/H18 -> 0.6 | I47: =-D22/I18 -> 0.24999593 | J47: =-E22/J18 -> 0 | M47: % se dedica del beneficio atribuir a los accionistas
G48: Cash flow | H48: =H18+(-C9)+C20 -> 178675 | I48: =I18+(-D9)+D20 -> 199425 | J48: =J18+(-E9)+E20 -> 141644
...

Sheet Full2
B2: BALANCE DE SITUACION | F2: CUENTA DE RESULTADOS
B3: ACTIVO | C3: Año 5 | D3: Año 7 | G3: Año 5 | H3: Año 7
B4: ACTIVO NO CORRIENTE | C4: =SUM(C5:C7) -> 63000 | D4: =SUM(D5:D7) -> 228000 | F4: Ventas netas | G4: 750000 | H4: 2300000
B5: Inmovilizado inmaterial | C5: 3000 | D5: 8000 | F5: TOTAL INGRESOS | G5: =G4 -> 750000 | H5: =H4 -> 2300000
B6: Inmovilizado material bruto | C6: 75000 | D6: 250000 | F6: Costes de personal | G6: 210000 | H6: 618800
B7: Amortizacion acumulada | C7: -15000 | D7: -30000 | F7: Aprovisionamientos | G7: 410000 | H7: 1578500
B8: ACTIVO CORRIENTE | C8: =SUM(C9:C11) -> 188000 | D8: =SUM(D9:D11) -> 415500 | F8: Amortizaciones | G8: 1500 | H8: 10000
B9: Existencias | C9: 123000 | D9: 203500 | F9: Otros gastos de explotación | G9: 18000 | H9: 36600
B10: Tesorería | C10: 27000 | D10: 6000 | F10: Resultado de Explotación | G10: =G5-(G6+G7+G9+G8) -> 110500 | H10: =H5-(H6+H7+H9) -> 66100
B11: Clientes y deudores | C11: 38000 | D11: 206000 | F11: Ingresos Financieros | G11: 3000 | H11: 6000
B12: TOTAL ACTIVO | C12: =C4+C8 -> 251000 | D12: =D4+D8 -> 643500 | F12: Gastos financieros | G12: 12000 | H12: 132000
B13: PASIVO | C13: Año 5 | D13: Año 7 | F13: Resultado Financiero | G13: =G11-G12 -> -9000 | H13: =H11-H12 -> -126000
B14: PATRIMONIO NETO | C14: =SUM(C15:C18) -> 143000 | D14: =SUM(D15:D18) -> 176644 | F14: Resultado Antes de impuestos | G14: =G10+G13 -> 101500 | H14: =H10+H13 -> -59900
B15: Capital social | C15: 25000 | D15: 65000 | F15: Impuesto de Sociedades | G15: 25375 | H15: -17475
B16: Reservas | C16: 87550 | D16: 164069 | F16: BENEFICIO NETO | G16: 76125 | H16: -52425
B17: Pérdidas y ganancias | C17: 76125 | D17: -52425
B18: Dividendo a cuenta | C18: -45675
B19: PASIVO NO CORRIENTE | C19: =SUM(C20:C20) -> 42000 | D19: =SUM(D20:D20) -> 209356
B20: Deudas bancarias a L.P. | C20: 42000 | D20: 209356
B21: PASIVO CORRIENTE | C21: =SUM(C22:C24) -> 66000 | D21: =SUM(D22:D24) -> 257500
B22: Deudas bancarias a C.P. | C22: 7000 | D22: 41000
B23: Proveedores | C23: 54000 | D23: 198500
B24: Otros acreedores | C24: 5000 | D24: 18000
B25: TOTAL PASIVO Y PN | C25: =C14+C21+C19 -> 251000 | D25: =D14+D21+D19 -> 643500

Sheet TOTS RATIOS
B1: VENTANIZATE | G1: MASVENTAS S.A.
B2: Ratio de liquidez | C2: Año 5 | D2: Año 6 | E2: Año 7 | G2: Ratio de liquidez | H2: Año 5 | I2: Año 6 | J2: Año 7
B3: Activo Circulante | C3: 188000 | D3: 289000 | E3: 415500 | G3: Activo Circulante
B4: Exigible a corto Plazo | C4: 66000 | D4: 123000 | E4: 257500 | G4: Exigible a corto Plazo
B5: Ratio de liquidez | C5: =C3/C4 -> 2.8484848 | D5: =D3/D4 -> 2.3495935 | E5: =E3/E4 -> 1.6135922 | G5: Ratio de liquidez | H5: 0.6 | I5: 0.6 | J5: 0.5
B7: Clientes + Disponible | C7: 65000 | D7: 127000 | E7: 212000 | G7: Clientes + Disponible
B8: Exigible a Corto Plazo | C8: 66000 | D8: 123000 | E8: 257500 | G8: Exigible a Corto Plazo
B9: Ratio de Tesoreria | C9: =C7/C8 -> 0.98484848 | D9: =D7/D8 -> 1.0325203 | E9: =E7/E8 -> 0.82330097 | G9: Ratio de Tesoreria | H9: 0.4 | I9: 0.4 | J9: 0.4
B11: Disponible | C11: 27000 | D11: 19000 | E11: 6000 | G11: Disponible
B12: Exigible a Corto Plazo | C12: 66000 | D12: 123000 | E12: 257500 | G12: Exigible a Corto Plazo
B13: Ratio de Disponibilidad | C13: =C11/C12 -> 0.40909091 | D13: =D11/D12 -> 0.15447154 | E13: =E11/E12 -> 0.023300971 | G13: Ratio de Disponibilidad | H13: 0.3 | I13: 0.3 | J13: 0.3
B16: Periodo Medio Pago y Cobro | C16: Año 5 | D16: Año 6 | E16: Año 7 | G16: Periodo Medio Pago y Cobro | H16: Año 5 | I16: Año 6 | J16: Año 7
B17: Saldo Medio Cuentas Clientes | C17: 38000 | D17: 73000 | E17: 157000 | G17: Saldo Medio Cuentas Clientes
B18: Ventas Netas | C18: 750000 | D18: 1250000 | E18: 2300000 | G18: Ventas Netas
B19: Periodo Medio Cobro | C19: =C17/(C18/360) -> 18.24 | D19: =D17/(D18/360) -> 21.024 | E19: =E17/(E18/360) -> 24.573913 | G19: Periodo Medio Cobro | H19: 9.1 | I19: 8.1 | J19: 7.9
B21: Saldo Medio Proveedores | C21: 54000 | D21: 76500 | E21: 148750 | G21: Saldo Medio Proveedores
B22: Compras Netas | C22: 410000 | D22: 717500 | E22: 1578500 | G22: Compras Netas
B23: Periodo Medio Pago | C23: =C21/(C22/360) -> 47.414634 | D23: =D21/(D22/360) -> 38.383275 | E23: =E21/(E22/360) -> 33.924612 | G23: Periodo Medio Pago | H23: 76 | I23: 58.4 | J23: 68.4
B26: Ratio de Solvencia | C26: Año 5 | D26: Año 6 | E26: Año 7 | G26: Ratio de Solvencia | H26: Año 5 | I26: Año 6 | J26: Año 7
B27: Activo Total Real | C27: 248000 | D27: 444000 | E27: 635500 | G27: Activo Total Real
B28: Recursos Ajenos | C28: 108000 | D28: 259931 | E28: 466856 | G28: Recursos Ajenos
B29: Ratio de Solvencia | C29: =C27/C28 -> 2.2962963 | D29: =D27/D28 -> 1.7081456 | E29: =E27/E28 -> 1.3612334 | G29: Ratio de Solvencia | H29: 1.2 | I29: 1.1 | J29: 1.1
B32: Ratios de Estructura y Endeudamiento | C32: Año 5 | D32: Año 6 | E32: Año 7 | G32: Ratios de Estructura y Endeudamiento | H32: Año 5 | I32: Año 6 | J32: Año 7
B33: Recursos Ajenos | C33: 108000 | D33: 259931 | E33: 466856 | G33: Recursos Ajenos
B34: Recursos Propios | C34: 143000 | D34: 189069 | E34: 176644 | G34: Recursos Propios
B35: Ratio de Endeudamiento | C35: =C33/C34 -> 0.75524476 | D35: =D33/D34 -> 1.3747944 | E35: =E33/E34 -> 2.6429202 | G35: Ratio de Endeudamiento | H35: 5.3 | I35: 8.6 | J35: 13.4
B37: Deuda a Medio y Largo Plazo | C37: 42000 | D37: 136931 | E37: 209356 | G37: Pasivo Total
B38: Exigible a corto Plazo | C38: 66000 | D38: 123000 | E38: 257500 | G38: Activo Total
B39: Ratio de Estrucutura Endeudamiento | C39: =C37/C38 -> 0.63636364 | D39: =D37/D38 -> 1.1132602 | E39: =E37/E38 -> 0.81303301 | G39: Ratio de Deuda | H39: 0.8 | I39: 0.9 | J39: 0.9
B41: Activo Corriente | C41: 188000 | D41: 289000 | E41: 415500 | G41: Exigible a Corto Plazo
B42: Pasivo Corriente | C42: 66000 | D42: 123000 | E42: 257500 | G42: Total Deuda
B43: Fondo Maniobra | C43: =C41-C42 -> 122000 | D43: =D41-D42 -> 166000 | E43: =E41-E42 -> 158000 | G43: Calidad de la Deuda | H43: 0.8 | I43: 0.8 | J43: 0.8 | L43: VENTANIZATE | M43: Año 5 | N43: Año 6 | O43: Año 7
L44: Ratio de liquidez | M44: =C5 -> 2.8484848 | N44: =D5 -> 2.3495935 | O44: =E5 -> 1.6135922
B45: Activo Circulante Operativo | C45: =SPRINT2!C11+SPRINT2!C13 -> 161000 | D45: =SPRINT2!D11+SPRINT2!D13 -> 270000 | E45: =SPRINT2!E11+SPRINT2!E13 -> 409500 | G45: Deuda a Medio y Largo Plazo | L45: Ratio de Tesoreria | M45: =C9 -> 0.98484848 | N45: =D9 -> 1.0325203 | O45: =E9 -> 0.82330097
B46: Pasivo Circulante Operativo | C46: =SPRINT2!C27 -> 54000 | D46: =SPRINT2!D27 -> 99000 | E46: =SPRINT2!E27 -> 198500 | G46: Exigible a corto Plazo | L46: Ratio de Disponibilidad | M46: =C13 -> 0.40909091 | N46: =D13 -> 0.15447154 | O46: =E13 -> 0.023300971
B47: NOF | C47: =C45-C46 -> 107000 | D47: =D45-D46 -> 171000 | E47: =E45-E46 -> 211000 | G47: Ratio de Estrucutura Endeudamiento | L47: Periodo Medio Cobro | M47: =C19 -> 18.24 | N47: =D19 -> 21.024 | O47: =E19 -> 24.573913
L48: Periodo Medio Pago | M48: =C23 -> 47.414634 | N48: =D23 -> 38.383275 | O48: =E23 -> 33.924612
B49: Beneficio Neto | C49: =SPRINT2!H18 -> 76125 | D49: =SPRINT2!I18 -> 61425 | E49: =SPRINT2!J18 -> -52425 | G49: Recursos Propios | L49: Ratio de Solvencia | M49: =C29 -> 2.2962963 | N49: =D29 -> 1.7081456 | O49: =E29 -> 1.3612334
B50: Capital Social | C50: =SPRINT2!C19 -> 25000 | D50: =SPRINT2!D19 -> 25000 | E50: =SPRINT2!E19 -> 65000 | G50: Activo total | L50: Ratio de Endeudamiento | M50: =C35 -> 0.75524476 | N50: =D35 -> 1.3747944 | O50: =E35 -> 2.6429202
B51: ROE | C51: =C49/C50 -> 3.045 | D51: =D49/D50 -> 2.457 | E51: =E49/E50 -> -0.80653846 | G51: Grado autonomía Financiera | L51: Ratio de Deuda | M51: =C76 -> 0.43027888 | N51: =D76 -> 0.57891091 | O51: =E76 -> 0.72549495
...
