Workbook

Sheet Servidores
C4: Coste Adquisición | D4: Amortización del ejercicio | E4: Valor contable fin de ejercicio | F4: Costes financieros | G4: Resto de gastos imputables | I4: Precio alquiler ofertado
B5: Servidor 1 | C5: 150947.88 | D5: -7547.39 | E5: 132079.39 | F5: 4431.95 | G5: 3668.85 | I5: 30000
B6: Servidor 2 | C6: 153940.44 | D6: -7697.02 | E6: 139829.23 | F6: 5031.44 | G6: 3668.85 | I6: 30000
B7: Servidor 3 | C7: 182110.41 | D7: -9105.52 | E7: 169969.72 | F7: 6076.84 | G7: 3668.85 | I7: 30000
B8: Servidor 4 | C8: 183200.25 | D8: -9160.01 | E8: 171750.23 | F8: 3294.72 | G8: 3668.85 | I8: 30000
C9: =SUM(C5:C8) -> 670198.98 | D9: =SUM(D5:D8) -> -33509.94 | E9: =SUM(E5:E8) -> 613628.57 | F9: =SUM(F5:F8) -> 18834.95 | G9: =SUM(G5:G8) -> 14675.4 | I9: =SUM(I5:I8) -> 120000
B14: Calculo ROA
B15: Total Ingresos | C15: =+I9 -> 120000
B17: Costees directos
B18: Amortización | C18: =+D9 -> -33509.94
B19: Costes financieros | C19: =-F9 -> -18834.95
B20: Resto de gastos imputables | C20: =-G9 -> -14675.4
C21: =SUM(C18:C20) -> -67020.29
B23: Resultado | C23: =+C15+C21 -> 52979.71
B25: Coste Propiedad | C25: =+C9 -> 670198.98
B27: ROA | C27: =+C23/C25 -> 0.079050717
B33: Comparabilidad:
C34: Mínimo | D34: Cuartil bajo | E34: Mediana | F34: Cuartil alto | G34: Máximo
B35: Valores comparabilidad | C35: =+'Empresas comparables'!N14 -> 0.023962148 | D35: =+'Empresas comparables'!N15 -> 0.044691766 | E35: =+'Empresas comparables'!N16 -> 0.062721631 | F35: =+'Empresas comparables'!N17 -> 0.091675744 | G35: =+'Empresas comparables'!N18 -> 0.12126283

Sheet Empresas comparables
B2: EMPRESAS QUE PRESTAN SERVICIOS DE ARRENDAMIENTO DE EQUIPOS INFORMÁTICOS
J4: ROA
B5: EMPRESA 1 | K5: 2018 | L5: 2017 | M5: 2016 | N5: Promedio 2 años
C6: 2018 | D6: 2017 | E6: 2016 | F6: 2015 | G6: 2014 | J6: EMPRESA 1 | K6: =+C19 -> 0.079025923 | L6: =+D19 -> 0.082877698 | M6: =+E19 -> #VALUE! | N6: =AVERAGE(K6:L6) -> 0.08095181
B7: Turnover | C7: 2223 | D7: 1192 | E7: 440 | F7: n.a. | G7: n.a. | J7: EMPRESA 2 | K7: =+C35 -> 0.09437751 | L7: =+D35 -> 0.14814815 | M7: =+E35 -> 0.04787234 | N7: =AVERAGE(K7:L7) -> 0.12126283
B8: Cost of goods sold | C8: 144 | D8: 65 | E8: 17 | F8: n.a. | G8: n.a. | J8: EMPRESA 3 | K8: =+C51 -> 0.025990099 | L8: =+D51 -> 0.021934197 | M8: =+E51 -> 0.031865042 | N8: =AVERAGE(K8:L8) -> 0.023962148
B9: Gross profit | C9: 2078 | D9: 1128 | E9: 423 | F9: n.a. | G9: n.a. | J9: EMPRESA 4 | K9: =+C67 -> 0.075503356 | L9: =+D67 -> 0.041894353 | M9: =+E67 -> 0.064030132 | N9: =AVERAGE(K9:L9) -> 0.058698855
B10: Other operating expenses | C10: 1575 | D10: 840 | E10: 382 | F10: n.a. | G10: n.a. | J10: EMPRESA 5 | K10: =+C83 -> 0.04921466 | L10: =+D83 -> 0.012154696 | M10: =+E83 -> -0.024444444 | N10: =AVERAGE(K10:L10) -> 0.030684678
B11: Operating P/L | C11: 503 | D11: 288 | E11: 41 | F11: n.a. | G11: n.a. | J11: EMPRESA 6 | K11: =+C99 -> 0.021276596 | L11: =+D99 -> 0.10416667 | M11: =+E99 -> 0.11904762 | N11: =AVERAGE(K11:L11) -> 0.062721631
B12: Total fixed assets | C12: 5390 | D12: 2790 | E12: n.a. | F12: n.a. | G12: n.a. | J12: EMPRESA 7 | K12: =+C115 -> 0.01532567 | L12: =+D115 -> 0.18947368 | M12: =+E115 -> 0.125 | N12: =AVERAGE(K12:L12) -> 0.10239968
B13: Intangible fixed assets | C13: 0 | D13: 0 | E13: n.a. | F13: n.a. | G13: n.a.
B14: Stocks | C14: 0 | D14: 0 | E14: n.a. | F14: n.a. | G14: n.a. | M14: Minimo | N14: =MIN(N6:N12) -> 0.023962148
B15: Debtors | C15: 859 | D15: 498 | E15: n.a. | F15: n.a. | G15: n.a. | M15: Cuartil bajo | N15: =QUARTILE(N6:N12,1) -> 0.044691766
B16: Cash | C16: 93 | D16: 176 | E16: n.a. | F16: n.a. | G16: n.a. | M16: Mediana | N16: =MEDIAN(N6:N12) -> 0.062721631
B17: Total assets | C17: 6365 | D17: 3475 | E17: n.a. | F17: n.a. | G17: n.a. | M17: Cuartil alto | N17: =QUARTILE(N6:N12,3) -> 0.091675744
B18: Creditors | C18: 534 | D18: 177 | E18: n.a. | F18: n.a. | G18: n.a. | M18: Máximo | N18: =MAX(N6:N12) -> 0.12126283
C19: =+C11/C17 -> 0.079025923 | D19: =+D11/D17 -> 0.082877698 | E19: =+E11/E17 -> #VALUE!
B21: EMPRESA 2
C22: 2018 | D22: 2017 | E22: 2016 | F22: 2015 | G22: 2014
B23: Turnover | C23: 308 | D23: 267 | E23: 233 | F23: 243 | G23: 207
B24: Cost of goods sold | C24: 56 | D24: 50 | E24: 41 | F24: 44 | G24: 34
B25: Gross profit | C25: 252 | D25: 217 | E25: 192 | F25: 199 | G25: 173
B26: Other operating expenses | C26: 206 | D26: 153 | E26: 174 | F26: 187 | G26: 158
B27: Operating P/L | C27: 47 | D27: 64 | E27: 18 | F27: 12 | G27: 15
B28: Total fixed assets | C28: 155 | D28: 125 | E28: 103 | F28: 110 | G28: 116
B29: Intangible fixed assets | C29: 0 | D29: 0 | E29: 0 | F29: 0 | G29: 0
B30: Stocks | C30: 0 | D30: 0 | E30: 0 | F30: 0 | G30: 0
B31: Debtors | C31: 294 | D31: 278 | E31: 246 | F31: 313 | G31: 291
B32: Cash | C32: 49 | D32: 29 | E32: 27 | F32: 28 | G32: 23
B33: Total assets | C33: 498 | D33: 432 | E33: 376 | F33: 451 | G33: 430
B34: Creditors | C34: 145 | D34: 232 | E34: 227 | F34: 271 | G34: 264
C35: =+C27/C33 -> 0.09437751 | D35: =+D27/D33 -> 0.14814815 | E35: =+E27/E33 -> 0.04787234
B37: EMPRESA 3
C38: 2018 | D38: 2017 | E38: 2016 | F38: 2015 | G38: 2014
B39: Turnover | C39: 949 | D39: 1143 | E39: 1158 | F39: 1074 | G39: 998
B40: Cost of goods sold | C40: 370 | D40: 511 | E40: 552 | F40: 392 | G40: 391
B41: Gross profit | C41: 579 | D41: 632 | E41: 606 | F41: 682 | G41: 607
B42: Other operating expenses | C42: 558 | D42: 610 | E42: 572 | F42: 622 | G42: 538
B43: Operating P/L | C43: 21 | D43: 22 | E43: 34 | F43: 60 | G43: 69
B44: Total fixed assets | C44: 313 | D44: 407 | E44: 487 | F44: 535 | G44: 537
...
