Workbook

Sheet Cuentas y asignaciones
B3: ANALISIS DE CUENTAS CONTABLES
B6: Cuenta | C6: Texto breve | D6: Descripción | E6: Tipo de coste | F6: Criterio de imputación | G6: Saldo
B7: 602550 | C7: Licencias Comerciales | D7: Venta de licencia Inerza | E7: Indirecto | F7: Número de trabajadores por CECO | G7: 0
B8: 602600 | C8: Mater.Oficina | D8: Material de oficina (todo aquel material que no se contabilice como inversión en inmovilizado) | E8: Indirecto | F8: Número de trabajadores por CECO | G8: 1612.69
B9: 602605 | C9: Prev. Mater Oficina | D9: Previsión de gasto para material de oficina (todo aquel material que no se contabilice como inversión en inmovilizado) | E9: Indirecto | F9: Número de trabajadores por CECO | G9: 211.65
B10: 602650 | C10: Mater. Diversos | D10: Suministro de material de limpieza, polos y otros materiales diversos | E10: Indirecto | F10: Número de trabajadores por CECO | G10: 628.5
B11: 602655 | C11: Prev. Mater. Diversos | D11: Previsión de gasto para el suministro de material de limpieza, polos y otros materiales diversos | E11: Indirecto | F11: Número de trabajadores por CECO | G11: 0
B12: 621200 | C12: Arrto. Vehículos | D12: Arrendamiento de vehículos | E12: Indirecto | F12: Ctbl: En función de quien realiza el pedido | G12: 0
B13: 621205 | C13: Prev. Arrto. Vehículos | D13: Previsión de gasto para el arrendamiento de vehículos | E13: Indirecto | F13: Ctbl: En función de quien realiza el pedido | G13: 0
B14: 621300 | C14: Arrto.Local y ofi | D14: Alquiler de las oficinas (LPA y TFE). | E14: Indirecto | F14: Número de trabajadores por CECO | G14: 215725.85
B15: 621305 | C15: Prev. Arrto.Local y ofi | D15: Alquiler de las oficinas (LPA y TFE). | E15: Indirecto | F15: Número de trabajadores por CECO | G15: 0
B16: 621400 | C16: Otros Arrtos | D16: Arrendamientos concretos que no se encuadran en la definición del resto de cuentas de arrendamiento (manos remotas, housing/housting, serviio de alijamiento y suministro elctrico, colocación en rack, etc.) | E16: Indirecto | F16: Ctbl: A partir de la información desagregada por concepto de gasto | G16: 579.95
B17: 621405 | C17: Prev. Otros Arrtos. | D17: Previsión para arrendamientos concretos que no se encuadran en la definición del resto de cuentas de arrendamiento | E17: Indirecto | F17: Ctbl: A partir de la información desagregada por concepto de gasto | G17: 0
B18: 621600 | C18: Canon Marca | E18: Indirecto | F18: Ctbl: A partir de la información desagregada por concepto de gasto | G18: 4.5488613e-13
B19: 621605 | C19: Canon Marca | E19: Indirecto | F19: Ctbl: A partir de la información desagregada por concepto de gasto | G19: 16452.25
B20: 622200 | C20: Rep.Mtto HW | D20: Reparaciones y mantenimiento de hardware | E20: Directo | F20: Número de trabajadores por CECO | G20: 49788.75
B21: 622200 | C21: Rep.Mtto HW | D21: Ampliación garantía CABIN | E21: Directo | F21: Número de trabajadores por CECO
B22: 622205 | C22: Rep.Mtto HW | D22: Ampliación garantía CABIN | E22: Directo | F22: Número de trabajadores por CECO | G22: 0
B23: 622200 | C23: Rep.Mtto HW | D23: Actualización Firware Maquinas IER | E23: Directo | F23: Número de trabajadores por CECO
B24: 622200 | C24: Rep.Mtto HW | D24: Unidades de distribución de alimentación (16A; 32A) | E24: Directo | F24: Número de trabajadores por CECO
B25: 622200 | C25: Rep.Mtto HW | D25: Mantenimiento anual hosting web empresa | E25: Directo | F25: Imputación indirecta a los CECOS Ctbl: En función de quien realiza el pedido ya que no se identifican directamnete con ningún producto
B26: 622200 | C26: Rep.Mtto HW | D26: Reclasificación cuenta web empresa | E26: Directo | F26: Imputación indirecta al CECO relcionado con la seguridad informática (Seguridad Informática)
B27: 622200 | C27: Rep.Mtto HW | D27: Módulo DPR2 | E27: Directo | F27: Ctbl: En función de quien realiza el pedido
B28: 622200 | C28: Rep.Mtto HW | D28: Ampliación garantía 7se | E28: Directo | F28: Ctbl: En función de quien realiza el pedido
B29: 622200 | C29: Rep.Mtto HW | D29: Mantenimiento CABIN | E29: Directo | F29: Número de trabajadores por CECO
B30: 622200 | C30: Rep.Mtto HW | D30: Mantenimiento CSMGR 3.3 Enterpris | E30: Directo | F30: Número de trabajadores por CECO
B31: 622200 | C31: Rep.Mtto HW | D31: Mantenimeinto CABIN y SWCX32020 | E31: Directo | F31: Ctbl: En función de quien realiza el pedido
B32: 622200 | C32: Rep.Mtto HW | D32: Mantenimiento switches lineas ONO | E32: Directo | F32: Ctbl: En función de quien realiza el pedido
B33: 622200 | C33: Rep.Mtto HW | D33: Mantenimeinto Appliance | E33: Directo | F33: Número de trabajadores por CECO
B34: 622200 | C34: Rep.Mtto HW | D34: Switches 8 puertos | E34: Directo | F34: Número de trabajadores por CECO
... B38: 622200 | C38: Rep.Mtto HW | D38: Teléfono y auricular | E38: Directo | F38: Número de trabajadores por CECO
B39: 622201 | C39: Rep.Mtto HW | D39: Ratón M90 óptico | E39: Directo | F39: Ctbl: En función de quien realiza el pedido | G39: 0
B40: 622200 | C40: Rep.Mtto HW | D40: Teckado negro USB K190 | E40: Directo | F40: Ctbl: En función de quien realiza el pedido
B41: 622300 | C41: Rep. y mant. equipos SW | D41: Reparaciones y mantenimiento de software | E41: Directo | F41: Ctbl: En función de quien realiza el pedido | G41: 110880.11
B42: 622305 | C42: Rep. y mant. equipos SW | D42: Reparaciones y mantenimiento de software | E42: Directo | F42: Ctbl: En función de quien realiza el pedido | G42: 691.34
B43: 622400 | C43: Rep.Edif.y Mobil. | D43: Reparaciones de edificio y mobiliario (LPA y TFE). | E43: Indirecto | F43: Número de trabajadores por CECO | G43: 10327.46
B44: 622405 | C44: Prev. Mtto. Edif. | D44: Reparaciones de edificio y mobiliario (LPA y TFE). | E44: Indirecto | F44: Número de trabajadores por CECO | G44: 7505.76
B45: 623020 | E45: Directo | F45: Directo a Canales On Line | G45: 0
B46: 623100 | C46: Asist Técnica | D46: Servicios profesionales contratatados a terceros | E46: Indirecto | F46: Ctbl: En función de quién realiza el pedido | G46: 198472.24
B47: 623100 | C47: Asist Técnica | D47: Costes corporativos, de administración y de gestión de rrhh imputados por empresas del grupo (auditorías, confirming, servicios, etc.) | E47: Indirecto | F47: Número de personas por CECO | G47: 119227.42
...

Sheet Organigrama
B3: ORGANIGRAMA GESTIN
B5: Dirección | C5: PMO
C6: SISTEMAS INFORMACION
C7: PROCESOS
C8: RESERVAS Y DISTRIBUCION (GDS-CDS)
C9: DSISTEMAS
C10: HELP DESK
C11: INFRAESTRUCTURA Y COMUNICACION
C12: SEGURIDAD

Sheet Servicios
B2: Servicios prestados
A3: 1 | B3: Servicio de asesoramiento y soporte funcional a usuarios
A4: 2 | B4: Nuevos desarrollos
A5: 3 | B5: Mantenimiento de aplicaciones
A6: 4 | B6: Mantenimiento Infraestrutcuras
A7: 5 | B7: Consultoría de Procesos
A8: 6 | B8: Canales On Line
A9: 7 | B9: Servicos de Seguridad Informática

Sheet Actividades
B2: MAPA DE ACTIVIDADES POR DEPARTAMENTO
A5: Plantilla | B5: Código | C5: CECO | D5: Actividades | E5: % dedicación RR.HH.
B6: C1 | C6: Dirección | D6: Planificación de BS | E6: 0.1666 | F6: =ROUND($A$11*E6,2) -> 0.33
B7: C1 | C7: Dirección | D7: Organización de BS | E7: 0.1666 | F7: =ROUND($A$11*E7,2) -> 0.33
B8: C1 | C8: Dirección | D8: Dirección de BS | E8: 0.167 | F8: =ROUND($A$11*E8,2) -> 0.33
B9: C1 | C9: Dirección | D9: Coordinación de recursos financieros | E9: 0.1666 | F9: =ROUND($A$11*E9,2) -> 0.33
B10: C1 | C10: Dirección | D10: Coordinación de recursos humanos | E10: 0.1666 | F10: =ROUND($A$11*E10,2) -> 0.33
A11: =+Plantilla!C7 -> 2 | B11: C1 | C11: Dirección | D11: Control de resultados | E11: 0.1666 | F11: =ROUND($A$11*E11,2) -> 0.33
B12: C2 | C12: Soporte GDS-CDS | D12: Gestión del Dpto. | E12: 0.01 | F12: =ROUND($A$24*E12,2) -> 0.08
B13: C2 | C13: Soporte GDS-CDS | D13: Gestión y Mantenimiento de Tarifas | E13: 0.11 | F13: =ROUND($A$24*E13,2) -> 0.83
B14: C2 | C14: Soporte GDS-CDS | D14: Desarrollo y mantenimiento de Acuerdos | E14: 0.03 | F14: =ROUND($A$24*E14,2) -> 0.23
B15: C2 | C15: Soporte GDS-CDS | D15: Gestión y mantenimiento de procedimientos | E15: 0.03 | F15: =ROUND($A$24*E15,2) -> 0.23
B16: C2 | C16: Soporte GDS-CDS | D16: Administración del Ticketing | E16: 0.07 | F16: =ROUND($A$24*E16,2) -> 0.53
B17: C2 | C17: Soporte GDS-CDS | D17: Gestión del proceso de Integridad en la venta | E17: 0.05 | F17: =ROUND($A$24*E17,2) -> 0.38
B18: C2 | C18: Soporte GDS-CDS | D18: Administración de usuarios de Altea | E18: 0.1 | F18: =ROUND($A$24*E18,2) -> 0.76
B19: C2 | C19: Soporte GDS-CDS | D19: Administración de Inventario | E19: 0.14 | F19: =ROUND($A$24*E19,2) -> 1.06
B20: C2 | C20: Soporte GDS-CDS | D20: Mantenimiento reservas | E20: 0.04 | F20: =ROUND($A$24*E20,2) -> 0.3
B21: C2 | C21: Soporte GDS-CDS | D21: Mantenimiento Amadeus SSDD | E21: 0.03 | F21: =ROUND($A$24*E21,2) -> 0.23
B22: C2 | C22: Soporte GDS-CDS | D22: Mantenimiento Amadeus CM | E22: 0.17 | F22: =ROUND($A$24*E22,2) -> 1.29
B23: C2 | C23: Soporte GDS-CDS | D23: Desarrollo de servicios de programación | E23: 0.08 | F23: =ROUND($A$24*E23,2) -> 0.61
A24: =+Plantilla!C6 -> 7.58775 | B24: C2 | C24: Soporte GDS-CDS | D24: Gestión de colas | E24: 0.14 | F24: =ROUND($A$24*E24,2) -> 1.06
B25: C3 | C25: Oficina de Gestión de Proyectos | D25: Gestión del Dpto. | E25: 0.1 | F25: =ROUND($A$33*E25,2) -> 0.1
B26: C3 | C26: Oficina de Gestión de Proyectos | D26: Control y gestión de compras | E26: 0.575 | F26: =ROUND($A$33*E26,2) -> 0.58
B27: C3 | C27: Oficina de Gestión de Proyectos | D27: Control y gestión de contratos | E27: 0.015 | F27: =ROUND($A$33*E27,2) -> 0.02
B28: C3 | C28: Oficina de Gestión de Proyectos | D28: Control y gestión de ayudas y subvenciones | E28: 0.025 | F28: =ROUND($A$33*E28,2) -> 0.03
B29: C3 | C29: Oficina de Gestión de Proyectos | D29: Control y seguimiento de proyectos | E29: 0.175 | F29: =ROUND($A$33*E29,2) -> 0.18
B30: C3 | C30: Oficina de Gestión de Proyectos | D30: Administración elementos amortizables | E30: 0.005 | F30: =ROUND($A$33*E30,2) -> 0.01
B31: C3 | C31: Oficina de Gestión de Proyectos | D31: Control inventario | E31: 0.05 | F31: =ROUND($A$33*E31,2) -> 0.05
B32: C3 | C32: Oficina de Gestión de Proyectos | D32: Doc. No vinculada a proyectos | E32: 0.035 | F32: =ROUND($A$33*E32,2) -> 0.04
A33: =+Plantilla!C3 -> 1 | B33: C3 | C33: Oficina de Gestión de Proyectos | D33: Doc. Vinculada a proyectos | E33: 0.02 | F33: =ROUND($A$33*E33,2) -> 0.02
B34: C4 | C34: Sistemas de Información | D34: Gestión del Dpto. | E34: 0.028571429 | F34: =ROUND($A$37*E34,2) -> 0.24
B35: C4 | C35: Sistemas de Información | D35: Análisis e informes técnicos | E35: 0.0071428571 | F35: =ROUND($A$37*E35,2) -> 0.06
B36: C4 | C36: Sistemas de Información | D36: Desarrollo de SSII | E36: 0.56428571 | F36: =ROUND($A$37*E36,2) -> 4.84
A37: =+Plantilla!C4 -> 8.5694167 | B37: C4 | C37: Sistemas de Información | D37: Mantenimiento de SSII | E37: 0.4 | F37: =ROUND($A$37*E37,2) -> 3.43
B38: C5 | C38: Infraestructuras | D38: Gestión del Dpto. | E38: 0.075 | F38: =ROUND($A$42*E38,2) -> 0.29
B39: C5 | C39: Infraestructuras | D39: Análisis y diseños técnicos | E39: 0.0583 | F39: =ROUND($A$42*E39,2) -> 0.23
B40: C5 | C40: Infraestructuras | D40: Mantenimiento de la infraestructura | E40: 0.2583 | F40: =ROUND($A$42*E40,2) -> 1
B41: C5 | C41: Infraestructuras | D41: Soporte al servicio (gestión de incidencias y peticiones) | E41: 0.25 | F41: =ROUND($A$42*E41,2) -> 0.97
A42: =+Plantilla!C9 -> 3.8764167 | B42: C5 | C42: Infraestructuras | D42: Gestión de proyectos | E42: 0.3584 | F42: =ROUND($A$42*E42,2) -> 1.39
B43: C6 | C43: Seguridad Informática | D43: Gestión del Dpto. | E43: 0.01 | F43: =ROUND($A$51*E43,2) -> 0.01
...

Sheet Plantilla
F1: Productos
C2: Personas equivalentes | E2: Cost treballador | F2: P1 | G2: Cost treballador P1 | H2: P2 | I2: Cost treballador P2 | J2: P3 | K2: Cost treballador P3 | L2: P4 | M2: Cost treballador P4 | N2: P5 | O2: Cost treballador P5 | P2: P6 | Q2: Cost treballador P6 | R2: P7 | S2: Cost treballador P7
A3: 1 | B3: PMO (Oficina proyectos) | C3: 1 | D3: =C3/$C$11 -> 0.038411923 | E3: =$C$13*D3 -> 30178.575 | H3: 0.9 | I3: =E3*H3 -> 27160.718 | N3: 0.1 | O3: =E3*N3 -> 3017.8575
A4: 2 | B4: SISTEMAS INFORMACION | C4: 8.5694167 | D4: =C4/$C$11 -> 0.32916777 | E4: =$C$13*D4 -> 258612.79 | H4: 0.5 | I4: =E4*H4 -> 129306.39 | J4: 0.5 | K4: =E4*J4 -> 129306.39 | O4: =E4*N4 -> 0
A5: 3 | B5: PROCESOS | C5: 1 | D5: =C5/$C$11 -> 0.038411923 | E5: =$C$13*D5 -> 30178.575 | H5: 0.25 | I5: =E5*H5 -> 7544.6439 | J5: 0.25 | K5: =E5*J5 -> 7544.6439 | N5: 0.5 | O5: =E5*N5 -> 15089.288
A6: 4 | B6: RESERVAS Y DISTRIBUCION (GDS-CDS) | C6: 7.58775 | D6: =C6/$C$11 -> 0.29146007 | E6: =$C$13*D6 -> 228987.49 | F6: 0.18 | G6: =F6*E6 -> 41217.748 | I6: =E6*H6 -> 0 | J6: 0.82 | K6: =J6*E6 -> 187769.74 | O6: =E6*N6 -> 0
A7: 5 | B7: DIRECCIÓN SISTEMAS | C7: 2 | D7: =C7/$C$11 -> 0.076823846 | E7: =$C$13*D7 -> 60357.151 | G7: =F7*E7 -> 0 | H7: 0.5 | I7: =E7*H7 -> 30178.575 | J7: 0.5 | K7: =E7*J7 -> 30178.575 | O7: =E7*N7 -> 0
A8: 6 | B8: HELP DESK | C8: 1 | D8: =C8/$C$11 -> 0.038411923 | E8: =$C$13*D8 -> 30178.575 | F8: 0.01 | G8: =F8*E8 -> 301.78575 | H8: 0.25 | I8: =E8*H8 -> 7544.6439 | J8: 0.04 | K8: =E8*J8 -> 1207.143 | L8: 0.7 | M8: =L8*E8 -> 21125.003 | O8: =E8*N8 -> 0
A9: 7 | B9: INFRAESTRUCTURA Y COMUNICACION | C9: 3.8764167 | D9: =C9/$C$11 -> 0.14890062 | E9: =$C$13*D9 -> 116984.73 | G9: =F9*E9 -> 0 | I9: =E9*H9 -> 0 | K9: =E9*J9 -> 0 | O9: =E9*N9 -> 0 | R9: 1 | S9: =R9*E9 -> 116984.73
A10: 8 | B10: SEGURIDAD | C10: 1 | D10: =C10/$C$11 -> 0.038411923 | E10: =$C$13*D10 -> 30178.575 | G10: =F10*E10 -> 0 | I10: =E10*H10 -> 0 | K10: =E10*J10 -> 0 | O10: =E10*N10 -> 0 | P10: 1 | Q10: =P10*E10 -> 30178.575
C11: 26.033583 | G11: =SUM(G3:G10) -> 41519.533 | I11: =SUM(I3:I10) -> 201734.98 | K11: =SUM(K3:K10) -> 356006.49 | M11: =SUM(M3:M10) -> 21125.003 | O11: =SUM(O3:O10) -> 18107.145 | Q11: =SUM(Q3:Q10) -> 30178.575 | S11: =SUM(S3:S10) -> 116984.73
B13: Cost total Personal | C13: 785656.46
A17: 640000 | B17: Remun.fijas | C17: Sueldos de los trabajadores | D17: Indirecto | E17: Imputación a CECO de las aplicaciones utilizadas por BS para prestar el servicio | F17: 785656.46

Sheet Asignación Actividades Directas
B2: ASIGNACIÓN DE ACTIVIDADES DIRECTAS
B4: CECO | C4: Actividad | D4: Inductor | F4: Productos
F5: Servicio de asesoramiento y soporte funcional a usuarios | G5: Nuevos desarrollos | H5: Mantenimiento de aplicaciones | I5: Mantenimiento Infraestrutcuras | J5: Consultoría de Procesos | K5: Canales On Line | L5: Servicos de Seguridad Informática | M5: Total
F6: P1 | G6: P2 | H6: P3 | I6: P4 | J6: P5 | K6: P7 | L6: P6
B7: Soporte GDS-CDS | C7: Gestión y Mantenimiento de Tarifas | D7: Imputación Directa al Producto Mantenimiento de Aplicaciones | H7: 1 | M7: =SUM(F7:L7) -> 1
B8: Soporte GDS-CDS | C8: Desarrollo y mantenimiento de Acuerdos | D8: Imputación Directa al Producto Mantenimiento de Aplicaciones | H8: 1 | M8: =SUM(F8:L8) -> 1
B9: Soporte GDS-CDS | C9: Gestión y mantenimiento de procedimientos | D9: Imputación Directa al Producto Servicio de Asesoramiento | F9: 1 | M9: =SUM(F9:L9) -> 1
B10: Soporte GDS-CDS | C10: Administración del Ticketing | D10: Imputación Directa al Producto Mantenimiento de Aplicaciones y Servicio de Asesoramiento y Soporte Funcional a usuarios | F10: 0.6 | H10: 0.4 | M10: =SUM(F10:L10) -> 1
B11: Soporte GDS-CDS | C11: Gestión Checkin | D11: Imputación Directa al Producto Mantenimiento de Aplicaciones | F11: 0.2 | H11: 0.8 | M11: =SUM(F11:L11) -> 1
B12: Soporte GDS-CDS | C12: Administración de oficinas y usuarios de Altea | D12: Imputación Directa al Producto Mantenimiento de Aplicaciones | H12: 1 | M12: =SUM(F12:L12) -> 1
B13: Soporte GDS-CDS | C13: Administración de Inventario | D13: Imputación Directa al Producto Mantenimiento de Aplicaciones | H13: 1 | M13: =SUM(F13:L13) -> 1
B14: Soporte GDS-CDS | C14: Mantenimiento reservas | D14: Imputación Directa al Producto Mantenimiento de Aplicaciones y Servicio de Asesoramiento y Soporte Funcional a usuarios | F14: 0.3 | H14: 0.7 | M14: =SUM(F14:L14) -> 1
B15: Soporte GDS-CDS | C15: Aministración otros GDS | D15: Imputación Directa al Producto Mantenimiento de Aplicaciones | H15: 1 | M15: =SUM(F15:L15) -> 1
B16: Soporte GDS-CDS | C16: Gestión del proceso de Revenue Integrity | D16: Imputación Directa al Producto Mantenimiento de Aplicaciones y Servicio de Asesoramiento y Soporte Funcional a usuarios | F16: 0 | H16: 1 | M16: =SUM(F16:L16) -> 1
B17: Soporte GDS-CDS | C17: Desarrollo de servicios de programación | D17: Imputación Directa al Producto Mantenimiento de Aplicaciones | H17: 1 | M17: =SUM(F17:L17) -> 1
B18: Soporte GDS-CDS | C18: Gestión de colas canales | D18: Imputación Directa al Producto Mantenimiento de Aplicaciones | H18: 1 | M18: =SUM(F18:L18) -> 1
B19: Oficina de Gestión de Proyectos | C19: Control y seguimiento de proyectos | D19: Imputación a los productos que conllevan control y seguimiento de proyectos (Nuevos Desarrollos y Consultoría de Procesos) | G19: 0.9 | J19: 0.1 | M19: =SUM(F19:L19) -> 1
B20: Sistemas de Información | C20: Proyectos nuevos Desarrollos de SSII | D20: Imputación Directa al Producto Nuevos Desarrollos | G20: 1 | M20: =SUM(F20:L20) -> 1
B21: Sistemas de Información | C21: Mantenimiento de SSII | D21: Imputación Directa al Producto Mantenimiento de Aplicaciones | H21: 1 | M21: =SUM(F21:L21) -> 1
B22: Infraestructuras | C22: Gestión de proyectos Infraestructura. Diseños. Implantaciones | D22: Imputación Directa al Producto Mantenimiento de Infraestructuras | I22: 1 | M22: =SUM(F22:L22) -> 1
B23: Infraestructuras | C23: Mantenimiento de la infraestructura y comunicaciones. Diseños | D23: Imputación Directa al Producto Mantenimiento de Infraestructuras | I23: 1 | M23: =SUM(F23:L23) -> 1
B24: Infraestructuras | C24: Soporte al servicio (gestión de incidencias y peticiones) | D24: Imputación Directa de los porudctos que conllevan servicios de soporte (Mant Aplic.; Mant. Infraestruc.; Servicio de Asesoramiento y Soporte Funcioanl a Usuarios) | F24: 0.05 | H24: 0.15 | I24: 0.8 | M24: =SUM(F24:L24) -> 1
B25: Infraestructuras | C25: Diseños e implantaciones proyectos de desarrollo | D25: Imputación Proporcional a cada uno de los productos que conllevan servicios de gestión de proyectos (Nuevos Desarrollos.; Mant. Infraestruc.) | G25: 1 | I25: 0 | M25: =SUM(F25:L25) -> 1
B26: Seguridad Informática | C26: Definición de políticas, normas y procedimientos seguridad | D26: Imputación Directa al Producto Servicios de Seguridad Informática | L26: 1 | M26: =SUM(F26:L26) -> 1
B27: Seguridad Informática | C27: Control y Gestión de la seguridad | D27: Imputación Directa al Producto Servicios de Seguridad Informática | L27: 1 | M27: =SUM(F27:L27) -> 1
B28: Seguridad Informática | C28: Control del cumplimiento de las políticas y normas de seguridad | D28: Imputación Directa al Producto Servicios de Seguridad Informática | L28: 1 | M28: =SUM(F28:L28) -> 1
B29: Seguridad Informática | C29: Administración de riesgos (vulnerabilidades, pruebas de rendimiento y resistencia, planes de contingencia, monitorización, etc.) | D29: Imputación Directa al Producto Servicios de Seguridad Informática | L29: 1 | M29: =SUM(F29:L29) -> 1
B30: Seguridad Informática | C30: Gestión de incidencias y continuidad | D30: Imputación Directa al Producto Servicios de Seguridad Informática | L30: 1 | M30: =SUM(F30:L30) -> 1
B31: Seguridad Informática | C31: Control de normas y procedimientos de seguridad | D31: Imputación Directa al Producto Servicios de Seguridad Informática | L31: 1 | M31: =SUM(F31:L31) -> 1
B32: Seguridad Informática | C32: Elaboración y mantenimiento del plan de continuidad del negocio | D32: Imputación Directa al Producto Servicios de Seguridad Informática | L32: 1 | M32: =SUM(F32:L32) -> 1
B33: Seguridad Informática | C33: Gestión de la LOPD, LSSI, etc. | D33: Imputación Directa al Producto Servicios de Seguridad Informática | L33: 1 | M33: =SUM(F33:L33) -> 1
B34: Canales On Line | C34: Gestión de Proyectos y documentación | D34: Imputación Directa al Producto Canales Online | K34: 1
B35: Canales On Line | C35: Elaboración de informes y análisis no relacionados con proyectos | D35: Imputación Directa al Producto Canales Online | K35: 1
B36: Canales On Line | C36: Gestión del Call Center | D36: Imputación Directa al Producto Canales Online | K36: 1
B37: Canales On Line | C37: Control y desarrollo de los canales web y móvil | D37: Imputación Directa al Producto Canales Online | K37: 1
B38: Procesos | C38: Mantenimiento de SSII | D38: Imputación Directa al Producto Mantenimiento de Aplicaciones | H38: 1 | J38: 0 | M38: =SUM(F38:L38) -> 1
B39: Procesos | C39: Elaboración de informes y análisis no relacionados con proyectos | D39: Imputación Directa al Producto Consultoría de Procesos | J39: 1 | M39: =SUM(F39:L39) -> 1
B40: Procesos | C40: Gestión de proyectos relacionados con procesos transversales | D40: Imputación Directa al Producto Consultoría de Procesos | J40: 1
B41: Procesos | C41: Desarrollo de proyectos (funcional) | D41: Imputación Directa al Producto Consultoría de Procesos | G41: 1 | M41: =SUM(F41:L41) -> 1

Sheet Volumen Servicios
B2: UNIDADES PROMEDIO Y VOLUMEN DE FACTURACIÓN POR SERVICIO/PRODUCTO
B4: Producto | C4: Unidad de Facturación | D4: Volumen | E4: Cost treballador | F4: Coste CECO | G4: TOTAL COSTE | H4: Precio | I4: Inc Venta Interna 15% | J4: Unidad
A5: 1 | B5: Servicio de asesoramiento y soporte funcional a usuarios | C5: Nº Usuarios a los que se da soporte | D5: 1169 | E5: =Plantilla!G11 -> 41519.533 | F5: 33831.339 | G5: =E5+F5 -> 75350.872 | H5: =G5/D5 -> 64.457547 | I5: =H5*1.15 -> 74.126178 | J5: € / hora
A6: 2 | B6: Nuevos desarrollos | C6: Hora/Hombre dedicación | D6: 5140.23 | E6: 201734.98 | F6: 166733.77 | G6: =E6+F6 -> 368468.75 | H6: =G6/D6 -> 71.68332 | I6: =H6*1.15 -> 82.435817 | J6: € / hora
A7: 3 | B7: Mantenimiento de aplicaciones | C7: Hora/Hombre dedicación | D7: 17829.8 | E7: 356006.49 | F7: 287981.04 | G7: =E7+F7 -> 643987.53 | H7: =G7/D7 -> 36.118607 | I7: =H7*1.15 -> 41.536398 | J7: € / hora
A8: 4 | B8: Mantenimiento Infraestrutcuras | C8: Nº Pcs a los que se da soporte | D8: 565.55 | E8: 21125.003 | F8: 12375.608 | G8: =E8+F8 -> 33500.611 | H8: =G8/D8 -> 59.235454 | I8: =H8*1.15 -> 68.120772 | J8: € / Und PC
A9: 5 | B9: Consultoría de Procesos | C9: Hora/Hombre dedicación | D9: 1296.54 | E9: 18107.145 | F9: 18903.468 | G9: =E9+F9 -> 37010.613 | H9: =G9/D9 -> 28.545678 | I9: =H9*1.15 -> 32.82753 | J9: € / hora
A10: 6 | B10: Canales On Line | C10: Hora/Hombre dedicación (*) | D10: 3344.68 | E10: 30178.575 | F10: 7152.15 | G10: =E10+F10 -> 37330.725 | H10: =G10/D10 -> 11.161225 | I10: =H10*1.15 -> 12.835409 | J10: € / hora
A11: 7 | B11: Servicos de Seguridad Informática | C11: Nº Pcs a los que se da soporte | D11: 525.33 | E11: 116984.73 | F11: 365.32 | G11: =E11+F11 -> 117350.05 | H11: =G11/D11 -> 223.3835 | I11: =H11*1.15 -> 256.89102 | J11: € / Und PC
E18: Producte | F18: 1 | G18: Cost CECO 1 | H18: 2 | I18: Cost CECO 2 | J18: 3 | K18: Cost CECO 3 | L18: 4 | M18: Cost CECO 4 | N18: 5 | O18: Cost CECO 5 | P18: 6 | Q18: Cost CECO 6 | R18: 7 | S18: Cost CECO 7 | T18: 8 | U18: Cost CECO 8 | V18: TOTAL
F19: 31505.78 | H19: 98759.93 | J19: 82890.55 | L19: 186969.69 | N19: 127712.22 | P19: 17679.44 | R19: 365.32 | T19: 7152.15
E20: 1 | L20: 0.18 | M20: =L20*L19 -> 33654.544 | O20: =N20*N19 -> 0 | P20: 0.01 | Q20: =P20*P19 -> 176.7944 | S20: =R20*R19 -> 0 | U20: =T20*T19 -> 0 | V20: =G20+I20+K20+M20+O20+Q20+S20+U20 -> 33831.339
E21: 2 | F21: 0.9 | G21: =F21*$F$19 -> 28355.202 | H21: 0.5 | I21: =H21*H19 -> 49379.965 | J21: 0.25 | K21: =J21*J19 -> 20722.637 | M21: =L21*L19 -> 0 | N21: 0.5 | O21: =N21*N19 -> 63856.11 | P21: 0.25 | Q21: =P21*P19 -> 4419.86 | S21: =R21*R19 -> 0 | U21: =T21*T19 -> 0 | V21: =G21+I21+K21+M21+O21+Q21+S21+U21 -> 166733.77
E22: 3 | H22: 0.5 | I22: =H22*H19 -> 49379.965 | J22: 0.25 | K22: =J22*J19 -> 20722.637 | L22: 0.82 | M22: =L22*L19 -> 153315.15 | N22: 0.5 | O22: =N22*N19 -> 63856.11 | P22: 0.04 | Q22: =P22*P19 -> 707.1776 | S22: =R22*R19 -> 0 | U22: =T22*T19 -> 0 | V22: =G22+I22+K22+M22+O22+Q22+S22+U22 -> 287981.04
E23: 4 | G23: =F23*F19 -> 0 | I23: =H23*H19 -> 0 | K23: =J23*J19 -> 0 | M23: =L23*L19 -> 0 | O23: =N23*N19 -> 0 | P23: 0.7 | Q23: =P23*P19 -> 12375.608 | S23: =R23*R19 -> 0 | U23: =T23*T19 -> 0 | V23: =G23+I23+K23+M23+O23+Q23+S23+U23 -> 12375.608
E24: 5 | F24: 0.1 | G24: =F24*$F$19 -> 3150.578 | I24: =H24*$F$19 -> 0 | J24: 0.5 | K24: =J24*$F$19 -> 15752.89 | M24: =L24*$F$19 -> 0 | O24: =N24*$F$19 -> 0 | Q24: =P24*$F$19 -> 0 | S24: =R24*$F$19 -> 0 | U24: =T24*$F$19 -> 0 | V24: =G24+I24+K24+M24+O24+Q24+S24+U24 -> 18903.468
E25: 6 | T25: 1 | U25: =T19*T25 -> 7152.15 | V25: =G25+I25+K25+M25+O25+Q25+S25+U25 -> 7152.15
E26: 7 | R26: 1 | S26: =R19*R26 -> 365.32 | V26: =G26+I26+K26+M26+O26+Q26+S26+U26 -> 365.32

Sheet Datos Ctbl
A2: INFORMACIÓN DE REGISTROS CONTABLES DE ALGUNAS CUENTAS
A5: Cuenta | D5: Criterio de imputación | G5: Dirección BS | H5: Soporte GDS-CDS | I5: Oficina de Gestión de Proyectos | J5: Sistemas de Información | K5: Infraestructuras | L5: Seguridad Informática | M5: Canales on line | N5: Procesos | O5: Total
A6: Varias | D6: Número de trabajadores por CECO | G6: 0.076823846 | H6: 0.29146007 | I6: 0.038411923 | J6: 0.32916777 | K6: 0.14890062 | L6: 0.038411923 | M6: 0.038411923 | N6: 0.038411923 | O6: 1
G7: 2 | H7: 7.58775 | I7: 1 | J7: 8.5694167 | K7: 3.8764167 | L7: 1 | M7: 1 | N7: 1 | O7: 26.033583
A8: 623105 | C8: Previsión de gasto para asistencias técnicas | D8: Reg contable | G8: 0 | H8: 0 | I8: 0 | J8: 0 | K8: 0 | N8: 0 | O8: 0
A9: 628004 | C9: Comb. Equipos Tierra | D9: Reg contable | G9: 40 | H9: 200 | I9: 0 | J9: 100 | K9: 80 | N9: 60 | O9: 480
A10: 628240 | C10: Teléfonos | D10: Reg contable | G10: 7676.11 | H10: 1593.03 | I10: 57.13 | J10: 1712.78 | K10: 26719.99 | L10: 450.97 | M10: 105.42 | N10: 216.5 | O10: 38531.93
A11: 629500 | C11: Desp. Aduanas | D11: Reg contable | G11: 268.85 | H11: 628.78 | I11: 1717.5 | J11: 36 | K11: 155.32 | N11: 0 | O11: 2806.45
A12: 629700 | C12: Gtos viajes | D12: Reg contable | O12: 0
A13: 629710 | C13: Bill de Servicio | D13: Reg contable | G13: 8156.35 | H13: 3389.49 | I13: 165.56 | J13: 6479.48 | K13: 4920.81 | L13: 796.85 | M13: -1.4210855e-14 | N13: 2846.57 | O13: 26755.11
A14: 629720 | C14: Gtos Locomoc | D14: Reg contable | G14: 766.03 | H14: 1133.4 | I14: 40 | J14: 488 | K14: 298.66 | L14: 93 | M14: 187.35 | N14: 303.9 | O14: 3310.34
A15: 640125 | C15: Prev. Plus, gratrif y pr | D15: Reg contable | O15: 0
A16: 642000 | C16: SS empresa | D16: Reg contable | G16: 13403.62 | H16: 21622.07 | I16: 77997.46 | J16: 110568.78 | K16: 0 | L16: 0 | M16: 0 | N16: 3327.38 | O16: 226919.31
A17: 649300 | C17: Com.Pers Tierr | D17: Reg contable | G17: 542.8 | H17: 3828.39 | I17: 1599.7 | J17: 2348.22 | K17: 1575.99 | L17: 416.03 | M17: 34.75 | N17: 56.48 | O17: 10402.36
A18: 649500/05 | C18: Orros Gastos Sociales | D18: Reg contable | G18: 127.84 | H18: 63.87 | I18: 63.87 | J18: 383.39 | K18: 191.68 | L18: 0 | M18: 0 | N18: 63.87 | O18: 894.52
A19: 680600 / 680601 | C19: Amort Aplicaciones Informáticas | D19: Reg contable
A20: 681600 / 681500 | C20: Amorti Mobiliario / Amort Otras Instalaciones | D20: Reg contable | G20: 318.85 | H20: 352.36 | I20: 70.37 | J20: 31370.32 | K20: 3085.51 | L20: 254.1 | M20: 0 | N20: 35.23 | O20: 35486.74
A21: 681700 / 681710 | C21: Amort equipos de proceso | D21: Reg contable | G21: 205.33 | H21: 65948.54 | I21: 1178.96 | J21: 33482.72 | K21: 90684.26 | L21: 15668.49 | M21: 37.8 | N21: 242.22 | O21: 207448.32
G22: =SUM(G8:G21) -> 31505.78 | H22: =SUM(H8:H21) -> 98759.93 | I22: =SUM(I8:I21) -> 82890.55 | J22: =SUM(J8:J21) -> 186969.69 | K22: =SUM(K8:K21) -> 127712.22 | L22: =SUM(L8:L21) -> 17679.44 | M22: =SUM(M8:M21) -> 365.32 | N22: =SUM(N8:N21) -> 7152.15 | O22: =SUM(O8:O21) -> 553035.08
C28: Servicios prestados
C29: Servicio de asesoramiento y soporte funcional a usuarios
C30: Nuevos desarrollos
C31: Mantenimiento de aplicaciones
C32: Mantenimiento Infraestrutcuras
C33: Consultoría de Procesos
C34: Canales On Line
C35: Servicos de Seguridad Informática
C38: Servicio de asesoramiento y soporte funcional a usuarios | D38: Nº Usuarios a los que se da soporte | E38: 1169
C39: Nuevos desarrollos | D39: Hora/Hombre dedicación | E39: 5140.23
C40: Mantenimiento de aplicaciones | D40: Hora/Hombre dedicación | E40: 17829.8 | G40: =E40/(H7+J7+(K7*15%)+N7) -> 1005.1397 | H40: cost | I40: {=Plantilla!D1Productos} -> #NAME?
C41: Mantenimiento Infraestrutcuras | D41: Nº Pcs a los que se da soporte | E41: 565.55
C42: Consultoría de Procesos | D42: Hora/Hombre dedicación | E42: 1296.54
C43: Canales On Line | D43: Hora/Hombre dedicación (*) | E43: 3344.68
C44: Servicos de Seguridad Informática | D44: Nº Pcs a los que se da soporte | E44: 525.33

Sheet Otros datos
B4: Departamento | C4: Plantilla | D4: M2 | E4: Ordenadores | F4: % Uso vehic
B5: PMO (Oficina proyectos) | C5: 1 | D5: 48.868 | E5: 2 | F5: 0.035
B6: SISTEMAS INFORMACION | C6: 8.5694167 | D6: 151.4908 | E6: 10 | F6: 0.035
B7: PROCESOS | C7: 1 | D7: 48.868 | E7: 2 | F7: 0.035
B8: RESERVAS Y DISTRIBUCION (GDS-CDS) | C8: 7.58775 | D8: 212.66452 | E8: 10 | F8: 0
B9: DIRECCIÓN SISTEMAS | C9: 2 | D9: 43.9812 | E9: 3 | F9: 0.035
B10: HELP DESK | C10: 1 | D10: 146.604 | E10: 6 | F10: 0.6
B11: INFRAESTRUCTURA Y COMUNICACION | C11: 3.8764167 | D11: 87.356527 | E11: 6 | F11: 0.13
B12: SEGURIDAD | C12: 1 | D12: 24.434 | E12: 1 | F12: 0.13
C13: 26.033583 | D13: =SUM(D5:D12) -> 764.26705 | E13: =SUM(E5:E12) -> 40 | F13: =SUM(F5:F12) -> 1
B16: Tipo Coste
B17: Directo
B18: Indirecto
