Workbook
Name DEUDA_INI: [1]Cuadro_vencimientos_y_devengos!$I$5
Name INTERÉS: [1]Cuadro_vencimientos_y_devengos!$J$5
Name IVA: Traslación_Pagos!$S$2
Name RET_TRABAJO: Traslación_Pagos!$S$5
Name RETENCIÓN: Traslación_Pagos!$S$6
Name SS_EMPRESA: Traslación_Pagos!$S$4
Name SS_TRABAJADOR: Traslación_Pagos!$S$3

Sheet Traslación_Cobros
A1: TRASLACIÓN DE COBROS DE CUENTA DE RESULTADOS A PRESUPUESTO DE TESORERÍA
B4: CUENTA DE RESULTADOS | C4: NOV A-1 | D4: DIC A-1 | E4: ENE | F4: FEB | G4: MAR | H4: ABR | I4: MAY | J4: JUN | K4: JUL | L4: AGO | M4: SEP | N4: OCT | O4: NOV | P4: DIC | R4: CONDICIONES | T4: IMPUESTO
B5: Cliente TOP 1 | C5: 50000 | D5: 50000 | E5: 50000 | F5: 50000 | G5: 50000 | H5: 50000 | I5: 50000 | J5: 50000 | K5: 50000 | L5: 50000 | M5: 50000 | N5: 50000 | O5: 50000 | P5: 50000 | R5: PAGO 30 DÍAS | T5: 0.21
B6: Cliente TOP 2 | C6: 75000 | E6: 60000 | G6: 80000 | I6: 70000 | K6: 60000 | M6: 80000 | O6: 70000 | R6: PAGO 30 DÍAS | T6: 0.21
B7: Cliente TOP 3 | C7: 30000 | D7: 40000 | E7: 35000 | F7: 45000 | G7: 45000 | H7: 45000 | I7: 40000 | J7: 35000 | K7: 35000 | L7: 45000 | M7: 45000 | N7: 45000 | O7: 40000 | P7: 35000 | R7: 40% CONTADO, 60% 60 DÍAS | T7: 0.21
B8: Resto Clientes | C8: 30000 | D8: 15000 | E8: 25000 | F8: 20000 | G8: 25000 | H8: 30000 | I8: 25000 | J8: 20000 | K8: 25000 | L8: 20000 | M8: 25000 | N8: 30000 | O8: 25000 | P8: 20000 | R8: PROMEDIO 45 DÍAS | T8: 0.21
B9: INGRESOS POR VENTAS | C9: =SUM(C5:C8) -> 185000 | D9: =SUM(D5:D8) -> 105000 | E9: =SUM(E5:E8) -> 170000 | F9: =SUM(F5:F8) -> 115000 | G9: =SUM(G5:G8) -> 200000 | H9: =SUM(H5:H8) -> 125000 | I9: =SUM(I5:I8) -> 185000 | J9: =SUM(J5:J8) -> 105000 | ... P9: =SUM(P5:P8) -> 105000
B11: PRESUPUESTO DE TESORERÍA (OPCIÓN 1) | E11: ENE | F11: FEB | G11: MAR | H11: ABR | I11: MAY | J11: JUN | K11: JUL | L11: AGO | M11: SEP | N11: OCT | O11: NOV | P11: DIC
B12: Cliente TOP 1 | E12: =+D5*(1+$T5) -> 60500 | F12: =+E5*(1+$T5) -> 60500 | G12: =+F5*(1+$T5) -> 60500 | H12: =+G5*(1+$T5) -> 60500 | I12: =+H5*(1+$T5) -> 60500 | J12: =+C5*(1+$T5) -> 60500 | K12: =+D5*(1+$T5) -> 60500 | L12: =+E5*(1+$T5) -> 60500 | M12: =+F5*(1+$T5) -> 60500 | N12: =+G5*(1+$T5) -> 60500 | O12: =+H5*(1+$T5) -> 60500 | P12: =+I5*(1+$T5) -> 60500
B13: Cliente TOP 2 | E13: =+D6*(1+$T6) -> 0 | F13: =+E6*(1+$T6) -> 72600 | G13: =+F6*(1+$T6) -> 0 | H13: =+G6*(1+$T6) -> 96800 | I13: =+H6*(1+$T6) -> 0 | J13: =+C6*(1+$T6) -> 90750 | K13: =+D6*(1+$T6) -> 0 | L13: =+E6*(1+$T6) -> 72600 | M13: =+F6*(1+$T6) -> 0 | N13: =+G6*(1+$T6) -> 96800 | O13: =+H6*(1+$T6) -> 0 | P13: =+I6*(1+$T6) -> 84700
B14: Cliente TOP 3 | E14: =+(C7*0.6+E7*0.7)*(1+$T7) -> 51425 | F14: =+(D7*0.6+F7*0.7)*(1+$T7) -> 67155 | G14: =+(E7*0.6+G7*0.7)*(1+$T7) -> 63525 | H14: =+(F7*0.6+H7*0.7)*(1+$T7) -> 70785 | I14: =+(G7*0.6+I7*0.7)*(1+$T7) -> 66550 | J14: =+(H7*0.6+J7*0.7)*(1+$T7) -> 62315 | K14: =+(I7*0.6+K7*0.7)*(1+$T7) -> 58685 | L14: =+(J7*0.6+L7*0.7)*(1+$T7) -> 63525 | ... P14: =+(N7*0.6+P7*0.7)*(1+$T7) -> 62315
B15: Resto Clientes | E15: =+AVERAGE(C8:D8)*(1+$T8) -> 27225 | F15: =+AVERAGE(D8:E8)*(1+$T8) -> 24200 | G15: =+AVERAGE(E8:F8)*(1+$T8) -> 27225 | H15: =+AVERAGE(F8:G8)*(1+$T8) -> 27225 | I15: =+AVERAGE(G8:H8)*(1+$T8) -> 33275 | J15: =+AVERAGE(H8:I8)*(1+$T8) -> 33275 | K15: =+AVERAGE(I8:J8)*(1+$T8) -> 27225 | L15: =+AVERAGE(J8:K8)*(1+$T8) -> 27225 | ... P15: =+AVERAGE(N8:O8)*(1+$T8) -> 33275
B16: COBROS EXPLOTACIÓN | E16: =SUM(E12:E15) -> 139150 | F16: =SUM(F12:F15) -> 224455 | G16: =SUM(G12:G15) -> 151250 | H16: =SUM(H12:H15) -> 255310 | I16: =SUM(I12:I15) -> 160325 | J16: =SUM(J12:J15) -> 246840 | K16: =SUM(K12:K15) -> 146410 | L16: =SUM(L12:L15) -> 223850 | ... P16: =SUM(P12:P15) -> 240790
B18: PRESUPUESTO DE TESORERÍA (OPCIÓN 2) | E18: ENE | F18: FEB | G18: MAR | H18: ABR | I18: MAY | J18: JUN | K18: JUL | L18: AGO | M18: SEP | N18: OCT | O18: NOV | P18: DIC
B19: Cliente TOP 1 | E19: =+D5 -> 50000 | F19: =+E5 -> 50000 | G19: =+F5 -> 50000 | H19: =+G5 -> 50000 | I19: =+H5 -> 50000 | J19: =+C5 -> 50000 | K19: =+D5 -> 50000 | L19: =+E5 -> 50000 | M19: =+F5 -> 50000 | N19: =+G5 -> 50000 | O19: =+H5 -> 50000 | P19: =+I5 -> 50000
B20: Cliente TOP 2 | E20: =+D6 -> 0 | F20: =+E6 -> 60000 | G20: =+F6 -> 0 | H20: =+G6 -> 80000 | I20: =+H6 -> 0 | J20: =+C6 -> 75000 | K20: =+D6 -> 0 | L20: =+E6 -> 60000 | M20: =+F6 -> 0 | N20: =+G6 -> 80000 | O20: =+H6 -> 0 | P20: =+I6 -> 70000
B21: Cliente TOP 3 | E21: =+C7*0.6+E7*0.7 -> 42500 | F21: =+D7*0.6+F7*0.7 -> 55500 | G21: =+E7*0.6+G7*0.7 -> 52500 | H21: =+F7*0.6+H7*0.7 -> 58500 | I21: =+G7*0.6+I7*0.7 -> 55000 | J21: =+H7*0.6+J7*0.7 -> 51500 | K21: =+I7*0.6+K7*0.7 -> 48500 | L21: =+J7*0.6+L7*0.7 -> 52500 | ... P21: =+N7*0.6+P7*0.7 -> 51500
B22: Resto Clientes | E22: =+AVERAGE(C8:D8) -> 22500 | F22: =+AVERAGE(D8:E8) -> 20000 | G22: =+AVERAGE(E8:F8) -> 22500 | H22: =+AVERAGE(F8:G8) -> 22500 | I22: =+AVERAGE(G8:H8) -> 27500 | J22: =+AVERAGE(H8:I8) -> 27500 | K22: =+AVERAGE(I8:J8) -> 22500 | L22: =+AVERAGE(J8:K8) -> 22500 | ... P22: =+AVERAGE(N8:O8) -> 27500
B23: IVA cobrado clientes | E23: =+SUMPRODUCT(E19:E22,$T$5:$T$8) -> 24150 | F23: =+SUMPRODUCT(F19:F22,$T$5:$T$8) -> 38955 | G23: =+SUMPRODUCT(G19:G22,$T$5:$T$8) -> 26250 | H23: =+SUMPRODUCT(H19:H22,$T$5:$T$8) -> 44310 | I23: =+SUMPRODUCT(I19:I22,$T$5:$T$8) -> 27825 | J23: =+SUMPRODUCT(J19:J22,$T$5:$T$8) -> 42840 | K23: =+SUMPRODUCT(K19:K22,$T$5:$T$8) -> 25410 | L23: =+SUMPRODUCT(L19:L22,$T$5:$T$8) -> 38850 | ... P23: =+SUMPRODUCT(P19:P22,$T$5:$T$8) -> 41790
B24: COBROS EXPLOTACIÓN | E24: =SUM(E19:E23) -> 139150 | F24: =SUM(F19:F23) -> 224455 | G24: =SUM(G19:G23) -> 151250 | H24: =SUM(H19:H23) -> 255310 | I24: =SUM(I19:I23) -> 160325 | J24: =SUM(J19:J23) -> 246840 | K24: =SUM(K19:K23) -> 146410 | L24: =SUM(L19:L23) -> 223850 | ... P24: =SUM(P19:P23) -> 240790

Sheet Traslación_Pagos
A1: TRASLACIÓN DE PAGOS DE CUENTA DE RESULTADOS A PRESUPUESTO DE TESORERÍA
R2: Tipo IVA | S2: 0.21
R3: Tipo Seguridad Social Trabajador | S3: 0.06
R4: Tipo Seguridad Social Empresa | S4: 0.33
R5: Tipo Retención Trabajadores | S5: 0.16
R6: Tipo Retención Alquileres y Profesionales | S6: 0.19
B8: CUENTA DE RESULTADOS | C8: NOV A-1 | D8: DIC A-1 | E8: ENE | F8: FEB | G8: MAR | H8: ABR | I8: MAY | J8: JUN | K8: JUL | L8: AGO | M8: SEP | N8: OCT | O8: NOV | P8: DIC | R8: PRESUPUESTO DE TESORERÍA | S8: ENE | T8: FEB | U8: MAR | V8: ABR | W8: MAY | X8: JUN | Y8: JUL | Z8: AGO | AA8: SEP | AB8: OCT | AC8: NOV | AD8: DIC
B9: Sueldos y Salarios | C9: -19500 | D9: -19500 | E9: -21000 | F9: -21000 | G9: -21000 | H9: -21000 | I9: -21000 | J9: -21000 | K9: -21000 | L9: -21000 | M9: -21000 | N9: -21000 | O9: -21000 | P9: -21000 | R9: Nómina mensual | S9: =+E9*12/14*(1-SS_TRABAJADOR-RET_TRABAJO) -> -14040 | T9: =+F9*12/14*(1-SS_TRABAJADOR-RET_TRABAJO) -> -14040 | U9: =+G9*12/14*(1-SS_TRABAJADOR-RET_TRABAJO) -> -14040 | V9: =+H9*12/14*(1-SS_TRABAJADOR-RET_TRABAJO) -> -14040 | W9: =+I9*12/14*(1-SS_TRABAJADOR-RET_TRABAJO) -> -14040 | X9: =+J9*12/14*(1-SS_TRABAJADOR-RET_TRABAJO) -> -14040 | Y9: =+K9*12/14*(1-SS_TRABAJADOR-RET_TRABAJO) -> -14040 | Z9: =+L9*12/14*(1-SS_TRABAJADOR-RET_TRABAJO) -> -14040 | ... AD9: =+P9*12/14*(1-SS_TRABAJADOR-RET_TRABAJO) -> -14040
R10: Pagas Extras | X10: =+X9 -> -14040 | AD10: =+AD9 -> -14040
R11: Retenciones a trabajadores | S11: =+D9*12/14*2*RET_TRABAJO*2 -> -10697.143 | V11: =+E9*12/14*RET_TRABAJO+F9*12/14*RET_TRABAJO+T12/(1-SS_TRABAJADOR-RET_TRABAJO)*RET_TRABAJO+G9*12/14*RET_TRABAJO -> -12672 | Y11: =+H9*12/14*RET_TRABAJO+I9*12/14*RET_TRABAJO+J9*12/14*2*RET_TRABAJO -> -11520 | AB11: =+K9*12/14*RET_TRABAJO+L9*12/14*RET_TRABAJO+M9*12/14*RET_TRABAJO -> -8640
B12: Bonus e Incentivos | C12: -2000 | D12: -2000 | E12: =+E9*0.1 -> -2100 | F12: =+F9*0.1 -> -2100 | G12: =+G9*0.1 -> -2100 | H12: =+H9*0.1 -> -2100 | I12: =+I9*0.1 -> -2100 | J12: =+J9*0.1 -> -2100 | K12: =+K9*0.1 -> -2100 | L12: =+L9*0.1 -> -2100 | ... P12: =+P9*0.1 -> -2100 | R12: Bonus e Incentivos | T12: =+C12*12*1.05*(1-SS_TRABAJADOR-RET_TRABAJO) -> -19656
B13: Seguridad Social Empresa | C13: =+C9*0.3 -> -5850 | D13: =+D9*0.3 -> -5850 | E13: =+E9*0.3 -> -6300 | F13: =+F9*0.3 -> -6300 | G13: =+G9*0.3 -> -6300 | H13: =+H9*0.3 -> -6300 | I13: =+I9*0.3 -> -6300 | J13: =+J9*0.3 -> -6300 | ... P13: =+P9*0.3 -> -6300 | R13: Seguridad Social | S13: =+D9*SS_TRABAJADOR+D13 -> -7020 | T13: =+E9*SS_TRABAJADOR+E13 -> -7560 | U13: =+F9*SS_TRABAJADOR+F13+T12/(1-SS_TRABAJADOR-RET_TRABAJO)*39% -> -17388 | V13: =+G9*SS_TRABAJADOR+G13 -> -7560 | W13: =+H9*SS_TRABAJADOR+H13 -> -7560 | X13: =+I9*SS_TRABAJADOR+I13 -> -7560 | Y13: =+J9*SS_TRABAJADOR+J13 -> -7560 | Z13: =+K9*SS_TRABAJADOR+K13 -> -7560 | AA13: =+L9*SS_TRABAJADOR+L13 -> -7560 | AB13: =+M9*SS_TRABAJADOR+M13 -> -7560 | AC13: =+N9*SS_TRABAJADOR+N13 -> -7560 | AD13: =+O9*SS_TRABAJADOR+O13 -> -7560
B14: COSTES DE PERSONAL | C14: =SUM(C9:C13) -> -27350 | D14: =SUM(D9:D13) -> -27350 | E14: =SUM(E9:E13) -> -29400 | F14: =SUM(F9:F13) -> -29400 | G14: =SUM(G9:G13) -> -29400 | H14: =SUM(H9:H13) -> -29400 | I14: =SUM(I9:I13) -> -29400 | J14: =SUM(J9:J13) -> -29400 | ... P14: =SUM(P9:P13) -> -29400 | R14: COSTES DE PERSONAL | S14: =SUM(S9:S13) -> -31757.143 | T14: =SUM(T9:T13) -> -41256 | U14: =SUM(U9:U13) -> -31428 | V14: =SUM(V9:V13) -> -34272 | W14: =SUM(W9:W13) -> -21600 | X14: =SUM(X9:X13) -> -35640 | Y14: =SUM(Y9:Y13) -> -33120 | Z14: =SUM(Z9:Z13) -> -21600 | ... AD14: =SUM(AD9:AD13) -> -35640
B15: Compra de mercancías al contado | C15: -5000 | D15: -5000 | E15: -21000 | F15: -7000 | G15: -8000 | H15: -10000 | I15: -11000 | J15: -12000 | K15: -11000 | L15: -12000 | M15: -13000 | N15: -10000 | O15: -11000 | P15: -12000 | R15: Compra de mercancías al contado | S15: =E15*(1+IVA) -> -25410 | T15: =F15*(1+IVA) -> -8470 | U15: =G15*(1+IVA) -> -9680 | V15: =H15*(1+IVA) -> -12100 | W15: =I15*(1+IVA) -> -13310 | X15: =J15*(1+IVA) -> -14520 | Y15: =K15*(1+IVA) -> -13310 | Z15: =L15*(1+IVA) -> -14520 | ... AD15: =P15*(1+IVA) -> -14520
B16: Compra de mercancías a 30 días | C16: -18000 | D16: -24000 | E16: -34000 | F16: -7500 | G16: -9500 | H16: -19000 | I16: -17000 | J16: -17500 | K16: -17000 | L16: -17500 | M16: -18000 | N16: -19000 | O16: -17000 | P16: -17500 | R16: Compra de mercancías a 30 días | S16: =+D16*(1+IVA) -> -29040 | T16: =+E16*(1+IVA) -> -41140 | U16: =+F16*(1+IVA) -> -9075 | V16: =+G16*(1+IVA) -> -11495 | W16: =+H16*(1+IVA) -> -22990 | X16: =+I16*(1+IVA) -> -20570 | Y16: =+J16*(1+IVA) -> -21175 | Z16: =+K16*(1+IVA) -> -20570 | ... AD16: =+O16*(1+IVA) -> -20570
B17: Compra de mercancías a 60 días | C17: -13000 | D17: -4000 | E17: -4500 | F17: -3000 | G17: -5000 | H17: -4000 | I17: -4500 | J17: -3000 | K17: -4500 | L17: -3000 | M17: -5000 | N17: -4000 | O17: -4500 | P17: -3000 | R17: Compra de mercancías a 60 días | S17: =+C17*(1+IVA) -> -15730 | T17: =+D17*(1+IVA) -> -4840 | U17: =+E17*(1+IVA) -> -5445 | V17: =+F17*(1+IVA) -> -3630 | W17: =+G17*(1+IVA) -> -6050 | X17: =+H17*(1+IVA) -> -4840 | Y17: =+I17*(1+IVA) -> -5445 | Z17: =+J17*(1+IVA) -> -3630 | ... AD17: =+N17*(1+IVA) -> -4840
B18: COMPRAS A PROVEEDORES | C18: =SUM(C15:C17) -> -36000 | D18: =SUM(D15:D17) -> -33000 | E18: =SUM(E15:E17) -> -59500 | F18: =SUM(F15:F17) -> -17500 | G18: =SUM(G15:G17) -> -22500 | H18: =SUM(H15:H17) -> -33000 | I18: =SUM(I15:I17) -> -32500 | J18: =SUM(J15:J17) -> -32500 | ... P18: =SUM(P15:P17) -> -32500 | R18: COMPRAS A PROVEEDORES | S18: =SUM(S15:S17) -> -70180 | T18: =SUM(T15:T17) -> -54450 | U18: =SUM(U15:U17) -> -24200 | V18: =SUM(V15:V17) -> -27225 | W18: =SUM(W15:W17) -> -42350 | X18: =SUM(X15:X17) -> -39930 | Y18: =SUM(Y15:Y17) -> -39930 | Z18: =SUM(Z15:Z17) -> -38720 | ... AD18: =SUM(AD15:AD17) -> -39930
B19: Alquileres | C19: -1450 | D19: -1450 | E19: -1500 | F19: -1500 | G19: -1500 | H19: -1500 | I19: -1500 | J19: -1500 | K19: -1500 | L19: -1500 | M19: -1500 | N19: -1500 | O19: -1500 | P19: -1500 | R19: Alquileres | S19: =+E19*(1+IVA-RETENCIÓN) -> -1530 | T19: =+F19*(1+IVA-RETENCIÓN) -> -1530 | U19: =+G19*(1+IVA-RETENCIÓN) -> -1530 | V19: =+H19*(1+IVA-RETENCIÓN) -> -1530 | W19: =+I19*(1+IVA-RETENCIÓN) -> -1530 | X19: =+J19*(1+IVA-RETENCIÓN) -> -1530 | Y19: =+K19*(1+IVA-RETENCIÓN) -> -1530 | Z19: =+L19*(1+IVA-RETENCIÓN) -> -1530 | ... AD19: =+P19*(1+IVA-RETENCIÓN) -> -1530
B20: Serv. Profesionales Independientes | C20: -800 | D20: -800 | E20: -1000 | F20: -800 | G20: -800 | H20: -1000 | I20: -800 | J20: -800 | K20: -1000 | L20: -800 | M20: -800 | N20: -1000 | O20: -800 | P20: -800 | R20: Serv. Profesionales Independientes | S20: =+E20*(1+IVA-RETENCIÓN) -> -1020 | T20: =+F20*(1+IVA-RETENCIÓN) -> -816 | U20: =+G20*(1+IVA-RETENCIÓN) -> -816 | V20: =+H20*(1+IVA-RETENCIÓN) -> -1020 | W20: =+I20*(1+IVA-RETENCIÓN) -> -816 | X20: =+J20*(1+IVA-RETENCIÓN) -> -816 | Y20: =+K20*(1+IVA-RETENCIÓN) -> -1020 | Z20: =+L20*(1+IVA-RETENCIÓN) -> -816 | ... AD20: =+P20*(1+IVA-RETENCIÓN) -> -816
B21: Transporte | C21: -450 | D21: -450 | E21: -450 | F21: -450 | G21: -450 | H21: -450 | I21: -450 | J21: -450 | K21: -450 | L21: -450 | M21: -450 | N21: -450 | O21: -450 | P21: -450 | R21: Transporte | S21: =+E21*(1+IVA) -> -544.5 | T21: =+F21*(1+IVA) -> -544.5 | U21: =+G21*(1+IVA) -> -544.5 | V21: =+H21*(1+IVA) -> -544.5 | W21: =+I21*(1+IVA) -> -544.5 | X21: =+J21*(1+IVA) -> -544.5 | Y21: =+K21*(1+IVA) -> -544.5 | Z21: =+L21*(1+IVA) -> -544.5 | ... AD21: =+P21*(1+IVA) -> -544.5
B22: Seguros | C22: -500 | D22: -500 | E22: -500 | F22: -500 | G22: -500 | H22: -500 | I22: -500 | J22: -500 | K22: -500 | L22: -500 | M22: -500 | N22: -500 | O22: -500 | P22: -500 | R22: Seguros | V22: -6000
B23: Publicidad y Márketing | C23: -1000 | D23: -1000 | E23: -1000 | F23: -1000 | G23: -1000 | H23: -1000 | I23: -1000 | J23: -1000 | K23: -1000 | L23: -1000 | M23: -1000 | N23: -1000 | O23: -1000 | P23: -1000 | R23: Publicidad y Márketing | S23: =-500*(1+IVA) -> -605 | T23: =-500*(1+IVA) -> -605 | U23: =-2000*(1+IVA) -> -2420 | V23: =-500*(1+IVA) -> -605 | W23: =-500*(1+IVA) -> -605 | X23: =-2000*(1+IVA) -> -2420 | Y23: =-500*(1+IVA) -> -605 | Z23: =-500*(1+IVA) -> -605 | AA23: =-2000*(1+IVA) -> -2420 | AB23: =-500*(1+IVA) -> -605 | AC23: =-500*(1+IVA) -> -605 | AD23: =-2000*(1+IVA) -> -2420
B24: Suministros | C24: -2500 | D24: -2500 | E24: -2600 | F24: -2600 | G24: -2600 | H24: -2600 | I24: -2600 | J24: -2600 | K24: -2600 | L24: -2600 | M24: -2600 | N24: -2600 | O24: -2600 | P24: -2600 | R24: Suministros | S24: =+E24*(1+IVA) -> -3146 | T24: =+F24*(1+IVA) -> -3146 | U24: =+G24*(1+IVA) -> -3146 | V24: =+H24*(1+IVA) -> -3146 | W24: =+I24*(1+IVA) -> -3146 | X24: =+J24*(1+IVA) -> -3146 | Y24: =+K24*(1+IVA) -> -3146 | Z24: =+L24*(1+IVA) -> -3146 | ... AD24: =+P24*(1+IVA) -> -3146
B25: SERVICIOS EXTERIORES | C25: =SUM(C19:C24) -> -6700 | D25: =SUM(D19:D24) -> -6700 | E25: =SUM(E19:E24) -> -7050 | F25: =SUM(F19:F24) -> -6850 | G25: =SUM(G19:G24) -> -6850 | H25: =SUM(H19:H24) -> -7050 | I25: =SUM(I19:I24) -> -6850 | J25: =SUM(J19:J24) -> -6850 | ... P25: =SUM(P19:P24) -> -6850 | R25: SERVICIOS EXTERIORES | S25: =SUM(S19:S24) -> -6845.5 | T25: =SUM(T19:T24) -> -6641.5 | U25: =SUM(U19:U24) -> -8456.5 | V25: =SUM(V19:V24) -> -12845.5 | W25: =SUM(W19:W24) -> -6641.5 | X25: =SUM(X19:X24) -> -8456.5 | Y25: =SUM(Y19:Y24) -> -6845.5 | Z25: =SUM(Z19:Z24) -> -6641.5 | ... AD25: =SUM(AD19:AD24) -> -8456.5
B26: Hacienda Pública por IVA (Neto) | R26: Hacienda Pública por IVA (Neto) | S26: -65000 | V26: -76000 | Y26: -65000 | AB26: -76000
B27: Hacienda Pública por Retenciones | R27: H. Pública por Retenciones Alq. Y Prof. | S27: -1300 | V27: -1350 | Y27: -1300 | AB27: -1350
B28: H. Pública por Impuesto de Sociedades | C28: -22620 | D28: -7220 | E28: -19870 | F28: -8910 | G28: -25210 | H28: -10770 | I28: -22910 | J28: -6910 | K28: -19870 | L28: -8910 | M28: -25210 | N28: -10770 | O28: -22910 | P28: -6910 | R28: H. Pública por Impuesto de Sociedades | V28: -40000 | Y28: -30000 | AB28: -80000 | AD28: -50000
B29: IAE y otros tributos locales | C29: -500 | D29: -500 | E29: -500 | F29: -500 | G29: -500 | H29: -500 | I29: -500 | J29: -500 | K29: -500 | L29: -500 | M29: -500 | N29: -500 | O29: -500 | P29: -500 | R29: IAE y otros tributos locales | S29: -500 | T29: -500 | U29: -500 | V29: -500 | W29: -500 | X29: -500 | Y29: -500 | Z29: -500 | AA29: -500 | AB29: -500 | AC29: -500 | AD29: -500
B30: IMPUESTOS Y TRIBUTOS | C30: =SUM(C26:C29) -> -23120 | D30: =SUM(D26:D29) -> -7720 | E30: =SUM(E26:E29) -> -20370 | F30: =SUM(F26:F29) -> -9410 | G30: =SUM(G26:G29) -> -25710 | H30: =SUM(H26:H29) -> -11270 | I30: =SUM(I26:I29) -> -23410 | J30: =SUM(J26:J29) -> -7410 | ... P30: =SUM(P26:P29) -> -7410 | R30: SERVICIOS EXTERIORES | S30: =SUM(S26:S29) -> -66800 | T30: =SUM(T26:T29) -> -500 | U30: =SUM(U26:U29) -> -500 | V30: =SUM(V26:V29) -> -117850 | W30: =SUM(W26:W29) -> -500 | X30: =SUM(X26:X29) -> -500 | Y30: =SUM(Y26:Y29) -> -96800 | Z30: =SUM(Z26:Z29) -> -500 | ... AD30: =SUM(AD26:AD29) -> -50500
B31: Gastos Bancarios | C31: -300 | D31: -300 | E31: -300 | F31: -300 | G31: -300 | H31: -300 | I31: -300 | J31: -300 | K31: -300 | L31: -300 | M31: -300 | N31: -300 | O31: -300 | P31: -300 | R31: Gastos Bancarios | S31: -300 | T31: -300 | U31: -300 | V31: -300 | W31: -300 | X31: -300 | Y31: -300 | Z31: -300 | AA31: -300 | AB31: -300 | AC31: -300 | AD31: -300
B32: Otros Gastos | C32: -1000 | D32: -1000 | E32: -1000 | F32: -1000 | G32: -1000 | H32: -1000 | I32: -1000 | J32: -1000 | K32: -1000 | L32: -1000 | M32: -1000 | N32: -1000 | O32: -1000 | P32: -1000 | R32: Otros Gastos | S32: -1000 | T32: -1000 | U32: -1000 | V32: -1000 | W32: -1000 | X32: -1000 | Y32: -1000 | Z32: -1000 | AA32: -1000 | AB32: -1000 | AC32: -1000 | AD32: -1000
B33: TOTAL GASTOS EXPLOTACIÓN | C33: =+C14+C18+C25+C30+C31+C32 -> -94470 | D33: =+D14+D18+D25+D30+D31+D32 -> -76070 | E33: =+E14+E18+E25+E30+E31+E32 -> -117620 | F33: =+F14+F18+F25+F30+F31+F32 -> -64460 | G33: =+G14+G18+G25+G30+G31+G32 -> -85760 | H33: =+H14+H18+H25+H30+H31+H32 -> -82020 | I33: =+I14+I18+I25+I30+I31+I32 -> -93460 | J33: =+J14+J18+J25+J30+J31+J32 -> -77460 | ... P33: =+P14+P18+P25+P30+P31+P32 -> -77460 | R33: TOTAL PAGOS EXPLOTACIÓN | S33: =+S14+S18+S25+S30+S31+S32 -> -176882.64 | T33: =+T14+T18+T25+T30+T31+T32 -> -104147.5 | U33: =+U14+U18+U25+U30+U31+U32 -> -65884.5 | V33: =+V14+V18+V25+V30+V31+V32 -> -193492.5 | W33: =+W14+W18+W25+W30+W31+W32 -> -72391.5 | X33: =+X14+X18+X25+X30+X31+X32 -> -85826.5 | Y33: =+Y14+Y18+Y25+Y30+Y31+Y32 -> -177995.5 | Z33: =+Z14+Z18+Z25+Z30+Z31+Z32 -> -68761.5 | ... AD33: =+AD14+AD18+AD25+AD30+AD31+AD32 -> -135826.5
L37: =-239*0.21 -> -50.19

Sheet Presupuesto_Tesorería_v1
A1: CONSOLIDACIÓN Y ANÁLISIS
B3: PRESUPUESTO DE TESORERÍA | D3: ENE | E3: FEB | F3: MAR | G3: ABR | H3: MAY | I3: JUN | J3: JUL | K3: AGO | L3: SEP | M3: OCT | N3: NOV | O3: DIC | Q3: TOTAL
B4: SALDO INICIAL | D4: 45000 | E4: =+D56 -> -39690.976 | F4: =+E56 -> 77387.357 | G4: =+F56 -> 34836.19 | H4: =+G56 -> 76924.524 | I4: =+H56 -> 161090.66 | J4: =+I56 -> 183336.8 | K4: =+J56 -> -52203.56 | L4: =+K56 -> 98579.385 | ... O4: =+N56 -> 121478.52 | Q4: =+D4 -> 45000
C5: Cliente TOP 1 | D5: =Traslación_Cobros!E12 -> 60500 | E5: =Traslación_Cobros!F12 -> 60500 | F5: =Traslación_Cobros!G12 -> 60500 | G5: =Traslación_Cobros!H12 -> 60500 | H5: =Traslación_Cobros!I12 -> 60500 | I5: =Traslación_Cobros!J12 -> 60500 | J5: =Traslación_Cobros!K12 -> 60500 | K5: =Traslación_Cobros!L12 -> 60500 | ... O5: =Traslación_Cobros!P12 -> 60500 | Q5: =SUM(D5:O5) -> 726000
C6: Cliente TOP 2 | D6: =Traslación_Cobros!E13 -> 0 | E6: =Traslación_Cobros!F13 -> 72600 | F6: =Traslación_Cobros!G13 -> 0 | G6: =Traslación_Cobros!H13 -> 96800 | H6: =Traslación_Cobros!I13 -> 0 | I6: =Traslación_Cobros!J13 -> 90750 | J6: =Traslación_Cobros!K13 -> 0 | K6: =Traslación_Cobros!L13 -> 72600 | ... O6: =Traslación_Cobros!P13 -> 84700 | Q6: =SUM(D6:O6) -> 514250
C7: Cliente TOP 3 | D7: =Traslación_Cobros!E14 -> 51425 | E7: =Traslación_Cobros!F14 -> 67155 | F7: =Traslación_Cobros!G14 -> 63525 | G7: =Traslación_Cobros!H14 -> 70785 | H7: =Traslación_Cobros!I14 -> 66550 | I7: =Traslación_Cobros!J14 -> 62315 | J7: =Traslación_Cobros!K14 -> 58685 | K7: =Traslación_Cobros!L14 -> 63525 | ... O7: =Traslación_Cobros!P14 -> 62315 | Q7: =SUM(D7:O7) -> 767140
C8: Resto Clientes | D8: =Traslación_Cobros!E15 -> 27225 | E8: =Traslación_Cobros!F15 -> 24200 | F8: =Traslación_Cobros!G15 -> 27225 | G8: =Traslación_Cobros!H15 -> 27225 | H8: =Traslación_Cobros!I15 -> 33275 | I8: =Traslación_Cobros!J15 -> 33275 | J8: =Traslación_Cobros!K15 -> 27225 | K8: =Traslación_Cobros!L15 -> 27225 | ... O8: =Traslación_Cobros!P15 -> 33275 | Q8: =SUM(D8:O8) -> 347875
C9: COBROS EXPLOTACIÓN | D9: =SUM(D5:D8) -> 139150 | E9: =SUM(E5:E8) -> 224455 | F9: =SUM(F5:F8) -> 151250 | G9: =SUM(G5:G8) -> 255310 | H9: =SUM(H5:H8) -> 160325 | I9: =SUM(I5:I8) -> 246840 | J9: =SUM(J5:J8) -> 146410 | K9: =SUM(K5:K8) -> 223850 | ... O9: =SUM(O5:O8) -> 240790 | Q9: =SUM(Q5:Q8) -> 2355265
C10: Nómina mensual | D10: =Traslación_Pagos!S9 -> -14040 | E10: =Traslación_Pagos!T9 -> -14040 | F10: =Traslación_Pagos!U9 -> -14040 | G10: =Traslación_Pagos!V9 -> -14040 | H10: =Traslación_Pagos!W9 -> -14040 | I10: =Traslación_Pagos!X9 -> -14040 | J10: =Traslación_Pagos!Y9 -> -14040 | K10: =Traslación_Pagos!Z9 -> -14040 | ... O10: =Traslación_Pagos!AD9 -> -14040 | Q10: =SUM(D10:O10) -> -168480
C11: Pagas Extras | D11: =Traslación_Pagos!S10 -> 0 | E11: =Traslación_Pagos!T10 -> 0 | F11: =Traslación_Pagos!U10 -> 0 | G11: =Traslación_Pagos!V10 -> 0 | H11: =Traslación_Pagos!W10 -> 0 | I11: =Traslación_Pagos!X10 -> -14040 | J11: =Traslación_Pagos!Y10 -> 0 | K11: =Traslación_Pagos!Z10 -> 0 | ... O11: =Traslación_Pagos!AD10 -> -14040 | Q11: =SUM(D11:O11) -> -28080
C12: Retenciones a trabajadores | D12: =Traslación_Pagos!S11 -> -10697.143 | E12: =Traslación_Pagos!T11 -> 0 | F12: =Traslación_Pagos!U11 -> 0 | G12: =Traslación_Pagos!V11 -> -12672 | H12: =Traslación_Pagos!W11 -> 0 | I12: =Traslación_Pagos!X11 -> 0 | J12: =Traslación_Pagos!Y11 -> -11520 | K12: =Traslación_Pagos!Z11 -> 0 | ... O12: =Traslación_Pagos!AD11 -> 0 | Q12: =SUM(D12:O12) -> -43529.143
C13: Bonus e Incentivos | D13: =Traslación_Pagos!S12 -> 0 | E13: =Traslación_Pagos!T12 -> -19656 | F13: =Traslación_Pagos!U12 -> 0 | G13: =Traslación_Pagos!V12 -> 0 | H13: =Traslación_Pagos!W12 -> 0 | I13: =Traslación_Pagos!X12 -> 0 | J13: =Traslación_Pagos!Y12 -> 0 | K13: =Traslación_Pagos!Z12 -> 0 | ... O13: =Traslación_Pagos!AD12 -> 0 | Q13: =SUM(D13:O13) -> -19656
C14: Seguridad Social | D14: =Traslación_Pagos!S13 -> -7020 | E14: =Traslación_Pagos!T13 -> -7560 | F14: =Traslación_Pagos!U13 -> -17388 | G14: =Traslación_Pagos!V13 -> -7560 | H14: =Traslación_Pagos!W13 -> -7560 | I14: =Traslación_Pagos!X13 -> -7560 | J14: =Traslación_Pagos!Y13 -> -7560 | K14: =Traslación_Pagos!Z13 -> -7560 | ... O14: =Traslación_Pagos!AD13 -> -7560 | Q14: =SUM(D14:O14) -> -100008
C15: COSTES DE PERSONAL | D15: =SUM(D10:D14) -> -31757.143 | E15: =SUM(E10:E14) -> -41256 | F15: =SUM(F10:F14) -> -31428 | G15: =SUM(G10:G14) -> -34272 | H15: =SUM(H10:H14) -> -21600 | I15: =SUM(I10:I14) -> -35640 | J15: =SUM(J10:J14) -> -33120 | K15: =SUM(K10:K14) -> -21600 | ... O15: =SUM(O10:O14) -> -35640 | Q15: =SUM(Q10:Q14) -> -359753.14
C16: Compra de mercancías al contado | D16: =Traslación_Pagos!S15 -> -25410 | E16: =Traslación_Pagos!T15 -> -8470 | F16: =Traslación_Pagos!U15 -> -9680 | G16: =Traslación_Pagos!V15 -> -12100 | H16: =Traslación_Pagos!W15 -> -13310 | I16: =Traslación_Pagos!X15 -> -14520 | J16: =Traslación_Pagos!Y15 -> -13310 | K16: =Traslación_Pagos!Z15 -> -14520 | ... O16: =Traslación_Pagos!AD15 -> -14520 | Q16: =SUM(D16:O16) -> -166980
C17: Compra de mercancías a 30 días | D17: =Traslación_Pagos!S16 -> -29040 | E17: =Traslación_Pagos!T16 -> -41140 | F17: =Traslación_Pagos!U16 -> -9075 | G17: =Traslación_Pagos!V16 -> -11495 | H17: =Traslación_Pagos!W16 -> -22990 | I17: =Traslación_Pagos!X16 -> -20570 | J17: =Traslación_Pagos!Y16 -> -21175 | K17: =Traslación_Pagos!Z16 -> -20570 | ... O17: =Traslación_Pagos!AD16 -> -20570 | Q17: =SUM(D17:O17) -> -262570
C18: Compra de mercancías a 60 días | D18: =Traslación_Pagos!S17 -> -15730 | E18: =Traslación_Pagos!T17 -> -4840 | F18: =Traslación_Pagos!U17 -> -5445 | G18: =Traslación_Pagos!V17 -> -3630 | H18: =Traslación_Pagos!W17 -> -6050 | I18: =Traslación_Pagos!X17 -> -4840 | J18: =Traslación_Pagos!Y17 -> -5445 | K18: =Traslación_Pagos!Z17 -> -3630 | ... O18: =Traslación_Pagos!AD17 -> -4840 | Q18: =SUM(D18:O18) -> -69575
C19: COMPRAS A PROVEEDORES | D19: =SUM(D16:D18) -> -70180 | E19: =SUM(E16:E18) -> -54450 | F19: =SUM(F16:F18) -> -24200 | G19: =SUM(G16:G18) -> -27225 | H19: =SUM(H16:H18) -> -42350 | I19: =SUM(I16:I18) -> -39930 | J19: =SUM(J16:J18) -> -39930 | K19: =SUM(K16:K18) -> -38720 | ... O19: =SUM(O16:O18) -> -39930 | Q19: =SUM(Q16:Q18) -> -499125
C20: Alquileres | D20: =Traslación_Pagos!S19 -> -1530 | E20: =Traslación_Pagos!T19 -> -1530 | F20: =Traslación_Pagos!U19 -> -1530 | G20: =Traslación_Pagos!V19 -> -1530 | H20: =Traslación_Pagos!W19 -> -1530 | I20: =Traslación_Pagos!X19 -> -1530 | J20: =Traslación_Pagos!Y19 -> -1530 | K20: =Traslación_Pagos!Z19 -> -1530 | ... O20: =Traslación_Pagos!AD19 -> -1530 | Q20: =SUM(D20:O20) -> -18360
C21: Serv. Profesionales Independientes | D21: =Traslación_Pagos!S20 -> -1020 | E21: =Traslación_Pagos!T20 -> -816 | F21: =Traslación_Pagos!U20 -> -816 | G21: =Traslación_Pagos!V20 -> -1020 | H21: =Traslación_Pagos!W20 -> -816 | I21: =Traslación_Pagos!X20 -> -816 | J21: =Traslación_Pagos!Y20 -> -1020 | K21: =Traslación_Pagos!Z20 -> -816 | ... O21: =Traslación_Pagos!AD20 -> -816 | Q21: =SUM(D21:O21) -> -10608
C22: Transporte | D22: =Traslación_Pagos!S21 -> -544.5 | E22: =Traslación_Pagos!T21 -> -544.5 | F22: =Traslación_Pagos!U21 -> -544.5 | G22: =Traslación_Pagos!V21 -> -544.5 | H22: =Traslación_Pagos!W21 -> -544.5 | I22: =Traslación_Pagos!X21 -> -544.5 | J22: =Traslación_Pagos!Y21 -> -544.5 | K22: =Traslación_Pagos!Z21 -> -544.5 | ... O22: =Traslación_Pagos!AD21 -> -544.5 | Q22: =SUM(D22:O22) -> -6534
C23: Seguros | D23: =Traslación_Pagos!S22 -> 0 | E23: =Traslación_Pagos!T22 -> 0 | F23: =Traslación_Pagos!U22 -> 0 | G23: =Traslación_Pagos!V22 -> -6000 | H23: =Traslación_Pagos!W22 -> 0 | I23: =Traslación_Pagos!X22 -> 0 | J23: =Traslación_Pagos!Y22 -> 0 | K23: =Traslación_Pagos!Z22 -> 0 | ... O23: =Traslación_Pagos!AD22 -> 0 | Q23: =SUM(D23:O23) -> -6000
C24: Publicidad y Márketing | D24: =Traslación_Pagos!S23 -> -605 | E24: =Traslación_Pagos!T23 -> -605 | F24: =Traslación_Pagos!U23 -> -2420 | G24: =Traslación_Pagos!V23 -> -605 | H24: =Traslación_Pagos!W23 -> -605 | I24: =Traslación_Pagos!X23 -> -2420 | J24: =Traslación_Pagos!Y23 -> -605 | K24: =Traslación_Pagos!Z23 -> -605 | ... O24: =Traslación_Pagos!AD23 -> -2420 | Q24: =SUM(D24:O24) -> -14520
C25: Suministros | D25: =Traslación_Pagos!S24 -> -3146 | E25: =Traslación_Pagos!T24 -> -3146 | F25: =Traslación_Pagos!U24 -> -3146 | G25: =Traslación_Pagos!V24 -> -3146 | H25: =Traslación_Pagos!W24 -> -3146 | I25: =Traslación_Pagos!X24 -> -3146 | J25: =Traslación_Pagos!Y24 -> -3146 | K25: =Traslación_Pagos!Z24 -> -3146 | ... O25: =Traslación_Pagos!AD24 -> -3146 | Q25: =SUM(D25:O25) -> -37752
C26: SERVICIOS EXTERIORES | D26: =SUM(D20:D25) -> -6845.5 | E26: =SUM(E20:E25) -> -6641.5 | F26: =SUM(F20:F25) -> -8456.5 | G26: =SUM(G20:G25) -> -12845.5 | H26: =SUM(H20:H25) -> -6641.5 | I26: =SUM(I20:I25) -> -8456.5 | J26: =SUM(J20:J25) -> -6845.5 | K26: =SUM(K20:K25) -> -6641.5 | ... O26: =SUM(O20:O25) -> -8456.5 | Q26: =SUM(Q20:Q25) -> -93774
C27: Hacienda Pública por IVA (Neto) | D27: =Traslación_Pagos!S26 -> -65000 | E27: =Traslación_Pagos!T26 -> 0 | F27: =Traslación_Pagos!U26 -> 0 | G27: =Traslación_Pagos!V26 -> -76000 | H27: =Traslación_Pagos!W26 -> 0 | I27: =Traslación_Pagos!X26 -> 0 | J27: =Traslación_Pagos!Y26 -> -65000 | K27: =Traslación_Pagos!Z26 -> 0 | ... O27: =Traslación_Pagos!AD26 -> 0 | Q27: =SUM(D27:O27) -> -282000
C28: H. Pública por Retenciones Alq. Y Prof. | D28: =Traslación_Pagos!S27 -> -1300 | E28: =Traslación_Pagos!T27 -> 0 | F28: =Traslación_Pagos!U27 -> 0 | G28: =Traslación_Pagos!V27 -> -1350 | H28: =Traslación_Pagos!W27 -> 0 | I28: =Traslación_Pagos!X27 -> 0 | J28: =Traslación_Pagos!Y27 -> -1300 | K28: =Traslación_Pagos!Z27 -> 0 | ... O28: =Traslación_Pagos!AD27 -> 0 | Q28: =SUM(D28:O28) -> -5300
C29: H. Pública por Impuesto de Sociedades | D29: =Traslación_Pagos!S28 -> 0 | E29: =Traslación_Pagos!T28 -> 0 | F29: =Traslación_Pagos!U28 -> 0 | G29: =Traslación_Pagos!V28 -> -40000 | H29: =Traslación_Pagos!W28 -> 0 | I29: =Traslación_Pagos!X28 -> 0 | J29: =Traslación_Pagos!Y28 -> -30000 | K29: =Traslación_Pagos!Z28 -> 0 | ... O29: =Traslación_Pagos!AD28 -> -50000 | Q29: =SUM(D29:O29) -> -200000
C30: IAE y otros tributos locales | D30: =Traslación_Pagos!S29 -> -500 | E30: =Traslación_Pagos!T29 -> -500 | F30: =Traslación_Pagos!U29 -> -500 | G30: =Traslación_Pagos!V29 -> -500 | H30: =Traslación_Pagos!W29 -> -500 | I30: =Traslación_Pagos!X29 -> -500 | J30: =Traslación_Pagos!Y29 -> -500 | K30: =Traslación_Pagos!Z29 -> -500 | ... O30: =Traslación_Pagos!AD29 -> -500 | Q30: =SUM(D30:O30) -> -6000
C31: IMPUESTOS Y TRIBUTOS | D31: =SUM(D27:D30) -> -66800 | E31: =SUM(E27:E30) -> -500 | F31: =SUM(F27:F30) -> -500 | G31: =SUM(G27:G30) -> -117850 | H31: =SUM(H27:H30) -> -500 | I31: =SUM(I27:I30) -> -500 | J31: =SUM(J27:J30) -> -96800 | K31: =SUM(K27:K30) -> -500 | ... O31: =SUM(O27:O30) -> -50500 | Q31: =SUM(Q27:Q30) -> -493300
C32: Gastos Bancarios | D32: =Traslación_Pagos!S31 -> -300 | E32: =Traslación_Pagos!T31 -> -300 | F32: =Traslación_Pagos!U31 -> -300 | G32: =Traslación_Pagos!V31 -> -300 | H32: =Traslación_Pagos!W31 -> -300 | I32: =Traslación_Pagos!X31 -> -300 | J32: =Traslación_Pagos!Y31 -> -300 | K32: =Traslación_Pagos!Z31 -> -300 | ... O32: =Traslación_Pagos!AD31 -> -300 | Q32: =SUM(D32:O32) -> -3600
C33: Otros Gastos | D33: =Traslación_Pagos!S32 -> -1000 | E33: =Traslación_Pagos!T32 -> -1000 | F33: =Traslación_Pagos!U32 -> -1000 | G33: =Traslación_Pagos!V32 -> -1000 | H33: =Traslación_Pagos!W32 -> -1000 | I33: =Traslación_Pagos!X32 -> -1000 | J33: =Traslación_Pagos!Y32 -> -1000 | K33: =Traslación_Pagos!Z32 -> -1000 | ... O33: =Traslación_Pagos!AD32 -> -1000 | Q33: =SUM(D33:O33) -> -12000
C34: PAGOS EXPLOTACIÓN (OPEX) | D34: =+D15+D19+D26+D31+D32+D33 -> -176882.64 | E34: =+E15+E19+E26+E31+E32+E33 -> -104147.5 | F34: =+F15+F19+F26+F31+F32+F33 -> -65884.5 | G34: =+G15+G19+G26+G31+G32+G33 -> -193492.5 | H34: =+H15+H19+H26+H31+H32+H33 -> -72391.5 | I34: =+I15+I19+I26+I31+I32+I33 -> -85826.5 | J34: =+J15+J19+J26+J31+J32+J33 -> -177995.5 | K34: =+K15+K19+K26+K31+K32+K33 -> -68761.5 | ... O34: =+O15+O19+O26+O31+O32+O33 -> -135826.5 | Q34: =+Q15+Q19+Q26+Q31+Q32+Q33 -> -1461552.1
B35: FLUJO CAJA EXPLOTACIÓN | D35: =+D9+D34 -> -37732.643 | E35: =+E9+E34 -> 120307.5 | F35: =+F9+F34 -> 85365.5 | G35: =+G9+G34 -> 61817.5 | H35: =+H9+H34 -> 87933.5 | I35: =+I9+I34 -> 161013.5 | J35: =+J9+J34 -> -31585.5 | K35: =+K9+K34 -> 155088.5 | ... O35: =+O9+O34 -> 104963.5 | Q35: =+Q9+Q34 -> 893712.86
C36: (-) Compra de Activos Fijos | D36: -50000 | G36: -15000 | I36: -10000 | L36: -25000 | Q36: =SUM(D36:O36) -> -100000
C37: (+) Enajenación de Activos Fijos | Q37: =SUM(D37:O37) -> 0
C38: FLUJO CAJA ACTIVOS FIJOS (CAPEX) | D38: =SUM(D36:D37) -> -50000 | E38: =SUM(E36:E37) -> 0 | F38: =SUM(F36:F37) -> 0 | G38: =SUM(G36:G37) -> -15000 | H38: =SUM(H36:H37) -> 0 | I38: =SUM(I36:I37) -> -10000 | J38: =SUM(J36:J37) -> 0 | K38: =SUM(K36:K37) -> 0 | ... O38: =SUM(O36:O37) -> 0 | Q38: =SUM(Q36:Q37) -> -100000
C39: (+) Cobros por disposición de deuda | Q39: =SUM(D39:O39) -> 0
C40: (-) Pagos por amortización de deuda | F40: =[1]Cuadro_vencimientos_y_devengos!D13 -> -125000 | I40: =[1]Cuadro_vencimientos_y_devengos!G13 -> -125000 | L40: =[1]Cuadro_vencimientos_y_devengos!J13 -> -125000 | O40: =[1]Cuadro_vencimientos_y_devengos!M13 -> -125000 | Q40: =SUM(D40:O40) -> -500000
C41: (+) Cobros por disposición de pólizas | Q41: =SUM(D41:O41) -> 0
...

Sheet Presupuesto_Tesorería_v2
A1: ACCIONES APLICADAS - VERSIÓN FINAL PRESUPUESTO TESORERÍA
B3: PRESUPUESTO DE TESORERÍA | D3: ENE | E3: FEB | F3: MAR | G3: ABR | H3: MAY | I3: JUN | J3: JUL | K3: AGO | L3: SEP | M3: OCT | N3: NOV | O3: DIC | Q3: TOTAL
B4: SALDO INICIAL | D4: 45000 | E4: =+D56 -> 10309.024 | F4: =+E56 -> 77387.357 | G4: =+F56 -> 34836.19 | H4: =+G56 -> 76924.524 | I4: =+H56 -> 161090.66 | J4: =+I56 -> 183336.8 | K4: =+J56 -> -52203.56 | L4: =+K56 -> 98579.385 | ... O4: =+N56 -> 121478.52 | Q4: =+D4 -> 45000
C5: Cliente TOP 1 | D5: =Traslación_Cobros!E12 -> 60500 | E5: =Traslación_Cobros!F12 -> 60500 | F5: =Traslación_Cobros!G12 -> 60500 | G5: =Traslación_Cobros!H12 -> 60500 | H5: =Traslación_Cobros!I12 -> 60500 | I5: =Traslación_Cobros!J12 -> 60500 | J5: =Traslación_Cobros!K12 -> 60500 | K5: =Traslación_Cobros!L12 -> 60500 | ... O5: =Traslación_Cobros!P12 -> 60500 | Q5: =SUM(D5:O5) -> 726000
C6: Cliente TOP 2 | D6: =Traslación_Cobros!E13 -> 0 | E6: =Traslación_Cobros!F13 -> 72600 | F6: =Traslación_Cobros!G13 -> 0 | G6: =Traslación_Cobros!H13 -> 96800 | H6: =Traslación_Cobros!I13 -> 0 | I6: =Traslación_Cobros!J13 -> 90750 | J6: =Traslación_Cobros!K13 -> 0 | K6: =Traslación_Cobros!L13 -> 72600 | ... O6: =Traslación_Cobros!P13 -> 84700 | Q6: =SUM(D6:O6) -> 514250
C7: Cliente TOP 3 | D7: =Traslación_Cobros!E14 -> 51425 | E7: =Traslación_Cobros!F14 -> 67155 | F7: =Traslación_Cobros!G14 -> 63525 | G7: =Traslación_Cobros!H14 -> 70785 | H7: =Traslación_Cobros!I14 -> 66550 | I7: =Traslación_Cobros!J14 -> 62315 | J7: =Traslación_Cobros!K14 -> 58685 | K7: =Traslación_Cobros!L14 -> 63525 | ... O7: =Traslación_Cobros!P14 -> 62315 | Q7: =SUM(D7:O7) -> 767140
C8: Resto Clientes | D8: =Traslación_Cobros!E15 -> 27225 | E8: =Traslación_Cobros!F15 -> 24200 | F8: =Traslación_Cobros!G15 -> 27225 | G8: =Traslación_Cobros!H15 -> 27225 | H8: =Traslación_Cobros!I15 -> 33275 | I8: =Traslación_Cobros!J15 -> 33275 | J8: =Traslación_Cobros!K15 -> 27225 | K8: =Traslación_Cobros!L15 -> 27225 | ... O8: =Traslación_Cobros!P15 -> 33275 | Q8: =SUM(D8:O8) -> 347875
C9: COBROS EXPLOTACIÓN | D9: =SUM(D5:D8) -> 139150 | E9: =SUM(E5:E8) -> 224455 | F9: =SUM(F5:F8) -> 151250 | G9: =SUM(G5:G8) -> 255310 | H9: =SUM(H5:H8) -> 160325 | I9: =SUM(I5:I8) -> 246840 | J9: =SUM(J5:J8) -> 146410 | K9: =SUM(K5:K8) -> 223850 | ... O9: =SUM(O5:O8) -> 240790 | Q9: =SUM(Q5:Q8) -> 2355265
C10: Nómina mensual | D10: =Traslación_Pagos!S9 -> -14040 | E10: =Traslación_Pagos!T9 -> -14040 | F10: =Traslación_Pagos!U9 -> -14040 | G10: =Traslación_Pagos!V9 -> -14040 | H10: =Traslación_Pagos!W9 -> -14040 | I10: =Traslación_Pagos!X9 -> -14040 | J10: =Traslación_Pagos!Y9 -> -14040 | K10: =Traslación_Pagos!Z9 -> -14040 | ... O10: =Traslación_Pagos!AD9 -> -14040 | Q10: =SUM(D10:O10) -> -168480
C11: Pagas Extras | D11: =Traslación_Pagos!S10 -> 0 | E11: =Traslación_Pagos!T10 -> 0 | F11: =Traslación_Pagos!U10 -> 0 | G11: =Traslación_Pagos!V10 -> 0 | H11: =Traslación_Pagos!W10 -> 0 | I11: =Traslación_Pagos!X10 -> -14040 | J11: =Traslación_Pagos!Y10 -> 0 | K11: =Traslación_Pagos!Z10 -> 0 | ... O11: =Traslación_Pagos!AD10 -> -14040 | Q11: =SUM(D11:O11) -> -28080
C12: Retenciones a trabajadores | D12: =Traslación_Pagos!S11 -> -10697.143 | E12: =Traslación_Pagos!T11 -> 0 | F12: =Traslación_Pagos!U11 -> 0 | G12: =Traslación_Pagos!V11 -> -12672 | H12: =Traslación_Pagos!W11 -> 0 | I12: =Traslación_Pagos!X11 -> 0 | J12: =Traslación_Pagos!Y11 -> -11520 | K12: =Traslación_Pagos!Z11 -> 0 | ... O12: =Traslación_Pagos!AD11 -> 0 | Q12: =SUM(D12:O12) -> -43529.143
C13: Bonus e Incentivos | D13: =Traslación_Pagos!S12 -> 0 | E13: =Traslación_Pagos!T12 -> -19656 | F13: =Traslación_Pagos!U12 -> 0 | G13: =Traslación_Pagos!V12 -> 0 | H13: =Traslación_Pagos!W12 -> 0 | I13: =Traslación_Pagos!X12 -> 0 | J13: =Traslación_Pagos!Y12 -> 0 | K13: =Traslación_Pagos!Z12 -> 0 | ... O13: =Traslación_Pagos!AD12 -> 0 | Q13: =SUM(D13:O13) -> -19656
C14: Seguridad Social | D14: =Traslación_Pagos!S13 -> -7020 | E14: =Traslación_Pagos!T13 -> -7560 | F14: =Traslación_Pagos!U13 -> -17388 | G14: =Traslación_Pagos!V13 -> -7560 | H14: =Traslación_Pagos!W13 -> -7560 | I14: =Traslación_Pagos!X13 -> -7560 | J14: =Traslación_Pagos!Y13 -> -7560 | K14: =Traslación_Pagos!Z13 -> -7560 | ... O14: =Traslación_Pagos!AD13 -> -7560 | Q14: =SUM(D14:O14) -> -100008
C15: COSTES DE PERSONAL | D15: =SUM(D10:D14) -> -31757.143 | E15: =SUM(E10:E14) -> -41256 | F15: =SUM(F10:F14) -> -31428 | G15: =SUM(G10:G14) -> -34272 | H15: =SUM(H10:H14) -> -21600 | I15: =SUM(I10:I14) -> -35640 | J15: =SUM(J10:J14) -> -33120 | K15: =SUM(K10:K14) -> -21600 | ... O15: =SUM(O10:O14) -> -35640 | Q15: =SUM(Q10:Q14) -> -359753.14
C16: Compra de mercancías al contado | D16: =Traslación_Pagos!S15 -> -25410 | E16: =Traslación_Pagos!T15 -> -8470 | F16: =Traslación_Pagos!U15 -> -9680 | G16: =Traslación_Pagos!V15 -> -12100 | H16: =Traslación_Pagos!W15 -> -13310 | I16: =Traslación_Pagos!X15 -> -14520 | J16: =Traslación_Pagos!Y15 -> -13310 | K16: =Traslación_Pagos!Z15 -> -14520 | ... O16: =Traslación_Pagos!AD15 -> -14520 | Q16: =SUM(D16:O16) -> -166980
C17: Compra de mercancías a 30 días | D17: =Traslación_Pagos!S16 -> -29040 | E17: =Traslación_Pagos!T16 -> -41140 | F17: =Traslación_Pagos!U16 -> -9075 | G17: =Traslación_Pagos!V16 -> -11495 | H17: =Traslación_Pagos!W16 -> -22990 | I17: =Traslación_Pagos!X16 -> -20570 | J17: =Traslación_Pagos!Y16 -> -21175 | K17: =Traslación_Pagos!Z16 -> -20570 | ... O17: =Traslación_Pagos!AD16 -> -20570 | Q17: =SUM(D17:O17) -> -262570
C18: Compra de mercancías a 60 días | D18: =Traslación_Pagos!S17 -> -15730 | E18: =Traslación_Pagos!T17 -> -4840 | F18: =Traslación_Pagos!U17 -> -5445 | G18: =Traslación_Pagos!V17 -> -3630 | H18: =Traslación_Pagos!W17 -> -6050 | I18: =Traslación_Pagos!X17 -> -4840 | J18: =Traslación_Pagos!Y17 -> -5445 | K18: =Traslación_Pagos!Z17 -> -3630 | ... O18: =Traslación_Pagos!AD17 -> -4840 | Q18: =SUM(D18:O18) -> -69575
C19: COMPRAS A PROVEEDORES | D19: =SUM(D16:D18) -> -70180 | E19: =SUM(E16:E18) -> -54450 | F19: =SUM(F16:F18) -> -24200 | G19: =SUM(G16:G18) -> -27225 | H19: =SUM(H16:H18) -> -42350 | I19: =SUM(I16:I18) -> -39930 | J19: =SUM(J16:J18) -> -39930 | K19: =SUM(K16:K18) -> -38720 | ... O19: =SUM(O16:O18) -> -39930 | Q19: =SUM(Q16:Q18) -> -499125
C20: Alquileres | D20: =Traslación_Pagos!S19 -> -1530 | E20: =Traslación_Pagos!T19 -> -1530 | F20: =Traslación_Pagos!U19 -> -1530 | G20: =Traslación_Pagos!V19 -> -1530 | H20: =Traslación_Pagos!W19 -> -1530 | I20: =Traslación_Pagos!X19 -> -1530 | J20: =Traslación_Pagos!Y19 -> -1530 | K20: =Traslación_Pagos!Z19 -> -1530 | ... O20: =Traslación_Pagos!AD19 -> -1530 | Q20: =SUM(D20:O20) -> -18360
C21: Serv. Profesionales Independientes | D21: =Traslación_Pagos!S20 -> -1020 | E21: =Traslación_Pagos!T20 -> -816 | F21: =Traslación_Pagos!U20 -> -816 | G21: =Traslación_Pagos!V20 -> -1020 | H21: =Traslación_Pagos!W20 -> -816 | I21: =Traslación_Pagos!X20 -> -816 | J21: =Traslación_Pagos!Y20 -> -1020 | K21: =Traslación_Pagos!Z20 -> -816 | ... O21: =Traslación_Pagos!AD20 -> -816 | Q21: =SUM(D21:O21) -> -10608
C22: Transporte | D22: =Traslación_Pagos!S21 -> -544.5 | E22: =Traslación_Pagos!T21 -> -544.5 | F22: =Traslación_Pagos!U21 -> -544.5 | G22: =Traslación_Pagos!V21 -> -544.5 | H22: =Traslación_Pagos!W21 -> -544.5 | I22: =Traslación_Pagos!X21 -> -544.5 | J22: =Traslación_Pagos!Y21 -> -544.5 | K22: =Traslación_Pagos!Z21 -> -544.5 | ... O22: =Traslación_Pagos!AD21 -> -544.5 | Q22: =SUM(D22:O22) -> -6534
C23: Seguros | D23: =Traslación_Pagos!S22 -> 0 | E23: =Traslación_Pagos!T22 -> 0 | F23: =Traslación_Pagos!U22 -> 0 | G23: =Traslación_Pagos!V22 -> -6000 | H23: =Traslación_Pagos!W22 -> 0 | I23: =Traslación_Pagos!X22 -> 0 | J23: =Traslación_Pagos!Y22 -> 0 | K23: =Traslación_Pagos!Z22 -> 0 | ... O23: =Traslación_Pagos!AD22 -> 0 | Q23: =SUM(D23:O23) -> -6000
C24: Publicidad y Márketing | D24: =Traslación_Pagos!S23 -> -605 | E24: =Traslación_Pagos!T23 -> -605 | F24: =Traslación_Pagos!U23 -> -2420 | G24: =Traslación_Pagos!V23 -> -605 | H24: =Traslación_Pagos!W23 -> -605 | I24: =Traslación_Pagos!X23 -> -2420 | J24: =Traslación_Pagos!Y23 -> -605 | K24: =Traslación_Pagos!Z23 -> -605 | ... O24: =Traslación_Pagos!AD23 -> -2420 | Q24: =SUM(D24:O24) -> -14520
C25: Suministros | D25: =Traslación_Pagos!S24 -> -3146 | E25: =Traslación_Pagos!T24 -> -3146 | F25: =Traslación_Pagos!U24 -> -3146 | G25: =Traslación_Pagos!V24 -> -3146 | H25: =Traslación_Pagos!W24 -> -3146 | I25: =Traslación_Pagos!X24 -> -3146 | J25: =Traslación_Pagos!Y24 -> -3146 | K25: =Traslación_Pagos!Z24 -> -3146 | ... O25: =Traslación_Pagos!AD24 -> -3146 | Q25: =SUM(D25:O25) -> -37752
C26: SERVICIOS EXTERIORES | D26: =SUM(D20:D25) -> -6845.5 | E26: =SUM(E20:E25) -> -6641.5 | F26: =SUM(F20:F25) -> -8456.5 | G26: =SUM(G20:G25) -> -12845.5 | H26: =SUM(H20:H25) -> -6641.5 | I26: =SUM(I20:I25) -> -8456.5 | J26: =SUM(J20:J25) -> -6845.5 | K26: =SUM(K20:K25) -> -6641.5 | ... O26: =SUM(O20:O25) -> -8456.5 | Q26: =SUM(Q20:Q25) -> -93774
C27: Hacienda Pública por IVA (Neto) | D27: =Traslación_Pagos!S26 -> -65000 | E27: =Traslación_Pagos!T26 -> 0 | F27: =Traslación_Pagos!U26 -> 0 | G27: =Traslación_Pagos!V26 -> -76000 | H27: =Traslación_Pagos!W26 -> 0 | I27: =Traslación_Pagos!X26 -> 0 | J27: =Traslación_Pagos!Y26 -> -65000 | K27: =Traslación_Pagos!Z26 -> 0 | ... O27: =Traslación_Pagos!AD26 -> 0 | Q27: =SUM(D27:O27) -> -282000
C28: H. Pública por Retenciones Alq. Y Prof. | D28: =Traslación_Pagos!S27 -> -1300 | E28: =Traslación_Pagos!T27 -> 0 | F28: =Traslación_Pagos!U27 -> 0 | G28: =Traslación_Pagos!V27 -> -1350 | H28: =Traslación_Pagos!W27 -> 0 | I28: =Traslación_Pagos!X27 -> 0 | J28: =Traslación_Pagos!Y27 -> -1300 | K28: =Traslación_Pagos!Z27 -> 0 | ... O28: =Traslación_Pagos!AD27 -> 0 | Q28: =SUM(D28:O28) -> -5300
C29: H. Pública por Impuesto de Sociedades | D29: =Traslación_Pagos!S28 -> 0 | E29: =Traslación_Pagos!T28 -> 0 | F29: =Traslación_Pagos!U28 -> 0 | G29: =Traslación_Pagos!V28 -> -40000 | H29: =Traslación_Pagos!W28 -> 0 | I29: =Traslación_Pagos!X28 -> 0 | J29: =Traslación_Pagos!Y28 -> -30000 | K29: =Traslación_Pagos!Z28 -> 0 | ... O29: =Traslación_Pagos!AD28 -> -50000 | Q29: =SUM(D29:O29) -> -200000
C30: IAE y otros tributos locales | D30: =Traslación_Pagos!S29 -> -500 | E30: =Traslación_Pagos!T29 -> -500 | F30: =Traslación_Pagos!U29 -> -500 | G30: =Traslación_Pagos!V29 -> -500 | H30: =Traslación_Pagos!W29 -> -500 | I30: =Traslación_Pagos!X29 -> -500 | J30: =Traslación_Pagos!Y29 -> -500 | K30: =Traslación_Pagos!Z29 -> -500 | ... O30: =Traslación_Pagos!AD29 -> -500 | Q30: =SUM(D30:O30) -> -6000
C31: IMPUESTOS Y TRIBUTOS | D31: =SUM(D27:D30) -> -66800 | E31: =SUM(E27:E30) -> -500 | F31: =SUM(F27:F30) -> -500 | G31: =SUM(G27:G30) -> -117850 | H31: =SUM(H27:H30) -> -500 | I31: =SUM(I27:I30) -> -500 | J31: =SUM(J27:J30) -> -96800 | K31: =SUM(K27:K30) -> -500 | ... O31: =SUM(O27:O30) -> -50500 | Q31: =SUM(Q27:Q30) -> -493300
C32: Gastos Bancarios | D32: =Traslación_Pagos!S31 -> -300 | E32: =Traslación_Pagos!T31 -> -300 | F32: =Traslación_Pagos!U31 -> -300 | G32: =Traslación_Pagos!V31 -> -300 | H32: =Traslación_Pagos!W31 -> -300 | I32: =Traslación_Pagos!X31 -> -300 | J32: =Traslación_Pagos!Y31 -> -300 | K32: =Traslación_Pagos!Z31 -> -300 | ... O32: =Traslación_Pagos!AD31 -> -300 | Q32: =SUM(D32:O32) -> -3600
C33: Otros Gastos | D33: =Traslación_Pagos!S32 -> -1000 | E33: =Traslación_Pagos!T32 -> -1000 | F33: =Traslación_Pagos!U32 -> -1000 | G33: =Traslación_Pagos!V32 -> -1000 | H33: =Traslación_Pagos!W32 -> -1000 | I33: =Traslación_Pagos!X32 -> -1000 | J33: =Traslación_Pagos!Y32 -> -1000 | K33: =Traslación_Pagos!Z32 -> -1000 | ... O33: =Traslación_Pagos!AD32 -> -1000 | Q33: =SUM(D33:O33) -> -12000
C34: PAGOS EXPLOTACIÓN (OPEX) | D34: =+D15+D19+D26+D31+D32+D33 -> -176882.64 | E34: =+E15+E19+E26+E31+E32+E33 -> -104147.5 | F34: =+F15+F19+F26+F31+F32+F33 -> -65884.5 | G34: =+G15+G19+G26+G31+G32+G33 -> -193492.5 | H34: =+H15+H19+H26+H31+H32+H33 -> -72391.5 | I34: =+I15+I19+I26+I31+I32+I33 -> -85826.5 | J34: =+J15+J19+J26+J31+J32+J33 -> -177995.5 | K34: =+K15+K19+K26+K31+K32+K33 -> -68761.5 | ... O34: =+O15+O19+O26+O31+O32+O33 -> -135826.5 | Q34: =+Q15+Q19+Q26+Q31+Q32+Q33 -> -1461552.1
B35: FLUJO CAJA EXPLOTACIÓN | D35: =+D9+D34 -> -37732.643 | E35: =+E9+E34 -> 120307.5 | F35: =+F9+F34 -> 85365.5 | G35: =+G9+G34 -> 61817.5 | H35: =+H9+H34 -> 87933.5 | I35: =+I9+I34 -> 161013.5 | J35: =+J9+J34 -> -31585.5 | K35: =+K9+K34 -> 155088.5 | ... O35: =+O9+O34 -> 104963.5 | Q35: =+Q9+Q34 -> 893712.86
C36: (-) Compra de Activos Fijos | E36: -50000 | G36: -15000 | I36: -10000 | L36: -25000 | Q36: =SUM(D36:O36) -> -100000
C37: (+) Enajenación de Activos Fijos | Q37: =SUM(D37:O37) -> 0
C38: FLUJO CAJA ACTIVOS FIJOS (CAPEX) | D38: =SUM(D36:D37) -> 0 | E38: =SUM(E36:E37) -> -50000 | F38: =SUM(F36:F37) -> 0 | G38: =SUM(G36:G37) -> -15000 | H38: =SUM(H36:H37) -> 0 | I38: =SUM(I36:I37) -> -10000 | J38: =SUM(J36:J37) -> 0 | K38: =SUM(K36:K37) -> 0 | ... O38: =SUM(O36:O37) -> 0 | Q38: =SUM(Q36:Q37) -> -100000
C39: (+) Cobros por disposición de deuda | Q39: =SUM(D39:O39) -> 0
C40: (-) Pagos por amortización de deuda | F40: =[1]Cuadro_vencimientos_y_devengos!D13 -> -125000 | I40: =[1]Cuadro_vencimientos_y_devengos!G13 -> -125000 | L40: =[1]Cuadro_vencimientos_y_devengos!J13 -> -125000 | O40: =[1]Cuadro_vencimientos_y_devengos!M13 -> -125000 | Q40: =SUM(D40:O40) -> -500000
C41: (+) Cobros por disposición de pólizas | Q41: =SUM(D41:O41) -> 0
...
