Workbook

Sheet SOLUCIÓN WACC
A1: ESTIMACIÓN DEL COSTE DEL CAPITAL MEDIO PONDERADO
A3: COSTE DE LOS FONDOS PROPIOS BODEGA | D3: COSTE DE LA DEUDA FINANCIERA | H3: COSTE DEL CAPITAL MEDIO PONDERADO
A5: Tipo sin riesgo | B5: 0.035 | D5: kd | F5: 0.05 | H5: DF/(DF+E) | J5: =+BODEGAS!B23/(BODEGAS!B23+BODEGAS!B16) -> 0.0085465048
A6: Prima de mercado | B6: 0.066 | D6: kd desp. impuestos | F6: =F5*(1-F9) -> 0.0375 | H6: DF/E | J6: =J5/(1-J5) -> 0.0086201772
A8: Beta desapalancada | B8: =+'Beta Bodega'!F19 -> 0.44213298 | H8: WACC | J8: =B13*(1-J5)+F6*J5 -> 0.083968864
A9: Beta reapalancada | B9: =B8*(1+J6*(1-F9)) -> 0.44499143 | D9: Tipo impositivo | F9: =-BODEGAS!B43/BODEGAS!B42 -> 0.25
A11: Prima de liquidez | B11: 0.02
A13: ke | B13: =B5+B6*B9+B11 -> 0.084369434
A15: COSTE DE LOS FONDOS PROPIOS HOTEL | D15: COSTE DE LA DEUDA FINANCIERA | H15: COSTE DEL CAPITAL MEDIO PONDERADO
A17: Tipo sin riesgo | B17: 0.074 | D17: kd | F17: 0.05 | H17: DF/(DF+E) | J17: =+(HOTEL!B47+HOTEL!B46+HOTEL!B37)/(HOTEL!B47+HOTEL!B46+HOTEL!B37+HOTEL!B23) -> 0.11666072
A18: Prima de mercado | B18: 0.117 | D18: kd desp. impuestos | F18: =F17*(1-F21) -> 0.038002484 | H18: DF/E | J18: =J17/(1-J17) -> 0.13206785
A20: Beta desapalancada | B20: =+'Beta Hotel'!F54 -> 0.60360731 | H20: WACC | J20: =B25*(1-J17)+F18*J17 -> 0.15611244
A21: Beta reapalancada | B21: =B20*(1+J18*(1-F21)) -> 0.66419628 | D21: Tipo impositivo | F21: =-HOTEL!B84/HOTEL!B83 -> 0.23995033
A23: Prima de liquidez | B23: 0.02
A25: ke | B25: =B17+B18*B21+B23 -> 0.17171096
A27: COSTE DE LOS FONDOS PROPIOS PROMOTORA | D27: COSTE DE LA DEUDA FINANCIERA | H27: COSTE DEL CAPITAL MEDIO PONDERADO
A29: Tipo sin riesgo | B29: 0.03 | D29: kd | F29: =-'Promotora inmobiliaria y alquil'!B60/('Promotora inmobiliaria y alquil'!B39+'Promotora inmobiliaria y alquil'!B33) -> 0.027065758 | H29: DF/(DF+E) | J29: =+('Promotora inmobiliaria y alquil'!B39+'Promotora inmobiliaria y alquil'!B33)/('Promotora inmobiliaria y alquil'!B39+'Promotora inmobiliaria y alquil'!B33+'Promotora inmobiliaria y alquil'!B23) -> 0.04194452
A30: Prima de mercado | B30: 0.06 | D30: kd desp. impuestos | F30: =F29*(1-F33) -> 0.020299319 | H30: DF/E | J30: =J29/(1-J29) -> 0.043780888
A32: Beta desapalancada | B32: =+'Beta Promotora'!J8 -> 0.20494175 | H32: WACC | J32: =B37*(1-J29)+F30*J29 -> 0.060921782
A33: Beta reapalancada | B33: =B32*(1+J30*(1-F33)) -> 0.21167115 | D33: Tipo impositivo | F33: =-'Promotora inmobiliaria y alquil'!B67/'Promotora inmobiliaria y alquil'!B66 -> 0.25
A35: Prima de liquidez | B35: 0.02
A37: ke | B37: =B29+B30*B33+B35 -> 0.062700269

Sheet Datos

Sheet BODEGAS
A1: ACTIVO | B1: 2023
A2: A) ACTIVO NO CORRIENTE | B2: 2084850.2
A3: I Inmovilizado intangible | B3: 0
A4: II Inmovilizado material | B4: 2082025.7
A5: III Inv. en emp. del grupo y asoc. a largo plazo | B5: 2824.49
A6: B) ACTIVO CORRIENTE | B6: 4335076.7
A7: I Existencias | B7: 498990.23
A8: II Deudores comerc. y otras cuentas a cobrar | B8: 807826.55
A9: III Inversiones financieras a corto plazo | B9: 0
A10: IV Periodificaciones a corto plazo
A11: V Efectivo y otros activos líquidos equiv. | B11: 3028260
A12: TOTAL ACTIVO | B12: 6419926.9
A14: PASIVO | B14: 2023
A15: A) PATRIMONIO NETO | B15: 4944359
A16: A-1) Fondos propios | B16: 4852364.3
A17: I Capital | B17: 108182.18
A18: II Prima de emisión | B18: 238061
A19: III Reservas | B19: 4206862.7
A20: IV Resultado del ejercicio | B20: 299258.43
A21: A-2) Subv., donaciones y legados recibidos | B21: 91994.69
A22: B) PASIVO NO CORRIENTE | B22: 41828.24
A23: I Deudas a largo plazo | B23: 41828.24
... A37: A1) RESULTADO DE EXPLOTACIÓN | B37: 399011.24
A38: 8. Ingresos financieros
A39: 9. Gastos financieros | B39: -0.010000478
A40: 10. Variación de valor razonable en instr. fin.
A41: 11. Diferencias de cambio
A42: A2) RESULTADO ANTES DE IMPUESTOS | B42: 399011.23
A43: 12. Impuestos sobre beneficios | B43: -99752.808
A44: A3) RESULTADO DEL EJERCICIO | B44: 299258.43

Sheet Beta Bodega
A1: Date updated: | B1: 45296 | H1: YouTube Video explaining estimation choices and process.
A2: Created by: | B2: Aswath Damodaran, adamodar@stern.nyu.edu
A3: What is this data? | B3: Beta, Unlevered beta and other risk measures | F3: Western Europe
A4: Home Page: | B4: http://www.damodaran.com
A5: Data website: | B5: https://pages.stern.nyu.edu/~adamodar/New_Home_Page/data.html
A6: Companies in each industry: | B6: https://pages.stern.nyu.edu/~adamodar/pc/datasets/indname.xls
A7: Variable definitions: | B7: https://pages.stern.nyu.edu/~adamodar/New_Home_Page/datafile/variable.htm
A8: Do you want to use marginal or effective tax rates in unlevering betas? | F8: Marginal
A9: If marginal tax rate, enter the marginal tax rate to use | F9: 0.2471 | L9: Beta over time
A10: Industry Name | B10: Number of firms | C10: Beta | D10: D/E Ratio | E10: Effective Tax rate | F10: Unlevered beta | G10: Cash/Firm value | H10: Unlevered beta corrected for cash | I10: HiLo Risk | J10: Standard deviation of equity | K10: Standard deviation in operating income (last 10 years) | L10: 2020 | M10: 2021 | N10: 2022 | O10: 2022 | P10: Average: 2020-24
A11: Advertising | B11: 89 | C11: 1.0096481 | D11: 0.4635852 | E11: 0.13698927 | F11: =IF($F$8="Effective",C11/(1+(1-E11)*D11),C11/(1+(1-$F$9)*D11)) -> 0.7484234 | G11: 0.11363434 | H11: =F11/(1-G11) -> 0.84437319 | I11: 0.37614553 | J11: 0.35163785 | K11: 0.45861753 | L11: 0.68 | M11: 0.73 | N11: 0.83 | O11: 0.90361403 | P11: =AVERAGE(H11,L11:O11) -> 0.79759744
A12: Aerospace/Defense | B12: 61 | C12: 0.90446607 | D12: 0.15337917 | E12: 0.12742614 | F12: =IF($F$8="Effective",C12/(1+(1-E12)*D12),C12/(1+(1-$F$9)*D12)) -> 0.81083187 | G12: 0.084754502 | H12: =F12/(1-G12) -> 0.88591735 | I12: 0.33615767 | J12: 0.35526089 | K12: 0.20735147 | L12: 1.2 | M12: 1.07 | N12: 1.14 | O12: 0.90335741 | P12: =AVERAGE(H12,L12:O12) -> 1.039855
A13: Air Transport | B13: 34 | C13: 1.3413063 | D13: 0.90658524 | E13: 0.1561402 | F13: =IF($F$8="Effective",C13/(1+(1-E13)*D13),C13/(1+(1-$F$9)*D13)) -> 0.79717804 | G13: 0.11509809 | H13: =F13/(1-G13) -> 0.90086599 | I13: 0.33432964 | J13: 0.30734502 | K13: 1.9268547 | L13: 0.67 | M13: 0.96 | N13: 1 | O13: 0.78495586 | P13: =AVERAGE(H13,L13:O13) -> 0.86316437
A14: Apparel | B14: 110 | C14: 1.0044827 | D14: 0.14175139 | E14: 0.14185236 | F14: =IF($F$8="Effective",C14/(1+(1-E14)*D14),C14/(1+(1-$F$9)*D14)) -> 0.90761753 | G14: 0.038663239 | H14: =F14/(1-G14) -> 0.94412028 | I14: 0.34046577 | J14: 0.3143481 | K14: 0.39156127 | L14: 0.92 | M14: 1.04 | N14: 1.07 | O14: 1.0336801 | P14: =AVERAGE(H14,L14:O14) -> 1.0015601
A15: Auto & Truck | B15: 31 | C15: 1.3951896 | D15: 1.0538962 | E15: 0.096291261 | F15: =IF($F$8="Effective",C15/(1+(1-E15)*D15),C15/(1+(1-$F$9)*D15)) -> 0.77792383 | G15: 0.17957991 | H15: =F15/(1-G15) -> 0.94820183 | I15: 0.37918398 | J15: 0.35583235 | K15: 0.40666862 | L15: 0.8 | M15: 0.69 | N15: 0.74 | O15: 0.860421 | P15: =AVERAGE(H15,L15:O15) -> 0.80772457
A16: Auto Parts | B16: 59 | C16: 1.4037711 | D16: 0.61975546 | E16: 0.17963719 | F16: =IF($F$8="Effective",C16/(1+(1-E16)*D16),C16/(1+(1-$F$9)*D16)) -> 0.95715107 | G16: 0.11256499 | H16: =F16/(1-G16) -> 1.0785591 | I16: 0.34650165 | J16: 0.30688712 | K16: 0.29873412 | L16: 1.3 | M16: 1.17 | N16: 1.29 | O16: 1.1829794 | P16: =AVERAGE(H16,L16:O16) -> 1.2043077
A17: Bank (Money Center) | B17: 112 | C17: 1.2153935 | D17: 5.6156759 | E17: 0.23544116 | F17: =IF($F$8="Effective",C17/(1+(1-E17)*D17),C17/(1+(1-$F$9)*D17)) -> 0.23247584 | G17: 0.36256628 | H17: =F17/(1-G17) -> 0.3647059 | I17: 0.24497998 | J17: 0.25358377 | K17: 1.5390714 | L17: 0.32 | M17: 0.28 | N17: 0.42 | O17: 0.36861154 | P17: =AVERAGE(H17,L17:O17) -> 0.35066349
A18: Banks (Regional) | B18: 72 | C18: 0.46828868 | D18: 2.8755637 | E18: 0.18768236 | F18: =IF($F$8="Effective",C18/(1+(1-E18)*D18),C18/(1+(1-$F$9)*D18)) -> 0.14795795 | G18: 0.30186276 | H18: =F18/(1-G18) -> 0.21193248 | I18: 0.11424833 | J18: 0.13283543 | K18: NA | L18: 0.2 | M18: 0.23 | N18: 0.29 | O18: 0.2430577 | P18: =AVERAGE(H18,L18:O18) -> 0.23499803
A19: Beverage (Alcoholic) | B19: 55 | C19: 0.59195866 | D19: 0.45008658 | E19: 0.1803345 | F19: =IF($F$8="Effective",C19/(1+(1-E19)*D19),C19/(1+(1-$F$9)*D19)) -> 0.44213298 | G19: 0.023482601 | H19: =F19/(1-G19) -> 0.45276508 | I19: 0.25121077 | J19: 0.26354589 | K19: 0.10848055 | L19: 0.45 | M19: 0.47 | N19: 0.52 | O19: 0.50666048 | P19: =AVERAGE(H19,L19:O19) -> 0.47988511
A20: Beverage (Soft) | B20: 15 | C20: 0.70767231 | D20: 0.36244154 | E20: 0.1969973 | F20: =IF($F$8="Effective",C20/(1+(1-E20)*D20),C20/(1+(1-$F$9)*D20)) -> 0.55596055 | G20: 0.049639704 | H20: =F20/(1-G20) -> 0.58499977 | I20: 0.21789967 | J20: 0.23722877 | K20: 0.25353294 | L20: 0.52 | M20: 0.65 | N20: 0.68 | O20: 0.71486423 | P20: =AVERAGE(H20,L20:O20) -> 0.6299728
A21: Broadcasting | B21: 22 | C21: 0.92826313 | D21: 0.44589104 | E21: 0.18398285 | F21: =IF($F$8="Effective",C21/(1+(1-E21)*D21),C21/(1+(1-$F$9)*D21)) -> 0.69495788 | G21: 0.10418903 | H21: =F21/(1-G21) -> 0.7757863 | I21: 0.28256885 | J21: 0.22521575 | K21: 0.14474658 | L21: 1.03 | M21: 0.75 | N21: 0.82 | O21: 0.80052851 | P21: =AVERAGE(H21,L21:O21) -> 0.83526296
A22: Brokerage & Investment Banking | B22: 74 | C22: 0.87073159 | D22: 0.68763896 | E22: 0.15189444 | F22: =IF($F$8="Effective",C22/(1+(1-E22)*D22),C22/(1+(1-$F$9)*D22)) -> 0.57370902 | G22: 0.24127415 | H22: =F22/(1-G22) -> 0.75614798 | I22: 0.31776252 | J22: 0.29262446 | K22: 0.82026081 | L22: 0.95 | M22: 0.73 | N22: 0.9 | O22: 0.69593196 | P22: =AVERAGE(H22,L22:O22) -> 0.80641599
A23: Building Materials | B23: 89 | C23: 1.0705706 | D23: 0.20528766 | E23: 0.14650837 | F23: =IF($F$8="Effective",C23/(1+(1-E23)*D23),C23/(1+(1-$F$9)*D23)) -> 0.92725331 | G23: 0.03848014 | H23: =F23/(1-G23) -> 0.96436209 | I23: 0.32895997 | J23: 0.29813525 | K23: 0.20345943 | L23: 0.87 | M23: 0.83 | N23: 0.94 | O23: 1.0371856 | P23: =AVERAGE(H23,L23:O23) -> 0.92830955
A24: Business & Consumer Services | B24: 194 | C24: 1.0050332 | D24: 0.27035027 | E24: 0.1637828 | F24: =IF($F$8="Effective",C24/(1+(1-E24)*D24),C24/(1+(1-$F$9)*D24)) -> 0.83505955 | G24: 0.046347618 | H24: =F24/(1-G24) -> 0.87564354 | I24: 0.31991796 | J24: 0.30739972 | K24: 0.18358584 | L24: 0.87 | M24: 0.85 | N24: 0.97 | O24: 0.91207822 | P24: =AVERAGE(H24,L24:O24) -> 0.89554435
A25: Cable TV | B25: 3 | C25: 0.77744457 | D25: 1.9682832 | E25: 0.16061353 | F25: =IF($F$8="Effective",C25/(1+(1-E25)*D25),C25/(1+(1-$F$9)*D25)) -> 0.31324315 | G25: 0.1154329 | H25: =F25/(1-G25) -> 0.35412028 | I25: 0.45820935 | J25: 0.28344665 | K25: 0.17407735 | L25: 0.51 | M25: 0.54 | N25: 0.41 | O25: 0.33377103 | P25: =AVERAGE(H25,L25:O25) -> 0.42957826
A26: Chemical (Basic) | B26: 61 | C26: 0.83507144 | D26: 0.40568245 | E26: 0.085926606 | F26: =IF($F$8="Effective",C26/(1+(1-E26)*D26),C26/(1+(1-$F$9)*D26)) -> 0.63968664 | G26: 0.074139746 | H26: =F26/(1-G26) -> 0.69091057 | I26: 0.38374073 | J26: 0.33332641 | K26: 0.45412489 | L26: 0.7 | M26: 0.75 | N26: 0.87 | O26: 0.90082767 | P26: =AVERAGE(H26,L26:O26) -> 0.78234765
A27: Chemical (Diversified) | B27: 7 | C27: 1.1086936 | D27: 0.51997021 | E27: 0.081336101 | F27: =IF($F$8="Effective",C27/(1+(1-E27)*D27),C27/(1+(1-$F$9)*D27)) -> 0.79676976 | G27: 0.058824816 | H27: =F27/(1-G27) -> 0.84656903 | I27: 0.27607451 | J27: 0.23183481 | K27: 0.20706193 | L27: 1.44 | M27: 1.08 | N27: 1.03 | O27: 0.78359123 | P27: =AVERAGE(H27,L27:O27) -> 1.0360321
A28: Chemical (Specialty) | B28: 102 | C28: 1.0757968 | D28: 0.182711 | E28: 0.10687577 | F28: =IF($F$8="Effective",C28/(1+(1-E28)*D28),C28/(1+(1-$F$9)*D28)) -> 0.94570295 | G28: 0.035252064 | H28: =F28/(1-G28) -> 0.98025911 | I28: 0.4022253 | J28: 0.34065717 | K28: 0.28389589 | L28: 1.07 | M28: 0.89 | N28: 0.91 | O28: 1.025278 | P28: =AVERAGE(H28,L28:O28) -> 0.97510743
A29: Coal & Related Energy | B29: 16 | C29: 0.87097446 | D29: 0.14811566 | E29: 0.068772811 | F29: =IF($F$8="Effective",C29/(1+(1-E29)*D29),C29/(1+(1-$F$9)*D29)) -> 0.78359127 | G29: 0.27381583 | H29: =F29/(1-G29) -> 1.0790531 | I29: 0.54964932 | J29: 0.50498611 | K29: 0.68724136 | L29: 1.1 | M29: 1.19 | N29: 1.95 | O29: 1.4007451 | P29: =AVERAGE(H29,L29:O29) -> 1.3439596
A30: Computer Services | B30: 226 | C30: 0.95331132 | D30: 0.10294257 | E30: 0.16295368 | F30: =IF($F$8="Effective",C30/(1+(1-E30)*D30),C30/(1+(1-$F$9)*D30)) -> 0.8847392 | G30: 0.057684759 | H30: =F30/(1-G30) -> 0.93889939 | I30: 0.33568765 | J30: 0.29529805 | K30: 0.29970541 | L30: 0.99 | M30: 0.91 | N30: 0.97 | O30: 0.99749626 | P30: =AVERAGE(H30,L30:O30) -> 0.96127913
... A33: Diversified | B33: 70 | C33: 1.1696176 | D33: 0.40550149 | E33: 0.13961929 | F33: =IF($F$8="Effective",C33/(1+(1-E33)*D33),C33/(1+(1-$F$9)*D33)) -> 0.89605126 | G33: 0.082811438 | H33: =F33/(1-G33) -> 0.97695425 | I33: 0.31391543 | J33: 0.26480141 | K33: 0.35276539 | L33: 1 | M33: 0.82 | N33: 0.97 | O33: 1.0170289 | P33: =AVERAGE(H33,L33:O33) -> 0.95679663
A34: Drugs (Biotechnology) | B34: 233 | C34: 1.1603519 | D34: 0.16040495 | E34: 0.017970566 | F34: =IF($F$8="Effective",C34/(1+(1-E34)*D34),C34/(1+(1-$F$9)*D34)) -> 1.0353177 | G34: 0.082542301 | H34: =F34/(1-G34) -> 1.1284637 | I34: 0.53555196 | J34: 0.51189288 | K34: NA | L34: 1.51 | M34: 1.03 | N34: 1.09 | O34: 1.2401789 | P34: =AVERAGE(H34,L34:O34) -> 1.1997285
A35: Drugs (Pharmaceutical) | B35: 131 | C35: 0.97730649 | D35: 0.15112858 | E35: 0.078774502 | F35: =IF($F$8="Effective",C35/(1+(1-E35)*D35),C35/(1+(1-$F$9)*D35)) -> 0.87746445 | G35: 0.026680971 | H35: =F35/(1-G35) -> 0.90151782 | I35: 0.45679025 | J35: 0.41840255 | K35: 0.1580115 | L35: 1.02 | M35: 0.83 | N35: 0.88 | O35: 0.92855178 | P35: =AVERAGE(H35,L35:O35) -> 0.91201392
A36: Education | B36: 21 | C36: 0.62166981 | D36: 0.29005772 | E36: 0.068220149 | F36: =IF($F$8="Effective",C36/(1+(1-E36)*D36),C36/(1+(1-$F$9)*D36)) -> 0.51024108 | G36: 0.04896325 | H36: =F36/(1-G36) -> 0.53651037 | I36: 0.33886517 | J36: 0.2782254 | K36: 0.22413231 | L36: 0.58 | M36: 0.61 | N36: 0.6 | O36: 0.63742146 | P36: =AVERAGE(H36,L36:O36) -> 0.59278637
A37: Electrical Equipment | B37: 157 | C37: 1.2935071 | D37: 0.15786596 | E37: 0.097337317 | F37: =IF($F$8="Effective",C37/(1+(1-E37)*D37),C37/(1+(1-$F$9)*D37)) -> 1.1560966 | G37: 0.051760011 | H37: =F37/(1-G37) -> 1.2192026 | I37: 0.45029032 | J37: 0.38250448 | K37: 0.10929321 | L37: 1.19 | M37: 1.16 | N37: 1.24 | O37: 1.2592649 | P37: =AVERAGE(H37,L37:O37) -> 1.2136935
A38: Electronics (Consumer & Office) | B38: 21 | C38: 1.0177045 | D38: 0.12963054 | E38: 0.10197209 | F38: =IF($F$8="Effective",C38/(1+(1-E38)*D38),C38/(1+(1-$F$9)*D38)) -> 0.92720989 | G38: 0.054685617 | H38: =F38/(1-G38) -> 0.98084818 | I38: 0.4558574 | J38: 0.39963971 | K38: 0.29394918 | L38: 1.38 | M38: 1.23 | N38: 1.27 | O38: 1.0800644 | P38: =AVERAGE(H38,L38:O38) -> 1.1881825
A39: Electronics (General) | B39: 151 | C39: 1.213133 | D39: 0.13376915 | E39: 0.12354536 | F39: =IF($F$8="Effective",C39/(1+(1-E39)*D39),C39/(1+(1-$F$9)*D39)) -> 1.102132 | G39: 0.04058463 | H39: =F39/(1-G39) -> 1.1487538 | I39: 0.39688715 | J39: 0.36147198 | K39: 0.19434389 | L39: 1.2 | M39: 0.95 | N39: 1.01 | O39: 1.139418 | P39: =AVERAGE(H39,L39:O39) -> 1.0896344
A40: Engineering/Construction | B40: 162 | C40: 0.96745491 | D40: 0.63561576 | E40: 0.15524469 | F40: =IF($F$8="Effective",C40/(1+(1-E40)*D40),C40/(1+(1-$F$9)*D40)) -> 0.65432455 | G40: 0.14785 | H40: =F40/(1-G40) -> 0.76785138 | I40: 0.33074896 | J40: 0.28933029 | K40: 0.1711022 | L40: 0.81 | M40: 0.74 | N40: 0.84 | O40: 0.76935136 | P40: =AVERAGE(H40,L40:O40) -> 0.78544055
A41: Entertainment | B41: 200 | C41: 0.89160583 | D41: 0.18789421 | E41: 0.06685698 | F41: =IF($F$8="Effective",C41/(1+(1-E41)*D41),C41/(1+(1-$F$9)*D41)) -> 0.78110621 | G41: 0.078502942 | H41: =F41/(1-G41) -> 0.84764916 | I41: 0.42428556 | J41: 0.39460049 | K41: 0.43947332 | L41: 1.04 | M41: 0.86 | N41: 0.93 | O41: 0.89632459 | P41: =AVERAGE(H41,L41:O41) -> 0.91479475
A42: Environmental & Waste Services | B42: 52 | C42: 1.1149114 | D42: 0.509166 | E42: 0.14445098 | F42: =IF($F$8="Effective",C42/(1+(1-E42)*D42),C42/(1+(1-$F$9)*D42)) -> 0.80594968 | G42: 0.094166068 | H42: =F42/(1-G42) -> 0.88973227 | I42: 0.36968611 | J42: 0.35073311 | K42: 0.49398722 | L42: 0.8 | M42: 0.82 | N42: 0.94 | O42: 1.0393065 | P42: =AVERAGE(H42,L42:O42) -> 0.89780775
...

Sheet HOTEL
A2: ACTIVO | B2: 2023
A3: A) ACTIVO NO CORRIENTE | B3: 70689770
A4: I Inmovilizado intangible | B4: 1049
A5: II Inmovilizado material | B5: 65594242
A6: III Inversiones inmobiliarias | B6: 0
A7: IV Inv. en emp. del grupo y asoc. a largo plazo | B7: 4572655
A8: V Inversiones financieras a largo plazo | B8: 0
A9: VI Activos por impuesto diferido | B9: 521824
A10: VI Deudas no comerciales corrientes
A11: B) ACTIVO CORRIENTE | B11: 118707739
A12: I Activos no corrientes mantenidos para la venta
A13: II Existencias | B13: 551607
A14: III Deudores comerc. y otras cuentas a cobrar | B14: 5391205
A15: IV Inv. en emp. del grupo y asoc. a corto plazo | B15: 53938811
A16: V Inversiones financieras a corto plazo | B16: 38297941
A17: VI Periodificaciones a corto plazo | B17: 119968
A18: VII Efectivo y otros activos líquidos equiv. | B18: 20408207
A19: TOTAL ACTIVO | B19: 189397509
A21: PASIVO | B21: 2023
A22: A) PATRIMONIO NETO | B22: 156685783
A23: A-1) Fondos propios | B23: 156643916
A24: I Capital | B24: 32040211
A25: II Prima de emisión | B25: 107623403
A26: III Reservas | B26: 7982191
A27: IV Acciones y particip en patrimonio propias
A28: V Resultado de ejercicions anteriores
A29: VI Otras aportaciones de socios
A30: VII Resultado del ejercicio | B30: 8998111
A31: VIII Dividendo a cuenta
A32: IX Otros instrumentos de patrimonio
A33: A-2) Ajustes por cambios de valor
A34: A-3) Subv., donaciones y legados recibidos | B34: 41867
A35: B) PASIVO NO CORRIENTE | B35: 4400833
A36: I Provisiones a largo plazo | B36: 17512
A37: II Deudas a largo plazo (entidades de crédito) | B37: 49886
A38: III Deudas con emp del gpo y asoc a l/plazo
A39: IV Pasivos por impuesto diferido | B39: 4333435
A40: V Periodificaciones a l/plazo
A41: VI Acreedores comerciales no corrientes
A42: VII Deuda con caracteristicas especiales a l/plazo
...

Sheet Beta Hotel
A1: Date updated: | B1: 45296 | H1: YouTube Video explaining estimation choices and process.
A2: Created by: | B2: Aswath Damodaran, adamodar@stern.nyu.edu
A3: What is this data? | B3: Beta, Unlevered beta and other risk measures | F3: Emerging Markets
A4: Home Page: | B4: http://www.damodaran.com
A5: Data website: | B5: https://pages.stern.nyu.edu/~adamodar/New_Home_Page/data.html
A6: Companies in each industry: | B6: https://pages.stern.nyu.edu/~adamodar/pc/datasets/indname.xls
A7: Variable definitions: | B7: https://pages.stern.nyu.edu/~adamodar/New_Home_Page/datafile/variable.htm
A8: Do you want to use marginal or effective tax rates in unlevering betas? | F8: Marginal
A9: If marginal tax rate, enter the marginal tax rate to use | F9: 0.2471 | L9: Beta over time
A10: Industry Name | B10: Number of firms | C10: Beta | D10: D/E Ratio | E10: Effective Tax rate | F10: Unlevered beta | G10: Cash/Firm value | H10: Unlevered beta corrected for cash | I10: HiLo Risk | J10: Standard deviation of equity | K10: Standard deviation in operating income (last 10 years) | L10: 2020 | M10: 2021 | N10: 2022 | O10: 2022 | P10: Average: 2020-24
A11: Advertising | B11: 154 | C11: 1.6134432 | D11: 0.088967209 | E11: 0.11420443 | F11: =IF($F$8="Effective",C11/(1+(1-E11)*D11),C11/(1+(1-$F$9)*D11)) -> 1.5121539 | G11: 0.11076488 | H11: =F11/(1-G11) -> 1.7005108 | I11: 0.44121601 | J11: 0.4156104 | K11: 0.23835513 | L11: 0.68 | M11: 0.73 | N11: 0.83 | O11: 0.90361403 | P11: =AVERAGE(H11,L11:O11) -> 0.96882497
A12: Aerospace/Defense | B12: 131 | C12: 0.94498401 | D12: 0.1138223 | E12: 0.10112576 | F12: =IF($F$8="Effective",C12/(1+(1-E12)*D12),C12/(1+(1-$F$9)*D12)) -> 0.87039402 | G12: 0.11245143 | H12: =F12/(1-G12) -> 0.98067198 | I12: 0.29302548 | J12: 0.30648515 | K12: 0.26287654 | L12: 1.2 | M12: 1.07 | N12: 1.14 | O12: 0.90335741 | P12: =AVERAGE(H12,L12:O12) -> 1.0588059
A13: Air Transport | B13: 78 | C13: 1.3341047 | D13: 0.9253915 | E13: 0.114039 | F13: =IF($F$8="Effective",C13/(1+(1-E13)*D13),C13/(1+(1-$F$9)*D13)) -> 0.78628117 | G13: 0.08908857 | H13: =F13/(1-G13) -> 0.8631807 | I13: 0.28343041 | J13: 0.26887715 | K13: 3.6604292 | L13: 0.67 | M13: 0.96 | N13: 1 | O13: 0.78495586 | P13: =AVERAGE(H13,L13:O13) -> 0.85562731
A14: Apparel | B14: 936 | C14: 0.80431437 | D14: 0.23506388 | E14: 0.13186284 | F14: =IF($F$8="Effective",C14/(1+(1-E14)*D14),C14/(1+(1-$F$9)*D14)) -> 0.68337155 | G14: 0.097729186 | H14: =F14/(1-G14) -> 0.75739072 | I14: 0.31903431 | J14: 0.33877835 | K14: 0.25667788 | L14: 0.92 | M14: 1.04 | N14: 1.07 | O14: 1.0336801 | P14: =AVERAGE(H14,L14:O14) -> 0.96421415
A15: Auto & Truck | B15: 86 | C15: 1.2932821 | D15: 0.3952392 | E15: 0.11648822 | F15: =IF($F$8="Effective",C15/(1+(1-E15)*D15),C15/(1+(1-$F$9)*D15)) -> 0.9966911 | G15: 0.17220279 | H15: =F15/(1-G15) -> 1.2040281 | I15: 0.34995142 | J15: 0.31234169 | K15: 0.2237225 | L15: 0.8 | M15: 0.69 | N15: 0.74 | O15: 0.860421 | P15: =AVERAGE(H15,L15:O15) -> 0.85888982
A16: Auto Parts | B16: 545 | C16: 1.3227085 | D16: 0.19751921 | E16: 0.13681931 | F16: =IF($F$8="Effective",C16/(1+(1-E16)*D16),C16/(1+(1-$F$9)*D16)) -> 1.1514708 | G16: 0.10746511 | H16: =F16/(1-G16) -> 1.2901129 | I16: 0.31813539 | J16: 0.31981452 | K16: 0.081337036 | L16: 1.3 | M16: 1.17 | N16: 1.29 | O16: 1.1829794 | P16: =AVERAGE(H16,L16:O16) -> 1.2466185
A17: Bank (Money Center) | B17: 459 | C17: 0.78136098 | D17: 1.981872 | E17: 0.21200702 | F17: =IF($F$8="Effective",C17/(1+(1-E17)*D17),C17/(1+(1-$F$9)*D17)) -> 0.3135287 | G17: 0.2271776 | H17: =F17/(1-G17) -> 0.40569308 | I17: 0.20278449 | J17: 0.20238685 | K17: 0.43946009 | L17: 0.32 | M17: 0.28 | N17: 0.42 | O17: 0.36861154 | P17: =AVERAGE(H17,L17:O17) -> 0.35886092
A18: Banks (Regional) | B18: 100 | C18: 0.78357262 | D18: 5.83214 | E18: 0.15511094 | F18: =IF($F$8="Effective",C18/(1+(1-E18)*D18),C18/(1+(1-$F$9)*D18)) -> 0.1453478 | G18: 0.11597142 | H18: =F18/(1-G18) -> 0.16441527 | I18: 0.21811943 | J18: 0.21158234 | K18: 0.74848161 | L18: 0.2 | M18: 0.23 | N18: 0.29 | O18: 0.2430577 | P18: =AVERAGE(H18,L18:O18) -> 0.22549459
A19: Beverage (Alcoholic) | B19: 126 | C19: 0.79757292 | D19: 0.028925919 | E19: 0.16271512 | F19: =IF($F$8="Effective",C19/(1+(1-E19)*D19),C19/(1+(1-$F$9)*D19)) -> 0.78057334 | G19: 0.069233141 | H19: =F19/(1-G19) -> 0.83863465 | I19: 0.26631047 | J19: 0.25688609 | K19: 0.30467923 | L19: 0.45 | M19: 0.47 | N19: 0.52 | O19: 0.50666048 | P19: =AVERAGE(H19,L19:O19) -> 0.55705903
A20: Beverage (Soft) | B20: 40 | C20: 0.44007084 | D20: 0.052856655 | E20: 0.12840583 | F20: =IF($F$8="Effective",C20/(1+(1-E20)*D20),C20/(1+(1-$F$9)*D20)) -> 0.42322814 | G20: 0.053191295 | H20: =F20/(1-G20) -> 0.44700491 | I20: 0.26081482 | J20: 0.24354816 | K20: 0.45448635 | L20: 0.52 | M20: 0.65 | N20: 0.68 | O20: 0.71486423 | P20: =AVERAGE(H20,L20:O20) -> 0.60237383
A21: Broadcasting | B21: 63 | C21: 1.0414715 | D21: 0.2993846 | E21: 0.13039306 | F21: =IF($F$8="Effective",C21/(1+(1-E21)*D21),C21/(1+(1-$F$9)*D21)) -> 0.84989869 | G21: 0.15176568 | H21: =F21/(1-G21) -> 1.0019622 | I21: 0.35438078 | J21: 0.34435989 | K21: 0.22032867 | L21: 1.03 | M21: 0.75 | N21: 0.82 | O21: 0.80052851 | P21: =AVERAGE(H21,L21:O21) -> 0.88049813
A22: Brokerage & Investment Banking | B22: 431 | C22: 0.91505369 | D22: 2.2569761 | E22: 0.1197201 | F22: =IF($F$8="Effective",C22/(1+(1-E22)*D22),C22/(1+(1-$F$9)*D22)) -> 0.33899951 | G22: 0.11082449 | H22: =F22/(1-G22) -> 0.38125152 | I22: 0.34718647 | J22: 0.33678472 | K22: 0.73081885 | L22: 0.95 | M22: 0.73 | N22: 0.9 | O22: 0.69593196 | P22: =AVERAGE(H22,L22:O22) -> 0.7314367
... A94: Software (System & Application) | B94: 521 | C94: 1.4389366 | D94: 0.042678159 | E94: 0.084322828 | F94: =IF($F$8="Effective",C94/(1+(1-E94)*D94),C94/(1+(1-$F$9)*D94)) -> 1.3941396 | G94: 0.083052171 | H94: =F94/(1-G94) -> 1.5204132 | I94: 0.40998396 | J94: 0.3889297 | K94: 0.36190838 | L94: 1.11 | M94: 0.86 | N94: 0.98 | O94: 1.1213891 | P94: =AVERAGE(H94,L94:O94) -> 1.1183604
A95: Steel | B95: 536 | C95: 1.2239093 | D95: 0.46841392 | E95: 0.13638759 | F95: =IF($F$8="Effective",C95/(1+(1-E95)*D95),C95/(1+(1-$F$9)*D95)) -> 0.90481072 | G95: 0.106268 | H95: =F95/(1-G95) -> 1.012396 | I95: 0.31671769 | J95: 0.32085912 | K95: NA | L95: 1 | M95: 1.04 | N95: 1.12 | O95: 1.0797169 | P95: =AVERAGE(H95,L95:O95) -> 1.0504226
A96: Telecom (Wireless) | B96: 63 | C96: 0.89443549 | D96: 0.39747973 | E96: 0.19046385 | F96: =IF($F$8="Effective",C96/(1+(1-E96)*D96),C96/(1+(1-$F$9)*D96)) -> 0.68841785 | G96: 0.077990865 | H96: =F96/(1-G96) -> 0.74664971 | I96: 0.21920429 | J96: 0.25038701 | K96: 0.13876232 | L96: 0.47 | M96: 0.43 | N96: 0.48 | O96: 0.30315371 | P96: =AVERAGE(H96,L96:O96) -> 0.48596068
A97: Telecom. Equipment | B97: 299 | C97: 1.2900211 | D97: 0.13157485 | E97: 0.078717097 | F97: =IF($F$8="Effective",C97/(1+(1-E97)*D97),C97/(1+(1-$F$9)*D97)) -> 1.1737466 | G97: 0.12064631 | H97: =F97/(1-G97) -> 1.3347833 | I97: 0.34900105 | J97: 0.34660452 | K97: 0.25636605 | L97: 1.3 | M97: 0.98 | N97: 1.06 | O97: 0.96115026 | P97: =AVERAGE(H97,L97:O97) -> 1.1271867
A98: Telecom. Services | B98: 140 | C98: 0.81686696 | D98: 0.43554484 | E98: 0.14132668 | F98: =IF($F$8="Effective",C98/(1+(1-E98)*D98),C98/(1+(1-$F$9)*D98)) -> 0.61514693 | G98: 0.06706179 | H98: =F98/(1-G98) -> 0.65936514 | I98: 0.28296082 | J98: 0.26326849 | K98: 0.051298225 | L98: 0.42 | M98: 0.37 | N98: 0.39 | O98: 0.44422768 | P98: =AVERAGE(H98,L98:O98) -> 0.45671856
A99: Tobacco | B99: 31 | C99: 0.4416217 | D99: 0.013245133 | E99: 0.22089552 | F99: =IF($F$8="Effective",C99/(1+(1-E99)*D99),C99/(1+(1-$F$9)*D99)) -> 0.43726122 | G99: 0.024814044 | H99: =F99/(1-G99) -> 0.44838753 | I99: 0.26690744 | J99: 0.2506297 | K99: 0.27366084 | L99: 0.4 | M99: 0.33 | N99: 0.37 | O99: 0.29390937 | P99: =AVERAGE(H99,L99:O99) -> 0.36845938
A100: Transportation | B100: 296 | C100: 0.94468661 | D100: 0.6181706 | E100: 0.15192109 | F100: =IF($F$8="Effective",C100/(1+(1-E100)*D100),C100/(1+(1-$F$9)*D100)) -> 0.64465218 | G100: 0.11189032 | H100: =F100/(1-G100) -> 0.72587 | I100: 0.29405885 | J100: 0.29033156 | K100: 0.17770528 | L100: 0.62 | M100: 0.61 | N100: 0.73 | O100: 0.85061104 | P100: =AVERAGE(H100,L100:O100) -> 0.70729621
A101: Transportation (Railroads) | B101: 15 | C101: 0.92631341 | D101: 0.30936832 | E101: 0.24221198 | F101: =IF($F$8="Effective",C101/(1+(1-E101)*D101),C101/(1+(1-$F$9)*D101)) -> 0.75131464 | G101: 0.1204434 | H101: =F101/(1-G101) -> 0.85419704 | I101: 0.2309671 | J101: 0.24330392 | K101: 0.24519053 | L101: 0.5 | M101: 0.54 | N101: 1.01 | O101: 0.81048456 | P101: =AVERAGE(H101,L101:O101) -> 0.74293632
A102: Trucking | B102: 55 | C102: 1.0738501 | D102: 1.2659805 | E102: 0.13966132 | F102: =IF($F$8="Effective",C102/(1+(1-E102)*D102),C102/(1+(1-$F$9)*D102)) -> 0.54980229 | G102: 0.049201237 | H102: =F102/(1-G102) -> 0.57825305 | I102: 0.38634784 | J102: 0.38434836 | K102: 0.50006104 | L102: 0.43 | M102: 0.39 | N102: 0.55 | O102: 0.44200071 | P102: =AVERAGE(H102,L102:O102) -> 0.47805075
A103: Utility (General) | B103: 14 | C103: 0.63598485 | D103: 0.33494508 | E103: 0.14484215 | F103: =IF($F$8="Effective",C103/(1+(1-E103)*D103),C103/(1+(1-$F$9)*D103)) -> 0.50790204 | G103: 0.036071373 | H103: =F103/(1-G103) -> 0.52690835 | I103: 0.34879019 | J103: 0.22898566 | K103: 0.27214422 | L103: 0.41 | M103: 0.43 | N103: 0.49 | O103: 0.46906876 | P103: =AVERAGE(H103,L103:O103) -> 0.46519542
A104: Utility (Water) | B104: 71 | C104: 0.65682069 | D104: 1.04072 | E104: 0.16148338 | F104: =IF($F$8="Effective",C104/(1+(1-E104)*D104),C104/(1+(1-$F$9)*D104)) -> 0.36826425 | G104: 0.079570467 | H104: =F104/(1-G104) -> 0.40010043 | I104: 0.23950278 | J104: 0.31499737 | K104: 0.22596151 | L104: 0.29 | M104: 0.26 | N104: 0.28 | O104: 0.3466602 | P104: =AVERAGE(H104,L104:O104) -> 0.31535213
A105: Total Market | B105: 25637 | C105: 1.0206471 | D105: 0.64523938 | E105: 0.13020908 | F105: =IF($F$8="Effective",C105/(1+(1-E105)*D105),C105/(1+(1-$F$9)*D105)) -> 0.68693404 | G105: 0.12879928 | H105: =F105/(1-G105) -> 0.78849112 | I105: 0.3174603 | J105: 0.31499737 | K105: 0.28104007 | L105: 0.7 | M105: 0.67 | N105: 0.79 | O105: 0.77718841 | P105: =AVERAGE(H105,L105:O105) -> 0.74513591
A106: Total Market (without financials) | B106: 23133 | C106: 1.0444083 | D106: 0.37967803 | E106: 0.12847384 | F106: =IF($F$8="Effective",C106/(1+(1-E106)*D106),C106/(1+(1-$F$9)*D106)) -> 0.81222574 | G106: 0.10397898 | H106: =F106/(1-G106) -> 0.90648067 | I106: 0.32024575 | J106: 0.31708583 | K106: 0.29141069 | L106: 0.85 | M106: 0.78 | N106: 0.87 | O106: 0.88171157 | P106: =AVERAGE(H106,L106:O106) -> 0.85763845

Sheet Promotora inmobiliaria y alquil
A1: Activo | B1: 2023
A3: A) ACTIVO NO CORRIENTE | B3: 16378314
A4: I. Inmovilizado intangible
A5: II. Inmovilizado material | B5: 57302
A6: III. Inversiones inmobiliarias | B6: 15239487
A7: IV. Inversiones en empresas del grupo y asociadas a largo plazo | B7: 1080000
A8: V. Inversiones financieras a largo plazo | B8: 1525
A9: VI. Activos por impuesto diferido
A10: B) ACTIVO CORRIENTE | B10: 4742369.6
A11: I. Activos no corrientes mantenidos para la venta
A12: II. Existencias | B12: 2343862
A13: III. Deudores y otras cuentas a cobrar | B13: 72015.72
A14: IV. Inversiones en empresas del grupo y asociadas a corto plazo
A15: V. Inversiones financieras a corto plazo | B15: 26090
A16: VI. Periodificaciones a corto plazo
A17: VII. Efectivo y otros activos líquidos equivalentes | B17: 2300401.9
A18: TOTAL ACTIVO (A + B) | B18: 21120684
A20: Patrimonio Neto y Pasivo | B20: 2023
A22: A) PATRIMONIO NETO | B22: 19520735
A23: A1) Fondos propios | B23: 17570406
A24: I. Capital | B24: 85185
A25: II. Prima de emisión | B25: 234227
A26: III. Reservas | B26: 17186274
A27: IV. Resultados de ejercicios anteriores | B27: -266659
A28: V. Resultado del ejercicio | B28: 331379.42
A29: A2) Ajustes por cambio de valor
A30: A3) Subvenciones | B30: 1950329
A31: B) PASIVO NO CORRIENTE | B31: 1208802
A32: I. Provisiones a largo plazo
A33: II. Deudas financieras a largo plazo | B33: 553069
A34: III. Deudas con empresas del grupo y asociadas a largo plazo
A35: IV. Pasivos por impuesto diferido | B35: 655733
A36: C) PASIVO CORRIENTE | B36: 395444.47
A37: I. Pasivo vinculados con activos no corrientes
A38: II. Provisiones a corto plazo
A39: III. Deudas financieras a corto plazo | B39: 216179
A40: IV. Deudas con empresas del grupo y asociadas a corto plazo
A41: V. Acreedores comerciales y otras cuentas a pagar | B41: 179265.47
A42: VI. Periodificaciones a corto plazo
A43: VII. Otros acreedores
...

Sheet Beta Promotora
A1: Ticker | B1: Company Name | C1: Global Region | D1: Industry | E1: Country | F1: Total Debt/Equity (2023) | G1: Effective Tax Rate - (Ratio) (2023) | H1: EBIT Margin % (2023) | I1: Beta (Yahoo Finance) | J1: Beta desapalancada
A2: CBOT | B2: CBo Territoria SA | C2: Europe | D2: Real Estate Management and Development | E2: FRA | F2: 1.0925 | G2: 0.2628 | H2: 0.2205 | I2: 0.37 | J2: =+I2/(1+F2*(1-G2)) -> 0.20494175
A3: FPO | B3: First Property Group plc | C3: Europe | D3: Real Estate Management and Development | E3: GBR | F3: 1.3509 | G3: 0.1113 | H3: 0.2275 | I3: 0.39 | J3: =+I3/(1+F3*(1-G3)) -> 0.17722884
A4: INP | B4: Inpro S.A. | C4: Europe | D4: Real Estate Management and Development | E4: POL | F4: 0.2843 | G4: 0.192 | H4: 0.2269 | I4: 0.37 | J4: =+I4/(1+F4*(1-G4)) -> 0.30088287
A5: PREMIA | B5: Premia S.A. | C5: Europe | D5: Real Estate Management and Development | E5: GRC | F5: 1.3121 | G5: -0.7421 | H5: 0.2206 | J5: =+I5/(1+F5*(1-G5)) -> 0 | K5: No tiene Beta en YAHOO FINANCE
A6: INR1L | B6: Special Closed-Ended Type Real Estate Investment Company INVL BALTIC REAL ESTATE | C6: Europe | D6: Real Estate Management and Development | E6: LTU | F6: 0.3644 | G6: -0.0046 | H6: 0.2261 | I6: -0.11 | J6: =+I6/(1+F6*(1-G6)) -> -0.080522592 | K6: Beta negativa descartada por dato incoherente
A7: TR61 | B7: TMM Real Estate Development Plc | C7: Europe | D7: Real Estate Management and Development | E7: DEU | F7: 0.9507 | G7: 0.5363 | H7: 0.2288 | I7: 3.44 | J7: =+I7/(1+F7*(1-G7)) -> 2.3874969 | K7: Descartada por exceso de volatilidad
I8: Mediana | J8: =+MEDIAN(J2:J4) -> 0.20494175
