Workbook

Sheet Activo
A1: ACTIVO (EN MILES) | B1: 2021 | C1: 2020 | D1: 2019
A2: ACTIVO NO CORRIENTE | B2: =B3+B9+B11+B14+B18 -> 5677400 | C2: =C3+C9+C11+C14+C18 -> 5817200 | D2: =D3+D9+D11+D14+D18 -> 5727000
A3: Inmovilizado intangible | B3: =SUM(B4:B8) -> 1241500 | C3: =SUM(C4:C8) -> 1362300 | D3: =SUM(D4:D8) -> 1537700
A4: Marcas | B4: 102800 | C4: 128400 | D4: 154000
A5: Fondo de comercio | B5: 555400 | C5: 694200 | D5: 833000
A6: Aplicaciones informáticas | B6: 900 | C6: 2300 | D6: 6000
A7: Gastos de desarrollo | B7: 524700 | C7: 459600 | D7: 393300
A8: Derechos intangibles | B8: 57700 | C8: 77800 | D8: 151400
A9: Inmovilizado material | B9: =SUM(B10) -> 6500 | C9: =SUM(C10) -> 6200 | D9: =SUM(D10) -> 6400
A10: Instalaciones técnicas y otro inmovilizado material | B10: 6500 | C10: 6200 | D10: 6400
A11: Inversiones en empresas del grupo y multigrupo a largo plazo | B11: =SUM(B12:B13) -> 3995600 | C11: =SUM(C12:C13) -> 4057500 | D11: =SUM(D12:D13) -> 3921200
A12: Instrumentos de patrimonio | B12: 3716700 | C12: 3715700 | D12: 3474900
A13: Créditos a empresas | B13: 278900 | C13: 341800 | D13: 446300
A14: Inversiones financieras a largo plazo | B14: =SUM(B15:B17) -> 86500 | C14: =SUM(C15:C17) -> 113200 | D14: =SUM(D15:D17) -> 104700
A15: Instrumentos de patrimonio | B15: 8700 | C15: 10300 | D15: 10200
A16: Derivados | B16: 1600 | C16: 21500 | D16: 3700
A17: Otros activos financieros | B17: 76200 | C17: 81400 | D17: 90800
A18: Activos por impuesto diferido | B18: 347300 | C18: 278000 | D18: 157000
A19: ACTIVO CORRIENTE | B19: =B20+B21+B27+B30+B33+B34 -> 2429600 | C19: =C20+C21+C27+C30+C33+C34 -> 2930200 | D19: =D20+D21+D27+D30+D33+D34 -> 926000
A20: Activos mantenidos para la venta | B20: 0 | C20: 3200 | D20: 0
A21: Deudores comerciales y otras cuentas a cobrar | B21: =SUM(B22:B26) -> 413100 | C21: =SUM(C22:C26) -> 230900 | D21: =SUM(D22:D26) -> 376600
A22: Clientes por ventas y prestaciones de servicios | B22: 203600 | C22: 30200 | D22: 247900
A23: Clientes, empresas grupo y multigrupo | B23: 85200 | C23: 69100 | D23: 42600
A24: Deudores varios | B24: 86500 | C24: 96500 | D24: 84100
A25: Personal | B25: 2400 | C25: 1500 | D25: 1300
A26: Otros créditos con administraciones públicas | B26: 35400 | C26: 33600 | D26: 700
A27: Inversiones en empresas del grupo y multigrupo a corto plazo | B27: =SUM(B28:B29) -> 333800 | C27: =SUM(C28:C29) -> 264300 | D27: =SUM(D28:D29) -> 121200
A28: Créditos a empresas | B28: 331800 | C28: 259700 | D28: 119100
A29: Otros activos financieros | B29: 2000 | C29: 4600 | D29: 2100
A30: Inversiones financieras a corto plazo | B30: =SUM(B31:B32) -> 697900 | C30: =SUM(C31:C32) -> 986500 | D30: =SUM(D31:D32) -> 16500
A31: Derivados | B31: 8200 | C31: 78700 | D31: 9300
A32: Otros activos financieros | B32: 689700 | C32: 907800 | D32: 7200
A33: Periodificaciones a corto plazo | B33: 19000 | C33: 13400 | D33: 11400
A34: Efectivo y otros activos líquidos equivalentes | B34: =SUM(B35:B36) -> 965800 | C34: =SUM(C35:C36) -> 1431900 | D34: =SUM(D35:D36) -> 400300
A35: Tesorería | B35: 715800 | C35: 706800 | D35: 342400
A36: Otros activos líquidos equivalentes | B36: 250000 | C36: 725100 | D36: 57900
A37: TOTAL ACTIVO | B37: =B2+B19 -> 8107000 | C37: =C2+C19 -> 8747400 | D37: =D2+D19 -> 6653000

Sheet Pasivo
A1: PASIVO (EN MILES) | B1: 2021 | C1: 2020 | D1: 2019
A2: PATRIMONIO NETO | B2: =B3+B12 -> 1556800 | C2: =C3+C12 -> 1972000 | D2: =D3+D12 -> 1347300
A3: Fondos propios | B3: =SUM(B4:B11) -> 1562300 | C3: =SUM(C4:C11) -> 1932700 | D3: =SUM(D4:D11) -> 1351600
A4: Capital | B4: 4500 | C4: 4500 | D4: 4300
A5: Prima de emisión | B5: 991300 | C5: 991300 | D5: 254500
A6: Reservas | B6: 1074900 | C6: 1071800 | D6: 670000
A7: Acciones propias | B7: -32900 | C7: -9500 | D7: -5600
A8: Resultados de ejercicios anteriores | B8: -164800 | C8: 26500 | D8: 26400
A9: Resultado del ejercicio | B9: -350100 | C9: -191300 | D9: 643400
A10: Dividendo a cuenta | B10: 0 | C10: 0 | D10: -241400
A11: Otros instrumentos de patrimonio neto | B11: 39400 | C11: 39400 | D11: 0
A12: Ajustes por cambios de valor | B12: =SUM(B13:B15) -> -5500 | C12: =SUM(C13:C15) -> 39300 | D12: =SUM(D13:D15) -> -4300
A13: Activos financieros disponibles para la venta | B13: -100 | C13: 100 | D13: 100
A14: Operaciones de cobertura | B14: -5700 | C14: 40100 | D14: -4800
A15: Diferencias de conversión | B15: 300 | C15: -900 | D15: 400
A16: PASIVO NO CORRIENTE | B16: =B17+B20+B26+B27+B28 -> 4598200 | C16: =C17+C20+C26+C27+C28 -> 4593700 | D16: =D17+D20+D26+D27+D28 -> 2509900
A17: Provisiones a largo plazo | B17: =SUM(B18:B19) -> 172300 | C17: =SUM(C18:C19) -> 150400 | D17: =SUM(D18:D19) -> 153900
A18: Obligaciones por prestaciones a largo plazo al personal | B18: 300 | C18: 300 | D18: 500
A19: Otras provisiones | B19: 172000 | C19: 150100 | D19: 153400
A20: Deudas a largo plazo | B20: =SUM(B21:B25) -> 4157400 | C20: =SUM(C21:C25) -> 4146400 | D20: =SUM(D21:D25) -> 1561800
A21: Obligaciones y otros valores negociables | B21: 3945400 | C21: 3930500 | D21: 1493900
A22: Deudas con entidades de crédito y con terceros | B22: 198900 | C22: 213500 | D22: 60700
A23: Acreedores por arrendamiento financiero | B23: 200 | C23: 500 | D23: 600
A24: Derivados | B24: 11800 | C24: 1000 | D24: 6000
A25: Otros pasivos financieros | B25: 1100 | C25: 900 | D25: 600
A26: Deudas con empresas del grupo y multigrupo a largo plazo | B26: 0 | C26: 0 | D26: 497900
A27: Pasivo por impuesto diferido | B27: 42800 | C27: 58900 | D27: 65200
A28: Periodificaciones a largo plazo | B28: 225700 | C28: 238000 | D28: 231100
A29: PASIVO CORRIENTE | B29: =B30+B31+B32+B38+B39+B45 -> 1952000 | C29: =C30+C31+C32+C38+C39+C45 -> 2181700 | D29: =D30+D31+D32+D38+D39+D45 -> 2795800
A30: Pasivos asociados a activos mantenidos para la venta | B30: 0 | C30: 700 | D30: 0
A31: Provisiones a corto plazo | B31: 600 | C31: 700 | D31: 3200
A32: Deudas a corto plazo | B32: =SUM(B33:B37) -> 599500 | C32: =SUM(C33:C37) -> 161800 | D32: =SUM(D33:D37) -> 339700
A33: Obligaciones y otros valores negociables | B33: 526400 | C33: 26400 | D33: 3400
A34: Deudas con entidades de crédito y con terceros | B34: 61100 | C34: 111500 | D34: 65900
A35: Acreedores por arrendamiento financiero | B35: 400 | C35: 500 | D35: 600
A36: Derivados | B36: 11300 | C36: 22500 | D36: 28100
A37: Otros pasivos financieros | B37: 300 | C37: 900 | D37: 241700
A38: Deudas con empresas del grupo y multigrupo a corto plazo | B38: 512900 | C38: 1411200 | D38: 1544600
A39: Acreedores comerciales y otras cuentas a pagar | B39: =SUM(B40:B44) -> 801000 | C39: =SUM(C40:C44) -> 573100 | D39: =SUM(D40:D44) -> 840500
A40: Proveedores | B40: 439200 | C40: 217700 | D40: 463300
...

Sheet PYG
A1: OPERACIONES CONTINUADAS (EN MILES) | B1: 2021 | C1: 2020 | D1: 2019
A2: Importe neto cifra de negocios | B2: =SUM(B3) -> 2014000 | C2: =C3 -> 1540500 | D2: =D3 -> 4737700
A3: Prestaciones de servicios | B3: 2014000 | C3: 1540500 | D3: 4737700
A4: Trabajos realizados por la empresa para su activo | B4: 110600 | C4: 107600 | D4: 143800
A5: Otros ingresos de explotación | B5: 0 | C5: 0 | D5: 6900
A6: Gastos de personal | B6: =SUM(B7:B8) -> -120000 | C6: =SUM(C7:C8) -> -126600 | D6: =SUM(D7:D8) -> -127400
A7: Sueldos, salarios y asimilados | B7: -89600 | C7: -95700 | D7: -94400
A8: Cargas sociales | B8: -30400 | C8: -30900 | D8: -33000
A9: Otros gastos de explotación | B9: =SUM(B10:B13) -> -2019800 | C9: =SUM(C10:C13) -> -1867000 | D9: =SUM(D10:D13) -> -4000800
A10: Servicios exteriores | B10: -81200 | C10: -56500 | D10: -68800
A11: Tributos | B11: -21400 | C11: -9900 | D11: -400
A12: Pérdidas, deterioros y variación de provisiones por operaciones comerciales | B12: 8000 | C12: -22800 | D12: -10400
A13: Otros gastos de gestión corriente | B13: -1925200 | C13: -1777800 | D13: -3921200
A14: Amortización del inmovilizado | B14: -230100 | C14: -267400 | D14: -303200
A15: Deterioro y resultado por enajenación del inmovilizado | B15: =SUM(B16:B17) -> -5000 | C15: =SUM(C16:C17) -> -17100 | D15: =SUM(D16:D17) -> -10500
A16: Deterioro y pérdidas | B16: -5000 | C16: -17000 | D16: -10500
A17: Resultados por enajenaciones y otras | B17: 0 | C17: -100 | D17: 0
A18: RESULTADO DE EXPLOTACIÓN | B18: =B2+B4+B5+B6+B9+B14+B15 -> -250300 | C18: =C2+C4+C5+C6+C9+C14+C15 -> -630000 | D18: =D2+D4+D5+D6+D9+D14+D15 -> 446500
A19: Ingresos financieros | B19: =B20+B23 -> 39700 | C19: =C20+C23 -> 416300 | D19: =D20+D23 -> 424700
A20: De participaciones en instrumentos de patrimonio | B20: =SUM(B21:B22) -> 25600 | C20: =SUM(C21:C22) -> 390300 | D20: =SUM(D21:D22) -> 378000
A21: En empresas del grupo y multigrupo | B21: 25600 | C21: 389800 | D21: 377400
A22: En terceros | B22: 0 | C22: 500 | D22: 600
A23: De valores negociables y otros instrumentos financieros | B23: =SUM(B24:B25) -> 14100 | C23: =SUM(C24:C25) -> 26000 | D23: =SUM(D24:D25) -> 46700
A24: De empresas del grupo y multigrupo | B24: 5200 | C24: 18300 | D24: 46400
A25: De terceros | B25: 8900 | C25: 7700 | D25: 300
A26: Gastos financieros | B26: =SUM(B27:B28) -> -100400 | C26: =SUM(C27:C28) -> -81000 | D26: =SUM(D27:D28) -> -43900
A27: Por deudas con empresas del grupo y multigrupo | B27: -6200 | C27: -13200 | D27: -16600
A28: Por deudas con terceros | B28: -94200 | C28: -67800 | D28: -27300
A29: Diferencias de cambio | B29: 6200 | C29: -19300 | D29: -14500
A30: Deterioro y resultado por enajenaciones de instrumentos financieros | B30: =SUM(B31:B32) -> -86300 | C30: =SUM(C31:C32) -> -23400 | D30: =SUM(D31:D32) -> -23500
A31: Deterioro y pérdidas | B31: -87400 | C31: -28200 | D31: -38500
A32: Resultado por enajenaciones y otras | B32: 1100 | C32: 4800 | D32: 15000
A33: RESULTADO FINANCIERO | B33: =B19+B26+B29+B30 -> -140800 | C33: =C19+C26+C29+C30 -> 292600 | D33: =D19+D26+D29+D30 -> 342800
A34: RESULTADO ANTES DE IMPUESTOS | B34: =B18+B33 -> -391100 | C34: =C18+C33 -> -337400 | D34: =D18+D33 -> 789300
A35: Impuesto sobre beneficios | B35: 53400 | C35: 146100 | D35: -145900
A36: RESULTADO DEL EJERCICIO | B36: =B34+B35 -> -337700 | C36: =C34+C35 -> -191300 | D36: =D34+D35 -> 643400

Sheet Balance financiero
A1: Capitales invertidos | B1: 2021 | C1: 2020 | D1: 2019 | H1: Año 2021 | I1: Valor | J1: % | K1: Coste | L1: Coste promedio
A2: Activo no corriente | B2: =SUM(B3:B5) -> 5677400 | C2: =SUM(C3:C5) -> 5817200 | D2: =SUM(D3:D5) -> 5727000 | H2: Deuda (D) | I2: ='Balance financiero'!B18+'Balance financiero'!B21 -> 5710600 | J2: =I2/$B$4 -> 1.3989368 | K2: =J6 -> #DIV/0! | L2: =+J2*K2 -> #DIV/0!
A3: Inmovilizados | B3: =Activo!B3+Activo!B9 -> 1248000 | C3: =Activo!C3+Activo!C9 -> 1368500 | D3: =Activo!D3+Activo!D9 -> 1544100 | H3: Patrimonio (E ) | I3: ='Balance financiero'!C14 -> 1972000 | J3: =I3/$B$4 -> 0.48308469 | K3: =I13 -> 0 | L3: =+J3*K3 -> 0
A4: Inversiones | B4: =Activo!B11+Activo!B14 -> 4082100 | C4: =Activo!C11+Activo!C14 -> 4170700 | D4: =Activo!D11+Activo!D14 -> 4025900 | I4: =SUM(I2:I3) -> 7682600 | J4: 1 | L4: =SUM(L2:L3) -> #DIV/0! | M4: WACC
A5: Otros | B5: =Activo!B18 -> 347300 | C5: =Activo!C18 -> 278000 | D5: =Activo!D18 -> 157000
A6: NOF | B6: =B7-B8 -> 558300 | C6: =C7-C8 -> 1070700 | D6: =D7-D8 -> -123200 | H6: Tasa bancos | I6: =I7/I2 -> 0 | J6: =I6*(1-I9) -> #DIV/0!
A7: Activo corriente operativo | B7: =Activo!B20+Activo!B21+Activo!B33+Activo!B34 -> 1397900 | C7: =Activo!C20+Activo!C21+Activo!C33+Activo!C34 -> 1679400 | D7: =Activo!D20+Activo!D21+Activo!D33+Activo!D34 -> 788300 | H7: Gasto financiero | I7: =PYG!I26*-1 -> 0
A8: Pasivo corriente operativo | B8: =Pasivo!B30+Pasivo!B31+Pasivo!B39+Pasivo!B45 -> 839600 | C8: =Pasivo!C30+Pasivo!C31+Pasivo!C39+Pasivo!C45 -> 608700 | D8: =Pasivo!D30+Pasivo!D31+Pasivo!D39+Pasivo!D45 -> 911500
A9: Inversiones financieras temporales | B9: =Activo!B27+Activo!B30 -> 1031700 | C9: =Activo!C27+Activo!C30 -> 1250800 | D9: =Activo!D27+Activo!D30 -> 137700 | H9: Tasa impuestos | I9: =I10/I11*-1 -> #DIV/0!
A10: Total | B10: =B2+B6+B9 -> 7267400 | C10: =C2+C6+C9 -> 8138700 | D10: =D2+D6+D9 -> 5741500 | H10: Gasto impuesto | I10: =PYG!I35 -> 0
H11: Resultado antes impuestos | I11: =PYG!I34 -> 0
A13: Capitales empleados | B13: 2021 | C13: 2020 | D13: 2019 | H13: Tasa accionistas | I13: =0 -> 0
A14: Patrimonio neto | B14: =SUM(B15:B17) -> 1556800 | C14: =SUM(C15:C17) -> 1972000 | D14: =SUM(D15:D17) -> 1347300 | H14: Dividendo | I14: 0
A15: Capital y reservas | B15: =Pasivo!B4+Pasivo!B5+Pasivo!B6+Pasivo!B7+Pasivo!B8+Pasivo!B10+Pasivo!B11 -> 1912400 | C15: =Pasivo!C4+Pasivo!C5+Pasivo!C6+Pasivo!C7+Pasivo!C8+Pasivo!C10+Pasivo!C11 -> 2124000 | D15: =Pasivo!D4+Pasivo!D5+Pasivo!D6+Pasivo!D7+Pasivo!D8+Pasivo!D10+Pasivo!D11 -> 708200
A16: Pérdidas y ganancias | B16: =Pasivo!B9 -> -350100 | C16: =Pasivo!C9 -> -191300 | D16: =Pasivo!D9 -> 643400
A17: Otros | B17: =Pasivo!B12 -> -5500 | C17: =Pasivo!C12 -> 39300 | D17: =Pasivo!D12 -> -4300
A18: Pasivo no corriente | B18: =SUM(B19:B20) -> 4598200 | C18: =SUM(C19:C20) -> 4593700 | D18: =SUM(D19:D20) -> 2509900
A19: Deudas a largo plazo | B19: =Pasivo!B20+Pasivo!B26 -> 4157400 | C19: =Pasivo!C20+Pasivo!C26 -> 4146400 | D19: =Pasivo!D20+Pasivo!D26 -> 2059700
A20: Otros pasivos no corrientes | B20: =Pasivo!B17+Pasivo!B27+Pasivo!B28 -> 440800 | C20: =Pasivo!C17+Pasivo!C27+Pasivo!C28 -> 447300 | D20: =Pasivo!D17+Pasivo!D27+Pasivo!D28 -> 450200
A21: Deudas a corto plazo | B21: =Pasivo!B32+Pasivo!B38 -> 1112400 | C21: =Pasivo!C32+Pasivo!C38 -> 1573000 | D21: =Pasivo!D32+Pasivo!D38 -> 1884300
A22: Total | B22: =B14+B18+B21 -> 7267400 | C22: =C14+C18+C21 -> 8138700 | D22: =D14+D18+D21 -> 5741500

Sheet WACC
A1: Año 2021 | B1: Valor | C1: % | D1: Coste | E1: Coste promedio
A2: Deuda (D) | C2: =B2/$B$4 -> 0 | D2: =C6 -> #DIV/0! | E2: =+C2*D2 -> #DIV/0!
A3: Patrimonio (E ) | B3: ='Balance financiero'!B14 -> 1556800 | C3: =B3/$B$4 -> 1 | D3: =B13 -> 0 | E3: =+C3*D3 -> 0
B4: =SUM(B2:B3) -> 1556800 | C4: 1 | E4: =SUM(E2:E3) -> #DIV/0! | F4: WACC
A6: Tasa bancos | B6: =B7/B2 -> #DIV/0! | C6: =B6*(1-B9) -> #DIV/0!
A7: Gasto financiero | B7: =PYG!B26*-1 -> 100400
A9: Tasa impuestos | B9: =B10/B11*-1 -> 0.13653797
A10: Gasto impuesto | B10: =PYG!B35 -> 53400
A11: Resultado antes impuestos | B11: =PYG!B34 -> -391100
A13: Tasa accionistas | B13: =0 -> 0
A14: Dividendo | B14: 0
A17: Año 2020 | B17: Valor | C17: % | D17: Coste | E17: Coste promedio
A18: Deuda (D) | B18: ='Balance financiero'!C18+'Balance financiero'!C21 -> 6166700 | C18: =B18/$B$20 -> 0.75770086 | D18: =C22 -> 0.0074473556 | E18: =+C18*D18 -> 0.0056428677
A19: Patrimonio (E ) | B19: ='Balance financiero'!C14 -> 1972000 | C19: =B19/$B$20 -> 0.24229914 | D19: =B29 -> 0 | E19: =+C19*D19 -> 0
B20: =SUM(B18:B19) -> 8138700 | C20: 1 | E20: =SUM(E18:E19) -> 0.0056428677 | F20: WACC
A22: Tasa bancos | B22: =B23/B18 -> 0.013135064 | C22: =B22*(1-B25) -> 0.0074473556
A23: Gasto financiero | B23: =PYG!C26*-1 -> 81000
A25: Tasa impuestos | B25: =B26/B27*-1 -> 0.43301719
A26: Gasto impuesto | B26: =PYG!C35 -> 146100
A27: Resultado antes impuestos | B27: =PYG!C34 -> -337400
A29: Tasa accionistas | B29: =B30/B19 -> 0
A30: Dividendo | B30: 0
A32: Año 2019 | B32: Valor | C32: % | D32: Coste | E32: Coste promedio
A33: Deuda (D) | B33: ='Balance financiero'!D18+'Balance financiero'!D21 -> 4394200 | C33: =B33/$B$35 -> 0.76534007 | D33: =C37 -> 0.0081437354 | E33: =+C33*D33 -> 0.006232727
A34: Patrimonio (E ) | B34: ='Balance financiero'!D14 -> 1347300 | C34: =B34/$B$35 -> 0.23465993 | D34: =B44 -> 0.41612781 | E34: =+C34*D34 -> 0.097648524
B35: =SUM(B33:B34) -> 5741500 | C35: 1 | E35: =SUM(E33:E34) -> 0.10388125 | F35: WACC
A37: Tasa bancos | B37: =B38/B33 -> 0.0099904419 | C37: =B37*(1-B40) -> 0.0081437354
A38: Gasto financiero | B38: =PYG!D26*-1 -> 43900
A40: Tasa impuestos | B40: =B41*-1/B42 -> 0.18484733
A41: Gasto impuesto | B41: =PYG!D35 -> -145900
A42: Resultado antes impuestos | B42: =PYG!D34 -> 789300
A44: Tasa accionistas | B44: =B45/B34 -> 0.41612781
A45: Dividendo | B45: 560649
